<sdf version='1.7'>
  <world name='default'>
    <physics type='ode'>
      <ode>
        <solver>
          <type>quick</type>
          <iters>50</iters>
          <sor>1.4</sor>
          <use_dynamic_moi_rescaling>0</use_dynamic_moi_rescaling>
        </solver>
        <constraints>
          <cfm>0</cfm>
          <erp>0.2</erp>
          <contact_max_correcting_vel>100</contact_max_correcting_vel>
          <contact_surface_layer>0</contact_surface_layer>
        </constraints>
      </ode>
      <real_time_update_rate>1000</real_time_update_rate>
      <max_step_size>0.001</max_step_size>
      <real_time_factor>1</real_time_factor>
    </physics>
    <light name='sun' type='directional'>
      <cast_shadows>1</cast_shadows>
      <pose>0 0 10 0 -0 0</pose>
      <diffuse>0.8 0.8 0.8 1</diffuse>
      <specular>0.2 0.2 0.2 1</specular>
      <attenuation>
        <range>1000</range>
        <constant>0.9</constant>
        <linear>0.01</linear>
        <quadratic>0.001</quadratic>
      </attenuation>
      <direction>-0.5 0.1 -0.9</direction>
      <spot>
        <inner_angle>0</inner_angle>
        <outer_angle>0</outer_angle>
        <falloff>0</falloff>
      </spot>
    </light>
    <model name='ground_plane'>
      <static>1</static>
      <link name='link'>
        <collision name='collision'>
          <geometry>
            <plane>
              <normal>0 0 1</normal>
              <size>100 100</size>
            </plane>
          </geometry>
          <surface>
            <friction>
              <ode>
                <mu>100</mu>
                <mu2>50</mu2>
              </ode>
              <torsional>
                <ode/>
              </torsional>
            </friction>
            <contact>
              <ode/>
            </contact>
            <bounce/>
          </surface>
          <max_contacts>10</max_contacts>
        </collision>
        <visual name='visual'>
          <cast_shadows>0</cast_shadows>
          <geometry>
            <plane>
              <normal>0 0 1</normal>
              <size>100 100</size>
            </plane>
          </geometry>
          <material>
            <script>
              <uri>file://media/materials/scripts/gazebo.material</uri>
              <name>Gazebo/Grey</name>
            </script>
          </material>
        </visual>
        <self_collide>0</self_collide>
        <enable_wind>0</enable_wind>
        <kinematic>0</kinematic>
      </link>
    </model>
    <gravity>0 0 -9.81</gravity>
    <magnetic_field>6e-06 2.3e-05 -4.2e-05</magnetic_field>
    <atmosphere type='adiabatic'/>
    <scene>
      <ambient>0.4 0.4 0.4 1</ambient>
      <background>0.7 0.7 0.7 1</background>
      <shadows>1</shadows>
    </scene>
    <audio>
      <device>default</device>
    </audio>
    <wind/>
    <spherical_coordinates>
      <surface_model>EARTH_WGS84</surface_model>
      <latitude_deg>0</latitude_deg>
      <longitude_deg>0</longitude_deg>
      <elevation>0</elevation>
      <heading_deg>0</heading_deg>
    </spherical_coordinates>
    <model name='tiago-pro'>
      <link name='base_footprint'>
        <inertial>
          <pose>0.00063 0.000227 0.15642 0 -0 0</pose>
          <mass>40.8677</mass>
          <inertia>
            <ixx>0.394752</ixx>
            <ixy>0.024869</ixy>
            <ixz>0.0117653</ixz>
            <iyy>0.731651</iyy>
            <iyz>-2.23541e-05</iyz>
            <izz>0.907254</izz>
          </inertia>
        </inertial>
        <collision name='base_footprint_fixed_joint_lump__base_link_collision'>
          <pose>0 0 0.26545 0 -0 0</pose>
          <geometry>
            <box>
              <size>0.717 0.497 0.0845</size>
            </box>
          </geometry>
          <surface>
            <contact>
              <ode/>
            </contact>
            <friction>
              <ode/>
              <torsional>
                <ode/>
              </torsional>
            </friction>
            <bounce/>
          </surface>
          <max_contacts>10</max_contacts>
        </collision>
        <collision name='base_footprint_fixed_joint_lump__base_link_collision_1'>
          <pose>0 0 0.2082 0 -0 0</pose>
          <geometry>
            <box>
              <size>0.58 0.39 0.03</size>
            </box>
          </geometry>
          <surface>
            <contact>
              <ode/>
            </contact>
            <friction>
              <ode/>
              <torsional>
                <ode/>
              </torsional>
            </friction>
            <bounce/>
          </surface>
          <max_contacts>10</max_contacts>
        </collision>
        <collision name='base_footprint_fixed_joint_lump__base_link_collision_2'>
          <pose>0 0 0.1097 0 -0 0</pose>
          <geometry>
            <box>
              <size>0.705 0.48 0.167</size>
            </box>
          </geometry>
          <surface>
            <contact>
              <ode/>
            </contact>
            <friction>
              <ode/>
              <torsional>
                <ode/>
              </torsional>
            </friction>
            <bounce/>
          </surface>
          <max_contacts>10</max_contacts>
        </collision>
        <collision name='base_footprint_fixed_joint_lump__base_antenna_left_link_collision_3'>
          <pose>-0.2015 0.13 0.2927 0 -0 0</pose>
          <geometry>
            <mesh>
              <scale>1 -1 1</scale>
              <uri>model://omni_base_description/meshes/base/base_antena_link.stl</uri>
            </mesh>
          </geometry>
          <surface>
            <contact>
              <ode/>
            </contact>
            <friction>
              <ode/>
              <torsional>
                <ode/>
              </torsional>
            </friction>
            <bounce/>
          </surface>
          <max_contacts>10</max_contacts>
        </collision>
        <collision name='base_footprint_fixed_joint_lump__base_antenna_right_link_collision_4'>
          <pose>-0.2015 -0.13 0.2927 0 -0 0</pose>
          <geometry>
            <mesh>
              <scale>1 1 1</scale>
              <uri>model://omni_base_description/meshes/base/base_antena_link.stl</uri>
            </mesh>
          </geometry>
          <surface>
            <contact>
              <ode/>
            </contact>
            <friction>
              <ode/>
              <torsional>
                <ode/>
              </torsional>
            </friction>
            <bounce/>
          </surface>
          <max_contacts>10</max_contacts>
        </collision>
        <collision name='base_footprint_fixed_joint_lump__base_dock_link_collision_5'>
          <pose>0.3535 0 0.1358 0 -0 0</pose>
          <geometry>
            <mesh>
              <scale>1 1 1</scale>
              <uri>model://omni_base_description/meshes/base/base_dock_link.stl</uri>
            </mesh>
          </geometry>
          <max_contacts>10</max_contacts>
          <surface>
            <contact>
              <ode/>
            </contact>
            <bounce/>
            <friction>
              <torsional>
                <ode/>
              </torsional>
              <ode/>
            </friction>
          </surface>
        </collision>
        <collision name='base_footprint_fixed_joint_lump__base_front_laser_link_collision_6'>
          <pose>0.27512 -0.18297 0.20864 -3.14159 -0 -0.785398</pose>
          <geometry>
            <cylinder>
              <length>0.01</length>
              <radius>0.01</radius>
            </cylinder>
          </geometry>
          <surface>
            <contact>
              <ode/>
            </contact>
            <friction>
              <ode/>
              <torsional>
                <ode/>
              </torsional>
            </friction>
            <bounce/>
          </surface>
          <max_contacts>10</max_contacts>
        </collision>
        <collision name='base_footprint_fixed_joint_lump__base_rear_laser_link_collision_7'>
          <pose>-0.27512 0.18297 0.20864 -3.14159 -0 2.35619</pose>
          <geometry>
            <cylinder>
              <length>0.01</length>
              <radius>0.01</radius>
            </cylinder>
          </geometry>
          <surface>
            <contact>
              <ode/>
            </contact>
            <friction>
              <ode/>
              <torsional>
                <ode/>
              </torsional>
            </friction>
            <bounce/>
          </surface>
          <max_contacts>10</max_contacts>
        </collision>
        <collision name='base_footprint_fixed_joint_lump__suspension_front_left_link_collision_8'>
          <pose>0.244 0.1725 0.0762 0 -0 1.5708</pose>
          <geometry>
            <mesh>
              <scale>1 -1 1</scale>
              <uri>model://omni_base_description/meshes/wheels/suspension_front_link.stl</uri>
            </mesh>
          </geometry>
          <max_contacts>10</max_contacts>
          <surface>
            <contact>
              <ode/>
            </contact>
            <bounce/>
            <friction>
              <torsional>
                <ode/>
              </torsional>
              <ode/>
            </friction>
          </surface>
        </collision>
        <collision name='base_footprint_fixed_joint_lump__suspension_front_right_link_collision_9'>
          <pose>0.244 -0.1725 0.0762 0 0 -1.5708</pose>
          <geometry>
            <mesh>
              <scale>1 1 1</scale>
              <uri>model://omni_base_description/meshes/wheels/suspension_front_link.stl</uri>
            </mesh>
          </geometry>
          <max_contacts>10</max_contacts>
          <surface>
            <contact>
              <ode/>
            </contact>
            <bounce/>
            <friction>
              <torsional>
                <ode/>
              </torsional>
              <ode/>
            </friction>
          </surface>
        </collision>
        <collision name='base_footprint_fixed_joint_lump__suspension_rear_left_link_collision_10'>
          <pose>-0.244 0.1725 0.0762 0 -0 1.5708</pose>
          <geometry>
            <mesh>
              <scale>1 -1 1</scale>
              <uri>model://omni_base_description/meshes/wheels/suspension_rear_link.stl</uri>
            </mesh>
          </geometry>
          <max_contacts>10</max_contacts>
          <surface>
            <contact>
              <ode/>
            </contact>
            <bounce/>
            <friction>
              <torsional>
                <ode/>
              </torsional>
              <ode/>
            </friction>
          </surface>
        </collision>
        <collision name='base_footprint_fixed_joint_lump__suspension_rear_right_link_collision_11'>
          <pose>-0.244 -0.1725 0.0762 0 0 -1.5708</pose>
          <geometry>
            <mesh>
              <scale>1 1 1</scale>
              <uri>model://omni_base_description/meshes/wheels/suspension_rear_link.stl</uri>
            </mesh>
          </geometry>
          <max_contacts>10</max_contacts>
          <surface>
            <contact>
              <ode/>
            </contact>
            <bounce/>
            <friction>
              <torsional>
                <ode/>
              </torsional>
              <ode/>
            </friction>
          </surface>
        </collision>
        <collision name='base_footprint_fixed_joint_lump__torso_fixed_column_link_collision_12'>
          <pose>-0.028 0 0.5562 0 -0 0</pose>
          <geometry>
            <box>
              <size>0.23 0.253 0.45</size>
            </box>
          </geometry>
          <surface>
            <contact>
              <ode/>
            </contact>
            <friction>
              <ode/>
              <torsional>
                <ode/>
              </torsional>
            </friction>
            <bounce/>
          </surface>
          <max_contacts>10</max_contacts>
        </collision>
        <collision name='base_footprint_fixed_joint_lump__torso_base_link_collision_13'>
          <pose>-0.0245 0 0.2912 0 -0 0</pose>
          <geometry>
            <mesh>
              <scale>1 1 1</scale>
              <uri>model://tiago_pro_description/meshes/torso/base_link_collision.stl</uri>
            </mesh>
          </geometry>
          <surface>
            <contact>
              <ode/>
            </contact>
            <friction>
              <ode/>
              <torsional>
                <ode/>
              </torsional>
            </friction>
            <bounce/>
          </surface>
          <max_contacts>10</max_contacts>
        </collision>
        <visual name='base_footprint_fixed_joint_lump__base_link_visual'>
          <pose>0 0 0.0762 0 -0 0</pose>
          <geometry>
            <mesh>
              <scale>1 1 1</scale>
              <uri>model://omni_base_description/meshes/base/base_link.stl</uri>
            </mesh>
          </geometry>
          <material>
            <script>
              <name>Gazebo/White</name>
              <uri>file://media/materials/scripts/gazebo.material</uri>
            </script>
          </material>
        </visual>
        <visual name='base_footprint_fixed_joint_lump__base_antenna_left_link_visual_1'>
          <pose>-0.2015 0.13 0.2927 0 -0 0</pose>
          <geometry>
            <mesh>
              <scale>1 -1 1</scale>
              <uri>model://omni_base_description/meshes/base/base_antena_link.stl</uri>
            </mesh>
          </geometry>
          <material>
            <script>
              <name>Gazebo/Black</name>
              <uri>file://media/materials/scripts/gazebo.material</uri>
            </script>
          </material>
        </visual>
        <visual name='base_footprint_fixed_joint_lump__base_antenna_right_link_visual_2'>
          <pose>-0.2015 -0.13 0.2927 0 -0 0</pose>
          <geometry>
            <mesh>
              <scale>1 1 1</scale>
              <uri>model://omni_base_description/meshes/base/base_antena_link.stl</uri>
            </mesh>
          </geometry>
          <material>
            <script>
              <name>Gazebo/Black</name>
              <uri>file://media/materials/scripts/gazebo.material</uri>
            </script>
          </material>
        </visual>
        <visual name='base_footprint_fixed_joint_lump__base_dock_link_visual_3'>
          <pose>0.3535 0 0.1358 0 -0 0</pose>
          <geometry>
            <mesh>
              <scale>1 1 1</scale>
              <uri>model://omni_base_description/meshes/base/base_dock_link.stl</uri>
            </mesh>
          </geometry>
        </visual>
        <visual name='base_footprint_fixed_joint_lump__base_front_laser_link_visual_4'>
          <pose>0.27512 -0.18297 0.20864 -3.14159 -0 -0.785398</pose>
          <geometry>
            <mesh>
              <scale>1 1 1</scale>
              <uri>model://omni_base_description/meshes/sensors/sick_tim551.stl</uri>
            </mesh>
          </geometry>
          <material>
            <script>
              <name>Gazebo/DarkGrey</name>
              <uri>file://media/materials/scripts/gazebo.material</uri>
            </script>
          </material>
        </visual>
        <visual name='base_footprint_fixed_joint_lump__base_rear_laser_link_visual_5'>
          <pose>-0.27512 0.18297 0.20864 -3.14159 -0 2.35619</pose>
          <geometry>
            <mesh>
              <scale>1 1 1</scale>
              <uri>model://omni_base_description/meshes/sensors/sick_tim551.stl</uri>
            </mesh>
          </geometry>
          <material>
            <script>
              <name>Gazebo/DarkGrey</name>
              <uri>file://media/materials/scripts/gazebo.material</uri>
            </script>
          </material>
        </visual>
        <visual name='base_footprint_fixed_joint_lump__suspension_front_left_link_visual_6'>
          <pose>0.244 0.1725 0.0762 0 -0 1.5708</pose>
          <geometry>
            <mesh>
              <scale>1 -1 1</scale>
              <uri>model://omni_base_description/meshes/wheels/suspension_front_link.stl</uri>
            </mesh>
          </geometry>
        </visual>
        <visual name='base_footprint_fixed_joint_lump__suspension_front_right_link_visual_7'>
          <pose>0.244 -0.1725 0.0762 0 0 -1.5708</pose>
          <geometry>
            <mesh>
              <scale>1 1 1</scale>
              <uri>model://omni_base_description/meshes/wheels/suspension_front_link.stl</uri>
            </mesh>
          </geometry>
        </visual>
        <visual name='base_footprint_fixed_joint_lump__suspension_rear_left_link_visual_8'>
          <pose>-0.244 0.1725 0.0762 0 -0 1.5708</pose>
          <geometry>
            <mesh>
              <scale>1 -1 1</scale>
              <uri>model://omni_base_description/meshes/wheels/suspension_rear_link.stl</uri>
            </mesh>
          </geometry>
        </visual>
        <visual name='base_footprint_fixed_joint_lump__suspension_rear_right_link_visual_9'>
          <pose>-0.244 -0.1725 0.0762 0 0 -1.5708</pose>
          <geometry>
            <mesh>
              <scale>1 1 1</scale>
              <uri>model://omni_base_description/meshes/wheels/suspension_rear_link.stl</uri>
            </mesh>
          </geometry>
        </visual>
        <visual name='base_footprint_fixed_joint_lump__torso_fixed_column_link_visual_10'>
          <pose>-0.028 0 0.5562 0 -0 0</pose>
          <geometry>
            <box>
              <size>0.18 0.2 0.55</size>
            </box>
          </geometry>
          <material>
            <script>
              <name>Gazebo/DarkGrey</name>
              <uri>file://media/materials/scripts/gazebo.material</uri>
            </script>
          </material>
        </visual>
        <visual name='base_footprint_fixed_joint_lump__torso_base_link_visual_11'>
          <pose>-0.0245 0 0.2912 0 -0 0</pose>
          <geometry>
            <mesh>
              <scale>1 1 1</scale>
              <uri>model://tiago_pro_description/meshes/torso/base_link.stl</uri>
            </mesh>
          </geometry>
          <material>
            <script>
              <name>Gazebo/DarkGrey</name>
              <uri>file://media/materials/scripts/gazebo.material</uri>
            </script>
          </material>
        </visual>
        <sensor name='base_front_laser' type='gpu_ray'>
          <update_rate>10</update_rate>
          <visualize>1</visualize>
          <ray>
            <scan>
              <horizontal>
                <samples>818</samples>
                <resolution>1</resolution>
                <min_angle>-2.35619</min_angle>
                <max_angle>2.35619</max_angle>
              </horizontal>
              <vertical>
                <samples>1</samples>
                <min_angle>0</min_angle>
                <max_angle>0</max_angle>
              </vertical>
            </scan>
            <range>
              <min>0.05</min>
              <max>25</max>
              <resolution>0.001</resolution>
            </range>
            <noise>
              <type>gaussian</type>
              <mean>0</mean>
              <stddev>0.01</stddev>
            </noise>
          </ray>
          <plugin name='base_front_laser' filename='libgazebo_ros_ray_sensor.so'>
            <ros>
              <remapping>~/out:=scan_front_raw</remapping>
            </ros>
            <output_type>sensor_msgs/LaserScan</output_type>
            <frame_name>base_front_laser_link</frame_name>
          </plugin>
          <pose>0.27512 -0.18297 0.20864 -3.14159 -0 -0.785398</pose>
        </sensor>
        <sensor name='base_imu_sensor' type='imu'>
          <always_on>1</always_on>
          <update_rate>100</update_rate>
          <imu>
            <noise>
              <type>gaussian</type>
              <rate>
                <mean>0.0</mean>
                <stddev>2e-4</stddev>
                <bias_mean>0.0000075</bias_mean>
                <bias_stddev>0.0000008</bias_stddev>
              </rate>
              <accel>
                <mean>0.0</mean>
                <stddev>1.7e-2</stddev>
                <bias_mean>0.1</bias_mean>
                <bias_stddev>0.001</bias_stddev>
              </accel>
            </noise>
          </imu>
          <plugin name='base_imu' filename='libgazebo_ros_imu_sensor.so'>
            <ros>
              <remapping>~/out:=base_imu</remapping>
            </ros>
          </plugin>
          <pose>-0.287 0 0.168363 0 -0 1.5708</pose>
        </sensor>
        <sensor name='base_rear_laser' type='gpu_ray'>
          <update_rate>10</update_rate>
          <visualize>1</visualize>
          <ray>
            <scan>
              <horizontal>
                <samples>818</samples>
                <resolution>1</resolution>
                <min_angle>-2.35619</min_angle>
                <max_angle>2.35619</max_angle>
              </horizontal>
              <vertical>
                <samples>1</samples>
                <min_angle>0</min_angle>
                <max_angle>0</max_angle>
              </vertical>
            </scan>
            <range>
              <min>0.05</min>
              <max>25</max>
              <resolution>0.001</resolution>
            </range>
            <noise>
              <type>gaussian</type>
              <mean>0</mean>
              <stddev>0.01</stddev>
            </noise>
          </ray>
          <plugin name='base_rear_laser' filename='libgazebo_ros_ray_sensor.so'>
            <ros>
              <remapping>~/out:=scan_rear_raw</remapping>
            </ros>
            <output_type>sensor_msgs/LaserScan</output_type>
            <frame_name>base_rear_laser_link</frame_name>
          </plugin>
          <pose>-0.27512 0.18297 0.20864 -3.14159 -0 2.35619</pose>
        </sensor>
        <self_collide>0</self_collide>
        <enable_wind>0</enable_wind>
        <kinematic>0</kinematic>
      </link>
      <joint name='wheel_front_left_joint' type='revolute'>
        <pose relative_to='base_footprint'>0.244 0.223175 0.0762 -1.5708 0 0</pose>
        <parent>base_footprint</parent>
        <child>wheel_front_left_link</child>
        <axis>
          <xyz>0 0 1</xyz>
          <limit>
            <effort>6</effort>
            <velocity>13.1234</velocity>
            <lower>-1e+16</lower>
            <upper>1e+16</upper>
          </limit>
          <dynamics>
            <damping>1</damping>
            <friction>2</friction>
            <spring_reference>0</spring_reference>
            <spring_stiffness>0</spring_stiffness>
          </dynamics>
        </axis>
      </joint>
      <link name='wheel_front_left_link'>
        <pose relative_to='wheel_front_left_joint'>0 0 0 0 -0 0</pose>
        <inertial>
          <pose>0 -7e-05 -0.011144 0 -0 0</pose>
          <mass>0.70767</mass>
          <inertia>
            <ixx>0.00035492</ixx>
            <ixy>7.5685e-13</ixy>
            <ixz>3.8795e-11</ixz>
            <iyy>0.00035529</iyy>
            <iyz>-2.0284e-07</iyz>
            <izz>0.00040131</izz>
          </inertia>
        </inertial>
        <collision name='wheel_front_left_link_collision'>
          <pose>0 0 0 0 -0 0</pose>
          <geometry>
            <cylinder>
              <length>0.05</length>
              <radius>0.0762</radius>
            </cylinder>
          </geometry>
          <surface>
            <contact>
              <ode>
                <kp>1e+06</kp>
                <kd>1000</kd>
                <max_vel>1</max_vel>
                <min_depth>0</min_depth>
              </ode>
            </contact>
            <friction>
              <ode>
                <mu>0</mu>
                <mu2>0</mu2>
                <fdir1>1 0 0</fdir1>
              </ode>
              <torsional>
                <ode/>
              </torsional>
            </friction>
            <bounce/>
          </surface>
          <max_contacts>10</max_contacts>
        </collision>
        <visual name='wheel_front_left_link_visual'>
          <pose>0 0 0 0 -0 0</pose>
          <geometry>
            <mesh>
              <scale>1 1 -1</scale>
              <uri>model://omni_base_description/meshes/wheels/wheel_link.stl</uri>
            </mesh>
          </geometry>
          <material>
            <script>
              <name>Gazebo/Grey</name>
              <uri>file://media/materials/scripts/gazebo.material</uri>
            </script>
          </material>
        </visual>
        <self_collide>0</self_collide>
        <enable_wind>0</enable_wind>
        <kinematic>0</kinematic>
      </link>
      <joint name='wheel_front_right_joint' type='revolute'>
        <pose relative_to='base_footprint'>0.244 -0.223175 0.0762 -1.5708 0 0</pose>
        <parent>base_footprint</parent>
        <child>wheel_front_right_link</child>
        <axis>
          <xyz>0 0 1</xyz>
          <limit>
            <effort>6</effort>
            <velocity>13.1234</velocity>
            <lower>-1e+16</lower>
            <upper>1e+16</upper>
          </limit>
          <dynamics>
            <damping>1</damping>
            <friction>2</friction>
            <spring_reference>0</spring_reference>
            <spring_stiffness>0</spring_stiffness>
          </dynamics>
        </axis>
      </joint>
      <link name='wheel_front_right_link'>
        <pose relative_to='wheel_front_right_joint'>0 0 0 0 -0 0</pose>
        <inertial>
          <pose>0 7e-05 0.011144 0 -0 0</pose>
          <mass>0.70767</mass>
          <inertia>
            <ixx>0.00035492</ixx>
            <ixy>7.5685e-13</ixy>
            <ixz>3.8795e-11</ixz>
            <iyy>0.00035529</iyy>
            <iyz>-2.0284e-07</iyz>
            <izz>0.00040131</izz>
          </inertia>
        </inertial>
        <collision name='wheel_front_right_link_collision'>
          <pose>0 0 0 0 -0 0</pose>
          <geometry>
            <cylinder>
              <length>0.05</length>
              <radius>0.0762</radius>
            </cylinder>
          </geometry>
          <surface>
            <contact>
              <ode>
                <kp>1e+06</kp>
                <kd>1000</kd>
                <max_vel>1</max_vel>
                <min_depth>0</min_depth>
              </ode>
            </contact>
            <friction>
              <ode>
                <mu>0</mu>
                <mu2>0</mu2>
                <fdir1>1 0 0</fdir1>
              </ode>
              <torsional>
                <ode/>
              </torsional>
            </friction>
            <bounce/>
          </surface>
          <max_contacts>10</max_contacts>
        </collision>
        <visual name='wheel_front_right_link_visual'>
          <pose>0 0 0 0 -0 0</pose>
          <geometry>
            <mesh>
              <scale>1 1 1</scale>
              <uri>model://omni_base_description/meshes/wheels/wheel_link.stl</uri>
            </mesh>
          </geometry>
          <material>
            <script>
              <name>Gazebo/Grey</name>
              <uri>file://media/materials/scripts/gazebo.material</uri>
            </script>
          </material>
        </visual>
        <self_collide>0</self_collide>
        <enable_wind>0</enable_wind>
        <kinematic>0</kinematic>
      </link>
      <joint name='wheel_rear_left_joint' type='revolute'>
        <pose relative_to='base_footprint'>-0.244 0.223175 0.0762 -1.5708 0 0</pose>
        <parent>base_footprint</parent>
        <child>wheel_rear_left_link</child>
        <axis>
          <xyz>0 0 1</xyz>
          <limit>
            <effort>6</effort>
            <velocity>13.1234</velocity>
            <lower>-1e+16</lower>
            <upper>1e+16</upper>
          </limit>
          <dynamics>
            <damping>1</damping>
            <friction>2</friction>
            <spring_reference>0</spring_reference>
            <spring_stiffness>0</spring_stiffness>
          </dynamics>
        </axis>
      </joint>
      <link name='wheel_rear_left_link'>
        <pose relative_to='wheel_rear_left_joint'>0 0 0 0 -0 0</pose>
        <inertial>
          <pose>-0 7e-05 -0.011144 0 -0 0</pose>
          <mass>0.70767</mass>
          <inertia>
            <ixx>0.00035492</ixx>
            <ixy>-7.5685e-13</ixy>
            <ixz>3.8795e-11</ixz>
            <iyy>0.00035529</iyy>
            <iyz>2.0284e-07</iyz>
            <izz>0.00040131</izz>
          </inertia>
        </inertial>
        <collision name='wheel_rear_left_link_collision'>
          <pose>0 0 0 0 -0 0</pose>
          <geometry>
            <cylinder>
              <length>0.05</length>
              <radius>0.0762</radius>
            </cylinder>
          </geometry>
          <surface>
            <contact>
              <ode>
                <kp>1e+06</kp>
                <kd>1000</kd>
                <max_vel>1</max_vel>
                <min_depth>0</min_depth>
              </ode>
            </contact>
            <friction>
              <ode>
                <mu>0</mu>
                <mu2>0</mu2>
                <fdir1>1 0 0</fdir1>
              </ode>
              <torsional>
                <ode/>
              </torsional>
            </friction>
            <bounce/>
          </surface>
          <max_contacts>10</max_contacts>
        </collision>
        <visual name='wheel_rear_left_link_visual'>
          <pose>0 0 0 0 -0 0</pose>
          <geometry>
            <mesh>
              <scale>1 1 -1</scale>
              <uri>model://omni_base_description/meshes/wheels/wheel_link.stl</uri>
            </mesh>
          </geometry>
          <material>
            <script>
              <name>Gazebo/Grey</name>
              <uri>file://media/materials/scripts/gazebo.material</uri>
            </script>
          </material>
        </visual>
        <self_collide>0</self_collide>
        <enable_wind>0</enable_wind>
        <kinematic>0</kinematic>
      </link>
      <joint name='wheel_rear_right_joint' type='revolute'>
        <pose relative_to='base_footprint'>-0.244 -0.223175 0.0762 -1.5708 0 0</pose>
        <parent>base_footprint</parent>
        <child>wheel_rear_right_link</child>
        <axis>
          <xyz>0 0 1</xyz>
          <limit>
            <effort>6</effort>
            <velocity>13.1234</velocity>
            <lower>-1e+16</lower>
            <upper>1e+16</upper>
          </limit>
          <dynamics>
            <damping>1</damping>
            <friction>2</friction>
            <spring_reference>0</spring_reference>
            <spring_stiffness>0</spring_stiffness>
          </dynamics>
        </axis>
      </joint>
      <link name='wheel_rear_right_link'>
        <pose relative_to='wheel_rear_right_joint'>0 0 0 0 -0 0</pose>
        <inertial>
          <pose>-0 -7e-05 0.011144 0 -0 0</pose>
          <mass>0.70767</mass>
          <inertia>
            <ixx>0.00035492</ixx>
            <ixy>-7.5685e-13</ixy>
            <ixz>3.8795e-11</ixz>
            <iyy>0.00035529</iyy>
            <iyz>2.0284e-07</iyz>
            <izz>0.00040131</izz>
          </inertia>
        </inertial>
        <collision name='wheel_rear_right_link_collision'>
          <pose>0 0 0 0 -0 0</pose>
          <geometry>
            <cylinder>
              <length>0.05</length>
              <radius>0.0762</radius>
            </cylinder>
          </geometry>
          <surface>
            <contact>
              <ode>
                <kp>1e+06</kp>
                <kd>1000</kd>
                <max_vel>1</max_vel>
                <min_depth>0</min_depth>
              </ode>
            </contact>
            <friction>
              <ode>
                <mu>0</mu>
                <mu2>0</mu2>
                <fdir1>1 0 0</fdir1>
              </ode>
              <torsional>
                <ode/>
              </torsional>
            </friction>
            <bounce/>
          </surface>
          <max_contacts>10</max_contacts>
        </collision>
        <visual name='wheel_rear_right_link_visual'>
          <pose>0 0 0 0 -0 0</pose>
          <geometry>
            <mesh>
              <scale>1 1 1</scale>
              <uri>model://omni_base_description/meshes/wheels/wheel_link.stl</uri>
            </mesh>
          </geometry>
          <material>
            <script>
              <name>Gazebo/Grey</name>
              <uri>file://media/materials/scripts/gazebo.material</uri>
            </script>
          </material>
        </visual>
        <self_collide>0</self_collide>
        <enable_wind>0</enable_wind>
        <kinematic>0</kinematic>
      </link>
      <joint name='torso_lift_joint' type='prismatic'>
        <pose relative_to='base_footprint'>-0.0245 0 0.8457 0 -0 0</pose>
        <parent>base_footprint</parent>
        <child>torso_lift_link</child>
        <axis>
          <xyz>0 0 1</xyz>
          <limit>
            <lower>0</lower>
            <upper>0.35</upper>
            <effort>2000</effort>
            <velocity>0.035</velocity>
          </limit>
          <dynamics>
            <damping>1000</damping>
            <friction>0</friction>
            <spring_reference>0</spring_reference>
            <spring_stiffness>0</spring_stiffness>
          </dynamics>
        </axis>
        <physics>
          <ode>
            <implicit_spring_damper>1</implicit_spring_damper>
            <cfm_damping>1</cfm_damping>
            <limit>
              <cfm>0</cfm>
              <erp>0.2</erp>
            </limit>
          </ode>
        </physics>
      </joint>
      <link name='torso_lift_link'>
        <pose relative_to='torso_lift_joint'>0 0 0 0 -0 0</pose>
        <inertial>
          <pose>0 -0 0.001812 0 -0 0</pose>
          <mass>3.43808</mass>
          <inertia>
            <ixx>0.0301635</ixx>
            <ixy>-7.85102e-07</ixy>
            <ixz>-8.58577e-05</ixz>
            <iyy>0.0177848</iyy>
            <iyz>-8.17944e-06</iyz>
            <izz>0.0298875</izz>
          </inertia>
        </inertial>
        <collision name='torso_lift_link_collision'>
          <pose>0 0 0 0 -0 0</pose>
          <geometry>
            <mesh>
              <scale>1 1 1</scale>
              <uri>model://tiago_pro_description/meshes/torso/torso_lift_link_collision.stl</uri>
            </mesh>
          </geometry>
          <max_contacts>10</max_contacts>
          <surface>
            <contact>
              <ode/>
            </contact>
            <bounce/>
            <friction>
              <torsional>
                <ode/>
              </torsional>
              <ode/>
            </friction>
          </surface>
        </collision>
        <collision name='torso_lift_link_collision_1'>
          <pose>-0.226436 3.1e-05 0.00524 0 0 -1.5708</pose>
          <geometry>
            <mesh>
              <scale>1 1 1</scale>
              <uri>model://tiago_pro_description/meshes/torso/laptop_tray_collision.stl</uri>
            </mesh>
          </geometry>
          <max_contacts>10</max_contacts>
          <surface>
            <contact>
              <ode/>
            </contact>
            <bounce/>
            <friction>
              <torsional>
                <ode/>
              </torsional>
              <ode/>
            </friction>
          </surface>
        </collision>
        <collision name='torso_lift_link_fixed_joint_lump__torso_head_link_collision_2'>
          <pose>0 0 0.05085 0 -0 0</pose>
          <geometry>
            <box>
              <size>0.11 0.092 0.0217</size>
            </box>
          </geometry>
          <max_contacts>10</max_contacts>
          <surface>
            <contact>
              <ode/>
            </contact>
            <bounce/>
            <friction>
              <torsional>
                <ode/>
              </torsional>
              <ode/>
            </friction>
          </surface>
        </collision>
        <visual name='torso_lift_link_visual'>
          <pose>0 0 0 0 -0 0</pose>
          <geometry>
            <mesh>
              <scale>1 1 1</scale>
              <uri>model://tiago_pro_description/meshes/torso/torso_lift_link.stl</uri>
            </mesh>
          </geometry>
        </visual>
        <visual name='torso_lift_link_fixed_joint_lump__torso_head_link_visual_1'>
          <pose>0 0 0.05085 0 -0 0</pose>
          <geometry>
            <box>
              <size>0.11 0.092 0.0217</size>
            </box>
          </geometry>
        </visual>
        <self_collide>0</self_collide>
        <enable_wind>0</enable_wind>
        <kinematic>0</kinematic>
      </link>
      <joint name='arm_left_1_joint' type='revolute'>
        <pose relative_to='torso_lift_link'>0.08976 0.15918 -0.092008 -2.0679 0 -1.2217</pose>
        <parent>torso_lift_link</parent>
        <child>arm_left_1_link</child>
        <axis>
          <xyz>0 0 1</xyz>
          <limit>
            <lower>-0.523599</lower>
            <upper>4.71239</upper>
            <effort>43</effort>
            <velocity>2.5</velocity>
          </limit>
          <dynamics>
            <damping>1</damping>
            <friction>1</friction>
            <spring_reference>0</spring_reference>
            <spring_stiffness>0</spring_stiffness>
          </dynamics>
        </axis>
        <physics>
          <ode>
            <implicit_spring_damper>1</implicit_spring_damper>
            <cfm_damping>1</cfm_damping>
            <limit>
              <cfm>0</cfm>
              <erp>0.2</erp>
            </limit>
          </ode>
        </physics>
      </joint>
      <link name='arm_left_1_link'>
        <pose relative_to='arm_left_1_joint'>0 0 0 0 -0 0</pose>
        <inertial>
          <pose>0.004392 0.016184 0.15576 0 -0 0</pose>
          <mass>1.1325</mass>
          <inertia>
            <ixx>0.0025497</ixx>
            <ixy>2.6206e-05</ixy>
            <ixz>6.2082e-05</ixz>
            <iyy>0.0023517</iyy>
            <iyz>-0.00020617</iyz>
            <izz>0.00097131</izz>
          </inertia>
        </inertial>
        <collision name='arm_left_1_link_collision'>
          <pose>0 0 0 0 -0 0</pose>
          <geometry>
            <mesh>
              <scale>1 1 1</scale>
              <uri>model://pal_sea_arm_description/meshes/arm_tiago_pro/arm_1_link_collision.stl</uri>
            </mesh>
          </geometry>
          <surface>
            <contact>
              <ode/>
            </contact>
            <friction>
              <ode>
                <mu>0.9</mu>
                <mu2>0.9</mu2>
              </ode>
              <torsional>
                <ode/>
              </torsional>
            </friction>
            <bounce/>
          </surface>
          <max_contacts>10</max_contacts>
        </collision>
        <visual name='arm_left_1_link_visual'>
          <pose>0 0 0 0 -0 0</pose>
          <geometry>
            <mesh>
              <scale>1 1 1</scale>
              <uri>model://pal_sea_arm_description/meshes/arm_tiago_pro/arm_1_link.stl</uri>
            </mesh>
          </geometry>
          <material>
            <script>
              <name>Gazebo/DarkGrey</name>
              <uri>file://media/materials/scripts/gazebo.material</uri>
            </script>
          </material>
        </visual>
        <self_collide>0</self_collide>
        <enable_wind>0</enable_wind>
        <kinematic>0</kinematic>
      </link>
      <joint name='arm_left_2_joint' type='revolute'>
        <pose relative_to='arm_left_1_link'>0.03711 0.02 0.18 -1.5708 -0 -1.5708</pose>
        <parent>arm_left_1_link</parent>
        <child>arm_left_2_link</child>
        <axis>
          <xyz>0 0 1</xyz>
          <limit>
            <lower>-2.44346</lower>
            <upper>1.13446</upper>
            <effort>43</effort>
            <velocity>2.5</velocity>
          </limit>
          <dynamics>
            <damping>1</damping>
            <friction>1</friction>
            <spring_reference>0</spring_reference>
            <spring_stiffness>0</spring_stiffness>
          </dynamics>
        </axis>
        <physics>
          <ode>
            <implicit_spring_damper>1</implicit_spring_damper>
            <cfm_damping>1</cfm_damping>
            <limit>
              <cfm>0</cfm>
              <erp>0.2</erp>
            </limit>
          </ode>
        </physics>
      </joint>
      <link name='arm_left_2_link'>
        <pose relative_to='arm_left_2_joint'>0 0 0 0 -0 0</pose>
        <inertial>
          <pose>0.01786 -0.11956 -0.032097 0 -0 0</pose>
          <mass>1.0436</mass>
          <inertia>
            <ixx>0.0015021</ixx>
            <ixy>0.00011264</ixy>
            <ixz>1.0692e-05</ixz>
            <iyy>0.00088017</iyy>
            <iyz>-0.00015843</iyz>
            <izz>0.0016021</izz>
          </inertia>
        </inertial>
        <collision name='arm_left_2_link_collision'>
          <pose>0 0 0 0 -0 0</pose>
          <geometry>
            <mesh>
              <scale>1 1 1</scale>
              <uri>model://pal_sea_arm_description/meshes/arm_tiago_pro/arm_2_link_collision.stl</uri>
            </mesh>
          </geometry>
          <surface>
            <contact>
              <ode/>
            </contact>
            <friction>
              <ode>
                <mu>0.9</mu>
                <mu2>0.9</mu2>
              </ode>
              <torsional>
                <ode/>
              </torsional>
            </friction>
            <bounce/>
          </surface>
          <max_contacts>10</max_contacts>
        </collision>
        <visual name='arm_left_2_link_visual'>
          <pose>0 0 0 0 -0 0</pose>
          <geometry>
            <mesh>
              <scale>1 1 1</scale>
              <uri>model://pal_sea_arm_description/meshes/arm_tiago_pro/arm_2_link.stl</uri>
            </mesh>
          </geometry>
          <material>
            <script>
              <name>Gazebo/DarkGrey</name>
              <uri>file://media/materials/scripts/gazebo.material</uri>
            </script>
          </material>
        </visual>
        <self_collide>0</self_collide>
        <enable_wind>0</enable_wind>
        <kinematic>0</kinematic>
      </link>
      <joint name='arm_left_3_joint' type='revolute'>
        <pose relative_to='arm_left_2_link'>0.02 -0.17011 -0.03711 1.5708 -0 0</pose>
        <parent>arm_left_2_link</parent>
        <child>arm_left_3_link</child>
        <axis>
          <xyz>0 0 1</xyz>
          <limit>
            <lower>-2.61799</lower>
            <upper>2.61799</upper>
            <effort>26</effort>
            <velocity>2.5</velocity>
          </limit>
          <dynamics>
            <damping>1</damping>
            <friction>1</friction>
            <spring_reference>0</spring_reference>
            <spring_stiffness>0</spring_stiffness>
          </dynamics>
        </axis>
        <physics>
          <ode>
            <implicit_spring_damper>1</implicit_spring_damper>
            <cfm_damping>1</cfm_damping>
            <limit>
              <cfm>0</cfm>
              <erp>0.2</erp>
            </limit>
          </ode>
        </physics>
      </joint>
      <link name='arm_left_3_link'>
        <pose relative_to='arm_left_3_joint'>0 0 0 0 -0 0</pose>
        <inertial>
          <pose>0.016184 -0.004392 0.13565 0 -0 0</pose>
          <mass>1.1325</mass>
          <inertia>
            <ixx>0.0023517</ixx>
            <ixy>-2.6206e-05</ixy>
            <ixz>-0.00020617</ixz>
            <iyy>0.0025497</iyy>
            <iyz>-6.2082e-05</iyz>
            <izz>0.00097131</izz>
          </inertia>
        </inertial>
        <collision name='arm_left_3_link_collision'>
          <pose>0 0 0 0 -0 0</pose>
          <geometry>
            <mesh>
              <scale>1 1 1</scale>
              <uri>model://pal_sea_arm_description/meshes/arm_tiago_pro/arm_3_link_collision.stl</uri>
            </mesh>
          </geometry>
          <surface>
            <contact>
              <ode/>
            </contact>
            <friction>
              <ode>
                <mu>0.9</mu>
                <mu2>0.9</mu2>
              </ode>
              <torsional>
                <ode/>
              </torsional>
            </friction>
            <bounce/>
          </surface>
          <max_contacts>10</max_contacts>
        </collision>
        <visual name='arm_left_3_link_visual'>
          <pose>0 0 0 0 -0 0</pose>
          <geometry>
            <mesh>
              <scale>1 1 1</scale>
              <uri>model://pal_sea_arm_description/meshes/arm_tiago_pro/arm_3_link.stl</uri>
            </mesh>
          </geometry>
          <material>
            <script>
              <name>Gazebo/DarkGrey</name>
              <uri>file://media/materials/scripts/gazebo.material</uri>
            </script>
          </material>
        </visual>
        <self_collide>0</self_collide>
        <enable_wind>0</enable_wind>
        <kinematic>0</kinematic>
      </link>
      <joint name='arm_left_4_joint' type='revolute'>
        <pose relative_to='arm_left_3_link'>0.02 -0.03711 0.15989 1.5708 -0 0</pose>
        <parent>arm_left_3_link</parent>
        <child>arm_left_4_link</child>
        <axis>
          <xyz>0 0 1</xyz>
          <limit>
            <lower>-2.44346</lower>
            <upper>1.13446</upper>
            <effort>26</effort>
            <velocity>2.5</velocity>
          </limit>
          <dynamics>
            <damping>1</damping>
            <friction>1</friction>
            <spring_reference>0</spring_reference>
            <spring_stiffness>0</spring_stiffness>
          </dynamics>
        </axis>
        <physics>
          <ode>
            <implicit_spring_damper>1</implicit_spring_damper>
            <cfm_damping>1</cfm_damping>
            <limit>
              <cfm>0</cfm>
              <erp>0.2</erp>
            </limit>
          </ode>
        </physics>
      </joint>
      <link name='arm_left_4_link'>
        <pose relative_to='arm_left_4_joint'>0 0 0 0 -0 0</pose>
        <inertial>
          <pose>-0.01786 0.11956 -0.032097 0 -0 0</pose>
          <mass>1.0436</mass>
          <inertia>
            <ixx>0.0015021</ixx>
            <ixy>0.00011264</ixy>
            <ixz>-1.0692e-05</ixz>
            <iyy>0.00088017</iyy>
            <iyz>0.00015843</iyz>
            <izz>0.0016021</izz>
          </inertia>
        </inertial>
        <collision name='arm_left_4_link_collision'>
          <pose>0 0 0 0 -0 0</pose>
          <geometry>
            <mesh>
              <scale>1 1 1</scale>
              <uri>model://pal_sea_arm_description/meshes/arm_tiago_pro/arm_4_link_collision.stl</uri>
            </mesh>
          </geometry>
          <surface>
            <contact>
              <ode/>
            </contact>
            <friction>
              <ode>
                <mu>0.9</mu>
                <mu2>0.9</mu2>
              </ode>
              <torsional>
                <ode/>
              </torsional>
            </friction>
            <bounce/>
          </surface>
          <max_contacts>10</max_contacts>
        </collision>
        <visual name='arm_left_4_link_visual'>
          <pose>0 0 0 0 -0 0</pose>
          <geometry>
            <mesh>
              <scale>1 1 1</scale>
              <uri>model://pal_sea_arm_description/meshes/arm_tiago_pro/arm_4_link.stl</uri>
            </mesh>
          </geometry>
          <material>
            <script>
              <name>Gazebo/DarkGrey</name>
              <uri>file://media/materials/scripts/gazebo.material</uri>
            </script>
          </material>
        </visual>
        <self_collide>0</self_collide>
        <enable_wind>0</enable_wind>
        <kinematic>0</kinematic>
      </link>
      <joint name='arm_left_5_joint' type='revolute'>
        <pose relative_to='arm_left_4_link'>-0.02 0.17011 -0.03711 1.5708 0.001593 -3.14159</pose>
        <parent>arm_left_4_link</parent>
        <child>arm_left_5_link</child>
        <axis>
          <xyz>0 0 1</xyz>
          <limit>
            <lower>-3.66519</lower>
            <upper>1.5708</upper>
            <effort>26</effort>
            <velocity>2.5</velocity>
          </limit>
          <dynamics>
            <damping>1</damping>
            <friction>1</friction>
            <spring_reference>0</spring_reference>
            <spring_stiffness>0</spring_stiffness>
          </dynamics>
        </axis>
        <physics>
          <ode>
            <implicit_spring_damper>1</implicit_spring_damper>
            <cfm_damping>1</cfm_damping>
            <limit>
              <cfm>0</cfm>
              <erp>0.2</erp>
            </limit>
          </ode>
        </physics>
      </joint>
      <link name='arm_left_5_link'>
        <pose relative_to='arm_left_5_joint'>0 0 0 0 -0 0</pose>
        <inertial>
          <pose>1.1e-05 -0.027586 0.067845 0 -0 0</pose>
          <mass>0.310763</mass>
          <inertia>
            <ixx>0.00140145</ixx>
            <ixy>9.16506e-08</ixy>
            <ixz>-9.26254e-08</ixz>
            <iyy>0.00139999</iyy>
            <iyz>0.000327713</iyz>
            <izz>0.000402008</izz>
          </inertia>
        </inertial>
        <collision name='arm_left_5_link_collision'>
          <pose>0 0 0 0 -0 0</pose>
          <geometry>
            <mesh>
              <scale>1 1 1</scale>
              <uri>model://pal_sea_arm_description/meshes/arm_tiago_pro/spherical-wrist/arm_5_link.stl</uri>
            </mesh>
          </geometry>
          <surface>
            <contact>
              <ode/>
            </contact>
            <friction>
              <ode>
                <mu>0.9</mu>
                <mu2>0.9</mu2>
              </ode>
              <torsional>
                <ode/>
              </torsional>
            </friction>
            <bounce/>
          </surface>
          <max_contacts>10</max_contacts>
        </collision>
        <visual name='arm_left_5_link_visual'>
          <pose>0 0 0 0 -0 0</pose>
          <geometry>
            <mesh>
              <scale>1 1 1</scale>
              <uri>model://pal_sea_arm_description/meshes/arm_tiago_pro/spherical-wrist/arm_5_link.stl</uri>
            </mesh>
          </geometry>
          <material>
            <script>
              <name>Gazebo/DarkGrey</name>
              <uri>file://media/materials/scripts/gazebo.material</uri>
            </script>
          </material>
        </visual>
        <self_collide>0</self_collide>
        <enable_wind>0</enable_wind>
        <kinematic>0</kinematic>
      </link>
      <joint name='arm_left_6_joint' type='revolute'>
        <pose relative_to='arm_left_5_link'>0 -0.0422 0.1654 -1.5708 -0 3.14</pose>
        <parent>arm_left_5_link</parent>
        <child>arm_left_6_link</child>
        <axis>
          <xyz>0 0 -1</xyz>
          <limit>
            <lower>-1.88496</lower>
            <upper>3.00197</upper>
            <effort>26</effort>
            <velocity>2.5</velocity>
          </limit>
          <dynamics>
            <damping>1</damping>
            <friction>1</friction>
            <spring_reference>0</spring_reference>
            <spring_stiffness>0</spring_stiffness>
          </dynamics>
        </axis>
        <physics>
          <ode>
            <implicit_spring_damper>1</implicit_spring_damper>
            <cfm_damping>1</cfm_damping>
            <limit>
              <cfm>0</cfm>
              <erp>0.2</erp>
            </limit>
          </ode>
        </physics>
      </joint>
      <link name='arm_left_6_link'>
        <pose relative_to='arm_left_6_joint'>0 0 0 0 -0 0</pose>
        <inertial>
          <pose>0.031765 -0.006515 -0.040805 0 -0 0</pose>
          <mass>1.34587</mass>
          <inertia>
            <ixx>0.00109886</ixx>
            <ixy>0.000130003</ixy>
            <ixz>-5.88209e-06</ixz>
            <iyy>0.00116495</iyy>
            <iyz>4.20092e-07</iyz>
            <izz>0.00118984</izz>
          </inertia>
        </inertial>
        <collision name='arm_left_6_link_collision'>
          <pose>0 0 0 0 -0 0</pose>
          <geometry>
            <mesh>
              <scale>1 1 1</scale>
              <uri>model://pal_sea_arm_description/meshes/arm_tiago_pro/spherical-wrist/arm_6_link_collision.stl</uri>
            </mesh>
          </geometry>
          <surface>
            <contact>
              <ode/>
            </contact>
            <friction>
              <ode>
                <mu>0.9</mu>
                <mu2>0.9</mu2>
              </ode>
              <torsional>
                <ode/>
              </torsional>
            </friction>
            <bounce/>
          </surface>
          <max_contacts>10</max_contacts>
        </collision>
        <visual name='arm_left_6_link_visual'>
          <pose>0 0 0 0 -0 0</pose>
          <geometry>
            <mesh>
              <scale>1 1 1</scale>
              <uri>model://pal_sea_arm_description/meshes/arm_tiago_pro/spherical-wrist/arm_6_link.stl</uri>
            </mesh>
          </geometry>
          <material>
            <script>
              <name>Gazebo/DarkGrey</name>
              <uri>file://media/materials/scripts/gazebo.material</uri>
            </script>
          </material>
        </visual>
        <self_collide>0</self_collide>
        <enable_wind>0</enable_wind>
        <kinematic>0</kinematic>
      </link>
      <joint name='arm_left_7_joint' type='revolute'>
        <pose relative_to='arm_left_6_link'>0.07 -0.0534 -0.0422 1.5708 -0 0</pose>
        <parent>arm_left_6_link</parent>
        <child>arm_left_7_link</child>
        <axis>
          <xyz>0 0 1</xyz>
          <limit>
            <lower>-2.61799</lower>
            <upper>2.61799</upper>
            <effort>26</effort>
            <velocity>2.5</velocity>
          </limit>
          <dynamics>
            <damping>1</damping>
            <friction>1</friction>
            <spring_reference>0</spring_reference>
            <spring_stiffness>0</spring_stiffness>
          </dynamics>
        </axis>
        <physics>
          <provide_feedback>1</provide_feedback>
          <ode>
            <implicit_spring_damper>1</implicit_spring_damper>
            <cfm_damping>1</cfm_damping>
            <limit>
              <cfm>0</cfm>
              <erp>0.2</erp>
            </limit>
            <provide_feedback>1</provide_feedback>
          </ode>
        </physics>
      </joint>
      <link name='arm_left_7_link'>
        <pose relative_to='arm_left_7_joint'>0 0 0 0 -0 0</pose>
        <inertial>
          <pose>0.000371 -0.00062 0.049358 0 -0 0</pose>
          <mass>0.475823</mass>
          <inertia>
            <ixx>0.000575813</ixx>
            <ixy>2.12403e-07</ixy>
            <ixz>9.89094e-06</ixz>
            <iyy>0.000502928</iyy>
            <iyz>-1.12781e-05</iyz>
            <izz>0.000374898</izz>
          </inertia>
        </inertial>
        <collision name='arm_left_7_link_collision'>
          <pose>0 0 0 0 -0 0</pose>
          <geometry>
            <cylinder>
              <length>0.0366</length>
              <radius>0.0375</radius>
            </cylinder>
          </geometry>
          <surface>
            <contact>
              <ode/>
            </contact>
            <friction>
              <ode>
                <mu>0.9</mu>
                <mu2>0.9</mu2>
              </ode>
              <torsional>
                <ode/>
              </torsional>
            </friction>
            <bounce/>
          </surface>
          <max_contacts>10</max_contacts>
        </collision>
        <collision name='arm_left_7_link_fixed_joint_lump__gripper_left_base_link_collision_1'>
          <pose>0 0 0.017 0 -0 0</pose>
          <geometry>
            <mesh>
              <scale>1 1 1</scale>
              <uri>model://pal_pro_gripper_description/meshes/base_link_tc.stl</uri>
            </mesh>
          </geometry>
          <surface>
            <contact>
              <ode/>
            </contact>
            <friction>
              <ode>
                <mu>0.9</mu>
                <mu2>0.9</mu2>
              </ode>
              <torsional>
                <ode/>
              </torsional>
            </friction>
            <bounce/>
          </surface>
          <max_contacts>10</max_contacts>
        </collision>
        <visual name='arm_left_7_link_visual'>
          <pose>0 0 0 0 -0 0</pose>
          <geometry>
            <mesh>
              <scale>1 1 1</scale>
              <uri>model://pal_sea_arm_description/meshes/arm_tiago_pro/spherical-wrist/arm_7_link.stl</uri>
            </mesh>
          </geometry>
          <material>
            <script>
              <name>Gazebo/DarkGrey</name>
              <uri>file://media/materials/scripts/gazebo.material</uri>
            </script>
          </material>
        </visual>
        <visual name='arm_left_7_link_fixed_joint_lump__gripper_left_base_link_visual_1'>
          <pose>0 0 0.017 0 -0 0</pose>
          <geometry>
            <mesh>
              <scale>1 1 1</scale>
              <uri>model://pal_pro_gripper_description/meshes/base_link_tc.stl</uri>
            </mesh>
          </geometry>
          <material>
            <script>
              <name>Gazebo/DarkGrey</name>
              <uri>file://media/materials/scripts/gazebo.material</uri>
            </script>
          </material>
        </visual>
        <self_collide>0</self_collide>
        <enable_wind>0</enable_wind>
        <kinematic>0</kinematic>
      </link>
      <joint name='gripper_left_finger_joint' type='revolute'>
        <pose relative_to='arm_left_7_link'>0 -0.0288 0.0913 1.5708 0.83776 -1.5708</pose>
        <parent>arm_left_7_link</parent>
        <child>gripper_left_outer_finger_left_link</child>
        <axis>
          <xyz>0 0 1</xyz>
          <limit>
            <lower>0</lower>
            <upper>0.802851</upper>
            <effort>0.1</effort>
            <velocity>2</velocity>
          </limit>
          <dynamics>
            <damping>0.03</damping>
            <friction>0</friction>
            <spring_reference>0</spring_reference>
            <spring_stiffness>0</spring_stiffness>
          </dynamics>
        </axis>
        <physics>
          <ode>
            <limit>
              <cfm>0</cfm>
              <erp>0.2</erp>
            </limit>
            <implicit_spring_damper>1</implicit_spring_damper>
            <cfm_damping>1</cfm_damping>
            <provide_feedback>1</provide_feedback>
          </ode>
          <provide_feedback>1</provide_feedback>
        </physics>
      </joint>
      <link name='gripper_left_outer_finger_left_link'>
        <pose relative_to='gripper_left_finger_joint'>0 0 0 0 -0 0</pose>
        <inertial>
          <pose>-0.001283 0.014397 0 0 -0 0</pose>
          <mass>0.0159888</mass>
          <inertia>
            <ixx>5.98786e-06</ixx>
            <ixy>-5.21729e-07</ixy>
            <ixz>-7.65399e-20</ixz>
            <iyy>4.87251e-07</iyy>
            <iyz>-7.03394e-19</iyz>
            <izz>6.14973e-06</izz>
          </inertia>
        </inertial>
        <collision name='gripper_left_outer_finger_left_link_collision'>
          <pose>0 0 0 0 -0 0</pose>
          <geometry>
            <mesh>
              <scale>1 1 1</scale>
              <uri>model://pal_pro_gripper_description/meshes/outer_finger.stl</uri>
            </mesh>
          </geometry>
          <surface>
            <contact>
              <ode/>
            </contact>
            <friction>
              <ode>
                <mu>0.9</mu>
                <mu2>0.9</mu2>
              </ode>
              <torsional>
                <ode/>
              </torsional>
            </friction>
            <bounce/>
          </surface>
          <max_contacts>10</max_contacts>
        </collision>
        <visual name='gripper_left_outer_finger_left_link_visual'>
          <pose>0 0 0 0 -0 0</pose>
          <geometry>
            <mesh>
              <scale>1 1 1</scale>
              <uri>model://pal_pro_gripper_description/meshes/outer_finger.stl</uri>
            </mesh>
          </geometry>
          <material>
            <script>
              <name>Gazebo/White</name>
              <uri>file://media/materials/scripts/gazebo.material</uri>
            </script>
          </material>
        </visual>
        <self_collide>0</self_collide>
        <enable_wind>0</enable_wind>
        <kinematic>0</kinematic>
      </link>
      <joint name='gripper_left_inner_finger_left_joint' type='revolute'>
        <pose relative_to='arm_left_7_link'>0 -0.013977 0.095832 1.5708 0.83776 -1.5708</pose>
        <parent>arm_left_7_link</parent>
        <child>gripper_left_inner_finger_left_link</child>
        <axis>
          <xyz>0 0 1</xyz>
          <limit>
            <lower>0</lower>
            <upper>0.802851</upper>
            <effort>0.1</effort>
            <velocity>2</velocity>
          </limit>
          <dynamics>
            <spring_reference>0</spring_reference>
            <spring_stiffness>0</spring_stiffness>
          </dynamics>
        </axis>
      </joint>
      <link name='gripper_left_inner_finger_left_link'>
        <pose relative_to='gripper_left_inner_finger_left_joint'>0 0 0 0 -0 0</pose>
        <inertial>
          <pose>-0 0.024759 0 0 -0 0</pose>
          <mass>0.018619</mass>
          <inertia>
            <ixx>4.8806e-06</ixx>
            <ixy>-7.6762e-22</ixy>
            <ixz>1.0244e-22</ixz>
            <iyy>2.5471e-07</iyy>
            <iyz>-1.1841e-21</iyz>
            <izz>4.9573e-06</izz>
          </inertia>
        </inertial>
        <collision name='gripper_left_inner_finger_left_link_collision'>
          <pose>0 0 0 0 -0 0</pose>
          <geometry>
            <mesh>
              <scale>1 1 1</scale>
              <uri>model://pal_pro_gripper_description/meshes/inner_finger.stl</uri>
            </mesh>
          </geometry>
          <surface>
            <contact>
              <ode/>
            </contact>
            <friction>
              <ode>
                <mu>0.9</mu>
                <mu2>0.9</mu2>
              </ode>
              <torsional>
                <ode/>
              </torsional>
            </friction>
            <bounce/>
          </surface>
          <max_contacts>10</max_contacts>
        </collision>
        <visual name='gripper_left_inner_finger_left_link_visual'>
          <pose>0 0 0 0 -0 0</pose>
          <geometry>
            <mesh>
              <scale>1 1 1</scale>
              <uri>model://pal_pro_gripper_description/meshes/inner_finger.stl</uri>
            </mesh>
          </geometry>
          <material>
            <script>
              <name>Gazebo/White</name>
              <uri>file://media/materials/scripts/gazebo.material</uri>
            </script>
          </material>
        </visual>
        <self_collide>0</self_collide>
        <enable_wind>0</enable_wind>
        <kinematic>0</kinematic>
      </link>
      <joint name='gripper_left_fingertip_left_joint' type='revolute'>
        <pose relative_to='gripper_left_inner_finger_left_link'>0 0.05 0 0 -0 0.83776</pose>
        <parent>gripper_left_inner_finger_left_link</parent>
        <child>gripper_left_fingertip_left_link</child>
        <axis>
          <xyz>0 0 1</xyz>
          <limit>
            <lower>-0.802851</lower>
            <upper>0</upper>
            <effort>0.1</effort>
            <velocity>2</velocity>
          </limit>
          <dynamics>
            <spring_reference>0</spring_reference>
            <spring_stiffness>0</spring_stiffness>
          </dynamics>
        </axis>
      </joint>
      <link name='gripper_left_fingertip_left_link'>
        <pose relative_to='gripper_left_fingertip_left_joint'>0 0 0 0 -0 0</pose>
        <inertial>
          <pose>-0.000865 0.011929 -0 0 -0 0</pose>
          <mass>0.033503</mass>
          <inertia>
            <ixx>3.63918e-06</ixx>
            <ixy>3.40522e-07</ixy>
            <ixz>-1.41919e-14</ixz>
            <iyy>1.7095e-06</iyy>
            <iyz>-4.24737e-14</iyz>
            <izz>2.84428e-06</izz>
          </inertia>
        </inertial>
        <collision name='gripper_left_fingertip_left_link_collision'>
          <pose>0 0 0 0 -0 0</pose>
          <geometry>
            <mesh>
              <scale>1 1 1</scale>
              <uri>model://pal_pro_gripper_description/meshes/fingertip.stl</uri>
            </mesh>
          </geometry>
          <surface>
            <contact>
              <ode/>
            </contact>
            <friction>
              <ode>
                <mu>0.9</mu>
                <mu2>0.9</mu2>
              </ode>
              <torsional>
                <ode/>
              </torsional>
            </friction>
            <bounce/>
          </surface>
          <max_contacts>10</max_contacts>
        </collision>
        <visual name='gripper_left_fingertip_left_link_visual'>
          <pose>0 0 0 0 -0 0</pose>
          <geometry>
            <mesh>
              <scale>1 1 1</scale>
              <uri>model://pal_pro_gripper_description/meshes/fingertip.stl</uri>
            </mesh>
          </geometry>
          <material>
            <script>
              <name>Gazebo/White</name>
              <uri>file://media/materials/scripts/gazebo.material</uri>
            </script>
          </material>
        </visual>
        <self_collide>0</self_collide>
        <enable_wind>0</enable_wind>
        <kinematic>0</kinematic>
      </link>
      <joint name='gripper_left_inner_finger_right_joint' type='revolute'>
        <pose relative_to='arm_left_7_link'>0 0.013977 0.095832 1.5708 0.83776 1.5708</pose>
        <parent>arm_left_7_link</parent>
        <child>gripper_left_inner_finger_right_link</child>
        <axis>
          <xyz>0 0 1</xyz>
          <limit>
            <lower>0</lower>
            <upper>0.802851</upper>
            <effort>0.1</effort>
            <velocity>2</velocity>
          </limit>
          <dynamics>
            <spring_reference>0</spring_reference>
            <spring_stiffness>0</spring_stiffness>
          </dynamics>
        </axis>
      </joint>
      <link name='gripper_left_inner_finger_right_link'>
        <pose relative_to='gripper_left_inner_finger_right_joint'>0 0 0 0 -0 0</pose>
        <inertial>
          <pose>-0 0.024759 0 0 -0 0</pose>
          <mass>0.018619</mass>
          <inertia>
            <ixx>4.8806e-06</ixx>
            <ixy>-7.6762e-22</ixy>
            <ixz>1.0244e-22</ixz>
            <iyy>2.5471e-07</iyy>
            <iyz>-1.1841e-21</iyz>
            <izz>4.9573e-06</izz>
          </inertia>
        </inertial>
        <collision name='gripper_left_inner_finger_right_link_collision'>
          <pose>0 0 0 0 -0 0</pose>
          <geometry>
            <mesh>
              <scale>1 1 1</scale>
              <uri>model://pal_pro_gripper_description/meshes/inner_finger.stl</uri>
            </mesh>
          </geometry>
          <surface>
            <contact>
              <ode/>
            </contact>
            <friction>
              <ode>
                <mu>0.9</mu>
                <mu2>0.9</mu2>
              </ode>
              <torsional>
                <ode/>
              </torsional>
            </friction>
            <bounce/>
          </surface>
          <max_contacts>10</max_contacts>
        </collision>
        <visual name='gripper_left_inner_finger_right_link_visual'>
          <pose>0 0 0 0 -0 0</pose>
          <geometry>
            <mesh>
              <scale>1 1 1</scale>
              <uri>model://pal_pro_gripper_description/meshes/inner_finger.stl</uri>
            </mesh>
          </geometry>
          <material>
            <script>
              <name>Gazebo/White</name>
              <uri>file://media/materials/scripts/gazebo.material</uri>
            </script>
          </material>
        </visual>
        <self_collide>0</self_collide>
        <enable_wind>0</enable_wind>
        <kinematic>0</kinematic>
      </link>
      <joint name='gripper_left_fingertip_right_joint' type='revolute'>
        <pose relative_to='gripper_left_inner_finger_right_link'>0 0.05 0 0 -0 0.83776</pose>
        <parent>gripper_left_inner_finger_right_link</parent>
        <child>gripper_left_fingertip_right_link</child>
        <axis>
          <xyz>0 0 1</xyz>
          <limit>
            <lower>-0.802851</lower>
            <upper>0</upper>
            <effort>0.1</effort>
            <velocity>2</velocity>
          </limit>
          <dynamics>
            <spring_reference>0</spring_reference>
            <spring_stiffness>0</spring_stiffness>
          </dynamics>
        </axis>
      </joint>
      <link name='gripper_left_fingertip_right_link'>
        <pose relative_to='gripper_left_fingertip_right_joint'>0 0 0 0 -0 0</pose>
        <inertial>
          <pose>-0.000865 0.011929 -0 0 -0 0</pose>
          <mass>0.033503</mass>
          <inertia>
            <ixx>3.63918e-06</ixx>
            <ixy>3.40522e-07</ixy>
            <ixz>-1.41919e-14</ixz>
            <iyy>1.7095e-06</iyy>
            <iyz>-4.24737e-14</iyz>
            <izz>2.84428e-06</izz>
          </inertia>
        </inertial>
        <collision name='gripper_left_fingertip_right_link_collision'>
          <pose>0 0 0 0 -0 0</pose>
          <geometry>
            <mesh>
              <scale>1 1 1</scale>
              <uri>model://pal_pro_gripper_description/meshes/fingertip.stl</uri>
            </mesh>
          </geometry>
          <surface>
            <contact>
              <ode/>
            </contact>
            <friction>
              <ode>
                <mu>0.9</mu>
                <mu2>0.9</mu2>
              </ode>
              <torsional>
                <ode/>
              </torsional>
            </friction>
            <bounce/>
          </surface>
          <max_contacts>10</max_contacts>
        </collision>
        <visual name='gripper_left_fingertip_right_link_visual'>
          <pose>0 0 0 0 -0 0</pose>
          <geometry>
            <mesh>
              <scale>1 1 1</scale>
              <uri>model://pal_pro_gripper_description/meshes/fingertip.stl</uri>
            </mesh>
          </geometry>
          <material>
            <script>
              <name>Gazebo/White</name>
              <uri>file://media/materials/scripts/gazebo.material</uri>
            </script>
          </material>
        </visual>
        <self_collide>0</self_collide>
        <enable_wind>0</enable_wind>
        <kinematic>0</kinematic>
      </link>
      <joint name='gripper_left_outer_finger_right_joint' type='revolute'>
        <pose relative_to='arm_left_7_link'>0 0.0288 0.0913 1.5708 0.83776 1.5708</pose>
        <parent>arm_left_7_link</parent>
        <child>gripper_left_outer_finger_right_link</child>
        <axis>
          <xyz>0 0 1</xyz>
          <limit>
            <lower>0</lower>
            <upper>0.802851</upper>
            <effort>0.1</effort>
            <velocity>2</velocity>
          </limit>
          <dynamics>
            <spring_reference>0</spring_reference>
            <spring_stiffness>0</spring_stiffness>
          </dynamics>
        </axis>
      </joint>
      <link name='gripper_left_outer_finger_right_link'>
        <pose relative_to='gripper_left_outer_finger_right_joint'>0 0 0 0 -0 0</pose>
        <inertial>
          <pose>-0.001283 0.014397 0 0 -0 0</pose>
          <mass>0.0159888</mass>
          <inertia>
            <ixx>5.98786e-06</ixx>
            <ixy>-5.21729e-07</ixy>
            <ixz>-7.65399e-20</ixz>
            <iyy>4.87251e-07</iyy>
            <iyz>-7.03394e-19</iyz>
            <izz>6.14973e-06</izz>
          </inertia>
        </inertial>
        <collision name='gripper_left_outer_finger_right_link_collision'>
          <pose>0 0 0 0 -0 0</pose>
          <geometry>
            <mesh>
              <scale>1 1 1</scale>
              <uri>model://pal_pro_gripper_description/meshes/outer_finger.stl</uri>
            </mesh>
          </geometry>
          <surface>
            <contact>
              <ode/>
            </contact>
            <friction>
              <ode>
                <mu>0.9</mu>
                <mu2>0.9</mu2>
              </ode>
              <torsional>
                <ode/>
              </torsional>
            </friction>
            <bounce/>
          </surface>
          <max_contacts>10</max_contacts>
        </collision>
        <visual name='gripper_left_outer_finger_right_link_visual'>
          <pose>0 0 0 0 -0 0</pose>
          <geometry>
            <mesh>
              <scale>1 1 1</scale>
              <uri>model://pal_pro_gripper_description/meshes/outer_finger.stl</uri>
            </mesh>
          </geometry>
          <material>
            <script>
              <name>Gazebo/White</name>
              <uri>file://media/materials/scripts/gazebo.material</uri>
            </script>
          </material>
        </visual>
        <self_collide>0</self_collide>
        <enable_wind>0</enable_wind>
        <kinematic>0</kinematic>
      </link>
      <joint name='arm_right_1_joint' type='revolute'>
        <pose relative_to='torso_lift_link'>0.08976 -0.15918 -0.092008 -2.0679 0 -1.91989</pose>
        <parent>torso_lift_link</parent>
        <child>arm_right_1_link</child>
        <axis>
          <xyz>0 0 1</xyz>
          <limit>
            <lower>-4.71239</lower>
            <upper>0.523599</upper>
            <effort>43</effort>
            <velocity>2.5</velocity>
          </limit>
          <dynamics>
            <damping>1</damping>
            <friction>1</friction>
            <spring_reference>0</spring_reference>
            <spring_stiffness>0</spring_stiffness>
          </dynamics>
        </axis>
        <physics>
          <ode>
            <implicit_spring_damper>1</implicit_spring_damper>
            <cfm_damping>1</cfm_damping>
            <limit>
              <cfm>0</cfm>
              <erp>0.2</erp>
            </limit>
          </ode>
        </physics>
      </joint>
      <link name='arm_right_1_link'>
        <pose relative_to='arm_right_1_joint'>0 0 0 0 -0 0</pose>
        <inertial>
          <pose>0.004392 0.016184 0.15576 0 -0 0</pose>
          <mass>1.1325</mass>
          <inertia>
            <ixx>0.0025497</ixx>
            <ixy>2.6206e-05</ixy>
            <ixz>6.2082e-05</ixz>
            <iyy>0.0023517</iyy>
            <iyz>-0.00020617</iyz>
            <izz>0.00097131</izz>
          </inertia>
        </inertial>
        <collision name='arm_right_1_link_collision'>
          <pose>0 0 0 0 -0 0</pose>
          <geometry>
            <mesh>
              <scale>1 1 1</scale>
              <uri>model://pal_sea_arm_description/meshes/arm_tiago_pro/arm_1_link_collision.stl</uri>
            </mesh>
          </geometry>
          <surface>
            <contact>
              <ode/>
            </contact>
            <friction>
              <ode>
                <mu>0.9</mu>
                <mu2>0.9</mu2>
              </ode>
              <torsional>
                <ode/>
              </torsional>
            </friction>
            <bounce/>
          </surface>
          <max_contacts>10</max_contacts>
        </collision>
        <visual name='arm_right_1_link_visual'>
          <pose>0 0 0 0 -0 0</pose>
          <geometry>
            <mesh>
              <scale>1 1 1</scale>
              <uri>model://pal_sea_arm_description/meshes/arm_tiago_pro/arm_1_link.stl</uri>
            </mesh>
          </geometry>
          <material>
            <script>
              <name>Gazebo/DarkGrey</name>
              <uri>file://media/materials/scripts/gazebo.material</uri>
            </script>
          </material>
        </visual>
        <self_collide>0</self_collide>
        <enable_wind>0</enable_wind>
        <kinematic>0</kinematic>
      </link>
      <joint name='arm_right_2_joint' type='revolute'>
        <pose relative_to='arm_right_1_link'>0.03711 0.02 0.18 -1.5708 -0 -1.5708</pose>
        <parent>arm_right_1_link</parent>
        <child>arm_right_2_link</child>
        <axis>
          <xyz>0 0 1</xyz>
          <limit>
            <lower>-2.44346</lower>
            <upper>1.13446</upper>
            <effort>43</effort>
            <velocity>2.5</velocity>
          </limit>
          <dynamics>
            <damping>1</damping>
            <friction>1</friction>
            <spring_reference>0</spring_reference>
            <spring_stiffness>0</spring_stiffness>
          </dynamics>
        </axis>
        <physics>
          <ode>
            <implicit_spring_damper>1</implicit_spring_damper>
            <cfm_damping>1</cfm_damping>
            <limit>
              <cfm>0</cfm>
              <erp>0.2</erp>
            </limit>
          </ode>
        </physics>
      </joint>
      <link name='arm_right_2_link'>
        <pose relative_to='arm_right_2_joint'>0 0 0 0 -0 0</pose>
        <inertial>
          <pose>0.01786 -0.11956 -0.032097 0 -0 0</pose>
          <mass>1.0436</mass>
          <inertia>
            <ixx>0.0015021</ixx>
            <ixy>0.00011264</ixy>
            <ixz>1.0692e-05</ixz>
            <iyy>0.00088017</iyy>
            <iyz>-0.00015843</iyz>
            <izz>0.0016021</izz>
          </inertia>
        </inertial>
        <collision name='arm_right_2_link_collision'>
          <pose>0 0 0 0 -0 0</pose>
          <geometry>
            <mesh>
              <scale>1 1 1</scale>
              <uri>model://pal_sea_arm_description/meshes/arm_tiago_pro/arm_2_link_collision.stl</uri>
            </mesh>
          </geometry>
          <surface>
            <contact>
              <ode/>
            </contact>
            <friction>
              <ode>
                <mu>0.9</mu>
                <mu2>0.9</mu2>
              </ode>
              <torsional>
                <ode/>
              </torsional>
            </friction>
            <bounce/>
          </surface>
          <max_contacts>10</max_contacts>
        </collision>
        <visual name='arm_right_2_link_visual'>
          <pose>0 0 0 0 -0 0</pose>
          <geometry>
            <mesh>
              <scale>1 1 1</scale>
              <uri>model://pal_sea_arm_description/meshes/arm_tiago_pro/arm_2_link.stl</uri>
            </mesh>
          </geometry>
          <material>
            <script>
              <name>Gazebo/DarkGrey</name>
              <uri>file://media/materials/scripts/gazebo.material</uri>
            </script>
          </material>
        </visual>
        <self_collide>0</self_collide>
        <enable_wind>0</enable_wind>
        <kinematic>0</kinematic>
      </link>
      <joint name='arm_right_3_joint' type='revolute'>
        <pose relative_to='arm_right_2_link'>0.02 -0.17011 -0.03711 1.5708 -0 0</pose>
        <parent>arm_right_2_link</parent>
        <child>arm_right_3_link</child>
        <axis>
          <xyz>0 0 1</xyz>
          <limit>
            <lower>-2.61799</lower>
            <upper>2.61799</upper>
            <effort>26</effort>
            <velocity>2.5</velocity>
          </limit>
          <dynamics>
            <damping>1</damping>
            <friction>1</friction>
            <spring_reference>0</spring_reference>
            <spring_stiffness>0</spring_stiffness>
          </dynamics>
        </axis>
        <physics>
          <ode>
            <implicit_spring_damper>1</implicit_spring_damper>
            <cfm_damping>1</cfm_damping>
            <limit>
              <cfm>0</cfm>
              <erp>0.2</erp>
            </limit>
          </ode>
        </physics>
      </joint>
      <link name='arm_right_3_link'>
        <pose relative_to='arm_right_3_joint'>0 0 0 0 -0 0</pose>
        <inertial>
          <pose>0.016184 -0.004392 0.13565 0 -0 0</pose>
          <mass>1.1325</mass>
          <inertia>
            <ixx>0.0023517</ixx>
            <ixy>-2.6206e-05</ixy>
            <ixz>-0.00020617</ixz>
            <iyy>0.0025497</iyy>
            <iyz>-6.2082e-05</iyz>
            <izz>0.00097131</izz>
          </inertia>
        </inertial>
        <collision name='arm_right_3_link_collision'>
          <pose>0 0 0 0 -0 0</pose>
          <geometry>
            <mesh>
              <scale>1 1 1</scale>
              <uri>model://pal_sea_arm_description/meshes/arm_tiago_pro/arm_3_link_collision.stl</uri>
            </mesh>
          </geometry>
          <surface>
            <contact>
              <ode/>
            </contact>
            <friction>
              <ode>
                <mu>0.9</mu>
                <mu2>0.9</mu2>
              </ode>
              <torsional>
                <ode/>
              </torsional>
            </friction>
            <bounce/>
          </surface>
          <max_contacts>10</max_contacts>
        </collision>
        <visual name='arm_right_3_link_visual'>
          <pose>0 0 0 0 -0 0</pose>
          <geometry>
            <mesh>
              <scale>1 1 1</scale>
              <uri>model://pal_sea_arm_description/meshes/arm_tiago_pro/arm_3_link.stl</uri>
            </mesh>
          </geometry>
          <material>
            <script>
              <name>Gazebo/DarkGrey</name>
              <uri>file://media/materials/scripts/gazebo.material</uri>
            </script>
          </material>
        </visual>
        <self_collide>0</self_collide>
        <enable_wind>0</enable_wind>
        <kinematic>0</kinematic>
      </link>
      <joint name='arm_right_4_joint' type='revolute'>
        <pose relative_to='arm_right_3_link'>0.02 -0.03711 0.15989 1.5708 -0 0</pose>
        <parent>arm_right_3_link</parent>
        <child>arm_right_4_link</child>
        <axis>
          <xyz>0 0 1</xyz>
          <limit>
            <lower>-2.44346</lower>
            <upper>1.13446</upper>
            <effort>26</effort>
            <velocity>2.5</velocity>
          </limit>
          <dynamics>
            <damping>1</damping>
            <friction>1</friction>
            <spring_reference>0</spring_reference>
            <spring_stiffness>0</spring_stiffness>
          </dynamics>
        </axis>
        <physics>
          <ode>
            <implicit_spring_damper>1</implicit_spring_damper>
            <cfm_damping>1</cfm_damping>
            <limit>
              <cfm>0</cfm>
              <erp>0.2</erp>
            </limit>
          </ode>
        </physics>
      </joint>
      <link name='arm_right_4_link'>
        <pose relative_to='arm_right_4_joint'>0 0 0 0 -0 0</pose>
        <inertial>
          <pose>-0.01786 0.11956 -0.032097 0 -0 0</pose>
          <mass>1.0436</mass>
          <inertia>
            <ixx>0.0015021</ixx>
            <ixy>0.00011264</ixy>
            <ixz>-1.0692e-05</ixz>
            <iyy>0.00088017</iyy>
            <iyz>0.00015843</iyz>
            <izz>0.0016021</izz>
          </inertia>
        </inertial>
        <collision name='arm_right_4_link_collision'>
          <pose>0 0 0 0 -0 0</pose>
          <geometry>
            <mesh>
              <scale>1 1 1</scale>
              <uri>model://pal_sea_arm_description/meshes/arm_tiago_pro/arm_4_link_collision.stl</uri>
            </mesh>
          </geometry>
          <surface>
            <contact>
              <ode/>
            </contact>
            <friction>
              <ode>
                <mu>0.9</mu>
                <mu2>0.9</mu2>
              </ode>
              <torsional>
                <ode/>
              </torsional>
            </friction>
            <bounce/>
          </surface>
          <max_contacts>10</max_contacts>
        </collision>
        <visual name='arm_right_4_link_visual'>
          <pose>0 0 0 0 -0 0</pose>
          <geometry>
            <mesh>
              <scale>1 1 1</scale>
              <uri>model://pal_sea_arm_description/meshes/arm_tiago_pro/arm_4_link.stl</uri>
            </mesh>
          </geometry>
          <material>
            <script>
              <name>Gazebo/DarkGrey</name>
              <uri>file://media/materials/scripts/gazebo.material</uri>
            </script>
          </material>
        </visual>
        <self_collide>0</self_collide>
        <enable_wind>0</enable_wind>
        <kinematic>0</kinematic>
      </link>
      <joint name='arm_right_5_joint' type='revolute'>
        <pose relative_to='arm_right_4_link'>-0.02 0.17011 -0.03711 1.5708 0.001593 -3.14159</pose>
        <parent>arm_right_4_link</parent>
        <child>arm_right_5_link</child>
        <axis>
          <xyz>0 0 1</xyz>
          <limit>
            <lower>-1.5708</lower>
            <upper>3.66519</upper>
            <effort>26</effort>
            <velocity>2.5</velocity>
          </limit>
          <dynamics>
            <damping>1</damping>
            <friction>1</friction>
            <spring_reference>0</spring_reference>
            <spring_stiffness>0</spring_stiffness>
          </dynamics>
        </axis>
        <physics>
          <ode>
            <implicit_spring_damper>1</implicit_spring_damper>
            <cfm_damping>1</cfm_damping>
            <limit>
              <cfm>0</cfm>
              <erp>0.2</erp>
            </limit>
          </ode>
        </physics>
      </joint>
      <link name='arm_right_5_link'>
        <pose relative_to='arm_right_5_joint'>0 0 0 0 -0 0</pose>
        <inertial>
          <pose>1.1e-05 -0.027586 0.067845 0 -0 0</pose>
          <mass>0.310763</mass>
          <inertia>
            <ixx>0.00140145</ixx>
            <ixy>9.16506e-08</ixy>
            <ixz>-9.26254e-08</ixz>
            <iyy>0.00139999</iyy>
            <iyz>0.000327713</iyz>
            <izz>0.000402008</izz>
          </inertia>
        </inertial>
        <collision name='arm_right_5_link_collision'>
          <pose>0 0 0 0 -0 0</pose>
          <geometry>
            <mesh>
              <scale>1 1 1</scale>
              <uri>model://pal_sea_arm_description/meshes/arm_tiago_pro/spherical-wrist/arm_5_link.stl</uri>
            </mesh>
          </geometry>
          <surface>
            <contact>
              <ode/>
            </contact>
            <friction>
              <ode>
                <mu>0.9</mu>
                <mu2>0.9</mu2>
              </ode>
              <torsional>
                <ode/>
              </torsional>
            </friction>
            <bounce/>
          </surface>
          <max_contacts>10</max_contacts>
        </collision>
        <visual name='arm_right_5_link_visual'>
          <pose>0 0 0 0 -0 0</pose>
          <geometry>
            <mesh>
              <scale>1 1 1</scale>
              <uri>model://pal_sea_arm_description/meshes/arm_tiago_pro/spherical-wrist/arm_5_link.stl</uri>
            </mesh>
          </geometry>
          <material>
            <script>
              <name>Gazebo/DarkGrey</name>
              <uri>file://media/materials/scripts/gazebo.material</uri>
            </script>
          </material>
        </visual>
        <self_collide>0</self_collide>
        <enable_wind>0</enable_wind>
        <kinematic>0</kinematic>
      </link>
      <joint name='arm_right_6_joint' type='revolute'>
        <pose relative_to='arm_right_5_link'>0 -0.0422 0.1654 -1.5708 -0 3.14</pose>
        <parent>arm_right_5_link</parent>
        <child>arm_right_6_link</child>
        <axis>
          <xyz>0 0 -1</xyz>
          <limit>
            <lower>-1.88496</lower>
            <upper>3.00197</upper>
            <effort>26</effort>
            <velocity>2.5</velocity>
          </limit>
          <dynamics>
            <damping>1</damping>
            <friction>1</friction>
            <spring_reference>0</spring_reference>
            <spring_stiffness>0</spring_stiffness>
          </dynamics>
        </axis>
        <physics>
          <ode>
            <implicit_spring_damper>1</implicit_spring_damper>
            <cfm_damping>1</cfm_damping>
            <limit>
              <cfm>0</cfm>
              <erp>0.2</erp>
            </limit>
          </ode>
        </physics>
      </joint>
      <link name='arm_right_6_link'>
        <pose relative_to='arm_right_6_joint'>0 0 0 0 -0 0</pose>
        <inertial>
          <pose>0.031765 -0.006515 -0.040805 0 -0 0</pose>
          <mass>1.34587</mass>
          <inertia>
            <ixx>0.00109886</ixx>
            <ixy>0.000130003</ixy>
            <ixz>-5.88209e-06</ixz>
            <iyy>0.00116495</iyy>
            <iyz>4.20092e-07</iyz>
            <izz>0.00118984</izz>
          </inertia>
        </inertial>
        <collision name='arm_right_6_link_collision'>
          <pose>0 0 0 0 -0 0</pose>
          <geometry>
            <mesh>
              <scale>1 1 1</scale>
              <uri>model://pal_sea_arm_description/meshes/arm_tiago_pro/spherical-wrist/arm_6_link_collision.stl</uri>
            </mesh>
          </geometry>
          <surface>
            <contact>
              <ode/>
            </contact>
            <friction>
              <ode>
                <mu>0.9</mu>
                <mu2>0.9</mu2>
              </ode>
              <torsional>
                <ode/>
              </torsional>
            </friction>
            <bounce/>
          </surface>
          <max_contacts>10</max_contacts>
        </collision>
        <visual name='arm_right_6_link_visual'>
          <pose>0 0 0 0 -0 0</pose>
          <geometry>
            <mesh>
              <scale>1 1 1</scale>
              <uri>model://pal_sea_arm_description/meshes/arm_tiago_pro/spherical-wrist/arm_6_link.stl</uri>
            </mesh>
          </geometry>
          <material>
            <script>
              <name>Gazebo/DarkGrey</name>
              <uri>file://media/materials/scripts/gazebo.material</uri>
            </script>
          </material>
        </visual>
        <self_collide>0</self_collide>
        <enable_wind>0</enable_wind>
        <kinematic>0</kinematic>
      </link>
      <joint name='arm_right_7_joint' type='revolute'>
        <pose relative_to='arm_right_6_link'>0.07 -0.0534 -0.0422 1.5708 -0 0</pose>
        <parent>arm_right_6_link</parent>
        <child>arm_right_7_link</child>
        <axis>
          <xyz>0 0 1</xyz>
          <limit>
            <lower>-2.61799</lower>
            <upper>2.61799</upper>
            <effort>26</effort>
            <velocity>2.5</velocity>
          </limit>
          <dynamics>
            <damping>1</damping>
            <friction>1</friction>
            <spring_reference>0</spring_reference>
            <spring_stiffness>0</spring_stiffness>
          </dynamics>
        </axis>
        <physics>
          <provide_feedback>1</provide_feedback>
          <ode>
            <implicit_spring_damper>1</implicit_spring_damper>
            <cfm_damping>1</cfm_damping>
            <limit>
              <cfm>0</cfm>
              <erp>0.2</erp>
            </limit>
            <provide_feedback>1</provide_feedback>
          </ode>
        </physics>
      </joint>
      <link name='arm_right_7_link'>
        <pose relative_to='arm_right_7_joint'>0 0 0 0 -0 0</pose>
        <inertial>
          <pose>0.000371 -0.00062 0.049358 0 -0 0</pose>
          <mass>0.475823</mass>
          <inertia>
            <ixx>0.000575813</ixx>
            <ixy>2.12403e-07</ixy>
            <ixz>9.89094e-06</ixz>
            <iyy>0.000502928</iyy>
            <iyz>-1.12781e-05</iyz>
            <izz>0.000374898</izz>
          </inertia>
        </inertial>
        <collision name='arm_right_7_link_collision'>
          <pose>0 0 0 0 -0 0</pose>
          <geometry>
            <cylinder>
              <length>0.0366</length>
              <radius>0.0375</radius>
            </cylinder>
          </geometry>
          <surface>
            <contact>
              <ode/>
            </contact>
            <friction>
              <ode>
                <mu>0.9</mu>
                <mu2>0.9</mu2>
              </ode>
              <torsional>
                <ode/>
              </torsional>
            </friction>
            <bounce/>
          </surface>
          <max_contacts>10</max_contacts>
        </collision>
        <collision name='arm_right_7_link_fixed_joint_lump__gripper_right_base_link_collision_1'>
          <pose>0 0 0.017 0 -0 0</pose>
          <geometry>
            <mesh>
              <scale>1 1 1</scale>
              <uri>model://pal_pro_gripper_description/meshes/base_link_tc.stl</uri>
            </mesh>
          </geometry>
          <surface>
            <contact>
              <ode/>
            </contact>
            <friction>
              <ode>
                <mu>0.9</mu>
                <mu2>0.9</mu2>
              </ode>
              <torsional>
                <ode/>
              </torsional>
            </friction>
            <bounce/>
          </surface>
          <max_contacts>10</max_contacts>
        </collision>
        <visual name='arm_right_7_link_visual'>
          <pose>0 0 0 0 -0 0</pose>
          <geometry>
            <mesh>
              <scale>1 1 1</scale>
              <uri>model://pal_sea_arm_description/meshes/arm_tiago_pro/spherical-wrist/arm_7_link.stl</uri>
            </mesh>
          </geometry>
          <material>
            <script>
              <name>Gazebo/DarkGrey</name>
              <uri>file://media/materials/scripts/gazebo.material</uri>
            </script>
          </material>
        </visual>
        <visual name='arm_right_7_link_fixed_joint_lump__gripper_right_base_link_visual_1'>
          <pose>0 0 0.017 0 -0 0</pose>
          <geometry>
            <mesh>
              <scale>1 1 1</scale>
              <uri>model://pal_pro_gripper_description/meshes/base_link_tc.stl</uri>
            </mesh>
          </geometry>
          <material>
            <script>
              <name>Gazebo/DarkGrey</name>
              <uri>file://media/materials/scripts/gazebo.material</uri>
            </script>
          </material>
        </visual>
        <self_collide>0</self_collide>
        <enable_wind>0</enable_wind>
        <kinematic>0</kinematic>
      </link>
      <joint name='gripper_right_finger_joint' type='revolute'>
        <pose relative_to='arm_right_7_link'>0 -0.0288 0.0913 1.5708 0.83776 -1.5708</pose>
        <parent>arm_right_7_link</parent>
        <child>gripper_right_outer_finger_left_link</child>
        <axis>
          <xyz>0 0 1</xyz>
          <limit>
            <lower>0</lower>
            <upper>0.802851</upper>
            <effort>0.1</effort>
            <velocity>2</velocity>
          </limit>
          <dynamics>
            <damping>0.03</damping>
            <friction>0</friction>
            <spring_reference>0</spring_reference>
            <spring_stiffness>0</spring_stiffness>
          </dynamics>
        </axis>
        <physics>
          <ode>
            <limit>
              <cfm>0</cfm>
              <erp>0.2</erp>
            </limit>
            <implicit_spring_damper>1</implicit_spring_damper>
            <cfm_damping>1</cfm_damping>
            <provide_feedback>1</provide_feedback>
          </ode>
          <provide_feedback>1</provide_feedback>
        </physics>
      </joint>
      <link name='gripper_right_outer_finger_left_link'>
        <pose relative_to='gripper_right_finger_joint'>0 0 0 0 -0 0</pose>
        <inertial>
          <pose>-0.001283 0.014397 0 0 -0 0</pose>
          <mass>0.0159888</mass>
          <inertia>
            <ixx>5.98786e-06</ixx>
            <ixy>-5.21729e-07</ixy>
            <ixz>-7.65399e-20</ixz>
            <iyy>4.87251e-07</iyy>
            <iyz>-7.03394e-19</iyz>
            <izz>6.14973e-06</izz>
          </inertia>
        </inertial>
        <collision name='gripper_right_outer_finger_left_link_collision'>
          <pose>0 0 0 0 -0 0</pose>
          <geometry>
            <mesh>
              <scale>1 1 1</scale>
              <uri>model://pal_pro_gripper_description/meshes/outer_finger.stl</uri>
            </mesh>
          </geometry>
          <surface>
            <contact>
              <ode/>
            </contact>
            <friction>
              <ode>
                <mu>0.9</mu>
                <mu2>0.9</mu2>
              </ode>
              <torsional>
                <ode/>
              </torsional>
            </friction>
            <bounce/>
          </surface>
          <max_contacts>10</max_contacts>
        </collision>
        <visual name='gripper_right_outer_finger_left_link_visual'>
          <pose>0 0 0 0 -0 0</pose>
          <geometry>
            <mesh>
              <scale>1 1 1</scale>
              <uri>model://pal_pro_gripper_description/meshes/outer_finger.stl</uri>
            </mesh>
          </geometry>
          <material>
            <script>
              <name>Gazebo/White</name>
              <uri>file://media/materials/scripts/gazebo.material</uri>
            </script>
          </material>
        </visual>
        <self_collide>0</self_collide>
        <enable_wind>0</enable_wind>
        <kinematic>0</kinematic>
      </link>
      <joint name='gripper_right_inner_finger_left_joint' type='revolute'>
        <pose relative_to='arm_right_7_link'>0 -0.013977 0.095832 1.5708 0.83776 -1.5708</pose>
        <parent>arm_right_7_link</parent>
        <child>gripper_right_inner_finger_left_link</child>
        <axis>
          <xyz>0 0 1</xyz>
          <limit>
            <lower>0</lower>
            <upper>0.802851</upper>
            <effort>0.1</effort>
            <velocity>2</velocity>
          </limit>
          <dynamics>
            <spring_reference>0</spring_reference>
            <spring_stiffness>0</spring_stiffness>
          </dynamics>
        </axis>
      </joint>
      <link name='gripper_right_inner_finger_left_link'>
        <pose relative_to='gripper_right_inner_finger_left_joint'>0 0 0 0 -0 0</pose>
        <inertial>
          <pose>-0 0.024759 0 0 -0 0</pose>
          <mass>0.018619</mass>
          <inertia>
            <ixx>4.8806e-06</ixx>
            <ixy>-7.6762e-22</ixy>
            <ixz>1.0244e-22</ixz>
            <iyy>2.5471e-07</iyy>
            <iyz>-1.1841e-21</iyz>
            <izz>4.9573e-06</izz>
          </inertia>
        </inertial>
        <collision name='gripper_right_inner_finger_left_link_collision'>
          <pose>0 0 0 0 -0 0</pose>
          <geometry>
            <mesh>
              <scale>1 1 1</scale>
              <uri>model://pal_pro_gripper_description/meshes/inner_finger.stl</uri>
            </mesh>
          </geometry>
          <surface>
            <contact>
              <ode/>
            </contact>
            <friction>
              <ode>
                <mu>0.9</mu>
                <mu2>0.9</mu2>
              </ode>
              <torsional>
                <ode/>
              </torsional>
            </friction>
            <bounce/>
          </surface>
          <max_contacts>10</max_contacts>
        </collision>
        <visual name='gripper_right_inner_finger_left_link_visual'>
          <pose>0 0 0 0 -0 0</pose>
          <geometry>
            <mesh>
              <scale>1 1 1</scale>
              <uri>model://pal_pro_gripper_description/meshes/inner_finger.stl</uri>
            </mesh>
          </geometry>
          <material>
            <script>
              <name>Gazebo/White</name>
              <uri>file://media/materials/scripts/gazebo.material</uri>
            </script>
          </material>
        </visual>
        <self_collide>0</self_collide>
        <enable_wind>0</enable_wind>
        <kinematic>0</kinematic>
      </link>
      <joint name='gripper_right_fingertip_left_joint' type='revolute'>
        <pose relative_to='gripper_right_inner_finger_left_link'>0 0.05 0 0 -0 0.83776</pose>
        <parent>gripper_right_inner_finger_left_link</parent>
        <child>gripper_right_fingertip_left_link</child>
        <axis>
          <xyz>0 0 1</xyz>
          <limit>
            <lower>-0.802851</lower>
            <upper>0</upper>
            <effort>0.1</effort>
            <velocity>2</velocity>
          </limit>
          <dynamics>
            <spring_reference>0</spring_reference>
            <spring_stiffness>0</spring_stiffness>
          </dynamics>
        </axis>
      </joint>
      <link name='gripper_right_fingertip_left_link'>
        <pose relative_to='gripper_right_fingertip_left_joint'>0 0 0 0 -0 0</pose>
        <inertial>
          <pose>-0.000865 0.011929 -0 0 -0 0</pose>
          <mass>0.033503</mass>
          <inertia>
            <ixx>3.63918e-06</ixx>
            <ixy>3.40522e-07</ixy>
            <ixz>-1.41919e-14</ixz>
            <iyy>1.7095e-06</iyy>
            <iyz>-4.24737e-14</iyz>
            <izz>2.84428e-06</izz>
          </inertia>
        </inertial>
        <collision name='gripper_right_fingertip_left_link_collision'>
          <pose>0 0 0 0 -0 0</pose>
          <geometry>
            <mesh>
              <scale>1 1 1</scale>
              <uri>model://pal_pro_gripper_description/meshes/fingertip.stl</uri>
            </mesh>
          </geometry>
          <surface>
            <contact>
              <ode/>
            </contact>
            <friction>
              <ode>
                <mu>0.9</mu>
                <mu2>0.9</mu2>
              </ode>
              <torsional>
                <ode/>
              </torsional>
            </friction>
            <bounce/>
          </surface>
          <max_contacts>10</max_contacts>
        </collision>
        <visual name='gripper_right_fingertip_left_link_visual'>
          <pose>0 0 0 0 -0 0</pose>
          <geometry>
            <mesh>
              <scale>1 1 1</scale>
              <uri>model://pal_pro_gripper_description/meshes/fingertip.stl</uri>
            </mesh>
          </geometry>
          <material>
            <script>
              <name>Gazebo/White</name>
              <uri>file://media/materials/scripts/gazebo.material</uri>
            </script>
          </material>
        </visual>
        <self_collide>0</self_collide>
        <enable_wind>0</enable_wind>
        <kinematic>0</kinematic>
      </link>
      <joint name='gripper_right_inner_finger_right_joint' type='revolute'>
        <pose relative_to='arm_right_7_link'>0 0.013977 0.095832 1.5708 0.83776 1.5708</pose>
        <parent>arm_right_7_link</parent>
        <child>gripper_right_inner_finger_right_link</child>
        <axis>
          <xyz>0 0 1</xyz>
          <limit>
            <lower>0</lower>
            <upper>0.802851</upper>
            <effort>0.1</effort>
            <velocity>2</velocity>
          </limit>
          <dynamics>
            <spring_reference>0</spring_reference>
            <spring_stiffness>0</spring_stiffness>
          </dynamics>
        </axis>
      </joint>
      <link name='gripper_right_inner_finger_right_link'>
        <pose relative_to='gripper_right_inner_finger_right_joint'>0 0 0 0 -0 0</pose>
        <inertial>
          <pose>-0 0.024759 0 0 -0 0</pose>
          <mass>0.018619</mass>
          <inertia>
            <ixx>4.8806e-06</ixx>
            <ixy>-7.6762e-22</ixy>
            <ixz>1.0244e-22</ixz>
            <iyy>2.5471e-07</iyy>
            <iyz>-1.1841e-21</iyz>
            <izz>4.9573e-06</izz>
          </inertia>
        </inertial>
        <collision name='gripper_right_inner_finger_right_link_collision'>
          <pose>0 0 0 0 -0 0</pose>
          <geometry>
            <mesh>
              <scale>1 1 1</scale>
              <uri>model://pal_pro_gripper_description/meshes/inner_finger.stl</uri>
            </mesh>
          </geometry>
          <surface>
            <contact>
              <ode/>
            </contact>
            <friction>
              <ode>
                <mu>0.9</mu>
                <mu2>0.9</mu2>
              </ode>
              <torsional>
                <ode/>
              </torsional>
            </friction>
            <bounce/>
          </surface>
          <max_contacts>10</max_contacts>
        </collision>
        <visual name='gripper_right_inner_finger_right_link_visual'>
          <pose>0 0 0 0 -0 0</pose>
          <geometry>
            <mesh>
              <scale>1 1 1</scale>
              <uri>model://pal_pro_gripper_description/meshes/inner_finger.stl</uri>
            </mesh>
          </geometry>
          <material>
            <script>
              <name>Gazebo/White</name>
              <uri>file://media/materials/scripts/gazebo.material</uri>
            </script>
          </material>
        </visual>
        <self_collide>0</self_collide>
        <enable_wind>0</enable_wind>
        <kinematic>0</kinematic>
      </link>
      <joint name='gripper_right_fingertip_right_joint' type='revolute'>
        <pose relative_to='gripper_right_inner_finger_right_link'>0 0.05 0 0 -0 0.83776</pose>
        <parent>gripper_right_inner_finger_right_link</parent>
        <child>gripper_right_fingertip_right_link</child>
        <axis>
          <xyz>0 0 1</xyz>
          <limit>
            <lower>-0.802851</lower>
            <upper>0</upper>
            <effort>0.1</effort>
            <velocity>2</velocity>
          </limit>
          <dynamics>
            <spring_reference>0</spring_reference>
            <spring_stiffness>0</spring_stiffness>
          </dynamics>
        </axis>
      </joint>
      <link name='gripper_right_fingertip_right_link'>
        <pose relative_to='gripper_right_fingertip_right_joint'>0 0 0 0 -0 0</pose>
        <inertial>
          <pose>-0.000865 0.011929 -0 0 -0 0</pose>
          <mass>0.033503</mass>
          <inertia>
            <ixx>3.63918e-06</ixx>
            <ixy>3.40522e-07</ixy>
            <ixz>-1.41919e-14</ixz>
            <iyy>1.7095e-06</iyy>
            <iyz>-4.24737e-14</iyz>
            <izz>2.84428e-06</izz>
          </inertia>
        </inertial>
        <collision name='gripper_right_fingertip_right_link_collision'>
          <pose>0 0 0 0 -0 0</pose>
          <geometry>
            <mesh>
              <scale>1 1 1</scale>
              <uri>model://pal_pro_gripper_description/meshes/fingertip.stl</uri>
            </mesh>
          </geometry>
          <surface>
            <contact>
              <ode/>
            </contact>
            <friction>
              <ode>
                <mu>0.9</mu>
                <mu2>0.9</mu2>
              </ode>
              <torsional>
                <ode/>
              </torsional>
            </friction>
            <bounce/>
          </surface>
          <max_contacts>10</max_contacts>
        </collision>
        <visual name='gripper_right_fingertip_right_link_visual'>
          <pose>0 0 0 0 -0 0</pose>
          <geometry>
            <mesh>
              <scale>1 1 1</scale>
              <uri>model://pal_pro_gripper_description/meshes/fingertip.stl</uri>
            </mesh>
          </geometry>
          <material>
            <script>
              <name>Gazebo/White</name>
              <uri>file://media/materials/scripts/gazebo.material</uri>
            </script>
          </material>
        </visual>
        <self_collide>0</self_collide>
        <enable_wind>0</enable_wind>
        <kinematic>0</kinematic>
      </link>
      <joint name='gripper_right_outer_finger_right_joint' type='revolute'>
        <pose relative_to='arm_right_7_link'>0 0.0288 0.0913 1.5708 0.83776 1.5708</pose>
        <parent>arm_right_7_link</parent>
        <child>gripper_right_outer_finger_right_link</child>
        <axis>
          <xyz>0 0 1</xyz>
          <limit>
            <lower>0</lower>
            <upper>0.802851</upper>
            <effort>0.1</effort>
            <velocity>2</velocity>
          </limit>
          <dynamics>
            <spring_reference>0</spring_reference>
            <spring_stiffness>0</spring_stiffness>
          </dynamics>
        </axis>
      </joint>
      <link name='gripper_right_outer_finger_right_link'>
        <pose relative_to='gripper_right_outer_finger_right_joint'>0 0 0 0 -0 0</pose>
        <inertial>
          <pose>-0.001283 0.014397 0 0 -0 0</pose>
          <mass>0.0159888</mass>
          <inertia>
            <ixx>5.98786e-06</ixx>
            <ixy>-5.21729e-07</ixy>
            <ixz>-7.65399e-20</ixz>
            <iyy>4.87251e-07</iyy>
            <iyz>-7.03394e-19</iyz>
            <izz>6.14973e-06</izz>
          </inertia>
        </inertial>
        <collision name='gripper_right_outer_finger_right_link_collision'>
          <pose>0 0 0 0 -0 0</pose>
          <geometry>
            <mesh>
              <scale>1 1 1</scale>
              <uri>model://pal_pro_gripper_description/meshes/outer_finger.stl</uri>
            </mesh>
          </geometry>
          <surface>
            <contact>
              <ode/>
            </contact>
            <friction>
              <ode>
                <mu>0.9</mu>
                <mu2>0.9</mu2>
              </ode>
              <torsional>
                <ode/>
              </torsional>
            </friction>
            <bounce/>
          </surface>
          <max_contacts>10</max_contacts>
        </collision>
        <visual name='gripper_right_outer_finger_right_link_visual'>
          <pose>0 0 0 0 -0 0</pose>
          <geometry>
            <mesh>
              <scale>1 1 1</scale>
              <uri>model://pal_pro_gripper_description/meshes/outer_finger.stl</uri>
            </mesh>
          </geometry>
          <material>
            <script>
              <name>Gazebo/White</name>
              <uri>file://media/materials/scripts/gazebo.material</uri>
            </script>
          </material>
        </visual>
        <self_collide>0</self_collide>
        <enable_wind>0</enable_wind>
        <kinematic>0</kinematic>
      </link>
      <joint name='head_1_joint' type='revolute'>
        <pose relative_to='torso_lift_link'>0 0 0.04 0 -0 0</pose>
        <parent>torso_lift_link</parent>
        <child>head_1_link</child>
        <axis>
          <xyz>0 0 1</xyz>
          <limit>
            <lower>-1.309</lower>
            <upper>1.309</upper>
            <effort>5.197</effort>
            <velocity>3</velocity>
          </limit>
          <dynamics>
            <damping>0.5</damping>
            <friction>1</friction>
            <spring_reference>0</spring_reference>
            <spring_stiffness>0</spring_stiffness>
          </dynamics>
        </axis>
        <physics>
          <ode>
            <implicit_spring_damper>1</implicit_spring_damper>
            <cfm_damping>1</cfm_damping>
            <limit>
              <cfm>0</cfm>
              <erp>0.2</erp>
            </limit>
          </ode>
        </physics>
      </joint>
      <link name='head_1_link'>
        <pose relative_to='head_1_joint'>0 0 0 0 -0 0</pose>
        <inertial>
          <pose>-0.003746 -4.7e-05 0.1055 0 -0 0</pose>
          <mass>0.15566</mass>
          <inertia>
            <ixx>0.0005208</ixx>
            <ixy>3.0453e-07</ixy>
            <ixz>-6.1005e-05</ixz>
            <iyy>0.00035021</iyy>
            <iyz>5.8627e-07</iyz>
            <izz>0.00033341</izz>
          </inertia>
        </inertial>
        <collision name='head_1_link_collision'>
          <pose>0 0 0 0 -0 0</pose>
          <geometry>
            <mesh>
              <scale>1 1 1</scale>
              <uri>model://tiago_pro_head_description/meshes/head_1_link_collision.stl</uri>
            </mesh>
          </geometry>
          <surface>
            <contact>
              <ode/>
            </contact>
            <friction>
              <ode>
                <mu>0.9</mu>
                <mu2>0.9</mu2>
              </ode>
              <torsional>
                <ode/>
              </torsional>
            </friction>
            <bounce/>
          </surface>
          <max_contacts>10</max_contacts>
        </collision>
        <visual name='head_1_link_visual'>
          <pose>0 0 0 0 -0 0</pose>
          <geometry>
            <mesh>
              <scale>1 1 1</scale>
              <uri>model://tiago_pro_head_description/meshes/head_1_link.stl</uri>
            </mesh>
          </geometry>
          <material>
            <script>
              <name>Gazebo/DarkGrey</name>
              <uri>file://media/materials/scripts/gazebo.material</uri>
            </script>
          </material>
        </visual>
        <self_collide>0</self_collide>
        <enable_wind>0</enable_wind>
        <kinematic>0</kinematic>
      </link>
      <joint name='head_2_joint' type='revolute'>
        <pose relative_to='head_1_link'>0.0425 0 0.10585 1.5708 -0 3.14159</pose>
        <parent>head_1_link</parent>
        <child>head_2_link</child>
        <axis>
          <xyz>0 0 -1</xyz>
          <limit>
            <lower>-1.0472</lower>
            <upper>0.34907</upper>
            <effort>2.77</effort>
            <velocity>3</velocity>
          </limit>
          <dynamics>
            <damping>0.5</damping>
            <friction>1</friction>
            <spring_reference>0</spring_reference>
            <spring_stiffness>0</spring_stiffness>
          </dynamics>
        </axis>
        <physics>
          <ode>
            <implicit_spring_damper>1</implicit_spring_damper>
            <cfm_damping>1</cfm_damping>
            <limit>
              <cfm>0</cfm>
              <erp>0.2</erp>
            </limit>
          </ode>
        </physics>
      </joint>
      <link name='head_2_link'>
        <pose relative_to='head_2_joint'>0 0 0 0 -0 0</pose>
        <inertial>
          <pose>-0.012157 0.118351 0.001013 0 -0 0</pose>
          <mass>0.918359</mass>
          <inertia>
            <ixx>0.0103336</ixx>
            <ixy>-0.000394794</ixy>
            <ixz>4.21719e-05</ixz>
            <iyy>0.00905778</iyy>
            <iyz>-6.96497e-05</iyz>
            <izz>0.0033149</izz>
          </inertia>
        </inertial>
        <collision name='head_2_link_collision'>
          <pose>0 0 0 0 -0 0</pose>
          <geometry>
            <mesh>
              <scale>1 1 1</scale>
              <uri>model://tiago_pro_head_description/meshes/head_2_link_collision.stl</uri>
            </mesh>
          </geometry>
          <surface>
            <contact>
              <ode/>
            </contact>
            <friction>
              <ode>
                <mu>0.9</mu>
                <mu2>0.9</mu2>
              </ode>
              <torsional>
                <ode/>
              </torsional>
            </friction>
            <bounce/>
          </surface>
          <max_contacts>10</max_contacts>
        </collision>
        <collision name='head_2_link_fixed_joint_lump__head_front_camera_link_collision_1'>
          <pose>-0.0522 0.168 -0 1.5708 -0 -3.14159</pose>
          <geometry>
            <box>
              <size>0.02505 0.09 0.025</size>
            </box>
          </geometry>
          <surface>
            <contact>
              <ode>
                <kp>1e+13</kp>
                <kd>1</kd>
              </ode>
            </contact>
            <friction>
              <ode>
                <mu2>1</mu2>
                <fdir1>0 0 0</fdir1>
              </ode>
              <torsional>
                <ode/>
              </torsional>
            </friction>
            <bounce/>
          </surface>
          <max_contacts>10</max_contacts>
        </collision>
        <visual name='head_2_link_visual'>
          <pose>0 0 0 0 -0 0</pose>
          <geometry>
            <mesh>
              <scale>1 1 1</scale>
              <uri>model://tiago_pro_head_description/meshes/head_2_link.stl</uri>
            </mesh>
          </geometry>
          <material>
            <script>
              <name>Gazebo/White</name>
              <uri>file://media/materials/scripts/gazebo.material</uri>
            </script>
          </material>
        </visual>
        <visual name='head_2_link_fixed_joint_lump__head_front_camera_link_visual_1'>
          <pose>-0.0565 0.168 -0 -3.14159 -1.57079 3.14159</pose>
          <geometry>
            <mesh>
              <scale>1 1 1</scale>
              <uri>file:///opt/pal/alum/share/realsense2_description/meshes/d435.dae</uri>
            </mesh>
          </geometry>
        </visual>
        <self_collide>0</self_collide>
        <enable_wind>0</enable_wind>
        <kinematic>0</kinematic>
        <gravity>1</gravity>
        <sensor name='head_front_cameracolor' type='camera'>
          <camera name='head_front_camera'>
            <horizontal_fov>1.21126</horizontal_fov>
            <image>
              <width>640</width>
              <height>480</height>
              <format>RGB_INT8</format>
            </image>
            <clip>
              <near>0.1</near>
              <far>100</far>
            </clip>
            <noise>
              <type>gaussian</type>
              <mean>0</mean>
              <stddev>0.007</stddev>
            </noise>
          </camera>
          <always_on>1</always_on>
          <update_rate>30</update_rate>
          <visualize>1</visualize>
          <pose>-0.0522 0.168 0.0175 1.5708 -0 -3.14159</pose>
        </sensor>
        <sensor name='head_front_cameraired1' type='camera'>
          <camera name='head_front_camera'>
            <horizontal_fov>1.48702</horizontal_fov>
            <image>
              <width>1280</width>
              <height>720</height>
              <format>L_INT8</format>
            </image>
            <clip>
              <near>0.1</near>
              <far>100</far>
            </clip>
            <noise>
              <type>gaussian</type>
              <mean>0</mean>
              <stddev>0.05</stddev>
            </noise>
          </camera>
          <always_on>1</always_on>
          <update_rate>30</update_rate>
          <visualize>0</visualize>
          <pose>-0.0522 0.168 0.0175 1.5708 -0 -3.14159</pose>
        </sensor>
        <sensor name='head_front_cameraired2' type='camera'>
          <camera name='head_front_camera'>
            <horizontal_fov>1.48702</horizontal_fov>
            <image>
              <width>1280</width>
              <height>720</height>
              <format>L_INT8</format>
            </image>
            <clip>
              <near>0.1</near>
              <far>100</far>
            </clip>
            <noise>
              <type>gaussian</type>
              <mean>0</mean>
              <stddev>0.05</stddev>
            </noise>
          </camera>
          <always_on>1</always_on>
          <update_rate>30</update_rate>
          <visualize>0</visualize>
          <pose>-0.0522 0.168 0.0175 1.5708 -0 -3.14159</pose>
        </sensor>
        <sensor name='head_front_cameradepth' type='depth'>
          <camera name='head_front_camera'>
            <horizontal_fov>1.48702</horizontal_fov>
            <image>
              <width>1280</width>
              <height>720</height>
            </image>
            <clip>
              <near>0.1</near>
              <far>100</far>
            </clip>
            <noise>
              <type>gaussian</type>
              <mean>0</mean>
              <stddev>0.1</stddev>
            </noise>
          </camera>
          <always_on>1</always_on>
          <update_rate>30</update_rate>
          <visualize>0</visualize>
          <pose>-0.0522 0.168 0.0175 1.5708 -0 -3.14159</pose>
        </sensor>
      </link>
      <plugin name='gazebo_ros_planar_move' filename='libgazebo_ros_planar_move.so'>
        <ros>
          <remapping>cmd_vel:=mobile_base_controller/cmd_vel_unstamped</remapping>
          <remapping>odom:=mobile_base_controller/odom</remapping>
        </ros>
        <update_rate>100</update_rate>
        <publish_rate>1000</publish_rate>
        <publish_odom>1</publish_odom>
        <publish_odom_tf>0</publish_odom_tf>
        <odometry_frame>odom</odometry_frame>
        <robot_base_frame>base_footprint</robot_base_frame>
        <covariance_x>0.0001</covariance_x>
        <covariance_y>0.0001</covariance_y>
        <covariance_yaw>0.01</covariance_yaw>
      </plugin>
      <plugin name='head_front_camera' filename='librealsense_gazebo_plugin.so'>
        <prefix>head_front_camera</prefix>
        <depthUpdateRate>30.0</depthUpdateRate>
        <colorUpdateRate>30.0</colorUpdateRate>
        <infraredUpdateRate>30.0</infraredUpdateRate>
        <depthTopicName>depth/image_raw</depthTopicName>
        <colorTopicName>color/image_raw</colorTopicName>
        <infrared1TopicName>infra1/image_raw</infrared1TopicName>
        <infrared2TopicName>infra2/image_raw</infrared2TopicName>
        <colorOpticalframeName>head_front_camera_color_optical_frame</colorOpticalframeName>
        <depthOpticalframeName>head_front_camera_depth_optical_frame</depthOpticalframeName>
        <infrared1OpticalframeName>head_front_camera_infra1_ir_optical_frame</infrared1OpticalframeName>
        <infrared2OpticalframeName>head_front_camera_infra2_ir_optical_frame</infrared2OpticalframeName>
        <rangeMinDepth>0.2</rangeMinDepth>
        <rangeMaxDepth>10.0</rangeMaxDepth>
        <pointCloud>1</pointCloud>
        <pointCloudTopicName>depth/color/points</pointCloudTopicName>
        <pointCloudCutoff>0.25</pointCloudCutoff>
        <pointCloudCutoffMax>9.0</pointCloudCutoffMax>
      </plugin>
      <static>0</static>
      <plugin name='gazebo_ros2_control' filename='libgazebo_ros2_control.so'>
        <parameters>/opt/pal/alum/share/tiago_pro_description/ros2_control/gazebo_controller_manager_cfg.yaml</parameters>
      </plugin>
      <pose>0 0 0 0 -0 0</pose>
    </model>
    <model name='MaleVisitorSit'>
      <static>1</static>
      <link name='body'>
        <pose>0 0 0 0 -0 0</pose>
        <visual name='visual'>
          <geometry>
            <mesh>
              <uri>model://MaleVisitorSit/meshes/MaleVisitorSit.obj</uri>
            </mesh>
          </geometry>
        </visual>
        <collision name='collision'>
          <geometry>
            <mesh>
              <uri>model://MaleVisitorSit/meshes/MaleVisitorSit_Col.obj</uri>
            </mesh>
          </geometry>
          <max_contacts>10</max_contacts>
          <surface>
            <contact>
              <ode/>
            </contact>
            <bounce/>
            <friction>
              <torsional>
                <ode/>
              </torsional>
              <ode/>
            </friction>
          </surface>
        </collision>
        <self_collide>0</self_collide>
        <enable_wind>0</enable_wind>
        <kinematic>0</kinematic>
      </link>
      <pose>1.86548 0.090942 0 0 -0 0</pose>
    </model>
    <state world_name='default'>
      <sim_time>174 22000000</sim_time>
      <real_time>82 3264482</real_time>
      <wall_time>1740316207 124379899</wall_time>
      <iterations>34222</iterations>
      <model name='MaleVisitorSit'>
        <pose>1.72474 -0.013736 0 0 -0 1.56203</pose>
        <scale>1 1 1</scale>
        <link name='body'>
          <pose>1.72474 -0.013736 0 0 -0 1.56203</pose>
          <velocity>0 0 0 0 -0 0</velocity>
          <acceleration>0 0 0 0 -0 0</acceleration>
          <wrench>0 0 0 0 -0 0</wrench>
        </link>
      </model>
      <model name='ground_plane'>
        <pose>0 0 0 0 -0 0</pose>
        <scale>1 1 1</scale>
        <link name='link'>
          <pose>0 0 0 0 -0 0</pose>
          <velocity>0 0 0 0 -0 0</velocity>
          <acceleration>0 0 0 0 -0 0</acceleration>
          <wrench>0 0 0 0 -0 0</wrench>
        </link>
      </model>
      <model name='tiago-pro'>
        <pose>-0.019866 -0.00026 -5.4e-05 0 -0 0.003496</pose>
        <scale>1 1 1</scale>
        <link name='arm_left_1_link'>
          <pose>0.044838 0.159148 0.853628 -2.09616 0.314811 -1.39581</pose>
          <velocity>-0.000125 0 -0.008928 -0.000475 -0.000177 0.000284</velocity>
          <acceleration>-0.039487 -0.008764 -8.96664 -1.07342 -0.479546 0.568247</acceleration>
          <wrench>-0.04472 -0.009925 -10.1547 0 -0 0</wrench>
        </link>
        <link name='arm_left_2_link'>
          <pose>0.188651 0.182566 0.739847 2.00205 0.736634 0.474784</pose>
          <velocity>-0.000111 -1.3e-05 -0.008914 -0.00028 -0.001272 -7.9e-05</velocity>
          <acceleration>0.079431 -0.030294 -9.06824 -0.346387 -0.711215 0.08206</acceleration>
          <wrench>0.082894 -0.031615 -9.46362 0 -0 0</wrench>
        </link>
        <link name='arm_left_3_link'>
          <pose>0.070844 0.239869 0.623432 3.09973 0.831857 -0.18237</pose>
          <velocity>4.1e-05 -3.6e-05 -0.00908 -6.3e-05 -0.001299 0.000119</velocity>
          <acceleration>0.255312 -0.053078 -9.23245 0.035443 -1.30287 0.164454</acceleration>
          <wrench>0.289141 -0.06011 -10.4558 0 -0 0</wrench>
        </link>
        <link name='arm_left_4_link'>
          <pose>-0.027653 0.288932 0.50001 -2.05918 -1.51069 0.336219</pose>
          <velocity>0.000195 -5.6e-05 -0.009211 0.000412 0.001812 3.1e-05</velocity>
          <acceleration>0.236348 -0.043266 -9.4725 0.565296 0.982984 0.193584</acceleration>
          <wrench>0.246653 -0.045152 -9.8855 0 -0 0</wrench>
        </link>
        <link name='arm_left_5_link'>
          <pose>0.133505 0.22599 0.472068 -2.63014 1.50992 -2.78227</pose>
          <velocity>0.000147 -3.9e-05 -0.009529 0.000335 0.001824 3.6e-05</velocity>
          <acceleration>0.224106 -0.03741 -9.69413 1.79176 0.635127 -2.62396</acceleration>
          <wrench>0.069644 -0.011626 -3.01258 0 -0 0</wrench>
        </link>
        <link name='arm_left_6_link'>
          <pose>0.290386 0.159131 0.46455 -1.53638 -0.423672 2.97618</pose>
          <velocity>0.000135 -3.1e-05 -0.009837 -0.000119 -0.00115 0.00013</velocity>
          <acceleration>0.190451 -0.033487 -9.90391 -0.24978 -1.1331 0.145297</acceleration>
          <wrench>0.256322 -0.04507 -13.3294 0 -0 0</wrench>
        </link>
        <link name='arm_left_7_link'>
          <pose>0.255744 0.209535 0.540654 0.034418 -0.423672 2.97618</pose>
          <velocity>4.1e-05 -2.7e-05 -0.009883 -0.000124 -0.00115 0.000119</velocity>
          <acceleration>0.071276 -0.020523 -9.89856 -0.113125 -1.15393 0.162148</acceleration>
          <wrench>0.033915 -0.009765 -4.70996 0 -0 0</wrench>
        </link>
        <link name='arm_right_1_link'>
          <pose>0.04595 -0.159211 0.853629 -2.09616 -0.314811 -1.73879</pose>
          <velocity>-0.000121 -1e-06 -0.008928 0.000525 -0.000193 -0.000292</velocity>
          <acceleration>-0.04057 0.008558 -8.97074 1.13793 -0.375884 -0.56583</acceleration>
          <wrench>-0.045945 0.009692 -10.1594 0 -0 0</wrench>
        </link>
        <link name='arm_right_2_link'>
          <pose>0.178125 -0.251202 0.762828 1.13953 0.73663 -0.467801</pose>
          <velocity>-0.000131 8e-06 -0.00895 0.000344 -0.001272 6.2e-05</velocity>
          <acceleration>0.077525 0.038146 -9.07396 0.41659 -0.687401 0.407607</acceleration>
          <wrench>0.080905 0.039809 -9.46958 0 -0 0</wrench>
        </link>
        <link name='arm_right_3_link'>
          <pose>0.072521 -0.239749 0.623432 -3.09974 0.831856 0.18935</pose>
          <velocity>4.5e-05 4.9e-05 -0.009081 4.1e-05 -0.001312 -0.000215</velocity>
          <acceleration>0.257694 0.072982 -9.23571 -0.093879 -1.33222 -0.262434</acceleration>
          <wrench>0.291839 0.082652 -10.4594 0 -0 0</wrench>
        </link>
        <link name='arm_right_4_link'>
          <pose>-0.037334 -0.216238 0.502102 -1.08239 -1.51069 -0.329257</pose>
          <velocity>0.00021 7.8e-05 -0.009224 -0.000455 0.001799 -0.000126</velocity>
          <acceleration>0.241377 0.050603 -9.4755 -0.612808 0.940177 0.109319</acceleration>
          <wrench>0.251901 0.052809 -9.88863 0 -0 0</wrench>
        </link>
        <link name='arm_right_5_link'>
          <pose>0.135084 -0.225434 0.472069 2.67688 1.51142 2.83607</pose>
          <velocity>0.000154 4.3e-05 -0.00953 -0.000386 0.00181 -0.000129</velocity>
          <acceleration>0.222698 0.030263 -9.69087 0.467058 1.17138 -2.62296</acceleration>
          <wrench>0.069206 0.009404 -3.01156 0 -0 0</wrench>
        </link>
        <link name='arm_right_6_link'>
          <pose>0.304802 -0.240794 0.462172 -1.59823 -0.423742 -2.97175</pose>
          <velocity>0.000135 1.7e-05 -0.009831 9.3e-05 -0.001187 -0.000206</velocity>
          <acceleration>0.196646 0.01967 -9.9049 -0.02749 -1.14665 -0.211648</acceleration>
          <wrench>0.26466 0.026473 -13.3307 0 -0 0</wrench>
        </link>
        <link name='arm_right_7_link'>
          <pose>0.25713 -0.207656 0.540668 -0.02743 -0.423742 -2.97175</pose>
          <velocity>4.8e-05 1.9e-05 -0.009885 0.000136 -0.001183 -0.00011</velocity>
          <acceleration>0.074008 0.009076 -9.89962 0.163428 -1.17436 -0.039771</acceleration>
          <wrench>0.035215 0.004318 -4.71047 0 -0 0</wrench>
        </link>
        <link name='base_footprint'>
          <pose>-0.019866 -0.00026 -5.4e-05 0 -0 0.003496</pose>
          <velocity>-0.000123 -1e-06 5.7e-05 -0 1e-06 1e-05</velocity>
          <acceleration>-0.040805 -0.000202 0.019334 -8.9e-05 4.8e-05 0.003372</acceleration>
          <wrench>-1.66762 -0.00826 0.790135 0 -0 0</wrench>
        </link>
        <link name='gripper_left_fingertip_left_link'>
          <pose>0.317885 0.250176 0.661724 1.99469 0.031378 1.41954</pose>
          <velocity>-9.6e-05 -3.8e-05 -0.009791 -0.002165 -0.000808 0.001055</velocity>
          <acceleration>-0.021615 -0.011894 -9.82273 -2.80364 -0.472377 1.088</acceleration>
          <wrench>-0.000724 -0.000398 -0.329091 0 -0 0</wrench>
        </link>
        <link name='gripper_left_fingertip_right_link'>
          <pose>0.304114 0.159829 0.664592 1.14691 -0.031372 -1.72205</pose>
          <velocity>-7.5e-05 3.5e-05 -0.009791 0.001521 -0.001425 -0.000635</velocity>
          <acceleration>-0.008248 0.013073 -9.82207 1.81457 -0.572148 -0.593458</acceleration>
          <wrench>-0.000276 0.000438 -0.329069 0 -0 0</wrench>
        </link>
        <link name='gripper_left_inner_finger_left_link'>
          <pose>0.297229 0.220115 0.627523 2.11197 0.646726 1.75285</pose>
          <velocity>-6e-05 -1.1e-05 -0.009837 0.00066 -0.001278 -0.000236</velocity>
          <acceleration>0.004155 -0.026578 -9.85258 1.12993 0.634261 0.553775</acceleration>
          <wrench>7.7e-05 -0.000495 -0.183445 0 -0 0</wrench>
        </link>
        <link name='gripper_left_inner_finger_right_link'>
          <pose>0.293019 0.192494 0.6284 1.05428 0.587284 -2.04109</pose>
          <velocity>-5.8e-05 -1.1e-05 -0.009838 -0.001103 -0.000986 0.000564</velocity>
          <acceleration>0.015625 0.00952 -9.85359 2.85566 -0.732343 0.026239</acceleration>
          <wrench>0.000291 0.000177 -0.183464 0 -0 0</wrench>
        </link>
        <link name='gripper_left_outer_finger_left_link'>
          <pose>0.297599 0.234915 0.622929 2.11197 0.646728 1.75285</pose>
          <velocity>-5.6e-05 -1.1e-05 -0.009838 -1.2e-05 -0.001169 6.7e-05</velocity>
          <acceleration>0.012891 -0.012959 -9.86979 0.144465 0.004259 0.152576</acceleration>
          <wrench>0.000206 -0.000207 -0.157806 0 -0 0</wrench>
        </link>
        <link name='gripper_left_outer_finger_right_link'>
          <pose>0.288924 0.178 0.624736 1.05428 0.587284 -2.04109</pose>
          <velocity>-5.2e-05 -1.2e-05 -0.009841 -0.000895 -0.001021 0.000472</velocity>
          <acceleration>0.022638 -0.002537 -9.86841 2.7634 -1.55615 -1.2087</acceleration>
          <wrench>0.000362 -4.1e-05 -0.157784 0 -0 0</wrench>
        </link>
        <link name='gripper_right_fingertip_left_link'>
          <pose>0.30501 -0.156819 0.664338 1.99468 -0.024999 1.72935</pose>
          <velocity>-7.5e-05 -3.8e-05 -0.009795 -0.001826 -0.00152 0.000789</velocity>
          <acceleration>-0.01113 -0.015811 -9.82534 -2.60824 -0.938332 0.656648</acceleration>
          <wrench>-0.000373 -0.00053 -0.329178 0 -0 0</wrench>
        </link>
        <link name='gripper_right_fingertip_right_link'>
          <pose>0.319443 -0.247078 0.662052 1.14692 0.025005 -1.41223</pose>
          <velocity>-9.3e-05 3.6e-05 -0.009786 0.001873 -0.000883 -0.00091</velocity>
          <acceleration>-0.022053 0.009384 -9.81791 2.24853 -0.154199 -0.954155</acceleration>
          <wrench>-0.000739 0.000314 -0.32893 0 -0 0</wrench>
        </link>
        <link name='gripper_right_inner_finger_left_link'>
          <pose>0.29419 -0.189791 0.628341 2.08972 0.593335 2.04973</pose>
          <velocity>-5.4e-05 3e-06 -0.009839 0.000984 -0.001037 -0.000496</velocity>
          <acceleration>0.015451 -0.01893 -9.85561 -2.9204 -0.807309 0.15126</acceleration>
          <wrench>0.000288 -0.000352 -0.183502 0 -0 0</wrench>
        </link>
        <link name='gripper_right_inner_finger_right_link'>
          <pose>0.298603 -0.217386 0.627642 1.03225 0.640708 -1.74398</pose>
          <velocity>-5.6e-05 3e-06 -0.009837 -0.000785 -0.001337 0.000306</velocity>
          <acceleration>0.004947 0.017343 -9.85044 -1.35361 0.758567 -0.65838</acceleration>
          <wrench>9.2e-05 0.000323 -0.183405 0 -0 0</wrench>
        </link>
        <link name='gripper_right_outer_finger_left_link'>
          <pose>0.289993 -0.175351 0.624582 2.08972 0.593336 2.04973</pose>
          <velocity>-4.8e-05 4e-06 -0.009842 0.000267 -0.001161 -0.000171</velocity>
          <acceleration>0.020475 -0.0013 -9.87374 0.039059 -1.40554 -1.35753</acceleration>
          <wrench>0.000327 -2.1e-05 -0.157869 0 -0 0</wrench>
        </link>
        <link name='gripper_right_outer_finger_right_link'>
          <pose>0.299086 -0.23221 0.623142 1.03225 0.640709 -1.74397</pose>
          <velocity>-5.2e-05 3e-06 -0.009839 -0.000554 -0.001301 0.000205</velocity>
          <acceleration>0.014468 0.008566 -9.86499 -0.483982 0.034907 0.113305</acceleration>
          <wrench>0.000231 0.000137 -0.157729 0 -0 0</wrench>
        </link>
        <link name='head_1_link'>
          <pose>-0.044366 -0.000346 0.985637 0 -0 0.003497</pose>
          <velocity>-0.000125 -1e-06 -0.008928 0 1e-06 1.8e-05</velocity>
          <acceleration>-0.042526 -0.000839 -8.96476 -0.000653 0.004534 0.011394</acceleration>
          <wrench>-0.00662 -0.000131 -1.39545 0 -0 0</wrench>
        </link>
        <link name='head_2_link'>
          <pose>-0.001867 -0.000197 1.09149 1.5708 -1e-06 -3.1381</pose>
          <velocity>-0.000125 -0 -0.008927 -2e-06 0.000815 1.8e-05</velocity>
          <acceleration>0.054271 0.000108 -8.97435 3.11087 0.902714 -3.1255</acceleration>
          <wrench>0.04984 9.9e-05 -8.24168 0 -0 0</wrench>
        </link>
        <link name='torso_lift_link'>
          <pose>-0.044365 -0.000345 0.945637 -0 -2e-06 0.003496</pose>
          <velocity>-0.000123 -1e-06 -0.008927 0 -5e-06 1e-05</velocity>
          <acceleration>-0.041155 -0.000683 -8.96462 -7.7e-05 -0.000552 0.00337</acceleration>
          <wrench>-0.141494 -0.002349 -30.8211 0 -0 0</wrench>
        </link>
        <link name='wheel_front_left_link'>
          <pose>0.223352 0.223767 0.076145 -1.5708 -3.3e-05 0.003496</pose>
          <velocity>-0.000125 2e-06 5.6e-05 -3e-06 -0 1e-05</velocity>
          <acceleration>-0.041524 0.000614 0.019218 -0.003175 -0.001345 0.00379</acceleration>
          <wrench>-0.029385 0.000435 0.0136 0 -0 0</wrench>
        </link>
        <link name='wheel_front_right_link'>
          <pose>0.224913 -0.222581 0.076146 -1.5708 -8.1e-05 0.003496</pose>
          <velocity>-0.00012 2e-06 5.6e-05 4e-06 -2e-06 1e-05</velocity>
          <acceleration>-0.04009 0.000614 0.019238 0.003539 -0.00325 0.00383</acceleration>
          <wrench>-0.028371 0.000435 0.013614 0 -0 0</wrench>
        </link>
        <link name='wheel_rear_left_link'>
          <pose>-0.264645 0.222061 0.076146 -1.5708 -0.000129 0.003496</pose>
          <velocity>-0.000125 -3e-06 5.7e-05 6e-06 -5e-06 1e-05</velocity>
          <acceleration>-0.041511 -0.001043 0.019401 0.005479 -0.00522 0.003781</acceleration>
          <wrench>-0.029376 -0.000738 0.01373 0 -0 0</wrench>
        </link>
        <link name='wheel_rear_right_link'>
          <pose>-0.263084 -0.224287 0.076146 -1.5708 -0.000178 0.003496</pose>
          <velocity>-0.00012 -3e-06 5.7e-05 -5e-06 -7e-06 1e-05</velocity>
          <acceleration>-0.040078 -0.001032 0.019435 -0.004964 -0.007284 0.003822</acceleration>
          <wrench>-0.028362 -0.000731 0.013754 0 -0 0</wrench>
        </link>
      </model>
      <model name='unit_box'>
        <pose>1.70393 0.022433 0.210932 0 -0 0</pose>
        <scale>0.442999 1 0.421864</scale>
        <link name='link'>
          <pose>1.70393 0.022433 0.210932 0 -0 0</pose>
          <velocity>0 0 0 0 -0 0</velocity>
          <acceleration>-0 -0 0 0 -0 0</acceleration>
          <wrench>-0 -0 0 0 -0 0</wrench>
        </link>
      </model>
      <light name='sun'>
        <pose>0 0 10 0 -0 0</pose>
      </light>
    </state>
    <gui fullscreen='0'>
      <camera name='user_camera'>
        <pose>-4.99041 -0.001592 2.28904 0 0.191643 -0.215807</pose>
        <view_controller>orbit</view_controller>
        <projection_type>perspective</projection_type>
      </camera>
    </gui>
    <model name='unit_box'>
      <pose>-0.182028 -2.41763 0.5 0 -0 0</pose>
      <link name='link'>
        <inertial>
          <mass>1</mass>
          <inertia>
            <ixx>0.166667</ixx>
            <ixy>0</ixy>
            <ixz>0</ixz>
            <iyy>0.166667</iyy>
            <iyz>0</iyz>
            <izz>0.166667</izz>
          </inertia>
          <pose>0 0 0 0 -0 0</pose>
        </inertial>
        <collision name='collision'>
          <geometry>
            <box>
              <size>1 1 0.999998</size>
            </box>
          </geometry>
          <max_contacts>10</max_contacts>
          <surface>
            <contact>
              <ode/>
            </contact>
            <bounce/>
            <friction>
              <torsional>
                <ode/>
              </torsional>
              <ode/>
            </friction>
          </surface>
        </collision>
        <visual name='visual'>
          <geometry>
            <box>
              <size>1 1 0.999998</size>
            </box>
          </geometry>
          <material>
            <script>
              <name>Gazebo/Grey</name>
              <uri>file://media/materials/scripts/gazebo.material</uri>
            </script>
          </material>
        </visual>
        <self_collide>0</self_collide>
        <enable_wind>0</enable_wind>
        <kinematic>0</kinematic>
      </link>
    </model>
  </world>
</sdf>
