<sdf version='1.7'>
  <world name='default'>
    <physics type='ode'>
      <ode>
        <solver>
          <type>quick</type>
          <iters>50</iters>
          <sor>1.4</sor>
          <use_dynamic_moi_rescaling>0</use_dynamic_moi_rescaling>
        </solver>
        <constraints>
          <cfm>0</cfm>
          <erp>0.2</erp>
          <contact_max_correcting_vel>100</contact_max_correcting_vel>
          <contact_surface_layer>0</contact_surface_layer>
        </constraints>
      </ode>
      <real_time_update_rate>1000</real_time_update_rate>
      <max_step_size>0.001</max_step_size>
      <real_time_factor>1</real_time_factor>
    </physics>
    <light name='sun' type='directional'>
      <cast_shadows>1</cast_shadows>
      <pose>0 0 10 0 -0 0</pose>
      <diffuse>0.8 0.8 0.8 1</diffuse>
      <specular>0.2 0.2 0.2 1</specular>
      <attenuation>
        <range>1000</range>
        <constant>0.9</constant>
        <linear>0.01</linear>
        <quadratic>0.001</quadratic>
      </attenuation>
      <direction>-0.5 0.1 -0.9</direction>
      <spot>
        <inner_angle>0</inner_angle>
        <outer_angle>0</outer_angle>
        <falloff>0</falloff>
      </spot>
    </light>
    <model name='ground_plane'>
      <static>1</static>
      <link name='link'>
        <collision name='collision'>
          <geometry>
            <plane>
              <normal>0 0 1</normal>
              <size>100 100</size>
            </plane>
          </geometry>
          <surface>
            <friction>
              <ode>
                <mu>100</mu>
                <mu2>50</mu2>
              </ode>
              <torsional>
                <ode/>
              </torsional>
            </friction>
            <contact>
              <ode/>
            </contact>
            <bounce/>
          </surface>
          <max_contacts>10</max_contacts>
        </collision>
        <visual name='visual'>
          <cast_shadows>0</cast_shadows>
          <geometry>
            <plane>
              <normal>0 0 1</normal>
              <size>100 100</size>
            </plane>
          </geometry>
          <material>
            <script>
              <uri>file://media/materials/scripts/gazebo.material</uri>
              <name>Gazebo/Grey</name>
            </script>
          </material>
        </visual>
        <self_collide>0</self_collide>
        <enable_wind>0</enable_wind>
        <kinematic>0</kinematic>
      </link>
    </model>
    <gravity>0 0 -9.81</gravity>
    <magnetic_field>6e-06 2.3e-05 -4.2e-05</magnetic_field>
    <atmosphere type='adiabatic'/>
    <scene>
      <ambient>0.4 0.4 0.4 1</ambient>
      <background>0.7 0.7 0.7 1</background>
      <shadows>1</shadows>
    </scene>
    <audio>
      <device>default</device>
    </audio>
    <wind/>
    <spherical_coordinates>
      <surface_model>EARTH_WGS84</surface_model>
      <latitude_deg>0</latitude_deg>
      <longitude_deg>0</longitude_deg>
      <elevation>0</elevation>
      <heading_deg>0</heading_deg>
    </spherical_coordinates>
    <model name='tiago-pro'>
      <link name='base_footprint'>
        <inertial>
          <pose>0.00063 0.000227 0.15642 0 -0 0</pose>
          <mass>40.8677</mass>
          <inertia>
            <ixx>0.394752</ixx>
            <ixy>0.024869</ixy>
            <ixz>0.0117653</ixz>
            <iyy>0.731651</iyy>
            <iyz>-2.23541e-05</iyz>
            <izz>0.907254</izz>
          </inertia>
        </inertial>
        <collision name='base_footprint_fixed_joint_lump__base_link_collision'>
          <pose>0 0 0.26545 0 -0 0</pose>
          <geometry>
            <box>
              <size>0.717 0.497 0.0845</size>
            </box>
          </geometry>
          <surface>
            <contact>
              <ode/>
            </contact>
            <friction>
              <ode/>
              <torsional>
                <ode/>
              </torsional>
            </friction>
            <bounce/>
          </surface>
          <max_contacts>10</max_contacts>
        </collision>
        <collision name='base_footprint_fixed_joint_lump__base_link_collision_1'>
          <pose>0 0 0.2082 0 -0 0</pose>
          <geometry>
            <box>
              <size>0.58 0.39 0.03</size>
            </box>
          </geometry>
          <surface>
            <contact>
              <ode/>
            </contact>
            <friction>
              <ode/>
              <torsional>
                <ode/>
              </torsional>
            </friction>
            <bounce/>
          </surface>
          <max_contacts>10</max_contacts>
        </collision>
        <collision name='base_footprint_fixed_joint_lump__base_link_collision_2'>
          <pose>0 0 0.1097 0 -0 0</pose>
          <geometry>
            <box>
              <size>0.705 0.48 0.167</size>
            </box>
          </geometry>
          <surface>
            <contact>
              <ode/>
            </contact>
            <friction>
              <ode/>
              <torsional>
                <ode/>
              </torsional>
            </friction>
            <bounce/>
          </surface>
          <max_contacts>10</max_contacts>
        </collision>
        <collision name='base_footprint_fixed_joint_lump__base_antenna_left_link_collision_3'>
          <pose>-0.2015 0.13 0.2927 0 -0 0</pose>
          <geometry>
            <mesh>
              <scale>1 -1 1</scale>
              <uri>model://omni_base_description/meshes/base/base_antena_link.stl</uri>
            </mesh>
          </geometry>
          <surface>
            <contact>
              <ode/>
            </contact>
            <friction>
              <ode/>
              <torsional>
                <ode/>
              </torsional>
            </friction>
            <bounce/>
          </surface>
          <max_contacts>10</max_contacts>
        </collision>
        <collision name='base_footprint_fixed_joint_lump__base_antenna_right_link_collision_4'>
          <pose>-0.2015 -0.13 0.2927 0 -0 0</pose>
          <geometry>
            <mesh>
              <scale>1 1 1</scale>
              <uri>model://omni_base_description/meshes/base/base_antena_link.stl</uri>
            </mesh>
          </geometry>
          <surface>
            <contact>
              <ode/>
            </contact>
            <friction>
              <ode/>
              <torsional>
                <ode/>
              </torsional>
            </friction>
            <bounce/>
          </surface>
          <max_contacts>10</max_contacts>
        </collision>
        <collision name='base_footprint_fixed_joint_lump__base_dock_link_collision_5'>
          <pose>0.3535 0 0.1358 0 -0 0</pose>
          <geometry>
            <mesh>
              <scale>1 1 1</scale>
              <uri>model://omni_base_description/meshes/base/base_dock_link.stl</uri>
            </mesh>
          </geometry>
          <max_contacts>10</max_contacts>
          <surface>
            <contact>
              <ode/>
            </contact>
            <bounce/>
            <friction>
              <torsional>
                <ode/>
              </torsional>
              <ode/>
            </friction>
          </surface>
        </collision>
        <collision name='base_footprint_fixed_joint_lump__base_front_laser_link_collision_6'>
          <pose>0.27512 -0.18297 0.20864 -3.14159 -0 -0.785398</pose>
          <geometry>
            <cylinder>
              <length>0.01</length>
              <radius>0.01</radius>
            </cylinder>
          </geometry>
          <surface>
            <contact>
              <ode/>
            </contact>
            <friction>
              <ode/>
              <torsional>
                <ode/>
              </torsional>
            </friction>
            <bounce/>
          </surface>
          <max_contacts>10</max_contacts>
        </collision>
        <collision name='base_footprint_fixed_joint_lump__base_rear_laser_link_collision_7'>
          <pose>-0.27512 0.18297 0.20864 -3.14159 -0 2.35619</pose>
          <geometry>
            <cylinder>
              <length>0.01</length>
              <radius>0.01</radius>
            </cylinder>
          </geometry>
          <surface>
            <contact>
              <ode/>
            </contact>
            <friction>
              <ode/>
              <torsional>
                <ode/>
              </torsional>
            </friction>
            <bounce/>
          </surface>
          <max_contacts>10</max_contacts>
        </collision>
        <collision name='base_footprint_fixed_joint_lump__suspension_front_left_link_collision_8'>
          <pose>0.244 0.1725 0.0762 0 -0 1.5708</pose>
          <geometry>
            <mesh>
              <scale>1 -1 1</scale>
              <uri>model://omni_base_description/meshes/wheels/suspension_front_link.stl</uri>
            </mesh>
          </geometry>
          <max_contacts>10</max_contacts>
          <surface>
            <contact>
              <ode/>
            </contact>
            <bounce/>
            <friction>
              <torsional>
                <ode/>
              </torsional>
              <ode/>
            </friction>
          </surface>
        </collision>
        <collision name='base_footprint_fixed_joint_lump__suspension_front_right_link_collision_9'>
          <pose>0.244 -0.1725 0.0762 0 0 -1.5708</pose>
          <geometry>
            <mesh>
              <scale>1 1 1</scale>
              <uri>model://omni_base_description/meshes/wheels/suspension_front_link.stl</uri>
            </mesh>
          </geometry>
          <max_contacts>10</max_contacts>
          <surface>
            <contact>
              <ode/>
            </contact>
            <bounce/>
            <friction>
              <torsional>
                <ode/>
              </torsional>
              <ode/>
            </friction>
          </surface>
        </collision>
        <collision name='base_footprint_fixed_joint_lump__suspension_rear_left_link_collision_10'>
          <pose>-0.244 0.1725 0.0762 0 -0 1.5708</pose>
          <geometry>
            <mesh>
              <scale>1 -1 1</scale>
              <uri>model://omni_base_description/meshes/wheels/suspension_rear_link.stl</uri>
            </mesh>
          </geometry>
          <max_contacts>10</max_contacts>
          <surface>
            <contact>
              <ode/>
            </contact>
            <bounce/>
            <friction>
              <torsional>
                <ode/>
              </torsional>
              <ode/>
            </friction>
          </surface>
        </collision>
        <collision name='base_footprint_fixed_joint_lump__suspension_rear_right_link_collision_11'>
          <pose>-0.244 -0.1725 0.0762 0 0 -1.5708</pose>
          <geometry>
            <mesh>
              <scale>1 1 1</scale>
              <uri>model://omni_base_description/meshes/wheels/suspension_rear_link.stl</uri>
            </mesh>
          </geometry>
          <max_contacts>10</max_contacts>
          <surface>
            <contact>
              <ode/>
            </contact>
            <bounce/>
            <friction>
              <torsional>
                <ode/>
              </torsional>
              <ode/>
            </friction>
          </surface>
        </collision>
        <collision name='base_footprint_fixed_joint_lump__torso_fixed_column_link_collision_12'>
          <pose>-0.028 0 0.5562 0 -0 0</pose>
          <geometry>
            <box>
              <size>0.23 0.253 0.45</size>
            </box>
          </geometry>
          <surface>
            <contact>
              <ode/>
            </contact>
            <friction>
              <ode/>
              <torsional>
                <ode/>
              </torsional>
            </friction>
            <bounce/>
          </surface>
          <max_contacts>10</max_contacts>
        </collision>
        <collision name='base_footprint_fixed_joint_lump__torso_base_link_collision_13'>
          <pose>-0.0245 0 0.2912 0 -0 0</pose>
          <geometry>
            <mesh>
              <scale>1 1 1</scale>
              <uri>model://tiago_pro_description/meshes/torso/base_link_collision.stl</uri>
            </mesh>
          </geometry>
          <surface>
            <contact>
              <ode/>
            </contact>
            <friction>
              <ode/>
              <torsional>
                <ode/>
              </torsional>
            </friction>
            <bounce/>
          </surface>
          <max_contacts>10</max_contacts>
        </collision>
        <visual name='base_footprint_fixed_joint_lump__base_link_visual'>
          <pose>0 0 0.0762 0 -0 0</pose>
          <geometry>
            <mesh>
              <scale>1 1 1</scale>
              <uri>model://omni_base_description/meshes/base/base_link.stl</uri>
            </mesh>
          </geometry>
          <material>
            <script>
              <name>Gazebo/White</name>
              <uri>file://media/materials/scripts/gazebo.material</uri>
            </script>
          </material>
        </visual>
        <visual name='base_footprint_fixed_joint_lump__base_antenna_left_link_visual_1'>
          <pose>-0.2015 0.13 0.2927 0 -0 0</pose>
          <geometry>
            <mesh>
              <scale>1 -1 1</scale>
              <uri>model://omni_base_description/meshes/base/base_antena_link.stl</uri>
            </mesh>
          </geometry>
          <material>
            <script>
              <name>Gazebo/Black</name>
              <uri>file://media/materials/scripts/gazebo.material</uri>
            </script>
          </material>
        </visual>
        <visual name='base_footprint_fixed_joint_lump__base_antenna_right_link_visual_2'>
          <pose>-0.2015 -0.13 0.2927 0 -0 0</pose>
          <geometry>
            <mesh>
              <scale>1 1 1</scale>
              <uri>model://omni_base_description/meshes/base/base_antena_link.stl</uri>
            </mesh>
          </geometry>
          <material>
            <script>
              <name>Gazebo/Black</name>
              <uri>file://media/materials/scripts/gazebo.material</uri>
            </script>
          </material>
        </visual>
        <visual name='base_footprint_fixed_joint_lump__base_dock_link_visual_3'>
          <pose>0.3535 0 0.1358 0 -0 0</pose>
          <geometry>
            <mesh>
              <scale>1 1 1</scale>
              <uri>model://omni_base_description/meshes/base/base_dock_link.stl</uri>
            </mesh>
          </geometry>
        </visual>
        <visual name='base_footprint_fixed_joint_lump__base_front_laser_link_visual_4'>
          <pose>0.27512 -0.18297 0.20864 -3.14159 -0 -0.785398</pose>
          <geometry>
            <mesh>
              <scale>1 1 1</scale>
              <uri>model://omni_base_description/meshes/sensors/sick_tim551.stl</uri>
            </mesh>
          </geometry>
          <material>
            <script>
              <name>Gazebo/DarkGrey</name>
              <uri>file://media/materials/scripts/gazebo.material</uri>
            </script>
          </material>
        </visual>
        <visual name='base_footprint_fixed_joint_lump__base_rear_laser_link_visual_5'>
          <pose>-0.27512 0.18297 0.20864 -3.14159 -0 2.35619</pose>
          <geometry>
            <mesh>
              <scale>1 1 1</scale>
              <uri>model://omni_base_description/meshes/sensors/sick_tim551.stl</uri>
            </mesh>
          </geometry>
          <material>
            <script>
              <name>Gazebo/DarkGrey</name>
              <uri>file://media/materials/scripts/gazebo.material</uri>
            </script>
          </material>
        </visual>
        <visual name='base_footprint_fixed_joint_lump__suspension_front_left_link_visual_6'>
          <pose>0.244 0.1725 0.0762 0 -0 1.5708</pose>
          <geometry>
            <mesh>
              <scale>1 -1 1</scale>
              <uri>model://omni_base_description/meshes/wheels/suspension_front_link.stl</uri>
            </mesh>
          </geometry>
        </visual>
        <visual name='base_footprint_fixed_joint_lump__suspension_front_right_link_visual_7'>
          <pose>0.244 -0.1725 0.0762 0 0 -1.5708</pose>
          <geometry>
            <mesh>
              <scale>1 1 1</scale>
              <uri>model://omni_base_description/meshes/wheels/suspension_front_link.stl</uri>
            </mesh>
          </geometry>
        </visual>
        <visual name='base_footprint_fixed_joint_lump__suspension_rear_left_link_visual_8'>
          <pose>-0.244 0.1725 0.0762 0 -0 1.5708</pose>
          <geometry>
            <mesh>
              <scale>1 -1 1</scale>
              <uri>model://omni_base_description/meshes/wheels/suspension_rear_link.stl</uri>
            </mesh>
          </geometry>
        </visual>
        <visual name='base_footprint_fixed_joint_lump__suspension_rear_right_link_visual_9'>
          <pose>-0.244 -0.1725 0.0762 0 0 -1.5708</pose>
          <geometry>
            <mesh>
              <scale>1 1 1</scale>
              <uri>model://omni_base_description/meshes/wheels/suspension_rear_link.stl</uri>
            </mesh>
          </geometry>
        </visual>
        <visual name='base_footprint_fixed_joint_lump__torso_fixed_column_link_visual_10'>
          <pose>-0.028 0 0.5562 0 -0 0</pose>
          <geometry>
            <box>
              <size>0.18 0.2 0.55</size>
            </box>
          </geometry>
          <material>
            <script>
              <name>Gazebo/DarkGrey</name>
              <uri>file://media/materials/scripts/gazebo.material</uri>
            </script>
          </material>
        </visual>
        <visual name='base_footprint_fixed_joint_lump__torso_base_link_visual_11'>
          <pose>-0.0245 0 0.2912 0 -0 0</pose>
          <geometry>
            <mesh>
              <scale>1 1 1</scale>
              <uri>model://tiago_pro_description/meshes/torso/base_link.stl</uri>
            </mesh>
          </geometry>
          <material>
            <script>
              <name>Gazebo/DarkGrey</name>
              <uri>file://media/materials/scripts/gazebo.material</uri>
            </script>
          </material>
        </visual>
        <sensor name='base_front_laser' type='gpu_ray'>
          <update_rate>10</update_rate>
          <visualize>1</visualize>
          <ray>
            <scan>
              <horizontal>
                <samples>818</samples>
                <resolution>1</resolution>
                <min_angle>-2.35619</min_angle>
                <max_angle>2.35619</max_angle>
              </horizontal>
              <vertical>
                <samples>1</samples>
                <min_angle>0</min_angle>
                <max_angle>0</max_angle>
              </vertical>
            </scan>
            <range>
              <min>0.05</min>
              <max>25</max>
              <resolution>0.001</resolution>
            </range>
            <noise>
              <type>gaussian</type>
              <mean>0</mean>
              <stddev>0.01</stddev>
            </noise>
          </ray>
          <plugin name='base_front_laser' filename='libgazebo_ros_ray_sensor.so'>
            <ros>
              <remapping>~/out:=scan_front_raw</remapping>
            </ros>
            <output_type>sensor_msgs/LaserScan</output_type>
            <frame_name>base_front_laser_link</frame_name>
          </plugin>
          <pose>0.27512 -0.18297 0.20864 -3.14159 -0 -0.785398</pose>
        </sensor>
        <sensor name='base_imu_sensor' type='imu'>
          <always_on>1</always_on>
          <update_rate>100</update_rate>
          <imu>
            <noise>
              <type>gaussian</type>
              <rate>
                <mean>0.0</mean>
                <stddev>2e-4</stddev>
                <bias_mean>0.0000075</bias_mean>
                <bias_stddev>0.0000008</bias_stddev>
              </rate>
              <accel>
                <mean>0.0</mean>
                <stddev>1.7e-2</stddev>
                <bias_mean>0.1</bias_mean>
                <bias_stddev>0.001</bias_stddev>
              </accel>
            </noise>
          </imu>
          <plugin name='base_imu' filename='libgazebo_ros_imu_sensor.so'>
            <ros>
              <remapping>~/out:=base_imu</remapping>
            </ros>
          </plugin>
          <pose>-0.287 0 0.168363 0 -0 1.5708</pose>
        </sensor>
        <sensor name='base_rear_laser' type='gpu_ray'>
          <update_rate>10</update_rate>
          <visualize>1</visualize>
          <ray>
            <scan>
              <horizontal>
                <samples>818</samples>
                <resolution>1</resolution>
                <min_angle>-2.35619</min_angle>
                <max_angle>2.35619</max_angle>
              </horizontal>
              <vertical>
                <samples>1</samples>
                <min_angle>0</min_angle>
                <max_angle>0</max_angle>
              </vertical>
            </scan>
            <range>
              <min>0.05</min>
              <max>25</max>
              <resolution>0.001</resolution>
            </range>
            <noise>
              <type>gaussian</type>
              <mean>0</mean>
              <stddev>0.01</stddev>
            </noise>
          </ray>
          <plugin name='base_rear_laser' filename='libgazebo_ros_ray_sensor.so'>
            <ros>
              <remapping>~/out:=scan_rear_raw</remapping>
            </ros>
            <output_type>sensor_msgs/LaserScan</output_type>
            <frame_name>base_rear_laser_link</frame_name>
          </plugin>
          <pose>-0.27512 0.18297 0.20864 -3.14159 -0 2.35619</pose>
        </sensor>
        <self_collide>0</self_collide>
        <enable_wind>0</enable_wind>
        <kinematic>0</kinematic>
      </link>
      <joint name='wheel_front_left_joint' type='revolute'>
        <pose relative_to='base_footprint'>0.244 0.223175 0.0762 -1.5708 0 0</pose>
        <parent>base_footprint</parent>
        <child>wheel_front_left_link</child>
        <axis>
          <xyz>0 0 1</xyz>
          <limit>
            <effort>6</effort>
            <velocity>13.1234</velocity>
            <lower>-1e+16</lower>
            <upper>1e+16</upper>
          </limit>
          <dynamics>
            <damping>1</damping>
            <friction>2</friction>
            <spring_reference>0</spring_reference>
            <spring_stiffness>0</spring_stiffness>
          </dynamics>
        </axis>
      </joint>
      <link name='wheel_front_left_link'>
        <pose relative_to='wheel_front_left_joint'>0 0 0 0 -0 0</pose>
        <inertial>
          <pose>0 -7e-05 -0.011144 0 -0 0</pose>
          <mass>0.70767</mass>
          <inertia>
            <ixx>0.00035492</ixx>
            <ixy>7.5685e-13</ixy>
            <ixz>3.8795e-11</ixz>
            <iyy>0.00035529</iyy>
            <iyz>-2.0284e-07</iyz>
            <izz>0.00040131</izz>
          </inertia>
        </inertial>
        <collision name='wheel_front_left_link_collision'>
          <pose>0 0 0 0 -0 0</pose>
          <geometry>
            <cylinder>
              <length>0.05</length>
              <radius>0.0762</radius>
            </cylinder>
          </geometry>
          <surface>
            <contact>
              <ode>
                <kp>1e+06</kp>
                <kd>1000</kd>
                <max_vel>1</max_vel>
                <min_depth>0</min_depth>
              </ode>
            </contact>
            <friction>
              <ode>
                <mu>0</mu>
                <mu2>0</mu2>
                <fdir1>1 0 0</fdir1>
              </ode>
              <torsional>
                <ode/>
              </torsional>
            </friction>
            <bounce/>
          </surface>
          <max_contacts>10</max_contacts>
        </collision>
        <visual name='wheel_front_left_link_visual'>
          <pose>0 0 0 0 -0 0</pose>
          <geometry>
            <mesh>
              <scale>1 1 -1</scale>
              <uri>model://omni_base_description/meshes/wheels/wheel_link.stl</uri>
            </mesh>
          </geometry>
          <material>
            <script>
              <name>Gazebo/Grey</name>
              <uri>file://media/materials/scripts/gazebo.material</uri>
            </script>
          </material>
        </visual>
        <self_collide>0</self_collide>
        <enable_wind>0</enable_wind>
        <kinematic>0</kinematic>
      </link>
      <joint name='wheel_front_right_joint' type='revolute'>
        <pose relative_to='base_footprint'>0.244 -0.223175 0.0762 -1.5708 0 0</pose>
        <parent>base_footprint</parent>
        <child>wheel_front_right_link</child>
        <axis>
          <xyz>0 0 1</xyz>
          <limit>
            <effort>6</effort>
            <velocity>13.1234</velocity>
            <lower>-1e+16</lower>
            <upper>1e+16</upper>
          </limit>
          <dynamics>
            <damping>1</damping>
            <friction>2</friction>
            <spring_reference>0</spring_reference>
            <spring_stiffness>0</spring_stiffness>
          </dynamics>
        </axis>
      </joint>
      <link name='wheel_front_right_link'>
        <pose relative_to='wheel_front_right_joint'>0 0 0 0 -0 0</pose>
        <inertial>
          <pose>0 7e-05 0.011144 0 -0 0</pose>
          <mass>0.70767</mass>
          <inertia>
            <ixx>0.00035492</ixx>
            <ixy>7.5685e-13</ixy>
            <ixz>3.8795e-11</ixz>
            <iyy>0.00035529</iyy>
            <iyz>-2.0284e-07</iyz>
            <izz>0.00040131</izz>
          </inertia>
        </inertial>
        <collision name='wheel_front_right_link_collision'>
          <pose>0 0 0 0 -0 0</pose>
          <geometry>
            <cylinder>
              <length>0.05</length>
              <radius>0.0762</radius>
            </cylinder>
          </geometry>
          <surface>
            <contact>
              <ode>
                <kp>1e+06</kp>
                <kd>1000</kd>
                <max_vel>1</max_vel>
                <min_depth>0</min_depth>
              </ode>
            </contact>
            <friction>
              <ode>
                <mu>0</mu>
                <mu2>0</mu2>
                <fdir1>1 0 0</fdir1>
              </ode>
              <torsional>
                <ode/>
              </torsional>
            </friction>
            <bounce/>
          </surface>
          <max_contacts>10</max_contacts>
        </collision>
        <visual name='wheel_front_right_link_visual'>
          <pose>0 0 0 0 -0 0</pose>
          <geometry>
            <mesh>
              <scale>1 1 1</scale>
              <uri>model://omni_base_description/meshes/wheels/wheel_link.stl</uri>
            </mesh>
          </geometry>
          <material>
            <script>
              <name>Gazebo/Grey</name>
              <uri>file://media/materials/scripts/gazebo.material</uri>
            </script>
          </material>
        </visual>
        <self_collide>0</self_collide>
        <enable_wind>0</enable_wind>
        <kinematic>0</kinematic>
      </link>
      <joint name='wheel_rear_left_joint' type='revolute'>
        <pose relative_to='base_footprint'>-0.244 0.223175 0.0762 -1.5708 0 0</pose>
        <parent>base_footprint</parent>
        <child>wheel_rear_left_link</child>
        <axis>
          <xyz>0 0 1</xyz>
          <limit>
            <effort>6</effort>
            <velocity>13.1234</velocity>
            <lower>-1e+16</lower>
            <upper>1e+16</upper>
          </limit>
          <dynamics>
            <damping>1</damping>
            <friction>2</friction>
            <spring_reference>0</spring_reference>
            <spring_stiffness>0</spring_stiffness>
          </dynamics>
        </axis>
      </joint>
      <link name='wheel_rear_left_link'>
        <pose relative_to='wheel_rear_left_joint'>0 0 0 0 -0 0</pose>
        <inertial>
          <pose>-0 7e-05 -0.011144 0 -0 0</pose>
          <mass>0.70767</mass>
          <inertia>
            <ixx>0.00035492</ixx>
            <ixy>-7.5685e-13</ixy>
            <ixz>3.8795e-11</ixz>
            <iyy>0.00035529</iyy>
            <iyz>2.0284e-07</iyz>
            <izz>0.00040131</izz>
          </inertia>
        </inertial>
        <collision name='wheel_rear_left_link_collision'>
          <pose>0 0 0 0 -0 0</pose>
          <geometry>
            <cylinder>
              <length>0.05</length>
              <radius>0.0762</radius>
            </cylinder>
          </geometry>
          <surface>
            <contact>
              <ode>
                <kp>1e+06</kp>
                <kd>1000</kd>
                <max_vel>1</max_vel>
                <min_depth>0</min_depth>
              </ode>
            </contact>
            <friction>
              <ode>
                <mu>0</mu>
                <mu2>0</mu2>
                <fdir1>1 0 0</fdir1>
              </ode>
              <torsional>
                <ode/>
              </torsional>
            </friction>
            <bounce/>
          </surface>
          <max_contacts>10</max_contacts>
        </collision>
        <visual name='wheel_rear_left_link_visual'>
          <pose>0 0 0 0 -0 0</pose>
          <geometry>
            <mesh>
              <scale>1 1 -1</scale>
              <uri>model://omni_base_description/meshes/wheels/wheel_link.stl</uri>
            </mesh>
          </geometry>
          <material>
            <script>
              <name>Gazebo/Grey</name>
              <uri>file://media/materials/scripts/gazebo.material</uri>
            </script>
          </material>
        </visual>
        <self_collide>0</self_collide>
        <enable_wind>0</enable_wind>
        <kinematic>0</kinematic>
      </link>
      <joint name='wheel_rear_right_joint' type='revolute'>
        <pose relative_to='base_footprint'>-0.244 -0.223175 0.0762 -1.5708 0 0</pose>
        <parent>base_footprint</parent>
        <child>wheel_rear_right_link</child>
        <axis>
          <xyz>0 0 1</xyz>
          <limit>
            <effort>6</effort>
            <velocity>13.1234</velocity>
            <lower>-1e+16</lower>
            <upper>1e+16</upper>
          </limit>
          <dynamics>
            <damping>1</damping>
            <friction>2</friction>
            <spring_reference>0</spring_reference>
            <spring_stiffness>0</spring_stiffness>
          </dynamics>
        </axis>
      </joint>
      <link name='wheel_rear_right_link'>
        <pose relative_to='wheel_rear_right_joint'>0 0 0 0 -0 0</pose>
        <inertial>
          <pose>-0 -7e-05 0.011144 0 -0 0</pose>
          <mass>0.70767</mass>
          <inertia>
            <ixx>0.00035492</ixx>
            <ixy>-7.5685e-13</ixy>
            <ixz>3.8795e-11</ixz>
            <iyy>0.00035529</iyy>
            <iyz>2.0284e-07</iyz>
            <izz>0.00040131</izz>
          </inertia>
        </inertial>
        <collision name='wheel_rear_right_link_collision'>
          <pose>0 0 0 0 -0 0</pose>
          <geometry>
            <cylinder>
              <length>0.05</length>
              <radius>0.0762</radius>
            </cylinder>
          </geometry>
          <surface>
            <contact>
              <ode>
                <kp>1e+06</kp>
                <kd>1000</kd>
                <max_vel>1</max_vel>
                <min_depth>0</min_depth>
              </ode>
            </contact>
            <friction>
              <ode>
                <mu>0</mu>
                <mu2>0</mu2>
                <fdir1>1 0 0</fdir1>
              </ode>
              <torsional>
                <ode/>
              </torsional>
            </friction>
            <bounce/>
          </surface>
          <max_contacts>10</max_contacts>
        </collision>
        <visual name='wheel_rear_right_link_visual'>
          <pose>0 0 0 0 -0 0</pose>
          <geometry>
            <mesh>
              <scale>1 1 1</scale>
              <uri>model://omni_base_description/meshes/wheels/wheel_link.stl</uri>
            </mesh>
          </geometry>
          <material>
            <script>
              <name>Gazebo/Grey</name>
              <uri>file://media/materials/scripts/gazebo.material</uri>
            </script>
          </material>
        </visual>
        <self_collide>0</self_collide>
        <enable_wind>0</enable_wind>
        <kinematic>0</kinematic>
      </link>
      <joint name='torso_lift_joint' type='prismatic'>
        <pose relative_to='base_footprint'>-0.0245 0 0.8457 0 -0 0</pose>
        <parent>base_footprint</parent>
        <child>torso_lift_link</child>
        <axis>
          <xyz>0 0 1</xyz>
          <limit>
            <lower>0</lower>
            <upper>0.35</upper>
            <effort>2000</effort>
            <velocity>0.035</velocity>
          </limit>
          <dynamics>
            <damping>1000</damping>
            <friction>0</friction>
            <spring_reference>0</spring_reference>
            <spring_stiffness>0</spring_stiffness>
          </dynamics>
        </axis>
        <physics>
          <ode>
            <implicit_spring_damper>1</implicit_spring_damper>
            <cfm_damping>1</cfm_damping>
            <limit>
              <cfm>0</cfm>
              <erp>0.2</erp>
            </limit>
          </ode>
        </physics>
      </joint>
      <link name='torso_lift_link'>
        <pose relative_to='torso_lift_joint'>0 0 0 0 -0 0</pose>
        <inertial>
          <pose>0 -0 0.001812 0 -0 0</pose>
          <mass>3.43808</mass>
          <inertia>
            <ixx>0.0301635</ixx>
            <ixy>-7.85102e-07</ixy>
            <ixz>-8.58577e-05</ixz>
            <iyy>0.0177848</iyy>
            <iyz>-8.17944e-06</iyz>
            <izz>0.0298875</izz>
          </inertia>
        </inertial>
        <collision name='torso_lift_link_collision'>
          <pose>0 0 0 0 -0 0</pose>
          <geometry>
            <mesh>
              <scale>1 1 1</scale>
              <uri>model://tiago_pro_description/meshes/torso/torso_lift_link_collision.stl</uri>
            </mesh>
          </geometry>
          <max_contacts>10</max_contacts>
          <surface>
            <contact>
              <ode/>
            </contact>
            <bounce/>
            <friction>
              <torsional>
                <ode/>
              </torsional>
              <ode/>
            </friction>
          </surface>
        </collision>
        <collision name='torso_lift_link_collision_1'>
          <pose>-0.226436 3.1e-05 0.00524 0 0 -1.5708</pose>
          <geometry>
            <mesh>
              <scale>1 1 1</scale>
              <uri>model://tiago_pro_description/meshes/torso/laptop_tray_collision.stl</uri>
            </mesh>
          </geometry>
          <max_contacts>10</max_contacts>
          <surface>
            <contact>
              <ode/>
            </contact>
            <bounce/>
            <friction>
              <torsional>
                <ode/>
              </torsional>
              <ode/>
            </friction>
          </surface>
        </collision>
        <collision name='torso_lift_link_fixed_joint_lump__torso_head_link_collision_2'>
          <pose>0 0 0.05085 0 -0 0</pose>
          <geometry>
            <box>
              <size>0.11 0.092 0.0217</size>
            </box>
          </geometry>
          <max_contacts>10</max_contacts>
          <surface>
            <contact>
              <ode/>
            </contact>
            <bounce/>
            <friction>
              <torsional>
                <ode/>
              </torsional>
              <ode/>
            </friction>
          </surface>
        </collision>
        <visual name='torso_lift_link_visual'>
          <pose>0 0 0 0 -0 0</pose>
          <geometry>
            <mesh>
              <scale>1 1 1</scale>
              <uri>model://tiago_pro_description/meshes/torso/torso_lift_link.stl</uri>
            </mesh>
          </geometry>
        </visual>
        <visual name='torso_lift_link_fixed_joint_lump__torso_head_link_visual_1'>
          <pose>0 0 0.05085 0 -0 0</pose>
          <geometry>
            <box>
              <size>0.11 0.092 0.0217</size>
            </box>
          </geometry>
        </visual>
        <self_collide>0</self_collide>
        <enable_wind>0</enable_wind>
        <kinematic>0</kinematic>
      </link>
      <joint name='arm_left_1_joint' type='revolute'>
        <pose relative_to='torso_lift_link'>0.08976 0.15918 -0.092008 -2.0679 0 -1.2217</pose>
        <parent>torso_lift_link</parent>
        <child>arm_left_1_link</child>
        <axis>
          <xyz>0 0 1</xyz>
          <limit>
            <lower>-0.523599</lower>
            <upper>4.71239</upper>
            <effort>43</effort>
            <velocity>2.5</velocity>
          </limit>
          <dynamics>
            <damping>1</damping>
            <friction>1</friction>
            <spring_reference>0</spring_reference>
            <spring_stiffness>0</spring_stiffness>
          </dynamics>
        </axis>
        <physics>
          <ode>
            <implicit_spring_damper>1</implicit_spring_damper>
            <cfm_damping>1</cfm_damping>
            <limit>
              <cfm>0</cfm>
              <erp>0.2</erp>
            </limit>
          </ode>
        </physics>
      </joint>
      <link name='arm_left_1_link'>
        <pose relative_to='arm_left_1_joint'>0 0 0 0 -0 0</pose>
        <inertial>
          <pose>0.004392 0.016184 0.15576 0 -0 0</pose>
          <mass>1.1325</mass>
          <inertia>
            <ixx>0.0025497</ixx>
            <ixy>2.6206e-05</ixy>
            <ixz>6.2082e-05</ixz>
            <iyy>0.0023517</iyy>
            <iyz>-0.00020617</iyz>
            <izz>0.00097131</izz>
          </inertia>
        </inertial>
        <collision name='arm_left_1_link_collision'>
          <pose>0 0 0 0 -0 0</pose>
          <geometry>
            <mesh>
              <scale>1 1 1</scale>
              <uri>model://pal_sea_arm_description/meshes/arm_tiago_pro/arm_1_link_collision.stl</uri>
            </mesh>
          </geometry>
          <surface>
            <contact>
              <ode/>
            </contact>
            <friction>
              <ode>
                <mu>0.9</mu>
                <mu2>0.9</mu2>
              </ode>
              <torsional>
                <ode/>
              </torsional>
            </friction>
            <bounce/>
          </surface>
          <max_contacts>10</max_contacts>
        </collision>
        <visual name='arm_left_1_link_visual'>
          <pose>0 0 0 0 -0 0</pose>
          <geometry>
            <mesh>
              <scale>1 1 1</scale>
              <uri>model://pal_sea_arm_description/meshes/arm_tiago_pro/arm_1_link.stl</uri>
            </mesh>
          </geometry>
          <material>
            <script>
              <name>Gazebo/DarkGrey</name>
              <uri>file://media/materials/scripts/gazebo.material</uri>
            </script>
          </material>
        </visual>
        <self_collide>0</self_collide>
        <enable_wind>0</enable_wind>
        <kinematic>0</kinematic>
      </link>
      <joint name='arm_left_2_joint' type='revolute'>
        <pose relative_to='arm_left_1_link'>0.03711 0.02 0.18 -1.5708 -0 -1.5708</pose>
        <parent>arm_left_1_link</parent>
        <child>arm_left_2_link</child>
        <axis>
          <xyz>0 0 1</xyz>
          <limit>
            <lower>-2.44346</lower>
            <upper>1.13446</upper>
            <effort>43</effort>
            <velocity>2.5</velocity>
          </limit>
          <dynamics>
            <damping>1</damping>
            <friction>1</friction>
            <spring_reference>0</spring_reference>
            <spring_stiffness>0</spring_stiffness>
          </dynamics>
        </axis>
        <physics>
          <ode>
            <implicit_spring_damper>1</implicit_spring_damper>
            <cfm_damping>1</cfm_damping>
            <limit>
              <cfm>0</cfm>
              <erp>0.2</erp>
            </limit>
          </ode>
        </physics>
      </joint>
      <link name='arm_left_2_link'>
        <pose relative_to='arm_left_2_joint'>0 0 0 0 -0 0</pose>
        <inertial>
          <pose>0.01786 -0.11956 -0.032097 0 -0 0</pose>
          <mass>1.0436</mass>
          <inertia>
            <ixx>0.0015021</ixx>
            <ixy>0.00011264</ixy>
            <ixz>1.0692e-05</ixz>
            <iyy>0.00088017</iyy>
            <iyz>-0.00015843</iyz>
            <izz>0.0016021</izz>
          </inertia>
        </inertial>
        <collision name='arm_left_2_link_collision'>
          <pose>0 0 0 0 -0 0</pose>
          <geometry>
            <mesh>
              <scale>1 1 1</scale>
              <uri>model://pal_sea_arm_description/meshes/arm_tiago_pro/arm_2_link_collision.stl</uri>
            </mesh>
          </geometry>
          <surface>
            <contact>
              <ode/>
            </contact>
            <friction>
              <ode>
                <mu>0.9</mu>
                <mu2>0.9</mu2>
              </ode>
              <torsional>
                <ode/>
              </torsional>
            </friction>
            <bounce/>
          </surface>
          <max_contacts>10</max_contacts>
        </collision>
        <visual name='arm_left_2_link_visual'>
          <pose>0 0 0 0 -0 0</pose>
          <geometry>
            <mesh>
              <scale>1 1 1</scale>
              <uri>model://pal_sea_arm_description/meshes/arm_tiago_pro/arm_2_link.stl</uri>
            </mesh>
          </geometry>
          <material>
            <script>
              <name>Gazebo/DarkGrey</name>
              <uri>file://media/materials/scripts/gazebo.material</uri>
            </script>
          </material>
        </visual>
        <self_collide>0</self_collide>
        <enable_wind>0</enable_wind>
        <kinematic>0</kinematic>
      </link>
      <joint name='arm_left_3_joint' type='revolute'>
        <pose relative_to='arm_left_2_link'>0.02 -0.17011 -0.03711 1.5708 -0 0</pose>
        <parent>arm_left_2_link</parent>
        <child>arm_left_3_link</child>
        <axis>
          <xyz>0 0 1</xyz>
          <limit>
            <lower>-2.61799</lower>
            <upper>2.61799</upper>
            <effort>26</effort>
            <velocity>2.5</velocity>
          </limit>
          <dynamics>
            <damping>1</damping>
            <friction>1</friction>
            <spring_reference>0</spring_reference>
            <spring_stiffness>0</spring_stiffness>
          </dynamics>
        </axis>
        <physics>
          <ode>
            <implicit_spring_damper>1</implicit_spring_damper>
            <cfm_damping>1</cfm_damping>
            <limit>
              <cfm>0</cfm>
              <erp>0.2</erp>
            </limit>
          </ode>
        </physics>
      </joint>
      <link name='arm_left_3_link'>
        <pose relative_to='arm_left_3_joint'>0 0 0 0 -0 0</pose>
        <inertial>
          <pose>0.016184 -0.004392 0.13565 0 -0 0</pose>
          <mass>1.1325</mass>
          <inertia>
            <ixx>0.0023517</ixx>
            <ixy>-2.6206e-05</ixy>
            <ixz>-0.00020617</ixz>
            <iyy>0.0025497</iyy>
            <iyz>-6.2082e-05</iyz>
            <izz>0.00097131</izz>
          </inertia>
        </inertial>
        <collision name='arm_left_3_link_collision'>
          <pose>0 0 0 0 -0 0</pose>
          <geometry>
            <mesh>
              <scale>1 1 1</scale>
              <uri>model://pal_sea_arm_description/meshes/arm_tiago_pro/arm_3_link_collision.stl</uri>
            </mesh>
          </geometry>
          <surface>
            <contact>
              <ode/>
            </contact>
            <friction>
              <ode>
                <mu>0.9</mu>
                <mu2>0.9</mu2>
              </ode>
              <torsional>
                <ode/>
              </torsional>
            </friction>
            <bounce/>
          </surface>
          <max_contacts>10</max_contacts>
        </collision>
        <visual name='arm_left_3_link_visual'>
          <pose>0 0 0 0 -0 0</pose>
          <geometry>
            <mesh>
              <scale>1 1 1</scale>
              <uri>model://pal_sea_arm_description/meshes/arm_tiago_pro/arm_3_link.stl</uri>
            </mesh>
          </geometry>
          <material>
            <script>
              <name>Gazebo/DarkGrey</name>
              <uri>file://media/materials/scripts/gazebo.material</uri>
            </script>
          </material>
        </visual>
        <self_collide>0</self_collide>
        <enable_wind>0</enable_wind>
        <kinematic>0</kinematic>
      </link>
      <joint name='arm_left_4_joint' type='revolute'>
        <pose relative_to='arm_left_3_link'>0.02 -0.03711 0.15989 1.5708 -0 0</pose>
        <parent>arm_left_3_link</parent>
        <child>arm_left_4_link</child>
        <axis>
          <xyz>0 0 1</xyz>
          <limit>
            <lower>-2.44346</lower>
            <upper>1.13446</upper>
            <effort>26</effort>
            <velocity>2.5</velocity>
          </limit>
          <dynamics>
            <damping>1</damping>
            <friction>1</friction>
            <spring_reference>0</spring_reference>
            <spring_stiffness>0</spring_stiffness>
          </dynamics>
        </axis>
        <physics>
          <ode>
            <implicit_spring_damper>1</implicit_spring_damper>
            <cfm_damping>1</cfm_damping>
            <limit>
              <cfm>0</cfm>
              <erp>0.2</erp>
            </limit>
          </ode>
        </physics>
      </joint>
      <link name='arm_left_4_link'>
        <pose relative_to='arm_left_4_joint'>0 0 0 0 -0 0</pose>
        <inertial>
          <pose>-0.01786 0.11956 -0.032097 0 -0 0</pose>
          <mass>1.0436</mass>
          <inertia>
            <ixx>0.0015021</ixx>
            <ixy>0.00011264</ixy>
            <ixz>-1.0692e-05</ixz>
            <iyy>0.00088017</iyy>
            <iyz>0.00015843</iyz>
            <izz>0.0016021</izz>
          </inertia>
        </inertial>
        <collision name='arm_left_4_link_collision'>
          <pose>0 0 0 0 -0 0</pose>
          <geometry>
            <mesh>
              <scale>1 1 1</scale>
              <uri>model://pal_sea_arm_description/meshes/arm_tiago_pro/arm_4_link_collision.stl</uri>
            </mesh>
          </geometry>
          <surface>
            <contact>
              <ode/>
            </contact>
            <friction>
              <ode>
                <mu>0.9</mu>
                <mu2>0.9</mu2>
              </ode>
              <torsional>
                <ode/>
              </torsional>
            </friction>
            <bounce/>
          </surface>
          <max_contacts>10</max_contacts>
        </collision>
        <visual name='arm_left_4_link_visual'>
          <pose>0 0 0 0 -0 0</pose>
          <geometry>
            <mesh>
              <scale>1 1 1</scale>
              <uri>model://pal_sea_arm_description/meshes/arm_tiago_pro/arm_4_link.stl</uri>
            </mesh>
          </geometry>
          <material>
            <script>
              <name>Gazebo/DarkGrey</name>
              <uri>file://media/materials/scripts/gazebo.material</uri>
            </script>
          </material>
        </visual>
        <self_collide>0</self_collide>
        <enable_wind>0</enable_wind>
        <kinematic>0</kinematic>
      </link>
      <joint name='arm_left_5_joint' type='revolute'>
        <pose relative_to='arm_left_4_link'>-0.02 0.17011 -0.03711 1.5708 0.001593 -3.14159</pose>
        <parent>arm_left_4_link</parent>
        <child>arm_left_5_link</child>
        <axis>
          <xyz>0 0 1</xyz>
          <limit>
            <lower>-3.66519</lower>
            <upper>1.5708</upper>
            <effort>26</effort>
            <velocity>2.5</velocity>
          </limit>
          <dynamics>
            <damping>1</damping>
            <friction>1</friction>
            <spring_reference>0</spring_reference>
            <spring_stiffness>0</spring_stiffness>
          </dynamics>
        </axis>
        <physics>
          <ode>
            <implicit_spring_damper>1</implicit_spring_damper>
            <cfm_damping>1</cfm_damping>
            <limit>
              <cfm>0</cfm>
              <erp>0.2</erp>
            </limit>
          </ode>
        </physics>
      </joint>
      <link name='arm_left_5_link'>
        <pose relative_to='arm_left_5_joint'>0 0 0 0 -0 0</pose>
        <inertial>
          <pose>1.1e-05 -0.027586 0.067845 0 -0 0</pose>
          <mass>0.310763</mass>
          <inertia>
            <ixx>0.00140145</ixx>
            <ixy>9.16506e-08</ixy>
            <ixz>-9.26254e-08</ixz>
            <iyy>0.00139999</iyy>
            <iyz>0.000327713</iyz>
            <izz>0.000402008</izz>
          </inertia>
        </inertial>
        <collision name='arm_left_5_link_collision'>
          <pose>0 0 0 0 -0 0</pose>
          <geometry>
            <mesh>
              <scale>1 1 1</scale>
              <uri>model://pal_sea_arm_description/meshes/arm_tiago_pro/spherical-wrist/arm_5_link.stl</uri>
            </mesh>
          </geometry>
          <surface>
            <contact>
              <ode/>
            </contact>
            <friction>
              <ode>
                <mu>0.9</mu>
                <mu2>0.9</mu2>
              </ode>
              <torsional>
                <ode/>
              </torsional>
            </friction>
            <bounce/>
          </surface>
          <max_contacts>10</max_contacts>
        </collision>
        <visual name='arm_left_5_link_visual'>
          <pose>0 0 0 0 -0 0</pose>
          <geometry>
            <mesh>
              <scale>1 1 1</scale>
              <uri>model://pal_sea_arm_description/meshes/arm_tiago_pro/spherical-wrist/arm_5_link.stl</uri>
            </mesh>
          </geometry>
          <material>
            <script>
              <name>Gazebo/DarkGrey</name>
              <uri>file://media/materials/scripts/gazebo.material</uri>
            </script>
          </material>
        </visual>
        <self_collide>0</self_collide>
        <enable_wind>0</enable_wind>
        <kinematic>0</kinematic>
      </link>
      <joint name='arm_left_6_joint' type='revolute'>
        <pose relative_to='arm_left_5_link'>0 -0.0422 0.1654 -1.5708 -0 3.14</pose>
        <parent>arm_left_5_link</parent>
        <child>arm_left_6_link</child>
        <axis>
          <xyz>0 0 -1</xyz>
          <limit>
            <lower>-1.88496</lower>
            <upper>3.00197</upper>
            <effort>26</effort>
            <velocity>2.5</velocity>
          </limit>
          <dynamics>
            <damping>1</damping>
            <friction>1</friction>
            <spring_reference>0</spring_reference>
            <spring_stiffness>0</spring_stiffness>
          </dynamics>
        </axis>
        <physics>
          <ode>
            <implicit_spring_damper>1</implicit_spring_damper>
            <cfm_damping>1</cfm_damping>
            <limit>
              <cfm>0</cfm>
              <erp>0.2</erp>
            </limit>
          </ode>
        </physics>
      </joint>
      <link name='arm_left_6_link'>
        <pose relative_to='arm_left_6_joint'>0 0 0 0 -0 0</pose>
        <inertial>
          <pose>0.031765 -0.006515 -0.040805 0 -0 0</pose>
          <mass>1.34587</mass>
          <inertia>
            <ixx>0.00109886</ixx>
            <ixy>0.000130003</ixy>
            <ixz>-5.88209e-06</ixz>
            <iyy>0.00116495</iyy>
            <iyz>4.20092e-07</iyz>
            <izz>0.00118984</izz>
          </inertia>
        </inertial>
        <collision name='arm_left_6_link_collision'>
          <pose>0 0 0 0 -0 0</pose>
          <geometry>
            <mesh>
              <scale>1 1 1</scale>
              <uri>model://pal_sea_arm_description/meshes/arm_tiago_pro/spherical-wrist/arm_6_link_collision.stl</uri>
            </mesh>
          </geometry>
          <surface>
            <contact>
              <ode/>
            </contact>
            <friction>
              <ode>
                <mu>0.9</mu>
                <mu2>0.9</mu2>
              </ode>
              <torsional>
                <ode/>
              </torsional>
            </friction>
            <bounce/>
          </surface>
          <max_contacts>10</max_contacts>
        </collision>
        <visual name='arm_left_6_link_visual'>
          <pose>0 0 0 0 -0 0</pose>
          <geometry>
            <mesh>
              <scale>1 1 1</scale>
              <uri>model://pal_sea_arm_description/meshes/arm_tiago_pro/spherical-wrist/arm_6_link.stl</uri>
            </mesh>
          </geometry>
          <material>
            <script>
              <name>Gazebo/DarkGrey</name>
              <uri>file://media/materials/scripts/gazebo.material</uri>
            </script>
          </material>
        </visual>
        <self_collide>0</self_collide>
        <enable_wind>0</enable_wind>
        <kinematic>0</kinematic>
      </link>
      <joint name='arm_left_7_joint' type='revolute'>
        <pose relative_to='arm_left_6_link'>0.07 -0.0534 -0.0422 1.5708 -0 0</pose>
        <parent>arm_left_6_link</parent>
        <child>arm_left_7_link</child>
        <axis>
          <xyz>0 0 1</xyz>
          <limit>
            <lower>-2.61799</lower>
            <upper>2.61799</upper>
            <effort>26</effort>
            <velocity>2.5</velocity>
          </limit>
          <dynamics>
            <damping>1</damping>
            <friction>1</friction>
            <spring_reference>0</spring_reference>
            <spring_stiffness>0</spring_stiffness>
          </dynamics>
        </axis>
        <physics>
          <provide_feedback>1</provide_feedback>
          <ode>
            <implicit_spring_damper>1</implicit_spring_damper>
            <cfm_damping>1</cfm_damping>
            <limit>
              <cfm>0</cfm>
              <erp>0.2</erp>
            </limit>
            <provide_feedback>1</provide_feedback>
          </ode>
        </physics>
      </joint>
      <link name='arm_left_7_link'>
        <pose relative_to='arm_left_7_joint'>0 0 0 0 -0 0</pose>
        <inertial>
          <pose>0.000371 -0.00062 0.049358 0 -0 0</pose>
          <mass>0.475823</mass>
          <inertia>
            <ixx>0.000575813</ixx>
            <ixy>2.12403e-07</ixy>
            <ixz>9.89094e-06</ixz>
            <iyy>0.000502928</iyy>
            <iyz>-1.12781e-05</iyz>
            <izz>0.000374898</izz>
          </inertia>
        </inertial>
        <collision name='arm_left_7_link_collision'>
          <pose>0 0 0 0 -0 0</pose>
          <geometry>
            <cylinder>
              <length>0.0366</length>
              <radius>0.0375</radius>
            </cylinder>
          </geometry>
          <surface>
            <contact>
              <ode/>
            </contact>
            <friction>
              <ode>
                <mu>0.9</mu>
                <mu2>0.9</mu2>
              </ode>
              <torsional>
                <ode/>
              </torsional>
            </friction>
            <bounce/>
          </surface>
          <max_contacts>10</max_contacts>
        </collision>
        <collision name='arm_left_7_link_fixed_joint_lump__gripper_left_base_link_collision_1'>
          <pose>0 0 0.017 0 -0 0</pose>
          <geometry>
            <mesh>
              <scale>1 1 1</scale>
              <uri>model://pal_pro_gripper_description/meshes/base_link_tc.stl</uri>
            </mesh>
          </geometry>
          <surface>
            <contact>
              <ode/>
            </contact>
            <friction>
              <ode>
                <mu>0.9</mu>
                <mu2>0.9</mu2>
              </ode>
              <torsional>
                <ode/>
              </torsional>
            </friction>
            <bounce/>
          </surface>
          <max_contacts>10</max_contacts>
        </collision>
        <visual name='arm_left_7_link_visual'>
          <pose>0 0 0 0 -0 0</pose>
          <geometry>
            <mesh>
              <scale>1 1 1</scale>
              <uri>model://pal_sea_arm_description/meshes/arm_tiago_pro/spherical-wrist/arm_7_link.stl</uri>
            </mesh>
          </geometry>
          <material>
            <script>
              <name>Gazebo/DarkGrey</name>
              <uri>file://media/materials/scripts/gazebo.material</uri>
            </script>
          </material>
        </visual>
        <visual name='arm_left_7_link_fixed_joint_lump__gripper_left_base_link_visual_1'>
          <pose>0 0 0.017 0 -0 0</pose>
          <geometry>
            <mesh>
              <scale>1 1 1</scale>
              <uri>model://pal_pro_gripper_description/meshes/base_link_tc.stl</uri>
            </mesh>
          </geometry>
          <material>
            <script>
              <name>Gazebo/DarkGrey</name>
              <uri>file://media/materials/scripts/gazebo.material</uri>
            </script>
          </material>
        </visual>
        <self_collide>0</self_collide>
        <enable_wind>0</enable_wind>
        <kinematic>0</kinematic>
      </link>
      <joint name='gripper_left_finger_joint' type='revolute'>
        <pose relative_to='arm_left_7_link'>0 -0.0288 0.0913 1.5708 0.83776 -1.5708</pose>
        <parent>arm_left_7_link</parent>
        <child>gripper_left_outer_finger_left_link</child>
        <axis>
          <xyz>0 0 1</xyz>
          <limit>
            <lower>0</lower>
            <upper>0.802851</upper>
            <effort>0.1</effort>
            <velocity>2</velocity>
          </limit>
          <dynamics>
            <damping>0.03</damping>
            <friction>0</friction>
            <spring_reference>0</spring_reference>
            <spring_stiffness>0</spring_stiffness>
          </dynamics>
        </axis>
        <physics>
          <ode>
            <limit>
              <cfm>0</cfm>
              <erp>0.2</erp>
            </limit>
            <implicit_spring_damper>1</implicit_spring_damper>
            <cfm_damping>1</cfm_damping>
            <provide_feedback>1</provide_feedback>
          </ode>
          <provide_feedback>1</provide_feedback>
        </physics>
      </joint>
      <link name='gripper_left_outer_finger_left_link'>
        <pose relative_to='gripper_left_finger_joint'>0 0 0 0 -0 0</pose>
        <inertial>
          <pose>-0.001283 0.014397 0 0 -0 0</pose>
          <mass>0.0159888</mass>
          <inertia>
            <ixx>5.98786e-06</ixx>
            <ixy>-5.21729e-07</ixy>
            <ixz>-7.65399e-20</ixz>
            <iyy>4.87251e-07</iyy>
            <iyz>-7.03394e-19</iyz>
            <izz>6.14973e-06</izz>
          </inertia>
        </inertial>
        <collision name='gripper_left_outer_finger_left_link_collision'>
          <pose>0 0 0 0 -0 0</pose>
          <geometry>
            <mesh>
              <scale>1 1 1</scale>
              <uri>model://pal_pro_gripper_description/meshes/outer_finger.stl</uri>
            </mesh>
          </geometry>
          <surface>
            <contact>
              <ode/>
            </contact>
            <friction>
              <ode>
                <mu>0.9</mu>
                <mu2>0.9</mu2>
              </ode>
              <torsional>
                <ode/>
              </torsional>
            </friction>
            <bounce/>
          </surface>
          <max_contacts>10</max_contacts>
        </collision>
        <visual name='gripper_left_outer_finger_left_link_visual'>
          <pose>0 0 0 0 -0 0</pose>
          <geometry>
            <mesh>
              <scale>1 1 1</scale>
              <uri>model://pal_pro_gripper_description/meshes/outer_finger.stl</uri>
            </mesh>
          </geometry>
          <material>
            <script>
              <name>Gazebo/White</name>
              <uri>file://media/materials/scripts/gazebo.material</uri>
            </script>
          </material>
        </visual>
        <self_collide>0</self_collide>
        <enable_wind>0</enable_wind>
        <kinematic>0</kinematic>
      </link>
      <joint name='gripper_left_inner_finger_left_joint' type='revolute'>
        <pose relative_to='arm_left_7_link'>0 -0.013977 0.095832 1.5708 0.83776 -1.5708</pose>
        <parent>arm_left_7_link</parent>
        <child>gripper_left_inner_finger_left_link</child>
        <axis>
          <xyz>0 0 1</xyz>
          <limit>
            <lower>0</lower>
            <upper>0.802851</upper>
            <effort>0.1</effort>
            <velocity>2</velocity>
          </limit>
          <dynamics>
            <spring_reference>0</spring_reference>
            <spring_stiffness>0</spring_stiffness>
          </dynamics>
        </axis>
      </joint>
      <link name='gripper_left_inner_finger_left_link'>
        <pose relative_to='gripper_left_inner_finger_left_joint'>0 0 0 0 -0 0</pose>
        <inertial>
          <pose>-0 0.024759 0 0 -0 0</pose>
          <mass>0.018619</mass>
          <inertia>
            <ixx>4.8806e-06</ixx>
            <ixy>-7.6762e-22</ixy>
            <ixz>1.0244e-22</ixz>
            <iyy>2.5471e-07</iyy>
            <iyz>-1.1841e-21</iyz>
            <izz>4.9573e-06</izz>
          </inertia>
        </inertial>
        <collision name='gripper_left_inner_finger_left_link_collision'>
          <pose>0 0 0 0 -0 0</pose>
          <geometry>
            <mesh>
              <scale>1 1 1</scale>
              <uri>model://pal_pro_gripper_description/meshes/inner_finger.stl</uri>
            </mesh>
          </geometry>
          <surface>
            <contact>
              <ode/>
            </contact>
            <friction>
              <ode>
                <mu>0.9</mu>
                <mu2>0.9</mu2>
              </ode>
              <torsional>
                <ode/>
              </torsional>
            </friction>
            <bounce/>
          </surface>
          <max_contacts>10</max_contacts>
        </collision>
        <visual name='gripper_left_inner_finger_left_link_visual'>
          <pose>0 0 0 0 -0 0</pose>
          <geometry>
            <mesh>
              <scale>1 1 1</scale>
              <uri>model://pal_pro_gripper_description/meshes/inner_finger.stl</uri>
            </mesh>
          </geometry>
          <material>
            <script>
              <name>Gazebo/White</name>
              <uri>file://media/materials/scripts/gazebo.material</uri>
            </script>
          </material>
        </visual>
        <self_collide>0</self_collide>
        <enable_wind>0</enable_wind>
        <kinematic>0</kinematic>
      </link>
      <joint name='gripper_left_fingertip_left_joint' type='revolute'>
        <pose relative_to='gripper_left_inner_finger_left_link'>0 0.05 0 0 -0 0.83776</pose>
        <parent>gripper_left_inner_finger_left_link</parent>
        <child>gripper_left_fingertip_left_link</child>
        <axis>
          <xyz>0 0 1</xyz>
          <limit>
            <lower>-0.802851</lower>
            <upper>0</upper>
            <effort>0.1</effort>
            <velocity>2</velocity>
          </limit>
          <dynamics>
            <spring_reference>0</spring_reference>
            <spring_stiffness>0</spring_stiffness>
          </dynamics>
        </axis>
      </joint>
      <link name='gripper_left_fingertip_left_link'>
        <pose relative_to='gripper_left_fingertip_left_joint'>0 0 0 0 -0 0</pose>
        <inertial>
          <pose>-0.000865 0.011929 -0 0 -0 0</pose>
          <mass>0.033503</mass>
          <inertia>
            <ixx>3.63918e-06</ixx>
            <ixy>3.40522e-07</ixy>
            <ixz>-1.41919e-14</ixz>
            <iyy>1.7095e-06</iyy>
            <iyz>-4.24737e-14</iyz>
            <izz>2.84428e-06</izz>
          </inertia>
        </inertial>
        <collision name='gripper_left_fingertip_left_link_collision'>
          <pose>0 0 0 0 -0 0</pose>
          <geometry>
            <mesh>
              <scale>1 1 1</scale>
              <uri>model://pal_pro_gripper_description/meshes/fingertip.stl</uri>
            </mesh>
          </geometry>
          <surface>
            <contact>
              <ode/>
            </contact>
            <friction>
              <ode>
                <mu>0.9</mu>
                <mu2>0.9</mu2>
              </ode>
              <torsional>
                <ode/>
              </torsional>
            </friction>
            <bounce/>
          </surface>
          <max_contacts>10</max_contacts>
        </collision>
        <visual name='gripper_left_fingertip_left_link_visual'>
          <pose>0 0 0 0 -0 0</pose>
          <geometry>
            <mesh>
              <scale>1 1 1</scale>
              <uri>model://pal_pro_gripper_description/meshes/fingertip.stl</uri>
            </mesh>
          </geometry>
          <material>
            <script>
              <name>Gazebo/White</name>
              <uri>file://media/materials/scripts/gazebo.material</uri>
            </script>
          </material>
        </visual>
        <self_collide>0</self_collide>
        <enable_wind>0</enable_wind>
        <kinematic>0</kinematic>
      </link>
      <joint name='gripper_left_inner_finger_right_joint' type='revolute'>
        <pose relative_to='arm_left_7_link'>0 0.013977 0.095832 1.5708 0.83776 1.5708</pose>
        <parent>arm_left_7_link</parent>
        <child>gripper_left_inner_finger_right_link</child>
        <axis>
          <xyz>0 0 1</xyz>
          <limit>
            <lower>0</lower>
            <upper>0.802851</upper>
            <effort>0.1</effort>
            <velocity>2</velocity>
          </limit>
          <dynamics>
            <spring_reference>0</spring_reference>
            <spring_stiffness>0</spring_stiffness>
          </dynamics>
        </axis>
      </joint>
      <link name='gripper_left_inner_finger_right_link'>
        <pose relative_to='gripper_left_inner_finger_right_joint'>0 0 0 0 -0 0</pose>
        <inertial>
          <pose>-0 0.024759 0 0 -0 0</pose>
          <mass>0.018619</mass>
          <inertia>
            <ixx>4.8806e-06</ixx>
            <ixy>-7.6762e-22</ixy>
            <ixz>1.0244e-22</ixz>
            <iyy>2.5471e-07</iyy>
            <iyz>-1.1841e-21</iyz>
            <izz>4.9573e-06</izz>
          </inertia>
        </inertial>
        <collision name='gripper_left_inner_finger_right_link_collision'>
          <pose>0 0 0 0 -0 0</pose>
          <geometry>
            <mesh>
              <scale>1 1 1</scale>
              <uri>model://pal_pro_gripper_description/meshes/inner_finger.stl</uri>
            </mesh>
          </geometry>
          <surface>
            <contact>
              <ode/>
            </contact>
            <friction>
              <ode>
                <mu>0.9</mu>
                <mu2>0.9</mu2>
              </ode>
              <torsional>
                <ode/>
              </torsional>
            </friction>
            <bounce/>
          </surface>
          <max_contacts>10</max_contacts>
        </collision>
        <visual name='gripper_left_inner_finger_right_link_visual'>
          <pose>0 0 0 0 -0 0</pose>
          <geometry>
            <mesh>
              <scale>1 1 1</scale>
              <uri>model://pal_pro_gripper_description/meshes/inner_finger.stl</uri>
            </mesh>
          </geometry>
          <material>
            <script>
              <name>Gazebo/White</name>
              <uri>file://media/materials/scripts/gazebo.material</uri>
            </script>
          </material>
        </visual>
        <self_collide>0</self_collide>
        <enable_wind>0</enable_wind>
        <kinematic>0</kinematic>
      </link>
      <joint name='gripper_left_fingertip_right_joint' type='revolute'>
        <pose relative_to='gripper_left_inner_finger_right_link'>0 0.05 0 0 -0 0.83776</pose>
        <parent>gripper_left_inner_finger_right_link</parent>
        <child>gripper_left_fingertip_right_link</child>
        <axis>
          <xyz>0 0 1</xyz>
          <limit>
            <lower>-0.802851</lower>
            <upper>0</upper>
            <effort>0.1</effort>
            <velocity>2</velocity>
          </limit>
          <dynamics>
            <spring_reference>0</spring_reference>
            <spring_stiffness>0</spring_stiffness>
          </dynamics>
        </axis>
      </joint>
      <link name='gripper_left_fingertip_right_link'>
        <pose relative_to='gripper_left_fingertip_right_joint'>0 0 0 0 -0 0</pose>
        <inertial>
          <pose>-0.000865 0.011929 -0 0 -0 0</pose>
          <mass>0.033503</mass>
          <inertia>
            <ixx>3.63918e-06</ixx>
            <ixy>3.40522e-07</ixy>
            <ixz>-1.41919e-14</ixz>
            <iyy>1.7095e-06</iyy>
            <iyz>-4.24737e-14</iyz>
            <izz>2.84428e-06</izz>
          </inertia>
        </inertial>
        <collision name='gripper_left_fingertip_right_link_collision'>
          <pose>0 0 0 0 -0 0</pose>
          <geometry>
            <mesh>
              <scale>1 1 1</scale>
              <uri>model://pal_pro_gripper_description/meshes/fingertip.stl</uri>
            </mesh>
          </geometry>
          <surface>
            <contact>
              <ode/>
            </contact>
            <friction>
              <ode>
                <mu>0.9</mu>
                <mu2>0.9</mu2>
              </ode>
              <torsional>
                <ode/>
              </torsional>
            </friction>
            <bounce/>
          </surface>
          <max_contacts>10</max_contacts>
        </collision>
        <visual name='gripper_left_fingertip_right_link_visual'>
          <pose>0 0 0 0 -0 0</pose>
          <geometry>
            <mesh>
              <scale>1 1 1</scale>
              <uri>model://pal_pro_gripper_description/meshes/fingertip.stl</uri>
            </mesh>
          </geometry>
          <material>
            <script>
              <name>Gazebo/White</name>
              <uri>file://media/materials/scripts/gazebo.material</uri>
            </script>
          </material>
        </visual>
        <self_collide>0</self_collide>
        <enable_wind>0</enable_wind>
        <kinematic>0</kinematic>
      </link>
      <joint name='gripper_left_outer_finger_right_joint' type='revolute'>
        <pose relative_to='arm_left_7_link'>0 0.0288 0.0913 1.5708 0.83776 1.5708</pose>
        <parent>arm_left_7_link</parent>
        <child>gripper_left_outer_finger_right_link</child>
        <axis>
          <xyz>0 0 1</xyz>
          <limit>
            <lower>0</lower>
            <upper>0.802851</upper>
            <effort>0.1</effort>
            <velocity>2</velocity>
          </limit>
          <dynamics>
            <spring_reference>0</spring_reference>
            <spring_stiffness>0</spring_stiffness>
          </dynamics>
        </axis>
      </joint>
      <link name='gripper_left_outer_finger_right_link'>
        <pose relative_to='gripper_left_outer_finger_right_joint'>0 0 0 0 -0 0</pose>
        <inertial>
          <pose>-0.001283 0.014397 0 0 -0 0</pose>
          <mass>0.0159888</mass>
          <inertia>
            <ixx>5.98786e-06</ixx>
            <ixy>-5.21729e-07</ixy>
            <ixz>-7.65399e-20</ixz>
            <iyy>4.87251e-07</iyy>
            <iyz>-7.03394e-19</iyz>
            <izz>6.14973e-06</izz>
          </inertia>
        </inertial>
        <collision name='gripper_left_outer_finger_right_link_collision'>
          <pose>0 0 0 0 -0 0</pose>
          <geometry>
            <mesh>
              <scale>1 1 1</scale>
              <uri>model://pal_pro_gripper_description/meshes/outer_finger.stl</uri>
            </mesh>
          </geometry>
          <surface>
            <contact>
              <ode/>
            </contact>
            <friction>
              <ode>
                <mu>0.9</mu>
                <mu2>0.9</mu2>
              </ode>
              <torsional>
                <ode/>
              </torsional>
            </friction>
            <bounce/>
          </surface>
          <max_contacts>10</max_contacts>
        </collision>
        <visual name='gripper_left_outer_finger_right_link_visual'>
          <pose>0 0 0 0 -0 0</pose>
          <geometry>
            <mesh>
              <scale>1 1 1</scale>
              <uri>model://pal_pro_gripper_description/meshes/outer_finger.stl</uri>
            </mesh>
          </geometry>
          <material>
            <script>
              <name>Gazebo/White</name>
              <uri>file://media/materials/scripts/gazebo.material</uri>
            </script>
          </material>
        </visual>
        <self_collide>0</self_collide>
        <enable_wind>0</enable_wind>
        <kinematic>0</kinematic>
      </link>
      <joint name='arm_right_1_joint' type='revolute'>
        <pose relative_to='torso_lift_link'>0.08976 -0.15918 -0.092008 -2.0679 0 -1.91989</pose>
        <parent>torso_lift_link</parent>
        <child>arm_right_1_link</child>
        <axis>
          <xyz>0 0 1</xyz>
          <limit>
            <lower>-4.71239</lower>
            <upper>0.523599</upper>
            <effort>43</effort>
            <velocity>2.5</velocity>
          </limit>
          <dynamics>
            <damping>1</damping>
            <friction>1</friction>
            <spring_reference>0</spring_reference>
            <spring_stiffness>0</spring_stiffness>
          </dynamics>
        </axis>
        <physics>
          <ode>
            <implicit_spring_damper>1</implicit_spring_damper>
            <cfm_damping>1</cfm_damping>
            <limit>
              <cfm>0</cfm>
              <erp>0.2</erp>
            </limit>
          </ode>
        </physics>
      </joint>
      <link name='arm_right_1_link'>
        <pose relative_to='arm_right_1_joint'>0 0 0 0 -0 0</pose>
        <inertial>
          <pose>0.004392 0.016184 0.15576 0 -0 0</pose>
          <mass>1.1325</mass>
          <inertia>
            <ixx>0.0025497</ixx>
            <ixy>2.6206e-05</ixy>
            <ixz>6.2082e-05</ixz>
            <iyy>0.0023517</iyy>
            <iyz>-0.00020617</iyz>
            <izz>0.00097131</izz>
          </inertia>
        </inertial>
        <collision name='arm_right_1_link_collision'>
          <pose>0 0 0 0 -0 0</pose>
          <geometry>
            <mesh>
              <scale>1 1 1</scale>
              <uri>model://pal_sea_arm_description/meshes/arm_tiago_pro/arm_1_link_collision.stl</uri>
            </mesh>
          </geometry>
          <surface>
            <contact>
              <ode/>
            </contact>
            <friction>
              <ode>
                <mu>0.9</mu>
                <mu2>0.9</mu2>
              </ode>
              <torsional>
                <ode/>
              </torsional>
            </friction>
            <bounce/>
          </surface>
          <max_contacts>10</max_contacts>
        </collision>
        <visual name='arm_right_1_link_visual'>
          <pose>0 0 0 0 -0 0</pose>
          <geometry>
            <mesh>
              <scale>1 1 1</scale>
              <uri>model://pal_sea_arm_description/meshes/arm_tiago_pro/arm_1_link.stl</uri>
            </mesh>
          </geometry>
          <material>
            <script>
              <name>Gazebo/DarkGrey</name>
              <uri>file://media/materials/scripts/gazebo.material</uri>
            </script>
          </material>
        </visual>
        <self_collide>0</self_collide>
        <enable_wind>0</enable_wind>
        <kinematic>0</kinematic>
      </link>
      <joint name='arm_right_2_joint' type='revolute'>
        <pose relative_to='arm_right_1_link'>0.03711 0.02 0.18 -1.5708 -0 -1.5708</pose>
        <parent>arm_right_1_link</parent>
        <child>arm_right_2_link</child>
        <axis>
          <xyz>0 0 1</xyz>
          <limit>
            <lower>-2.44346</lower>
            <upper>1.13446</upper>
            <effort>43</effort>
            <velocity>2.5</velocity>
          </limit>
          <dynamics>
            <damping>1</damping>
            <friction>1</friction>
            <spring_reference>0</spring_reference>
            <spring_stiffness>0</spring_stiffness>
          </dynamics>
        </axis>
        <physics>
          <ode>
            <implicit_spring_damper>1</implicit_spring_damper>
            <cfm_damping>1</cfm_damping>
            <limit>
              <cfm>0</cfm>
              <erp>0.2</erp>
            </limit>
          </ode>
        </physics>
      </joint>
      <link name='arm_right_2_link'>
        <pose relative_to='arm_right_2_joint'>0 0 0 0 -0 0</pose>
        <inertial>
          <pose>0.01786 -0.11956 -0.032097 0 -0 0</pose>
          <mass>1.0436</mass>
          <inertia>
            <ixx>0.0015021</ixx>
            <ixy>0.00011264</ixy>
            <ixz>1.0692e-05</ixz>
            <iyy>0.00088017</iyy>
            <iyz>-0.00015843</iyz>
            <izz>0.0016021</izz>
          </inertia>
        </inertial>
        <collision name='arm_right_2_link_collision'>
          <pose>0 0 0 0 -0 0</pose>
          <geometry>
            <mesh>
              <scale>1 1 1</scale>
              <uri>model://pal_sea_arm_description/meshes/arm_tiago_pro/arm_2_link_collision.stl</uri>
            </mesh>
          </geometry>
          <surface>
            <contact>
              <ode/>
            </contact>
            <friction>
              <ode>
                <mu>0.9</mu>
                <mu2>0.9</mu2>
              </ode>
              <torsional>
                <ode/>
              </torsional>
            </friction>
            <bounce/>
          </surface>
          <max_contacts>10</max_contacts>
        </collision>
        <visual name='arm_right_2_link_visual'>
          <pose>0 0 0 0 -0 0</pose>
          <geometry>
            <mesh>
              <scale>1 1 1</scale>
              <uri>model://pal_sea_arm_description/meshes/arm_tiago_pro/arm_2_link.stl</uri>
            </mesh>
          </geometry>
          <material>
            <script>
              <name>Gazebo/DarkGrey</name>
              <uri>file://media/materials/scripts/gazebo.material</uri>
            </script>
          </material>
        </visual>
        <self_collide>0</self_collide>
        <enable_wind>0</enable_wind>
        <kinematic>0</kinematic>
      </link>
      <joint name='arm_right_3_joint' type='revolute'>
        <pose relative_to='arm_right_2_link'>0.02 -0.17011 -0.03711 1.5708 -0 0</pose>
        <parent>arm_right_2_link</parent>
        <child>arm_right_3_link</child>
        <axis>
          <xyz>0 0 1</xyz>
          <limit>
            <lower>-2.61799</lower>
            <upper>2.61799</upper>
            <effort>26</effort>
            <velocity>2.5</velocity>
          </limit>
          <dynamics>
            <damping>1</damping>
            <friction>1</friction>
            <spring_reference>0</spring_reference>
            <spring_stiffness>0</spring_stiffness>
          </dynamics>
        </axis>
        <physics>
          <ode>
            <implicit_spring_damper>1</implicit_spring_damper>
            <cfm_damping>1</cfm_damping>
            <limit>
              <cfm>0</cfm>
              <erp>0.2</erp>
            </limit>
          </ode>
        </physics>
      </joint>
      <link name='arm_right_3_link'>
        <pose relative_to='arm_right_3_joint'>0 0 0 0 -0 0</pose>
        <inertial>
          <pose>0.016184 -0.004392 0.13565 0 -0 0</pose>
          <mass>1.1325</mass>
          <inertia>
            <ixx>0.0023517</ixx>
            <ixy>-2.6206e-05</ixy>
            <ixz>-0.00020617</ixz>
            <iyy>0.0025497</iyy>
            <iyz>-6.2082e-05</iyz>
            <izz>0.00097131</izz>
          </inertia>
        </inertial>
        <collision name='arm_right_3_link_collision'>
          <pose>0 0 0 0 -0 0</pose>
          <geometry>
            <mesh>
              <scale>1 1 1</scale>
              <uri>model://pal_sea_arm_description/meshes/arm_tiago_pro/arm_3_link_collision.stl</uri>
            </mesh>
          </geometry>
          <surface>
            <contact>
              <ode/>
            </contact>
            <friction>
              <ode>
                <mu>0.9</mu>
                <mu2>0.9</mu2>
              </ode>
              <torsional>
                <ode/>
              </torsional>
            </friction>
            <bounce/>
          </surface>
          <max_contacts>10</max_contacts>
        </collision>
        <visual name='arm_right_3_link_visual'>
          <pose>0 0 0 0 -0 0</pose>
          <geometry>
            <mesh>
              <scale>1 1 1</scale>
              <uri>model://pal_sea_arm_description/meshes/arm_tiago_pro/arm_3_link.stl</uri>
            </mesh>
          </geometry>
          <material>
            <script>
              <name>Gazebo/DarkGrey</name>
              <uri>file://media/materials/scripts/gazebo.material</uri>
            </script>
          </material>
        </visual>
        <self_collide>0</self_collide>
        <enable_wind>0</enable_wind>
        <kinematic>0</kinematic>
      </link>
      <joint name='arm_right_4_joint' type='revolute'>
        <pose relative_to='arm_right_3_link'>0.02 -0.03711 0.15989 1.5708 -0 0</pose>
        <parent>arm_right_3_link</parent>
        <child>arm_right_4_link</child>
        <axis>
          <xyz>0 0 1</xyz>
          <limit>
            <lower>-2.44346</lower>
            <upper>1.13446</upper>
            <effort>26</effort>
            <velocity>2.5</velocity>
          </limit>
          <dynamics>
            <damping>1</damping>
            <friction>1</friction>
            <spring_reference>0</spring_reference>
            <spring_stiffness>0</spring_stiffness>
          </dynamics>
        </axis>
        <physics>
          <ode>
            <implicit_spring_damper>1</implicit_spring_damper>
            <cfm_damping>1</cfm_damping>
            <limit>
              <cfm>0</cfm>
              <erp>0.2</erp>
            </limit>
          </ode>
        </physics>
      </joint>
      <link name='arm_right_4_link'>
        <pose relative_to='arm_right_4_joint'>0 0 0 0 -0 0</pose>
        <inertial>
          <pose>-0.01786 0.11956 -0.032097 0 -0 0</pose>
          <mass>1.0436</mass>
          <inertia>
            <ixx>0.0015021</ixx>
            <ixy>0.00011264</ixy>
            <ixz>-1.0692e-05</ixz>
            <iyy>0.00088017</iyy>
            <iyz>0.00015843</iyz>
            <izz>0.0016021</izz>
          </inertia>
        </inertial>
        <collision name='arm_right_4_link_collision'>
          <pose>0 0 0 0 -0 0</pose>
          <geometry>
            <mesh>
              <scale>1 1 1</scale>
              <uri>model://pal_sea_arm_description/meshes/arm_tiago_pro/arm_4_link_collision.stl</uri>
            </mesh>
          </geometry>
          <surface>
            <contact>
              <ode/>
            </contact>
            <friction>
              <ode>
                <mu>0.9</mu>
                <mu2>0.9</mu2>
              </ode>
              <torsional>
                <ode/>
              </torsional>
            </friction>
            <bounce/>
          </surface>
          <max_contacts>10</max_contacts>
        </collision>
        <visual name='arm_right_4_link_visual'>
          <pose>0 0 0 0 -0 0</pose>
          <geometry>
            <mesh>
              <scale>1 1 1</scale>
              <uri>model://pal_sea_arm_description/meshes/arm_tiago_pro/arm_4_link.stl</uri>
            </mesh>
          </geometry>
          <material>
            <script>
              <name>Gazebo/DarkGrey</name>
              <uri>file://media/materials/scripts/gazebo.material</uri>
            </script>
          </material>
        </visual>
        <self_collide>0</self_collide>
        <enable_wind>0</enable_wind>
        <kinematic>0</kinematic>
      </link>
      <joint name='arm_right_5_joint' type='revolute'>
        <pose relative_to='arm_right_4_link'>-0.02 0.17011 -0.03711 1.5708 0.001593 -3.14159</pose>
        <parent>arm_right_4_link</parent>
        <child>arm_right_5_link</child>
        <axis>
          <xyz>0 0 1</xyz>
          <limit>
            <lower>-1.5708</lower>
            <upper>3.66519</upper>
            <effort>26</effort>
            <velocity>2.5</velocity>
          </limit>
          <dynamics>
            <damping>1</damping>
            <friction>1</friction>
            <spring_reference>0</spring_reference>
            <spring_stiffness>0</spring_stiffness>
          </dynamics>
        </axis>
        <physics>
          <ode>
            <implicit_spring_damper>1</implicit_spring_damper>
            <cfm_damping>1</cfm_damping>
            <limit>
              <cfm>0</cfm>
              <erp>0.2</erp>
            </limit>
          </ode>
        </physics>
      </joint>
      <link name='arm_right_5_link'>
        <pose relative_to='arm_right_5_joint'>0 0 0 0 -0 0</pose>
        <inertial>
          <pose>1.1e-05 -0.027586 0.067845 0 -0 0</pose>
          <mass>0.310763</mass>
          <inertia>
            <ixx>0.00140145</ixx>
            <ixy>9.16506e-08</ixy>
            <ixz>-9.26254e-08</ixz>
            <iyy>0.00139999</iyy>
            <iyz>0.000327713</iyz>
            <izz>0.000402008</izz>
          </inertia>
        </inertial>
        <collision name='arm_right_5_link_collision'>
          <pose>0 0 0 0 -0 0</pose>
          <geometry>
            <mesh>
              <scale>1 1 1</scale>
              <uri>model://pal_sea_arm_description/meshes/arm_tiago_pro/spherical-wrist/arm_5_link.stl</uri>
            </mesh>
          </geometry>
          <surface>
            <contact>
              <ode/>
            </contact>
            <friction>
              <ode>
                <mu>0.9</mu>
                <mu2>0.9</mu2>
              </ode>
              <torsional>
                <ode/>
              </torsional>
            </friction>
            <bounce/>
          </surface>
          <max_contacts>10</max_contacts>
        </collision>
        <visual name='arm_right_5_link_visual'>
          <pose>0 0 0 0 -0 0</pose>
          <geometry>
            <mesh>
              <scale>1 1 1</scale>
              <uri>model://pal_sea_arm_description/meshes/arm_tiago_pro/spherical-wrist/arm_5_link.stl</uri>
            </mesh>
          </geometry>
          <material>
            <script>
              <name>Gazebo/DarkGrey</name>
              <uri>file://media/materials/scripts/gazebo.material</uri>
            </script>
          </material>
        </visual>
        <self_collide>0</self_collide>
        <enable_wind>0</enable_wind>
        <kinematic>0</kinematic>
      </link>
      <joint name='arm_right_6_joint' type='revolute'>
        <pose relative_to='arm_right_5_link'>0 -0.0422 0.1654 -1.5708 -0 3.14</pose>
        <parent>arm_right_5_link</parent>
        <child>arm_right_6_link</child>
        <axis>
          <xyz>0 0 -1</xyz>
          <limit>
            <lower>-1.88496</lower>
            <upper>3.00197</upper>
            <effort>26</effort>
            <velocity>2.5</velocity>
          </limit>
          <dynamics>
            <damping>1</damping>
            <friction>1</friction>
            <spring_reference>0</spring_reference>
            <spring_stiffness>0</spring_stiffness>
          </dynamics>
        </axis>
        <physics>
          <ode>
            <implicit_spring_damper>1</implicit_spring_damper>
            <cfm_damping>1</cfm_damping>
            <limit>
              <cfm>0</cfm>
              <erp>0.2</erp>
            </limit>
          </ode>
        </physics>
      </joint>
      <link name='arm_right_6_link'>
        <pose relative_to='arm_right_6_joint'>0 0 0 0 -0 0</pose>
        <inertial>
          <pose>0.031765 -0.006515 -0.040805 0 -0 0</pose>
          <mass>1.34587</mass>
          <inertia>
            <ixx>0.00109886</ixx>
            <ixy>0.000130003</ixy>
            <ixz>-5.88209e-06</ixz>
            <iyy>0.00116495</iyy>
            <iyz>4.20092e-07</iyz>
            <izz>0.00118984</izz>
          </inertia>
        </inertial>
        <collision name='arm_right_6_link_collision'>
          <pose>0 0 0 0 -0 0</pose>
          <geometry>
            <mesh>
              <scale>1 1 1</scale>
              <uri>model://pal_sea_arm_description/meshes/arm_tiago_pro/spherical-wrist/arm_6_link_collision.stl</uri>
            </mesh>
          </geometry>
          <surface>
            <contact>
              <ode/>
            </contact>
            <friction>
              <ode>
                <mu>0.9</mu>
                <mu2>0.9</mu2>
              </ode>
              <torsional>
                <ode/>
              </torsional>
            </friction>
            <bounce/>
          </surface>
          <max_contacts>10</max_contacts>
        </collision>
        <visual name='arm_right_6_link_visual'>
          <pose>0 0 0 0 -0 0</pose>
          <geometry>
            <mesh>
              <scale>1 1 1</scale>
              <uri>model://pal_sea_arm_description/meshes/arm_tiago_pro/spherical-wrist/arm_6_link.stl</uri>
            </mesh>
          </geometry>
          <material>
            <script>
              <name>Gazebo/DarkGrey</name>
              <uri>file://media/materials/scripts/gazebo.material</uri>
            </script>
          </material>
        </visual>
        <self_collide>0</self_collide>
        <enable_wind>0</enable_wind>
        <kinematic>0</kinematic>
      </link>
      <joint name='arm_right_7_joint' type='revolute'>
        <pose relative_to='arm_right_6_link'>0.07 -0.0534 -0.0422 1.5708 -0 0</pose>
        <parent>arm_right_6_link</parent>
        <child>arm_right_7_link</child>
        <axis>
          <xyz>0 0 1</xyz>
          <limit>
            <lower>-2.61799</lower>
            <upper>2.61799</upper>
            <effort>26</effort>
            <velocity>2.5</velocity>
          </limit>
          <dynamics>
            <damping>1</damping>
            <friction>1</friction>
            <spring_reference>0</spring_reference>
            <spring_stiffness>0</spring_stiffness>
          </dynamics>
        </axis>
        <physics>
          <provide_feedback>1</provide_feedback>
          <ode>
            <implicit_spring_damper>1</implicit_spring_damper>
            <cfm_damping>1</cfm_damping>
            <limit>
              <cfm>0</cfm>
              <erp>0.2</erp>
            </limit>
            <provide_feedback>1</provide_feedback>
          </ode>
        </physics>
      </joint>
      <link name='arm_right_7_link'>
        <pose relative_to='arm_right_7_joint'>0 0 0 0 -0 0</pose>
        <inertial>
          <pose>0.000371 -0.00062 0.049358 0 -0 0</pose>
          <mass>0.475823</mass>
          <inertia>
            <ixx>0.000575813</ixx>
            <ixy>2.12403e-07</ixy>
            <ixz>9.89094e-06</ixz>
            <iyy>0.000502928</iyy>
            <iyz>-1.12781e-05</iyz>
            <izz>0.000374898</izz>
          </inertia>
        </inertial>
        <collision name='arm_right_7_link_collision'>
          <pose>0 0 0 0 -0 0</pose>
          <geometry>
            <cylinder>
              <length>0.0366</length>
              <radius>0.0375</radius>
            </cylinder>
          </geometry>
          <surface>
            <contact>
              <ode/>
            </contact>
            <friction>
              <ode>
                <mu>0.9</mu>
                <mu2>0.9</mu2>
              </ode>
              <torsional>
                <ode/>
              </torsional>
            </friction>
            <bounce/>
          </surface>
          <max_contacts>10</max_contacts>
        </collision>
        <collision name='arm_right_7_link_fixed_joint_lump__gripper_right_base_link_collision_1'>
          <pose>0 0 0.017 0 -0 0</pose>
          <geometry>
            <mesh>
              <scale>1 1 1</scale>
              <uri>model://pal_pro_gripper_description/meshes/base_link_tc.stl</uri>
            </mesh>
          </geometry>
          <surface>
            <contact>
              <ode/>
            </contact>
            <friction>
              <ode>
                <mu>0.9</mu>
                <mu2>0.9</mu2>
              </ode>
              <torsional>
                <ode/>
              </torsional>
            </friction>
            <bounce/>
          </surface>
          <max_contacts>10</max_contacts>
        </collision>
        <visual name='arm_right_7_link_visual'>
          <pose>0 0 0 0 -0 0</pose>
          <geometry>
            <mesh>
              <scale>1 1 1</scale>
              <uri>model://pal_sea_arm_description/meshes/arm_tiago_pro/spherical-wrist/arm_7_link.stl</uri>
            </mesh>
          </geometry>
          <material>
            <script>
              <name>Gazebo/DarkGrey</name>
              <uri>file://media/materials/scripts/gazebo.material</uri>
            </script>
          </material>
        </visual>
        <visual name='arm_right_7_link_fixed_joint_lump__gripper_right_base_link_visual_1'>
          <pose>0 0 0.017 0 -0 0</pose>
          <geometry>
            <mesh>
              <scale>1 1 1</scale>
              <uri>model://pal_pro_gripper_description/meshes/base_link_tc.stl</uri>
            </mesh>
          </geometry>
          <material>
            <script>
              <name>Gazebo/DarkGrey</name>
              <uri>file://media/materials/scripts/gazebo.material</uri>
            </script>
          </material>
        </visual>
        <self_collide>0</self_collide>
        <enable_wind>0</enable_wind>
        <kinematic>0</kinematic>
      </link>
      <joint name='gripper_right_finger_joint' type='revolute'>
        <pose relative_to='arm_right_7_link'>0 -0.0288 0.0913 1.5708 0.83776 -1.5708</pose>
        <parent>arm_right_7_link</parent>
        <child>gripper_right_outer_finger_left_link</child>
        <axis>
          <xyz>0 0 1</xyz>
          <limit>
            <lower>0</lower>
            <upper>0.802851</upper>
            <effort>0.1</effort>
            <velocity>2</velocity>
          </limit>
          <dynamics>
            <damping>0.03</damping>
            <friction>0</friction>
            <spring_reference>0</spring_reference>
            <spring_stiffness>0</spring_stiffness>
          </dynamics>
        </axis>
        <physics>
          <ode>
            <limit>
              <cfm>0</cfm>
              <erp>0.2</erp>
            </limit>
            <implicit_spring_damper>1</implicit_spring_damper>
            <cfm_damping>1</cfm_damping>
            <provide_feedback>1</provide_feedback>
          </ode>
          <provide_feedback>1</provide_feedback>
        </physics>
      </joint>
      <link name='gripper_right_outer_finger_left_link'>
        <pose relative_to='gripper_right_finger_joint'>0 0 0 0 -0 0</pose>
        <inertial>
          <pose>-0.001283 0.014397 0 0 -0 0</pose>
          <mass>0.0159888</mass>
          <inertia>
            <ixx>5.98786e-06</ixx>
            <ixy>-5.21729e-07</ixy>
            <ixz>-7.65399e-20</ixz>
            <iyy>4.87251e-07</iyy>
            <iyz>-7.03394e-19</iyz>
            <izz>6.14973e-06</izz>
          </inertia>
        </inertial>
        <collision name='gripper_right_outer_finger_left_link_collision'>
          <pose>0 0 0 0 -0 0</pose>
          <geometry>
            <mesh>
              <scale>1 1 1</scale>
              <uri>model://pal_pro_gripper_description/meshes/outer_finger.stl</uri>
            </mesh>
          </geometry>
          <surface>
            <contact>
              <ode/>
            </contact>
            <friction>
              <ode>
                <mu>0.9</mu>
                <mu2>0.9</mu2>
              </ode>
              <torsional>
                <ode/>
              </torsional>
            </friction>
            <bounce/>
          </surface>
          <max_contacts>10</max_contacts>
        </collision>
        <visual name='gripper_right_outer_finger_left_link_visual'>
          <pose>0 0 0 0 -0 0</pose>
          <geometry>
            <mesh>
              <scale>1 1 1</scale>
              <uri>model://pal_pro_gripper_description/meshes/outer_finger.stl</uri>
            </mesh>
          </geometry>
          <material>
            <script>
              <name>Gazebo/White</name>
              <uri>file://media/materials/scripts/gazebo.material</uri>
            </script>
          </material>
        </visual>
        <self_collide>0</self_collide>
        <enable_wind>0</enable_wind>
        <kinematic>0</kinematic>
      </link>
      <joint name='gripper_right_inner_finger_left_joint' type='revolute'>
        <pose relative_to='arm_right_7_link'>0 -0.013977 0.095832 1.5708 0.83776 -1.5708</pose>
        <parent>arm_right_7_link</parent>
        <child>gripper_right_inner_finger_left_link</child>
        <axis>
          <xyz>0 0 1</xyz>
          <limit>
            <lower>0</lower>
            <upper>0.802851</upper>
            <effort>0.1</effort>
            <velocity>2</velocity>
          </limit>
          <dynamics>
            <spring_reference>0</spring_reference>
            <spring_stiffness>0</spring_stiffness>
          </dynamics>
        </axis>
      </joint>
      <link name='gripper_right_inner_finger_left_link'>
        <pose relative_to='gripper_right_inner_finger_left_joint'>0 0 0 0 -0 0</pose>
        <inertial>
          <pose>-0 0.024759 0 0 -0 0</pose>
          <mass>0.018619</mass>
          <inertia>
            <ixx>4.8806e-06</ixx>
            <ixy>-7.6762e-22</ixy>
            <ixz>1.0244e-22</ixz>
            <iyy>2.5471e-07</iyy>
            <iyz>-1.1841e-21</iyz>
            <izz>4.9573e-06</izz>
          </inertia>
        </inertial>
        <collision name='gripper_right_inner_finger_left_link_collision'>
          <pose>0 0 0 0 -0 0</pose>
          <geometry>
            <mesh>
              <scale>1 1 1</scale>
              <uri>model://pal_pro_gripper_description/meshes/inner_finger.stl</uri>
            </mesh>
          </geometry>
          <surface>
            <contact>
              <ode/>
            </contact>
            <friction>
              <ode>
                <mu>0.9</mu>
                <mu2>0.9</mu2>
              </ode>
              <torsional>
                <ode/>
              </torsional>
            </friction>
            <bounce/>
          </surface>
          <max_contacts>10</max_contacts>
        </collision>
        <visual name='gripper_right_inner_finger_left_link_visual'>
          <pose>0 0 0 0 -0 0</pose>
          <geometry>
            <mesh>
              <scale>1 1 1</scale>
              <uri>model://pal_pro_gripper_description/meshes/inner_finger.stl</uri>
            </mesh>
          </geometry>
          <material>
            <script>
              <name>Gazebo/White</name>
              <uri>file://media/materials/scripts/gazebo.material</uri>
            </script>
          </material>
        </visual>
        <self_collide>0</self_collide>
        <enable_wind>0</enable_wind>
        <kinematic>0</kinematic>
      </link>
      <joint name='gripper_right_fingertip_left_joint' type='revolute'>
        <pose relative_to='gripper_right_inner_finger_left_link'>0 0.05 0 0 -0 0.83776</pose>
        <parent>gripper_right_inner_finger_left_link</parent>
        <child>gripper_right_fingertip_left_link</child>
        <axis>
          <xyz>0 0 1</xyz>
          <limit>
            <lower>-0.802851</lower>
            <upper>0</upper>
            <effort>0.1</effort>
            <velocity>2</velocity>
          </limit>
          <dynamics>
            <spring_reference>0</spring_reference>
            <spring_stiffness>0</spring_stiffness>
          </dynamics>
        </axis>
      </joint>
      <link name='gripper_right_fingertip_left_link'>
        <pose relative_to='gripper_right_fingertip_left_joint'>0 0 0 0 -0 0</pose>
        <inertial>
          <pose>-0.000865 0.011929 -0 0 -0 0</pose>
          <mass>0.033503</mass>
          <inertia>
            <ixx>3.63918e-06</ixx>
            <ixy>3.40522e-07</ixy>
            <ixz>-1.41919e-14</ixz>
            <iyy>1.7095e-06</iyy>
            <iyz>-4.24737e-14</iyz>
            <izz>2.84428e-06</izz>
          </inertia>
        </inertial>
        <collision name='gripper_right_fingertip_left_link_collision'>
          <pose>0 0 0 0 -0 0</pose>
          <geometry>
            <mesh>
              <scale>1 1 1</scale>
              <uri>model://pal_pro_gripper_description/meshes/fingertip.stl</uri>
            </mesh>
          </geometry>
          <surface>
            <contact>
              <ode/>
            </contact>
            <friction>
              <ode>
                <mu>0.9</mu>
                <mu2>0.9</mu2>
              </ode>
              <torsional>
                <ode/>
              </torsional>
            </friction>
            <bounce/>
          </surface>
          <max_contacts>10</max_contacts>
        </collision>
        <visual name='gripper_right_fingertip_left_link_visual'>
          <pose>0 0 0 0 -0 0</pose>
          <geometry>
            <mesh>
              <scale>1 1 1</scale>
              <uri>model://pal_pro_gripper_description/meshes/fingertip.stl</uri>
            </mesh>
          </geometry>
          <material>
            <script>
              <name>Gazebo/White</name>
              <uri>file://media/materials/scripts/gazebo.material</uri>
            </script>
          </material>
        </visual>
        <self_collide>0</self_collide>
        <enable_wind>0</enable_wind>
        <kinematic>0</kinematic>
      </link>
      <joint name='gripper_right_inner_finger_right_joint' type='revolute'>
        <pose relative_to='arm_right_7_link'>0 0.013977 0.095832 1.5708 0.83776 1.5708</pose>
        <parent>arm_right_7_link</parent>
        <child>gripper_right_inner_finger_right_link</child>
        <axis>
          <xyz>0 0 1</xyz>
          <limit>
            <lower>0</lower>
            <upper>0.802851</upper>
            <effort>0.1</effort>
            <velocity>2</velocity>
          </limit>
          <dynamics>
            <spring_reference>0</spring_reference>
            <spring_stiffness>0</spring_stiffness>
          </dynamics>
        </axis>
      </joint>
      <link name='gripper_right_inner_finger_right_link'>
        <pose relative_to='gripper_right_inner_finger_right_joint'>0 0 0 0 -0 0</pose>
        <inertial>
          <pose>-0 0.024759 0 0 -0 0</pose>
          <mass>0.018619</mass>
          <inertia>
            <ixx>4.8806e-06</ixx>
            <ixy>-7.6762e-22</ixy>
            <ixz>1.0244e-22</ixz>
            <iyy>2.5471e-07</iyy>
            <iyz>-1.1841e-21</iyz>
            <izz>4.9573e-06</izz>
          </inertia>
        </inertial>
        <collision name='gripper_right_inner_finger_right_link_collision'>
          <pose>0 0 0 0 -0 0</pose>
          <geometry>
            <mesh>
              <scale>1 1 1</scale>
              <uri>model://pal_pro_gripper_description/meshes/inner_finger.stl</uri>
            </mesh>
          </geometry>
          <surface>
            <contact>
              <ode/>
            </contact>
            <friction>
              <ode>
                <mu>0.9</mu>
                <mu2>0.9</mu2>
              </ode>
              <torsional>
                <ode/>
              </torsional>
            </friction>
            <bounce/>
          </surface>
          <max_contacts>10</max_contacts>
        </collision>
        <visual name='gripper_right_inner_finger_right_link_visual'>
          <pose>0 0 0 0 -0 0</pose>
          <geometry>
            <mesh>
              <scale>1 1 1</scale>
              <uri>model://pal_pro_gripper_description/meshes/inner_finger.stl</uri>
            </mesh>
          </geometry>
          <material>
            <script>
              <name>Gazebo/White</name>
              <uri>file://media/materials/scripts/gazebo.material</uri>
            </script>
          </material>
        </visual>
        <self_collide>0</self_collide>
        <enable_wind>0</enable_wind>
        <kinematic>0</kinematic>
      </link>
      <joint name='gripper_right_fingertip_right_joint' type='revolute'>
        <pose relative_to='gripper_right_inner_finger_right_link'>0 0.05 0 0 -0 0.83776</pose>
        <parent>gripper_right_inner_finger_right_link</parent>
        <child>gripper_right_fingertip_right_link</child>
        <axis>
          <xyz>0 0 1</xyz>
          <limit>
            <lower>-0.802851</lower>
            <upper>0</upper>
            <effort>0.1</effort>
            <velocity>2</velocity>
          </limit>
          <dynamics>
            <spring_reference>0</spring_reference>
            <spring_stiffness>0</spring_stiffness>
          </dynamics>
        </axis>
      </joint>
      <link name='gripper_right_fingertip_right_link'>
        <pose relative_to='gripper_right_fingertip_right_joint'>0 0 0 0 -0 0</pose>
        <inertial>
          <pose>-0.000865 0.011929 -0 0 -0 0</pose>
          <mass>0.033503</mass>
          <inertia>
            <ixx>3.63918e-06</ixx>
            <ixy>3.40522e-07</ixy>
            <ixz>-1.41919e-14</ixz>
            <iyy>1.7095e-06</iyy>
            <iyz>-4.24737e-14</iyz>
            <izz>2.84428e-06</izz>
          </inertia>
        </inertial>
        <collision name='gripper_right_fingertip_right_link_collision'>
          <pose>0 0 0 0 -0 0</pose>
          <geometry>
            <mesh>
              <scale>1 1 1</scale>
              <uri>model://pal_pro_gripper_description/meshes/fingertip.stl</uri>
            </mesh>
          </geometry>
          <surface>
            <contact>
              <ode/>
            </contact>
            <friction>
              <ode>
                <mu>0.9</mu>
                <mu2>0.9</mu2>
              </ode>
              <torsional>
                <ode/>
              </torsional>
            </friction>
            <bounce/>
          </surface>
          <max_contacts>10</max_contacts>
        </collision>
        <visual name='gripper_right_fingertip_right_link_visual'>
          <pose>0 0 0 0 -0 0</pose>
          <geometry>
            <mesh>
              <scale>1 1 1</scale>
              <uri>model://pal_pro_gripper_description/meshes/fingertip.stl</uri>
            </mesh>
          </geometry>
          <material>
            <script>
              <name>Gazebo/White</name>
              <uri>file://media/materials/scripts/gazebo.material</uri>
            </script>
          </material>
        </visual>
        <self_collide>0</self_collide>
        <enable_wind>0</enable_wind>
        <kinematic>0</kinematic>
      </link>
      <joint name='gripper_right_outer_finger_right_joint' type='revolute'>
        <pose relative_to='arm_right_7_link'>0 0.0288 0.0913 1.5708 0.83776 1.5708</pose>
        <parent>arm_right_7_link</parent>
        <child>gripper_right_outer_finger_right_link</child>
        <axis>
          <xyz>0 0 1</xyz>
          <limit>
            <lower>0</lower>
            <upper>0.802851</upper>
            <effort>0.1</effort>
            <velocity>2</velocity>
          </limit>
          <dynamics>
            <spring_reference>0</spring_reference>
            <spring_stiffness>0</spring_stiffness>
          </dynamics>
        </axis>
      </joint>
      <link name='gripper_right_outer_finger_right_link'>
        <pose relative_to='gripper_right_outer_finger_right_joint'>0 0 0 0 -0 0</pose>
        <inertial>
          <pose>-0.001283 0.014397 0 0 -0 0</pose>
          <mass>0.0159888</mass>
          <inertia>
            <ixx>5.98786e-06</ixx>
            <ixy>-5.21729e-07</ixy>
            <ixz>-7.65399e-20</ixz>
            <iyy>4.87251e-07</iyy>
            <iyz>-7.03394e-19</iyz>
            <izz>6.14973e-06</izz>
          </inertia>
        </inertial>
        <collision name='gripper_right_outer_finger_right_link_collision'>
          <pose>0 0 0 0 -0 0</pose>
          <geometry>
            <mesh>
              <scale>1 1 1</scale>
              <uri>model://pal_pro_gripper_description/meshes/outer_finger.stl</uri>
            </mesh>
          </geometry>
          <surface>
            <contact>
              <ode/>
            </contact>
            <friction>
              <ode>
                <mu>0.9</mu>
                <mu2>0.9</mu2>
              </ode>
              <torsional>
                <ode/>
              </torsional>
            </friction>
            <bounce/>
          </surface>
          <max_contacts>10</max_contacts>
        </collision>
        <visual name='gripper_right_outer_finger_right_link_visual'>
          <pose>0 0 0 0 -0 0</pose>
          <geometry>
            <mesh>
              <scale>1 1 1</scale>
              <uri>model://pal_pro_gripper_description/meshes/outer_finger.stl</uri>
            </mesh>
          </geometry>
          <material>
            <script>
              <name>Gazebo/White</name>
              <uri>file://media/materials/scripts/gazebo.material</uri>
            </script>
          </material>
        </visual>
        <self_collide>0</self_collide>
        <enable_wind>0</enable_wind>
        <kinematic>0</kinematic>
      </link>
      <joint name='head_1_joint' type='revolute'>
        <pose relative_to='torso_lift_link'>0 0 0.04 0 -0 0</pose>
        <parent>torso_lift_link</parent>
        <child>head_1_link</child>
        <axis>
          <xyz>0 0 1</xyz>
          <limit>
            <lower>-1.309</lower>
            <upper>1.309</upper>
            <effort>5.197</effort>
            <velocity>3</velocity>
          </limit>
          <dynamics>
            <damping>0.5</damping>
            <friction>1</friction>
            <spring_reference>0</spring_reference>
            <spring_stiffness>0</spring_stiffness>
          </dynamics>
        </axis>
        <physics>
          <ode>
            <implicit_spring_damper>1</implicit_spring_damper>
            <cfm_damping>1</cfm_damping>
            <limit>
              <cfm>0</cfm>
              <erp>0.2</erp>
            </limit>
          </ode>
        </physics>
      </joint>
      <link name='head_1_link'>
        <pose relative_to='head_1_joint'>0 0 0 0 -0 0</pose>
        <inertial>
          <pose>-0.003746 -4.7e-05 0.1055 0 -0 0</pose>
          <mass>0.15566</mass>
          <inertia>
            <ixx>0.0005208</ixx>
            <ixy>3.0453e-07</ixy>
            <ixz>-6.1005e-05</ixz>
            <iyy>0.00035021</iyy>
            <iyz>5.8627e-07</iyz>
            <izz>0.00033341</izz>
          </inertia>
        </inertial>
        <collision name='head_1_link_collision'>
          <pose>0 0 0 0 -0 0</pose>
          <geometry>
            <mesh>
              <scale>1 1 1</scale>
              <uri>model://tiago_pro_head_description/meshes/head_1_link_collision.stl</uri>
            </mesh>
          </geometry>
          <surface>
            <contact>
              <ode/>
            </contact>
            <friction>
              <ode>
                <mu>0.9</mu>
                <mu2>0.9</mu2>
              </ode>
              <torsional>
                <ode/>
              </torsional>
            </friction>
            <bounce/>
          </surface>
          <max_contacts>10</max_contacts>
        </collision>
        <visual name='head_1_link_visual'>
          <pose>0 0 0 0 -0 0</pose>
          <geometry>
            <mesh>
              <scale>1 1 1</scale>
              <uri>model://tiago_pro_head_description/meshes/head_1_link.stl</uri>
            </mesh>
          </geometry>
          <material>
            <script>
              <name>Gazebo/DarkGrey</name>
              <uri>file://media/materials/scripts/gazebo.material</uri>
            </script>
          </material>
        </visual>
        <self_collide>0</self_collide>
        <enable_wind>0</enable_wind>
        <kinematic>0</kinematic>
      </link>
      <joint name='head_2_joint' type='revolute'>
        <pose relative_to='head_1_link'>0.0425 0 0.10585 1.5708 -0 3.14159</pose>
        <parent>head_1_link</parent>
        <child>head_2_link</child>
        <axis>
          <xyz>0 0 -1</xyz>
          <limit>
            <lower>-1.0472</lower>
            <upper>0.34907</upper>
            <effort>2.77</effort>
            <velocity>3</velocity>
          </limit>
          <dynamics>
            <damping>0.5</damping>
            <friction>1</friction>
            <spring_reference>0</spring_reference>
            <spring_stiffness>0</spring_stiffness>
          </dynamics>
        </axis>
        <physics>
          <ode>
            <implicit_spring_damper>1</implicit_spring_damper>
            <cfm_damping>1</cfm_damping>
            <limit>
              <cfm>0</cfm>
              <erp>0.2</erp>
            </limit>
          </ode>
        </physics>
      </joint>
      <link name='head_2_link'>
        <pose relative_to='head_2_joint'>0 0 0 0 -0 0</pose>
        <inertial>
          <pose>-0.012157 0.118351 0.001013 0 -0 0</pose>
          <mass>0.918359</mass>
          <inertia>
            <ixx>0.0103336</ixx>
            <ixy>-0.000394794</ixy>
            <ixz>4.21719e-05</ixz>
            <iyy>0.00905778</iyy>
            <iyz>-6.96497e-05</iyz>
            <izz>0.0033149</izz>
          </inertia>
        </inertial>
        <collision name='head_2_link_collision'>
          <pose>0 0 0 0 -0 0</pose>
          <geometry>
            <mesh>
              <scale>1 1 1</scale>
              <uri>model://tiago_pro_head_description/meshes/head_2_link_collision.stl</uri>
            </mesh>
          </geometry>
          <surface>
            <contact>
              <ode/>
            </contact>
            <friction>
              <ode>
                <mu>0.9</mu>
                <mu2>0.9</mu2>
              </ode>
              <torsional>
                <ode/>
              </torsional>
            </friction>
            <bounce/>
          </surface>
          <max_contacts>10</max_contacts>
        </collision>
        <collision name='head_2_link_fixed_joint_lump__head_front_camera_link_collision_1'>
          <pose>-0.0522 0.168 -0 1.5708 -0 -3.14159</pose>
          <geometry>
            <box>
              <size>0.02505 0.09 0.025</size>
            </box>
          </geometry>
          <surface>
            <contact>
              <ode>
                <kp>1e+13</kp>
                <kd>1</kd>
              </ode>
            </contact>
            <friction>
              <ode>
                <mu2>1</mu2>
                <fdir1>0 0 0</fdir1>
              </ode>
              <torsional>
                <ode/>
              </torsional>
            </friction>
            <bounce/>
          </surface>
          <max_contacts>10</max_contacts>
        </collision>
        <visual name='head_2_link_visual'>
          <pose>0 0 0 0 -0 0</pose>
          <geometry>
            <mesh>
              <scale>1 1 1</scale>
              <uri>model://tiago_pro_head_description/meshes/head_2_link.stl</uri>
            </mesh>
          </geometry>
          <material>
            <script>
              <name>Gazebo/White</name>
              <uri>file://media/materials/scripts/gazebo.material</uri>
            </script>
          </material>
        </visual>
        <visual name='head_2_link_fixed_joint_lump__head_front_camera_link_visual_1'>
          <pose>-0.0565 0.168 -0 -3.14159 -1.57079 3.14159</pose>
          <geometry>
            <mesh>
              <scale>1 1 1</scale>
              <uri>file:///opt/pal/alum/share/realsense2_description/meshes/d435.dae</uri>
            </mesh>
          </geometry>
        </visual>
        <self_collide>0</self_collide>
        <enable_wind>0</enable_wind>
        <kinematic>0</kinematic>
        <gravity>1</gravity>
        <sensor name='head_front_cameracolor' type='camera'>
          <camera name='head_front_camera'>
            <horizontal_fov>1.21126</horizontal_fov>
            <image>
              <width>640</width>
              <height>480</height>
              <format>RGB_INT8</format>
            </image>
            <clip>
              <near>0.1</near>
              <far>100</far>
            </clip>
            <noise>
              <type>gaussian</type>
              <mean>0</mean>
              <stddev>0.007</stddev>
            </noise>
          </camera>
          <always_on>1</always_on>
          <update_rate>30</update_rate>
          <visualize>1</visualize>
          <pose>-0.0522 0.168 0.0175 1.5708 -0 -3.14159</pose>
        </sensor>
        <sensor name='head_front_cameraired1' type='camera'>
          <camera name='head_front_camera'>
            <horizontal_fov>1.48702</horizontal_fov>
            <image>
              <width>1280</width>
              <height>720</height>
              <format>L_INT8</format>
            </image>
            <clip>
              <near>0.1</near>
              <far>100</far>
            </clip>
            <noise>
              <type>gaussian</type>
              <mean>0</mean>
              <stddev>0.05</stddev>
            </noise>
          </camera>
          <always_on>1</always_on>
          <update_rate>30</update_rate>
          <visualize>0</visualize>
          <pose>-0.0522 0.168 0.0175 1.5708 -0 -3.14159</pose>
        </sensor>
        <sensor name='head_front_cameraired2' type='camera'>
          <camera name='head_front_camera'>
            <horizontal_fov>1.48702</horizontal_fov>
            <image>
              <width>1280</width>
              <height>720</height>
              <format>L_INT8</format>
            </image>
            <clip>
              <near>0.1</near>
              <far>100</far>
            </clip>
            <noise>
              <type>gaussian</type>
              <mean>0</mean>
              <stddev>0.05</stddev>
            </noise>
          </camera>
          <always_on>1</always_on>
          <update_rate>30</update_rate>
          <visualize>0</visualize>
          <pose>-0.0522 0.168 0.0175 1.5708 -0 -3.14159</pose>
        </sensor>
        <sensor name='head_front_cameradepth' type='depth'>
          <camera name='head_front_camera'>
            <horizontal_fov>1.48702</horizontal_fov>
            <image>
              <width>1280</width>
              <height>720</height>
            </image>
            <clip>
              <near>0.1</near>
              <far>100</far>
            </clip>
            <noise>
              <type>gaussian</type>
              <mean>0</mean>
              <stddev>0.1</stddev>
            </noise>
          </camera>
          <always_on>1</always_on>
          <update_rate>30</update_rate>
          <visualize>0</visualize>
          <pose>-0.0522 0.168 0.0175 1.5708 -0 -3.14159</pose>
        </sensor>
      </link>
      <plugin name='gazebo_ros_planar_move' filename='libgazebo_ros_planar_move.so'>
        <ros>
          <remapping>cmd_vel:=mobile_base_controller/cmd_vel_unstamped</remapping>
          <remapping>odom:=mobile_base_controller/odom</remapping>
        </ros>
        <update_rate>100</update_rate>
        <publish_rate>1000</publish_rate>
        <publish_odom>1</publish_odom>
        <publish_odom_tf>0</publish_odom_tf>
        <odometry_frame>odom</odometry_frame>
        <robot_base_frame>base_footprint</robot_base_frame>
        <covariance_x>0.0001</covariance_x>
        <covariance_y>0.0001</covariance_y>
        <covariance_yaw>0.01</covariance_yaw>
      </plugin>
      <plugin name='head_front_camera' filename='librealsense_gazebo_plugin.so'>
        <prefix>head_front_camera</prefix>
        <depthUpdateRate>30.0</depthUpdateRate>
        <colorUpdateRate>30.0</colorUpdateRate>
        <infraredUpdateRate>30.0</infraredUpdateRate>
        <depthTopicName>depth/image_raw</depthTopicName>
        <colorTopicName>color/image_raw</colorTopicName>
        <infrared1TopicName>infra1/image_raw</infrared1TopicName>
        <infrared2TopicName>infra2/image_raw</infrared2TopicName>
        <colorOpticalframeName>head_front_camera_color_optical_frame</colorOpticalframeName>
        <depthOpticalframeName>head_front_camera_depth_optical_frame</depthOpticalframeName>
        <infrared1OpticalframeName>head_front_camera_infra1_ir_optical_frame</infrared1OpticalframeName>
        <infrared2OpticalframeName>head_front_camera_infra2_ir_optical_frame</infrared2OpticalframeName>
        <rangeMinDepth>0.2</rangeMinDepth>
        <rangeMaxDepth>10.0</rangeMaxDepth>
        <pointCloud>1</pointCloud>
        <pointCloudTopicName>depth/color/points</pointCloudTopicName>
        <pointCloudCutoff>0.25</pointCloudCutoff>
        <pointCloudCutoffMax>9.0</pointCloudCutoffMax>
      </plugin>
      <static>0</static>
      <plugin name='gazebo_ros2_control' filename='libgazebo_ros2_control.so'>
        <parameters>/opt/pal/alum/share/tiago_pro_description/ros2_control/gazebo_controller_manager_cfg.yaml</parameters>
      </plugin>
      <pose>0 0 0 0 -0 0</pose>
    </model>
    <model name='MaleVisitorSit'>
      <static>1</static>
      <link name='body'>
        <pose>0 0 0 0 -0 0</pose>
        <visual name='visual'>
          <geometry>
            <mesh>
              <uri>model://MaleVisitorSit/meshes/MaleVisitorSit.obj</uri>
            </mesh>
          </geometry>
        </visual>
        <collision name='collision'>
          <geometry>
            <mesh>
              <uri>model://MaleVisitorSit/meshes/MaleVisitorSit_Col.obj</uri>
            </mesh>
          </geometry>
          <max_contacts>10</max_contacts>
          <surface>
            <contact>
              <ode/>
            </contact>
            <bounce/>
            <friction>
              <torsional>
                <ode/>
              </torsional>
              <ode/>
            </friction>
          </surface>
        </collision>
        <self_collide>0</self_collide>
        <enable_wind>0</enable_wind>
        <kinematic>0</kinematic>
      </link>
      <pose>1.86548 0.090942 0 0 -0 0</pose>
    </model>
    <state world_name='default'>
      <sim_time>45 166000000</sim_time>
      <real_time>132 62621061</real_time>
      <wall_time>1738236004 950840033</wall_time>
      <iterations>45166</iterations>
      <model name='MaleVisitorSit'>
        <pose>1.72441 -0.050949 0 0 -0 1.56203</pose>
        <scale>1 1 1</scale>
        <link name='body'>
          <pose>1.72441 -0.050949 0 0 -0 1.56203</pose>
          <velocity>0 0 0 0 -0 0</velocity>
          <acceleration>0 0 0 0 -0 0</acceleration>
          <wrench>0 0 0 0 -0 0</wrench>
        </link>
      </model>
      <model name='ground_plane'>
        <pose>0 0 0 0 -0 0</pose>
        <scale>1 1 1</scale>
        <link name='link'>
          <pose>0 0 0 0 -0 0</pose>
          <velocity>0 0 0 0 -0 0</velocity>
          <acceleration>0 0 0 0 -0 0</acceleration>
          <wrench>0 0 0 0 -0 0</wrench>
        </link>
      </model>
      <model name='tiago-pro'>
        <pose>-0.006431 -3.2e-05 -5.4e-05 0 -0 0.000718</pose>
        <scale>1 1 1</scale>
        <link name='arm_left_1_link'>
          <pose>0.058715 0.159195 0.853628 -2.09616 0.314811 -1.39859</pose>
          <velocity>-0.000166 1e-06 -0.008909 -0.000475 -0.000176 0.000287</velocity>
          <acceleration>-0.039553 -0.008684 -8.9669 -1.07381 -0.475555 0.567523</acceleration>
          <wrench>-0.044794 -0.009835 -10.155 0 -0 0</wrench>
        </link>
        <link name='arm_left_2_link'>
          <pose>0.202593 0.182214 0.739847 2.00205 0.736634 0.472006</pose>
          <velocity>-0.000153 -1.2e-05 -0.008895 -0.000283 -0.001271 -7.6e-05</velocity>
          <acceleration>0.079289 -0.030516 -9.06848 -0.349913 -0.710621 0.081486</acceleration>
          <wrench>0.082746 -0.031847 -9.46387 0 -0 0</wrench>
        </link>
        <link name='arm_left_3_link'>
          <pose>0.084946 0.239844 0.623432 3.09973 0.831857 -0.185148</pose>
          <velocity>-1e-06 -3.6e-05 -0.00906 -6.6e-05 -0.001299 0.000123</velocity>
          <acceleration>0.255076 -0.053768 -9.23265 0.032662 -1.30256 0.165249</acceleration>
          <wrench>0.288873 -0.060892 -10.456 0 -0 0</wrench>
        </link>
        <link name='arm_left_4_link'>
          <pose>-0.013415 0.28918 0.50001 -2.05918 -1.51069 0.333442</pose>
          <velocity>0.000154 -5.6e-05 -0.009192 0.000417 0.00181 3.4e-05</velocity>
          <acceleration>0.236151 -0.043902 -9.47261 0.570821 0.98177 0.193037</acceleration>
          <wrench>0.246447 -0.045816 -9.88562 0 -0 0</wrench>
        </link>
        <link name='arm_left_5_link'>
          <pose>0.147568 0.22579 0.472068 -2.63013 1.50992 -2.78504</pose>
          <velocity>0.000105 -3.9e-05 -0.009509 0.00034 0.001822 3.9e-05</velocity>
          <acceleration>0.223929 -0.038021 -9.69417 1.79887 0.632053 -2.62435</acceleration>
          <wrench>0.069589 -0.011815 -3.01259 0 -0 0</wrench>
        </link>
        <link name='arm_left_6_link'>
          <pose>0.304262 0.158497 0.46455 -1.53638 -0.423672 2.97341</pose>
          <velocity>9.4e-05 -3.1e-05 -0.009818 -0.000122 -0.00115 0.000133</velocity>
          <acceleration>0.190298 -0.034007 -9.90388 -0.252602 -1.13273 0.14516</acceleration>
          <wrench>0.256117 -0.04577 -13.3293 0 -0 0</wrench>
        </link>
        <link name='arm_left_7_link'>
          <pose>0.269761 0.208997 0.540654 0.034418 -0.423672 2.97341</pose>
          <velocity>-0 -2.6e-05 -0.009864 -0.000127 -0.00115 0.000122</velocity>
          <acceleration>0.071196 -0.020716 -9.89853 -0.116753 -1.15332 0.161884</acceleration>
          <wrench>0.033877 -0.009857 -4.70995 0 -0 0</wrench>
        </link>
        <link name='arm_right_1_link'>
          <pose>0.058944 -0.159165 0.853629 -2.09616 -0.314811 -1.74156</pose>
          <velocity>-0.000161 -0 -0.008909 0.000524 -0.000195 -0.000289</velocity>
          <acceleration>-0.040602 0.008731 -8.97107 1.13627 -0.377931 -0.565414</acceleration>
          <wrench>-0.045981 0.009888 -10.1597 0 -0 0</wrench>
        </link>
        <link name='arm_right_2_link'>
          <pose>0.190862 -0.251523 0.762828 1.13953 0.73663 -0.470578</pose>
          <velocity>-0.000171 9e-06 -0.008931 0.00034 -0.001273 6.6e-05</velocity>
          <acceleration>0.077551 0.037961 -9.07428 0.412559 -0.688418 0.407459</acceleration>
          <wrench>0.080933 0.039616 -9.46991 0 -0 0</wrench>
        </link>
        <link name='arm_right_3_link'>
          <pose>0.085291 -0.239777 0.623432 -3.09974 0.831856 0.186573</pose>
          <velocity>6e-06 5e-05 -0.009062 3.7e-05 -0.001312 -0.000211</velocity>
          <acceleration>0.257776 0.072221 -9.23598 -0.097334 -1.33138 -0.261601</acceleration>
          <wrench>0.291931 0.081791 -10.4597 0 -0 0</wrench>
        </link>
        <link name='arm_right_4_link'>
          <pose>-0.024499 -0.215961 0.502102 -1.08239 -1.51069 -0.332034</pose>
          <velocity>0.00017 7.7e-05 -0.009205 -0.00045 0.001799 -0.000122</velocity>
          <acceleration>0.24141 0.049899 -9.47565 -0.606595 0.941544 0.109148</acceleration>
          <wrench>0.251935 0.052074 -9.88879 0 -0 0</wrench>
        </link>
        <link name='arm_right_5_link'>
          <pose>0.147893 -0.225636 0.472069 2.67687 1.51142 2.83328</pose>
          <velocity>0.000115 4.3e-05 -0.009511 -0.000381 0.00181 -0.000126</velocity>
          <acceleration>0.222687 0.029629 -9.69092 0.473826 1.1648 -2.62291</acceleration>
          <wrench>0.069203 0.009208 -3.01158 0 -0 0</wrench>
        </link>
        <link name='arm_right_6_link'>
          <pose>0.317568 -0.241467 0.462172 -1.59823 -0.423742 -2.97453</pose>
          <velocity>9.5e-05 1.7e-05 -0.009812 9e-05 -0.001188 -0.000202</velocity>
          <acceleration>0.196614 0.019121 -9.90486 -0.030536 -1.14681 -0.21143</acceleration>
          <wrench>0.264616 0.025735 -13.3307 0 -0 0</wrench>
        </link>
        <link name='arm_right_7_link'>
          <pose>0.269988 -0.208196 0.540668 -0.027431 -0.423742 -2.97453</pose>
          <velocity>8e-06 2e-05 -0.009865 0.000132 -0.001183 -0.000107</velocity>
          <acceleration>0.073999 0.00887 -9.89958 0.159641 -1.17426 -0.039847</acceleration>
          <wrench>0.03521 0.004221 -4.71045 0 -0 0</wrench>
        </link>
        <link name='base_footprint'>
          <pose>-0.006431 -3.2e-05 -5.4e-05 0 -0 0.000718</pose>
          <velocity>-0.000163 -0 7.3e-05 0 1e-06 1.3e-05</velocity>
          <acceleration>-0.040793 -9e-05 0.016292 -8.6e-05 -0.000117 0.003391</acceleration>
          <wrench>-1.66713 -0.003661 0.665824 0 -0 0</wrench>
        </link>
        <link name='gripper_left_fingertip_left_link'>
          <pose>0.332014 0.249464 0.661724 1.99469 0.031378 1.41676</pose>
          <velocity>-0.000138 -3.7e-05 -0.009771 -0.002167 -0.000803 0.001058</velocity>
          <acceleration>-0.021639 -0.011831 -9.82273 -2.80392 -0.468125 1.08803</acceleration>
          <wrench>-0.000725 -0.000396 -0.329091 0 -0 0</wrench>
        </link>
        <link name='gripper_left_fingertip_right_link'>
          <pose>0.317993 0.159157 0.664592 1.14691 -0.031372 -1.72483</pose>
          <velocity>-0.000116 3.6e-05 -0.009772 0.001517 -0.00143 -0.000632</velocity>
          <acceleration>-0.008205 0.013091 -9.82206 1.80825 -0.575466 -0.594102</acceleration>
          <wrench>-0.000275 0.000439 -0.329069 0 -0 0</wrench>
        </link>
        <link name='gripper_left_inner_finger_left_link'>
          <pose>0.311275 0.219462 0.627523 2.11197 0.646727 1.75007</pose>
          <velocity>-0.000101 -1e-05 -0.009817 0.000656 -0.00128 -0.000232</velocity>
          <acceleration>0.00408 -0.026584 -9.85257 1.12347 0.626308 0.546128</acceleration>
          <wrench>7.6e-05 -0.000495 -0.183445 0 -0 0</wrench>
        </link>
        <link name='gripper_left_inner_finger_right_link'>
          <pose>0.306988 0.191852 0.6284 1.05428 0.587283 -2.04387</pose>
          <velocity>-9.9e-05 -1e-05 -0.009819 -0.001105 -0.000983 0.000567</velocity>
          <acceleration>0.015646 0.009472 -9.85358 2.85174 -0.715426 0.042465</acceleration>
          <wrench>0.000291 0.000176 -0.183464 0 -0 0</wrench>
        </link>
        <link name='gripper_left_outer_finger_left_link'>
          <pose>0.311686 0.23426 0.622929 2.11197 0.646728 1.75007</pose>
          <velocity>-9.8e-05 -1e-05 -0.009819 -1.6e-05 -0.001169 7.1e-05</velocity>
          <acceleration>0.012851 -0.012994 -9.86977 0.137228 -0.00282 0.145789</acceleration>
          <wrench>0.000205 -0.000208 -0.157806 0 -0 0</wrench>
        </link>
        <link name='gripper_left_outer_finger_right_link'>
          <pose>0.302853 0.17737 0.624736 1.05428 0.587283 -2.04387</pose>
          <velocity>-9.3e-05 -1.1e-05 -0.009822 -0.000898 -0.001019 0.000475</velocity>
          <acceleration>0.02262 -0.002601 -9.86839 2.7577 -1.54957 -1.20345</acceleration>
          <wrench>0.000362 -4.2e-05 -0.157784 0 -0 0</wrench>
        </link>
        <link name='gripper_right_fingertip_left_link'>
          <pose>0.318009 -0.157493 0.664338 1.99468 -0.024999 1.72658</pose>
          <velocity>-0.000115 -3.6e-05 -0.009775 -0.001829 -0.001515 0.000792</velocity>
          <acceleration>-0.011163 -0.015772 -9.82534 -2.61128 -0.934011 0.656446</acceleration>
          <wrench>-0.000374 -0.000528 -0.329178 0 -0 0</wrench>
        </link>
        <link name='gripper_right_fingertip_right_link'>
          <pose>0.332191 -0.247792 0.662052 1.14692 0.025006 -1.41501</pose>
          <velocity>-0.000132 3.8e-05 -0.009766 0.00187 -0.000888 -0.000906</velocity>
          <acceleration>-0.022016 0.009442 -9.81791 2.24469 -0.15818 -0.953443</acceleration>
          <wrench>-0.000738 0.000316 -0.328929 0 -0 0</wrench>
        </link>
        <link name='gripper_right_inner_finger_left_link'>
          <pose>0.307098 -0.190435 0.628341 2.08971 0.593335 2.04695</pose>
          <velocity>-9.4e-05 4e-06 -0.009819 0.000981 -0.00104 -0.000492</velocity>
          <acceleration>0.015391 -0.01896 -9.85559 -2.92525 -0.823601 0.167041</acceleration>
          <wrench>0.000287 -0.000353 -0.183501 0 -0 0</wrench>
        </link>
        <link name='gripper_right_inner_finger_right_link'>
          <pose>0.311433 -0.218042 0.627642 1.03224 0.640708 -1.74675</pose>
          <velocity>-9.6e-05 4e-06 -0.009818 -0.000788 -0.001335 0.00031</velocity>
          <acceleration>0.004992 0.017326 -9.85042 -1.35322 0.758667 -0.656337</acceleration>
          <wrench>9.3e-05 0.000323 -0.183405 0 -0 0</wrench>
        </link>
        <link name='gripper_right_outer_finger_left_link'>
          <pose>0.302941 -0.175983 0.624582 2.08972 0.593335 2.04696</pose>
          <velocity>-8.8e-05 5e-06 -0.009822 0.000264 -0.001161 -0.000167</velocity>
          <acceleration>0.020457 -0.001352 -9.87372 0.033443 -1.39972 -1.35313</acceleration>
          <wrench>0.000327 -2.2e-05 -0.157869 0 -0 0</wrench>
        </link>
        <link name='gripper_right_outer_finger_right_link'>
          <pose>0.311875 -0.232868 0.623142 1.03225 0.640709 -1.74675</pose>
          <velocity>-9.2e-05 5e-06 -0.009819 -0.000557 -0.0013 0.000209</velocity>
          <acceleration>0.014485 0.008525 -9.86497 -0.491403 0.042709 0.106377</acceleration>
          <wrench>0.000232 0.000136 -0.157729 0 -0 0</wrench>
        </link>
        <link name='head_1_link'>
          <pose>-0.030931 -5e-05 0.985637 0 -0 0.000717</pose>
          <velocity>-0.000166 -1e-06 -0.008908 -1e-06 -0 2.1e-05</velocity>
          <acceleration>-0.042212 -0.00072 -8.96494 -0.000668 0.005007 0.01138</acceleration>
          <wrench>-0.006571 -0.000112 -1.39548 0 -0 0</wrench>
        </link>
        <link name='head_2_link'>
          <pose>0.011569 -1.9e-05 1.09149 1.5708 -1e-06 -3.14088</pose>
          <velocity>-0.000166 -0 -0.008908 0 0.000812 2.1e-05</velocity>
          <acceleration>0.054332 -4.2e-05 -8.97457 3.11743 0.909387 -3.12554</acceleration>
          <wrench>0.049897 -3.9e-05 -8.24188 0 -0 0</wrench>
        </link>
        <link name='torso_lift_link'>
          <pose>-0.030931 -5e-05 0.945637 -0 -2e-06 0.000718</pose>
          <velocity>-0.000164 -1e-06 -0.008908 0 -4e-06 1.3e-05</velocity>
          <acceleration>-0.041079 -0.000569 -8.96481 -9.7e-05 0.000362 0.003394</acceleration>
          <wrench>-0.141233 -0.001955 -30.8217 0 -0 0</wrench>
        </link>
        <link name='wheel_front_left_link'>
          <pose>0.237409 0.223318 0.076145 -1.5708 -5.9e-05 0.000718</pose>
          <velocity>-0.000166 3e-06 7.2e-05 -3e-06 0 1.3e-05</velocity>
          <acceleration>-0.041501 0.000733 0.016222 -0.002952 -0.00148 0.003812</acceleration>
          <wrench>-0.029369 0.000519 0.01148 0 -0 0</wrench>
        </link>
        <link name='wheel_front_right_link'>
          <pose>0.237729 -0.223032 0.076146 -1.5708 -0.000143 0.000718</pose>
          <velocity>-0.00016 3e-06 7.2e-05 4e-06 -3e-06 1.3e-05</velocity>
          <acceleration>-0.040059 0.000729 0.016241 0.003266 -0.003405 0.003852</acceleration>
          <wrench>-0.028349 0.000516 0.011493 0 -0 0</wrench>
        </link>
        <link name='wheel_rear_left_link'>
          <pose>-0.250591 0.222968 0.076146 -1.5708 -0.000228 0.000718</pose>
          <velocity>-0.000166 -4e-06 7.3e-05 5e-06 -5e-06 1.3e-05</velocity>
          <acceleration>-0.041493 -0.000933 0.016315 0.005187 -0.005376 0.003803</acceleration>
          <wrench>-0.029363 -0.00066 0.011546 0 -0 0</wrench>
        </link>
        <link name='wheel_rear_right_link'>
          <pose>-0.250271 -0.223382 0.076146 -1.5708 -0.000315 0.000718</pose>
          <velocity>-0.00016 -4e-06 7.3e-05 -4e-06 -7e-06 1.3e-05</velocity>
          <acceleration>-0.040052 -0.000926 0.016348 -0.004734 -0.007407 0.003843</acceleration>
          <wrench>-0.028344 -0.000655 0.011569 0 -0 0</wrench>
        </link>
      </model>
      <light name='sun'>
        <pose>0 0 10 0 -0 0</pose>
      </light>
    </state>
    <gui fullscreen='0'>
      <camera name='user_camera'>
        <pose>5.07221 -4.89479 2.0825 0 0.275643 2.35619</pose>
        <view_controller>orbit</view_controller>
        <projection_type>perspective</projection_type>
      </camera>
    </gui>
  </world>
</sdf>
