<sdf version='1.7'>
  <world name='default'>
    <light name='sun' type='directional'>
      <cast_shadows>1</cast_shadows>
      <pose>0 0 10 0 -0 0</pose>
      <diffuse>0.8 0.8 0.8 1</diffuse>
      <specular>0.2 0.2 0.2 1</specular>
      <attenuation>
        <range>1000</range>
        <constant>0.9</constant>
        <linear>0.01</linear>
        <quadratic>0.001</quadratic>
      </attenuation>
      <direction>-0.5 0.1 -0.9</direction>
      <spot>
        <inner_angle>0</inner_angle>
        <outer_angle>0</outer_angle>
        <falloff>0</falloff>
      </spot>
    </light>
    <model name='ground_plane'>
      <static>1</static>
      <link name='link'>
        <collision name='collision'>
          <geometry>
            <plane>
              <normal>0 0 1</normal>
              <size>100 100</size>
            </plane>
          </geometry>
          <surface>
            <friction>
              <ode>
                <mu>100</mu>
                <mu2>50</mu2>
              </ode>
              <torsional>
                <ode/>
              </torsional>
            </friction>
            <contact>
              <ode/>
            </contact>
            <bounce/>
          </surface>
          <max_contacts>10</max_contacts>
        </collision>
        <visual name='visual'>
          <cast_shadows>0</cast_shadows>
          <geometry>
            <plane>
              <normal>0 0 1</normal>
              <size>100 100</size>
            </plane>
          </geometry>
          <material>
            <script>
              <uri>file://media/materials/scripts/gazebo.material</uri>
              <name>Gazebo/Grey</name>
            </script>
          </material>
        </visual>
        <self_collide>0</self_collide>
        <enable_wind>0</enable_wind>
        <kinematic>0</kinematic>
      </link>
    </model>
    <gravity>0 0 -9.8</gravity>
    <magnetic_field>6e-06 2.3e-05 -4.2e-05</magnetic_field>
    <atmosphere type='adiabatic'/>
    <physics type='ode'>
      <max_step_size>0.001</max_step_size>
      <real_time_factor>1</real_time_factor>
      <real_time_update_rate>1000</real_time_update_rate>
    </physics>
    <scene>
      <ambient>0.4 0.4 0.4 1</ambient>
      <background>0.7 0.7 0.7 1</background>
      <shadows>1</shadows>
    </scene>
    <audio>
      <device>default</device>
    </audio>
    <wind/>
    <spherical_coordinates>
      <surface_model>EARTH_WGS84</surface_model>
      <latitude_deg>0</latitude_deg>
      <longitude_deg>0</longitude_deg>
      <elevation>0</elevation>
      <heading_deg>0</heading_deg>
    </spherical_coordinates>
    <model name='tiago-pro'>
      <link name='base_footprint'>
        <inertial>
          <pose>-0.004805 -0.001991 0.232434 0 -0 0</pose>
          <mass>55.4026</mass>
          <inertia>
            <ixx>1.45363</ixx>
            <ixy>0.0228042</ixy>
            <ixz>0.0765957</ixz>
            <iyy>1.81443</iyy>
            <iyz>0.0254408</iyz>
            <izz>0.983133</izz>
          </inertia>
        </inertial>
        <collision name='base_footprint_fixed_joint_lump__base_link_collision'>
          <pose>0 0 0.26545 0 -0 0</pose>
          <geometry>
            <box>
              <size>0.717 0.497 0.0845</size>
            </box>
          </geometry>
          <max_contacts>10</max_contacts>
          <surface>
            <contact>
              <ode/>
            </contact>
            <bounce/>
            <friction>
              <torsional>
                <ode/>
              </torsional>
              <ode/>
            </friction>
          </surface>
        </collision>
        <collision name='base_footprint_fixed_joint_lump__base_link_collision_1'>
          <pose>0 0 0.2082 0 -0 0</pose>
          <geometry>
            <box>
              <size>0.58 0.39 0.03</size>
            </box>
          </geometry>
          <max_contacts>10</max_contacts>
          <surface>
            <contact>
              <ode/>
            </contact>
            <bounce/>
            <friction>
              <torsional>
                <ode/>
              </torsional>
              <ode/>
            </friction>
          </surface>
        </collision>
        <collision name='base_footprint_fixed_joint_lump__base_link_collision_2'>
          <pose>0 0 0.1097 0 -0 0</pose>
          <geometry>
            <box>
              <size>0.705 0.48 0.167</size>
            </box>
          </geometry>
          <max_contacts>10</max_contacts>
          <surface>
            <contact>
              <ode/>
            </contact>
            <bounce/>
            <friction>
              <torsional>
                <ode/>
              </torsional>
              <ode/>
            </friction>
          </surface>
        </collision>
        <collision name='base_footprint_fixed_joint_lump__base_antenna_left_link_collision_3'>
          <pose>-0.2015 0.13 0.2927 0 -0 0</pose>
          <geometry>
            <mesh>
              <scale>1 -1 1</scale>
              <uri>model://omni_base_description/meshes/base/base_antena_link.stl</uri>
            </mesh>
          </geometry>
          <surface>
            <contact>
              <ode/>
            </contact>
            <friction>
              <ode/>
              <torsional>
                <ode/>
              </torsional>
            </friction>
            <bounce/>
          </surface>
          <max_contacts>10</max_contacts>
        </collision>
        <collision name='base_footprint_fixed_joint_lump__base_antenna_right_link_collision_4'>
          <pose>-0.2015 -0.13 0.2927 0 -0 0</pose>
          <geometry>
            <mesh>
              <scale>1 1 1</scale>
              <uri>model://omni_base_description/meshes/base/base_antena_link.stl</uri>
            </mesh>
          </geometry>
          <surface>
            <contact>
              <ode/>
            </contact>
            <friction>
              <ode/>
              <torsional>
                <ode/>
              </torsional>
            </friction>
            <bounce/>
          </surface>
          <max_contacts>10</max_contacts>
        </collision>
        <collision name='base_footprint_fixed_joint_lump__base_dock_link_collision_5'>
          <pose>0.3535 0 0.1358 0 -0 0</pose>
          <geometry>
            <mesh>
              <scale>1 1 1</scale>
              <uri>model://omni_base_description/meshes/base/base_dock_link.stl</uri>
            </mesh>
          </geometry>
          <max_contacts>10</max_contacts>
          <surface>
            <contact>
              <ode/>
            </contact>
            <bounce/>
            <friction>
              <torsional>
                <ode/>
              </torsional>
              <ode/>
            </friction>
          </surface>
        </collision>
        <collision name='base_footprint_fixed_joint_lump__base_front_laser_link_collision_6'>
          <pose>0.27512 -0.18297 0.20864 -3.14159 -0 -0.785398</pose>
          <geometry>
            <cylinder>
              <length>0.01</length>
              <radius>0.01</radius>
            </cylinder>
          </geometry>
          <surface>
            <contact>
              <ode/>
            </contact>
            <friction>
              <ode/>
              <torsional>
                <ode/>
              </torsional>
            </friction>
            <bounce/>
          </surface>
          <max_contacts>10</max_contacts>
        </collision>
        <collision name='base_footprint_fixed_joint_lump__base_rear_laser_link_collision_7'>
          <pose>-0.27512 0.18297 0.20864 -3.14159 -0 2.35619</pose>
          <geometry>
            <cylinder>
              <length>0.01</length>
              <radius>0.01</radius>
            </cylinder>
          </geometry>
          <surface>
            <contact>
              <ode/>
            </contact>
            <friction>
              <ode/>
              <torsional>
                <ode/>
              </torsional>
            </friction>
            <bounce/>
          </surface>
          <max_contacts>10</max_contacts>
        </collision>
        <collision name='base_footprint_fixed_joint_lump__suspension_front_left_link_collision_8'>
          <pose>0.244 0.1725 0.0762 0 -0 1.5708</pose>
          <geometry>
            <mesh>
              <scale>1 -1 1</scale>
              <uri>model://omni_base_description/meshes/wheels/suspension_front_link.stl</uri>
            </mesh>
          </geometry>
          <max_contacts>10</max_contacts>
          <surface>
            <contact>
              <ode/>
            </contact>
            <bounce/>
            <friction>
              <torsional>
                <ode/>
              </torsional>
              <ode/>
            </friction>
          </surface>
        </collision>
        <collision name='base_footprint_fixed_joint_lump__suspension_front_right_link_collision_9'>
          <pose>0.244 -0.1725 0.0762 0 0 -1.5708</pose>
          <geometry>
            <mesh>
              <scale>1 1 1</scale>
              <uri>model://omni_base_description/meshes/wheels/suspension_front_link.stl</uri>
            </mesh>
          </geometry>
          <max_contacts>10</max_contacts>
          <surface>
            <contact>
              <ode/>
            </contact>
            <bounce/>
            <friction>
              <torsional>
                <ode/>
              </torsional>
              <ode/>
            </friction>
          </surface>
        </collision>
        <collision name='base_footprint_fixed_joint_lump__suspension_rear_left_link_collision_10'>
          <pose>-0.244 0.1725 0.0762 0 -0 1.5708</pose>
          <geometry>
            <mesh>
              <scale>1 -1 1</scale>
              <uri>model://omni_base_description/meshes/wheels/suspension_rear_link.stl</uri>
            </mesh>
          </geometry>
          <max_contacts>10</max_contacts>
          <surface>
            <contact>
              <ode/>
            </contact>
            <bounce/>
            <friction>
              <torsional>
                <ode/>
              </torsional>
              <ode/>
            </friction>
          </surface>
        </collision>
        <collision name='base_footprint_fixed_joint_lump__suspension_rear_right_link_collision_11'>
          <pose>-0.244 -0.1725 0.0762 0 0 -1.5708</pose>
          <geometry>
            <mesh>
              <scale>1 1 1</scale>
              <uri>model://omni_base_description/meshes/wheels/suspension_rear_link.stl</uri>
            </mesh>
          </geometry>
          <max_contacts>10</max_contacts>
          <surface>
            <contact>
              <ode/>
            </contact>
            <bounce/>
            <friction>
              <torsional>
                <ode/>
              </torsional>
              <ode/>
            </friction>
          </surface>
        </collision>
        <collision name='base_footprint_fixed_joint_lump__torso_fixed_column_link_collision_12'>
          <pose>-0.028 0 0.5562 0 -0 0</pose>
          <geometry>
            <box>
              <size>0.23 0.253 0.45</size>
            </box>
          </geometry>
          <surface>
            <contact>
              <ode/>
            </contact>
            <friction>
              <ode/>
              <torsional>
                <ode/>
              </torsional>
            </friction>
            <bounce/>
          </surface>
          <max_contacts>10</max_contacts>
        </collision>
        <collision name='base_footprint_fixed_joint_lump__torso_fixed_link_collision_13'>
          <pose>-0.0245 0 0.3912 0 -0 0</pose>
          <geometry>
            <box>
              <size>0.23 0.253 0.2</size>
            </box>
          </geometry>
          <surface>
            <contact>
              <ode/>
            </contact>
            <friction>
              <ode/>
              <torsional>
                <ode/>
              </torsional>
            </friction>
            <bounce/>
          </surface>
          <max_contacts>10</max_contacts>
        </collision>
        <collision name='base_footprint_fixed_joint_lump__torso_fixed_link_collision_14'>
          <pose>0.1555 0 0.3212 0 -0 0</pose>
          <geometry>
            <box>
              <size>0.15 0.253 0.06</size>
            </box>
          </geometry>
          <surface>
            <contact>
              <ode/>
            </contact>
            <friction>
              <ode/>
              <torsional>
                <ode/>
              </torsional>
            </friction>
            <bounce/>
          </surface>
          <max_contacts>10</max_contacts>
        </collision>
        <collision name='base_footprint_fixed_joint_lump__torso_fixed_link_collision_15'>
          <pose>-0.1145 0 0.2912 0 -0 0</pose>
          <geometry>
            <box>
              <size>0.47 0.5 0.02</size>
            </box>
          </geometry>
          <surface>
            <contact>
              <ode/>
            </contact>
            <friction>
              <ode/>
              <torsional>
                <ode/>
              </torsional>
            </friction>
            <bounce/>
          </surface>
          <max_contacts>10</max_contacts>
        </collision>
        <visual name='base_footprint_fixed_joint_lump__base_link_visual'>
          <pose>0 0 0.0762 0 -0 0</pose>
          <geometry>
            <mesh>
              <scale>1 1 1</scale>
              <uri>model://omni_base_description/meshes/base/base_link.stl</uri>
            </mesh>
          </geometry>
        </visual>
        <visual name='base_footprint_fixed_joint_lump__base_antenna_left_link_visual_1'>
          <pose>-0.2015 0.13 0.2927 0 -0 0</pose>
          <geometry>
            <mesh>
              <scale>1 -1 1</scale>
              <uri>model://omni_base_description/meshes/base/base_antena_link.stl</uri>
            </mesh>
          </geometry>
          <material>
            <script>
              <name>Gazebo/Black</name>
              <uri>file://media/materials/scripts/gazebo.material</uri>
            </script>
          </material>
        </visual>
        <visual name='base_footprint_fixed_joint_lump__base_antenna_right_link_visual_2'>
          <pose>-0.2015 -0.13 0.2927 0 -0 0</pose>
          <geometry>
            <mesh>
              <scale>1 1 1</scale>
              <uri>model://omni_base_description/meshes/base/base_antena_link.stl</uri>
            </mesh>
          </geometry>
          <material>
            <script>
              <name>Gazebo/Black</name>
              <uri>file://media/materials/scripts/gazebo.material</uri>
            </script>
          </material>
        </visual>
        <visual name='base_footprint_fixed_joint_lump__base_dock_link_visual_3'>
          <pose>0.3535 0 0.1358 0 -0 0</pose>
          <geometry>
            <mesh>
              <scale>1 1 1</scale>
              <uri>model://omni_base_description/meshes/base/base_dock_link.stl</uri>
            </mesh>
          </geometry>
        </visual>
        <visual name='base_footprint_fixed_joint_lump__base_front_laser_link_visual_4'>
          <pose>0.27512 -0.18297 0.20864 -3.14159 -0 -0.785398</pose>
          <geometry>
            <mesh>
              <scale>1 1 1</scale>
              <uri>model://omni_base_description/meshes/sensors/sick_tim551.stl</uri>
            </mesh>
          </geometry>
          <material>
            <script>
              <name>Gazebo/DarkGrey</name>
              <uri>file://media/materials/scripts/gazebo.material</uri>
            </script>
          </material>
        </visual>
        <visual name='base_footprint_fixed_joint_lump__base_rear_laser_link_visual_5'>
          <pose>-0.27512 0.18297 0.20864 -3.14159 -0 2.35619</pose>
          <geometry>
            <mesh>
              <scale>1 1 1</scale>
              <uri>model://omni_base_description/meshes/sensors/sick_tim551.stl</uri>
            </mesh>
          </geometry>
          <material>
            <script>
              <name>Gazebo/DarkGrey</name>
              <uri>file://media/materials/scripts/gazebo.material</uri>
            </script>
          </material>
        </visual>
        <visual name='base_footprint_fixed_joint_lump__suspension_front_left_link_visual_6'>
          <pose>0.244 0.1725 0.0762 0 -0 1.5708</pose>
          <geometry>
            <mesh>
              <scale>1 -1 1</scale>
              <uri>model://omni_base_description/meshes/wheels/suspension_front_link.stl</uri>
            </mesh>
          </geometry>
        </visual>
        <visual name='base_footprint_fixed_joint_lump__suspension_front_right_link_visual_7'>
          <pose>0.244 -0.1725 0.0762 0 0 -1.5708</pose>
          <geometry>
            <mesh>
              <scale>1 1 1</scale>
              <uri>model://omni_base_description/meshes/wheels/suspension_front_link.stl</uri>
            </mesh>
          </geometry>
        </visual>
        <visual name='base_footprint_fixed_joint_lump__suspension_rear_left_link_visual_8'>
          <pose>-0.244 0.1725 0.0762 0 -0 1.5708</pose>
          <geometry>
            <mesh>
              <scale>1 -1 1</scale>
              <uri>model://omni_base_description/meshes/wheels/suspension_rear_link.stl</uri>
            </mesh>
          </geometry>
        </visual>
        <visual name='base_footprint_fixed_joint_lump__suspension_rear_right_link_visual_9'>
          <pose>-0.244 -0.1725 0.0762 0 0 -1.5708</pose>
          <geometry>
            <mesh>
              <scale>1 1 1</scale>
              <uri>model://omni_base_description/meshes/wheels/suspension_rear_link.stl</uri>
            </mesh>
          </geometry>
        </visual>
        <visual name='base_footprint_fixed_joint_lump__torso_fixed_column_link_visual_10'>
          <pose>-0.028 0 0.5562 0 -0 0</pose>
          <geometry>
            <box>
              <size>0.18 0.2 0.55</size>
            </box>
          </geometry>
          <material>
            <script>
              <name>Gazebo/DarkGrey</name>
              <uri>file://media/materials/scripts/gazebo.material</uri>
            </script>
          </material>
        </visual>
        <visual name='base_footprint_fixed_joint_lump__torso_fixed_link_visual_11'>
          <pose>-0.0245 0 0.2912 0 -0 0</pose>
          <geometry>
            <mesh>
              <scale>1 1 1</scale>
              <uri>model://tiago_pro_description/meshes/torso/torso_fixed_link.stl</uri>
            </mesh>
          </geometry>
          <material>
            <script>
              <name>Gazebo/DarkGrey</name>
              <uri>file://media/materials/scripts/gazebo.material</uri>
            </script>
          </material>
        </visual>
        <sensor name='base_front_laser' type='gpu_ray'>
          <update_rate>10</update_rate>
          <visualize>1</visualize>
          <ray>
            <scan>
              <horizontal>
                <samples>818</samples>
                <resolution>1</resolution>
                <min_angle>-2.35619</min_angle>
                <max_angle>2.35619</max_angle>
              </horizontal>
              <vertical>
                <samples>1</samples>
                <min_angle>0</min_angle>
                <max_angle>0</max_angle>
              </vertical>
            </scan>
            <range>
              <min>0.05</min>
              <max>25</max>
              <resolution>0.001</resolution>
            </range>
            <noise>
              <type>gaussian</type>
              <mean>0</mean>
              <stddev>0.01</stddev>
            </noise>
          </ray>
          <plugin name='base_front_laser' filename='libgazebo_ros_ray_sensor.so'>
            <ros>
              <remapping>~/out:=scan_front_raw</remapping>
            </ros>
            <output_type>sensor_msgs/LaserScan</output_type>
            <frame_name>base_front_laser_link</frame_name>
          </plugin>
          <pose>0.27512 -0.18297 0.20864 -3.14159 -0 -0.785398</pose>
        </sensor>
        <sensor name='imu_sensor' type='imu'>
          <always_on>1</always_on>
          <update_rate>10</update_rate>
          <imu>
            <noise>
              <type>gaussian</type>
              <rate>
                <mean>0.0</mean>
                <stddev>2e-4</stddev>
                <bias_mean>0.0000075</bias_mean>
                <bias_stddev>0.0000008</bias_stddev>
              </rate>
              <accel>
                <mean>0.0</mean>
                <stddev>1.7e-2</stddev>
                <bias_mean>0.1</bias_mean>
                <bias_stddev>0.001</bias_stddev>
              </accel>
            </noise>
          </imu>
          <plugin name='base_imu' filename='libgazebo_ros_imu_sensor.so'>
            <ros>
              <remapping>~/out:=base_imu</remapping>
            </ros>
          </plugin>
          <pose>-0.287 0 0.168363 0 -0 1.5708</pose>
        </sensor>
        <sensor name='base_imu_sensor' type='imu'>
          <always_on>1</always_on>
          <update_rate>100</update_rate>
          <imu>
            <noise>
              <type>gaussian</type>
              <rate>
                <mean>0.0</mean>
                <stddev>2e-4</stddev>
                <bias_mean>0.0000075</bias_mean>
                <bias_stddev>0.0000008</bias_stddev>
              </rate>
              <accel>
                <mean>0.0</mean>
                <stddev>1.7e-2</stddev>
                <bias_mean>0.1</bias_mean>
                <bias_stddev>0.001</bias_stddev>
              </accel>
            </noise>
          </imu>
          <pose>-0.287 0 0.168363 0 -0 1.5708</pose>
        </sensor>
        <sensor name='base_rear_laser' type='gpu_ray'>
          <update_rate>10</update_rate>
          <visualize>1</visualize>
          <ray>
            <scan>
              <horizontal>
                <samples>818</samples>
                <resolution>1</resolution>
                <min_angle>-2.35619</min_angle>
                <max_angle>2.35619</max_angle>
              </horizontal>
              <vertical>
                <samples>1</samples>
                <min_angle>0</min_angle>
                <max_angle>0</max_angle>
              </vertical>
            </scan>
            <range>
              <min>0.05</min>
              <max>25</max>
              <resolution>0.001</resolution>
            </range>
            <noise>
              <type>gaussian</type>
              <mean>0</mean>
              <stddev>0.01</stddev>
            </noise>
          </ray>
          <plugin name='base_rear_laser' filename='libgazebo_ros_ray_sensor.so'>
            <ros>
              <remapping>~/out:=scan_rear_raw</remapping>
            </ros>
            <output_type>sensor_msgs/LaserScan</output_type>
            <frame_name>base_rear_laser_link</frame_name>
          </plugin>
          <pose>-0.27512 0.18297 0.20864 -3.14159 -0 2.35619</pose>
        </sensor>
        <self_collide>0</self_collide>
        <enable_wind>0</enable_wind>
        <kinematic>0</kinematic>
      </link>
      <joint name='wheel_front_left_joint' type='revolute'>
        <pose relative_to='base_footprint'>0.244 0.223175 0.0762 -1.5708 0 0</pose>
        <parent>base_footprint</parent>
        <child>wheel_front_left_link</child>
        <axis>
          <xyz>0 0 1</xyz>
          <limit>
            <effort>6</effort>
            <velocity>13.1234</velocity>
            <lower>-1e+16</lower>
            <upper>1e+16</upper>
          </limit>
          <dynamics>
            <damping>1</damping>
            <friction>2</friction>
            <spring_reference>0</spring_reference>
            <spring_stiffness>0</spring_stiffness>
          </dynamics>
        </axis>
      </joint>
      <link name='wheel_front_left_link'>
        <pose relative_to='wheel_front_left_joint'>0 0 0 0 -0 0</pose>
        <inertial>
          <pose>0 -7e-05 -0.011144 0 -0 0</pose>
          <mass>0.70767</mass>
          <inertia>
            <ixx>0.00035492</ixx>
            <ixy>7.5685e-13</ixy>
            <ixz>3.8795e-11</ixz>
            <iyy>0.00035529</iyy>
            <iyz>-2.0284e-07</iyz>
            <izz>0.00040131</izz>
          </inertia>
        </inertial>
        <collision name='wheel_front_left_link_collision'>
          <pose>0 0 0 0 -0 0</pose>
          <geometry>
            <cylinder>
              <length>0.05</length>
              <radius>0.0762</radius>
            </cylinder>
          </geometry>
          <surface>
            <contact>
              <ode>
                <kp>1e+06</kp>
                <kd>1000</kd>
                <max_vel>1</max_vel>
                <min_depth>0</min_depth>
              </ode>
            </contact>
            <friction>
              <ode>
                <mu>0</mu>
                <mu2>0</mu2>
                <fdir1>1 0 0</fdir1>
              </ode>
              <torsional>
                <ode/>
              </torsional>
            </friction>
            <bounce/>
          </surface>
          <max_contacts>10</max_contacts>
        </collision>
        <visual name='wheel_front_left_link_visual'>
          <pose>0 0 0 0 -0 0</pose>
          <geometry>
            <mesh>
              <scale>1 1 -1</scale>
              <uri>model://omni_base_description/meshes/wheels/wheel_link.stl</uri>
            </mesh>
          </geometry>
          <material>
            <script>
              <name>Gazebo/Grey</name>
              <uri>file://media/materials/scripts/gazebo.material</uri>
            </script>
          </material>
        </visual>
        <self_collide>0</self_collide>
        <enable_wind>0</enable_wind>
        <kinematic>0</kinematic>
      </link>
      <joint name='wheel_front_right_joint' type='revolute'>
        <pose relative_to='base_footprint'>0.244 -0.223175 0.0762 -1.5708 0 0</pose>
        <parent>base_footprint</parent>
        <child>wheel_front_right_link</child>
        <axis>
          <xyz>0 0 1</xyz>
          <limit>
            <effort>6</effort>
            <velocity>13.1234</velocity>
            <lower>-1e+16</lower>
            <upper>1e+16</upper>
          </limit>
          <dynamics>
            <damping>1</damping>
            <friction>2</friction>
            <spring_reference>0</spring_reference>
            <spring_stiffness>0</spring_stiffness>
          </dynamics>
        </axis>
      </joint>
      <link name='wheel_front_right_link'>
        <pose relative_to='wheel_front_right_joint'>0 0 0 0 -0 0</pose>
        <inertial>
          <pose>0 7e-05 0.011144 0 -0 0</pose>
          <mass>0.70767</mass>
          <inertia>
            <ixx>0.00035492</ixx>
            <ixy>7.5685e-13</ixy>
            <ixz>3.8795e-11</ixz>
            <iyy>0.00035529</iyy>
            <iyz>-2.0284e-07</iyz>
            <izz>0.00040131</izz>
          </inertia>
        </inertial>
        <collision name='wheel_front_right_link_collision'>
          <pose>0 0 0 0 -0 0</pose>
          <geometry>
            <cylinder>
              <length>0.05</length>
              <radius>0.0762</radius>
            </cylinder>
          </geometry>
          <surface>
            <contact>
              <ode>
                <kp>1e+06</kp>
                <kd>1000</kd>
                <max_vel>1</max_vel>
                <min_depth>0</min_depth>
              </ode>
            </contact>
            <friction>
              <ode>
                <mu>0</mu>
                <mu2>0</mu2>
                <fdir1>1 0 0</fdir1>
              </ode>
              <torsional>
                <ode/>
              </torsional>
            </friction>
            <bounce/>
          </surface>
          <max_contacts>10</max_contacts>
        </collision>
        <visual name='wheel_front_right_link_visual'>
          <pose>0 0 0 0 -0 0</pose>
          <geometry>
            <mesh>
              <scale>1 1 1</scale>
              <uri>model://omni_base_description/meshes/wheels/wheel_link.stl</uri>
            </mesh>
          </geometry>
          <material>
            <script>
              <name>Gazebo/Grey</name>
              <uri>file://media/materials/scripts/gazebo.material</uri>
            </script>
          </material>
        </visual>
        <self_collide>0</self_collide>
        <enable_wind>0</enable_wind>
        <kinematic>0</kinematic>
      </link>
      <joint name='wheel_rear_left_joint' type='revolute'>
        <pose relative_to='base_footprint'>-0.244 0.223175 0.0762 -1.5708 0 0</pose>
        <parent>base_footprint</parent>
        <child>wheel_rear_left_link</child>
        <axis>
          <xyz>0 0 1</xyz>
          <limit>
            <effort>6</effort>
            <velocity>13.1234</velocity>
            <lower>-1e+16</lower>
            <upper>1e+16</upper>
          </limit>
          <dynamics>
            <damping>1</damping>
            <friction>2</friction>
            <spring_reference>0</spring_reference>
            <spring_stiffness>0</spring_stiffness>
          </dynamics>
        </axis>
      </joint>
      <link name='wheel_rear_left_link'>
        <pose relative_to='wheel_rear_left_joint'>0 0 0 0 -0 0</pose>
        <inertial>
          <pose>-0 7e-05 -0.011144 0 -0 0</pose>
          <mass>0.70767</mass>
          <inertia>
            <ixx>0.00035492</ixx>
            <ixy>-7.5685e-13</ixy>
            <ixz>3.8795e-11</ixz>
            <iyy>0.00035529</iyy>
            <iyz>2.0284e-07</iyz>
            <izz>0.00040131</izz>
          </inertia>
        </inertial>
        <collision name='wheel_rear_left_link_collision'>
          <pose>0 0 0 0 -0 0</pose>
          <geometry>
            <cylinder>
              <length>0.05</length>
              <radius>0.0762</radius>
            </cylinder>
          </geometry>
          <surface>
            <contact>
              <ode>
                <kp>1e+06</kp>
                <kd>1000</kd>
                <max_vel>1</max_vel>
                <min_depth>0</min_depth>
              </ode>
            </contact>
            <friction>
              <ode>
                <mu>0</mu>
                <mu2>0</mu2>
                <fdir1>1 0 0</fdir1>
              </ode>
              <torsional>
                <ode/>
              </torsional>
            </friction>
            <bounce/>
          </surface>
          <max_contacts>10</max_contacts>
        </collision>
        <visual name='wheel_rear_left_link_visual'>
          <pose>0 0 0 0 -0 0</pose>
          <geometry>
            <mesh>
              <scale>1 1 -1</scale>
              <uri>model://omni_base_description/meshes/wheels/wheel_link.stl</uri>
            </mesh>
          </geometry>
          <material>
            <script>
              <name>Gazebo/Grey</name>
              <uri>file://media/materials/scripts/gazebo.material</uri>
            </script>
          </material>
        </visual>
        <self_collide>0</self_collide>
        <enable_wind>0</enable_wind>
        <kinematic>0</kinematic>
      </link>
      <joint name='wheel_rear_right_joint' type='revolute'>
        <pose relative_to='base_footprint'>-0.244 -0.223175 0.0762 -1.5708 0 0</pose>
        <parent>base_footprint</parent>
        <child>wheel_rear_right_link</child>
        <axis>
          <xyz>0 0 1</xyz>
          <limit>
            <effort>6</effort>
            <velocity>13.1234</velocity>
            <lower>-1e+16</lower>
            <upper>1e+16</upper>
          </limit>
          <dynamics>
            <damping>1</damping>
            <friction>2</friction>
            <spring_reference>0</spring_reference>
            <spring_stiffness>0</spring_stiffness>
          </dynamics>
        </axis>
      </joint>
      <link name='wheel_rear_right_link'>
        <pose relative_to='wheel_rear_right_joint'>0 0 0 0 -0 0</pose>
        <inertial>
          <pose>-0 -7e-05 0.011144 0 -0 0</pose>
          <mass>0.70767</mass>
          <inertia>
            <ixx>0.00035492</ixx>
            <ixy>-7.5685e-13</ixy>
            <ixz>3.8795e-11</ixz>
            <iyy>0.00035529</iyy>
            <iyz>2.0284e-07</iyz>
            <izz>0.00040131</izz>
          </inertia>
        </inertial>
        <collision name='wheel_rear_right_link_collision'>
          <pose>0 0 0 0 -0 0</pose>
          <geometry>
            <cylinder>
              <length>0.05</length>
              <radius>0.0762</radius>
            </cylinder>
          </geometry>
          <surface>
            <contact>
              <ode>
                <kp>1e+06</kp>
                <kd>1000</kd>
                <max_vel>1</max_vel>
                <min_depth>0</min_depth>
              </ode>
            </contact>
            <friction>
              <ode>
                <mu>0</mu>
                <mu2>0</mu2>
                <fdir1>1 0 0</fdir1>
              </ode>
              <torsional>
                <ode/>
              </torsional>
            </friction>
            <bounce/>
          </surface>
          <max_contacts>10</max_contacts>
        </collision>
        <visual name='wheel_rear_right_link_visual'>
          <pose>0 0 0 0 -0 0</pose>
          <geometry>
            <mesh>
              <scale>1 1 1</scale>
              <uri>model://omni_base_description/meshes/wheels/wheel_link.stl</uri>
            </mesh>
          </geometry>
          <material>
            <script>
              <name>Gazebo/Grey</name>
              <uri>file://media/materials/scripts/gazebo.material</uri>
            </script>
          </material>
        </visual>
        <self_collide>0</self_collide>
        <enable_wind>0</enable_wind>
        <kinematic>0</kinematic>
      </link>
      <joint name='torso_lift_joint' type='prismatic'>
        <pose relative_to='base_footprint'>-0.0245 0 0.8457 0 -0 0</pose>
        <parent>base_footprint</parent>
        <child>torso_lift_link</child>
        <axis>
          <xyz>0 0 1</xyz>
          <limit>
            <lower>0</lower>
            <upper>0.35</upper>
            <effort>2000</effort>
            <velocity>0.07</velocity>
          </limit>
          <dynamics>
            <damping>1000</damping>
            <friction>0</friction>
            <spring_reference>0</spring_reference>
            <spring_stiffness>0</spring_stiffness>
          </dynamics>
        </axis>
        <physics>
          <ode>
            <implicit_spring_damper>1</implicit_spring_damper>
            <cfm_damping>1</cfm_damping>
            <limit>
              <cfm>0</cfm>
              <erp>0.2</erp>
            </limit>
          </ode>
        </physics>
      </joint>
      <link name='torso_lift_link'>
        <pose relative_to='torso_lift_joint'>0 0 0 0 -0 0</pose>
        <inertial>
          <pose>0.001474 0.006528 -0.20301 0 -0 0</pose>
          <mass>9.547</mass>
          <inertia>
            <ixx>0.042078</ixx>
            <ixy>5.6766e-05</ixy>
            <ixz>0.00014731</ixz>
            <iyy>0.031115</iyy>
            <iyz>-5.0165e-05</iyz>
            <izz>0.018659</izz>
          </inertia>
        </inertial>
        <collision name='torso_lift_link_collision'>
          <pose>0 0 0 0 -0 0</pose>
          <geometry>
            <mesh>
              <scale>1 1 1</scale>
              <uri>model://tiago_pro_description/meshes/torso/torso_lift_link_collision.stl</uri>
            </mesh>
          </geometry>
          <max_contacts>10</max_contacts>
          <surface>
            <contact>
              <ode/>
            </contact>
            <bounce/>
            <friction>
              <torsional>
                <ode/>
              </torsional>
              <ode/>
            </friction>
          </surface>
        </collision>
        <visual name='torso_lift_link_visual'>
          <pose>0 0 0 0 -0 0</pose>
          <geometry>
            <mesh>
              <scale>1 1 1</scale>
              <uri>model://tiago_pro_description/meshes/torso/torso_lift_link.stl</uri>
            </mesh>
          </geometry>
        </visual>
        <self_collide>0</self_collide>
        <enable_wind>0</enable_wind>
        <kinematic>0</kinematic>
      </link>
      <joint name='arm_left_1_joint' type='revolute'>
        <pose relative_to='torso_lift_link'>0.08976 0.15918 -0.092008 -2.0679 0 -1.2217</pose>
        <parent>torso_lift_link</parent>
        <child>arm_left_1_link</child>
        <axis>
          <xyz>0 0 1</xyz>
          <limit>
            <lower>-2.60002</lower>
            <upper>2.60002</upper>
            <effort>43</effort>
            <velocity>1.95</velocity>
          </limit>
          <dynamics>
            <damping>1</damping>
            <friction>1</friction>
            <spring_reference>0</spring_reference>
            <spring_stiffness>0</spring_stiffness>
          </dynamics>
        </axis>
        <physics>
          <ode>
            <implicit_spring_damper>1</implicit_spring_damper>
            <cfm_damping>1</cfm_damping>
            <limit>
              <cfm>0</cfm>
              <erp>0.2</erp>
            </limit>
          </ode>
        </physics>
      </joint>
      <link name='arm_left_1_link'>
        <pose relative_to='arm_left_1_joint'>0 0 0 0 -0 0</pose>
        <inertial>
          <pose>0.002391 0.015901 0.1545 0 -0 0</pose>
          <mass>1.0816</mass>
          <inertia>
            <ixx>0.0024426</ixx>
            <ixy>2.3307e-05</ixy>
            <ixz>5.9333e-05</ixz>
            <iyy>0.0023089</iyy>
            <iyz>-0.00020369</iyz>
            <izz>0.00092843</izz>
          </inertia>
        </inertial>
        <collision name='arm_left_1_link_collision'>
          <pose>0 0 0 0 -0 0</pose>
          <geometry>
            <mesh>
              <scale>1 1 1</scale>
              <uri>model://pal_sea_arm_description/meshes/arm_tiago_pro/arm_1_link_collision.stl</uri>
            </mesh>
          </geometry>
          <surface>
            <contact>
              <ode/>
            </contact>
            <friction>
              <ode>
                <mu>0.9</mu>
                <mu2>0.9</mu2>
              </ode>
              <torsional>
                <ode/>
              </torsional>
            </friction>
            <bounce/>
          </surface>
          <max_contacts>10</max_contacts>
        </collision>
        <visual name='arm_left_1_link_visual'>
          <pose>0 0 0 0 -0 0</pose>
          <geometry>
            <mesh>
              <scale>1 1 1</scale>
              <uri>model://pal_sea_arm_description/meshes/arm_tiago_pro/arm_1_link.stl</uri>
            </mesh>
          </geometry>
          <material>
            <script>
              <name>Gazebo/DarkGrey</name>
              <uri>file://media/materials/scripts/gazebo.material</uri>
            </script>
          </material>
        </visual>
        <self_collide>0</self_collide>
        <enable_wind>0</enable_wind>
        <kinematic>0</kinematic>
      </link>
      <joint name='arm_left_2_joint' type='revolute'>
        <pose relative_to='arm_left_1_link'>0 0.02 0.18 3.14159 1.57079 3.14159</pose>
        <parent>arm_left_1_link</parent>
        <child>arm_left_2_link</child>
        <axis>
          <xyz>0 0 1</xyz>
          <limit>
            <lower>-2.43997</lower>
            <upper>1.10008</upper>
            <effort>43</effort>
            <velocity>1.95</velocity>
          </limit>
          <dynamics>
            <damping>1</damping>
            <friction>1</friction>
            <spring_reference>0</spring_reference>
            <spring_stiffness>0</spring_stiffness>
          </dynamics>
        </axis>
        <physics>
          <ode>
            <implicit_spring_damper>1</implicit_spring_damper>
            <cfm_damping>1</cfm_damping>
            <limit>
              <cfm>0</cfm>
              <erp>0.2</erp>
            </limit>
          </ode>
        </physics>
      </joint>
      <link name='arm_left_2_link'>
        <pose relative_to='arm_left_2_joint'>0 0 0 0 -0 0</pose>
        <inertial>
          <pose>-0.11649 -0.017864 0.005377 0 -0 0</pose>
          <mass>0.99204</mass>
          <inertia>
            <ixx>0.00077294</ixx>
            <ixy>-0.00011001</ixy>
            <ixz>-0.00016136</ixz>
            <iyy>0.0014605</iyy>
            <iyz>-1.3224e-05</iyz>
            <izz>0.0015605</izz>
          </inertia>
        </inertial>
        <collision name='arm_left_2_link_collision'>
          <pose>0 0 0 0 -0 0</pose>
          <geometry>
            <mesh>
              <scale>1 1 1</scale>
              <uri>model://pal_sea_arm_description/meshes/arm_tiago_pro/arm_2_link_collision.stl</uri>
            </mesh>
          </geometry>
          <surface>
            <contact>
              <ode/>
            </contact>
            <friction>
              <ode>
                <mu>0.9</mu>
                <mu2>0.9</mu2>
              </ode>
              <torsional>
                <ode/>
              </torsional>
            </friction>
            <bounce/>
          </surface>
          <max_contacts>10</max_contacts>
        </collision>
        <visual name='arm_left_2_link_visual'>
          <pose>0 0 0 0 -0 0</pose>
          <geometry>
            <mesh>
              <scale>1 1 1</scale>
              <uri>model://pal_sea_arm_description/meshes/arm_tiago_pro/arm_2_link.stl</uri>
            </mesh>
          </geometry>
          <material>
            <script>
              <name>Gazebo/DarkGrey</name>
              <uri>file://media/materials/scripts/gazebo.material</uri>
            </script>
          </material>
        </visual>
        <self_collide>0</self_collide>
        <enable_wind>0</enable_wind>
        <kinematic>0</kinematic>
      </link>
      <joint name='arm_left_3_joint' type='revolute'>
        <pose relative_to='arm_left_2_link'>-0.15 -0.02 0 3.1415 1.5707 0</pose>
        <parent>arm_left_2_link</parent>
        <child>arm_left_3_link</child>
        <axis>
          <xyz>0 0 1</xyz>
          <limit>
            <lower>-2.60002</lower>
            <upper>2.60002</upper>
            <effort>26</effort>
            <velocity>2.35</velocity>
          </limit>
          <dynamics>
            <damping>1</damping>
            <friction>1</friction>
            <spring_reference>0</spring_reference>
            <spring_stiffness>0</spring_stiffness>
          </dynamics>
        </axis>
        <physics>
          <ode>
            <implicit_spring_damper>1</implicit_spring_damper>
            <cfm_damping>1</cfm_damping>
            <limit>
              <cfm>0</cfm>
              <erp>0.2</erp>
            </limit>
          </ode>
        </physics>
      </joint>
      <link name='arm_left_3_link'>
        <pose relative_to='arm_left_3_joint'>0 0 0 0 -0 0</pose>
        <inertial>
          <pose>0.002391 0.015901 0.1545 0 -0 0</pose>
          <mass>1.0816</mass>
          <inertia>
            <ixx>0.0024426</ixx>
            <ixy>2.3307e-05</ixy>
            <ixz>5.9333e-05</ixz>
            <iyy>0.0023089</iyy>
            <iyz>-0.00020369</iyz>
            <izz>0.00092843</izz>
          </inertia>
        </inertial>
        <collision name='arm_left_3_link_collision'>
          <pose>0 0 0 0 -0 0</pose>
          <geometry>
            <mesh>
              <scale>1 1 1</scale>
              <uri>model://pal_sea_arm_description/meshes/arm_tiago_pro/arm_3_link_collision.stl</uri>
            </mesh>
          </geometry>
          <surface>
            <contact>
              <ode/>
            </contact>
            <friction>
              <ode>
                <mu>0.9</mu>
                <mu2>0.9</mu2>
              </ode>
              <torsional>
                <ode/>
              </torsional>
            </friction>
            <bounce/>
          </surface>
          <max_contacts>10</max_contacts>
        </collision>
        <visual name='arm_left_3_link_visual'>
          <pose>0 0 0 0 -0 0</pose>
          <geometry>
            <mesh>
              <scale>1 1 1</scale>
              <uri>model://pal_sea_arm_description/meshes/arm_tiago_pro/arm_3_link.stl</uri>
            </mesh>
          </geometry>
          <material>
            <script>
              <name>Gazebo/DarkGrey</name>
              <uri>file://media/materials/scripts/gazebo.material</uri>
            </script>
          </material>
        </visual>
        <self_collide>0</self_collide>
        <enable_wind>0</enable_wind>
        <kinematic>0</kinematic>
      </link>
      <joint name='arm_left_4_joint' type='revolute'>
        <pose relative_to='arm_left_3_link'>0 0.02 0.18 3.14159 1.57079 3.14159</pose>
        <parent>arm_left_3_link</parent>
        <child>arm_left_4_link</child>
        <axis>
          <xyz>0 0 1</xyz>
          <limit>
            <lower>-2.43997</lower>
            <upper>1.10008</upper>
            <effort>26</effort>
            <velocity>2.35</velocity>
          </limit>
          <dynamics>
            <damping>1</damping>
            <friction>1</friction>
            <spring_reference>0</spring_reference>
            <spring_stiffness>0</spring_stiffness>
          </dynamics>
        </axis>
        <physics>
          <ode>
            <implicit_spring_damper>1</implicit_spring_damper>
            <cfm_damping>1</cfm_damping>
            <limit>
              <cfm>0</cfm>
              <erp>0.2</erp>
            </limit>
          </ode>
        </physics>
      </joint>
      <link name='arm_left_4_link'>
        <pose relative_to='arm_left_4_joint'>0 0 0 0 -0 0</pose>
        <inertial>
          <pose>-0.11649 -0.017864 0.005377 0 -0 0</pose>
          <mass>0.99204</mass>
          <inertia>
            <ixx>0.00077294</ixx>
            <ixy>-0.00011001</ixy>
            <ixz>-0.00016136</ixz>
            <iyy>0.0014605</iyy>
            <iyz>-1.3224e-05</iyz>
            <izz>0.0015605</izz>
          </inertia>
        </inertial>
        <collision name='arm_left_4_link_collision'>
          <pose>0 0 0 0 -0 0</pose>
          <geometry>
            <mesh>
              <scale>1 1 1</scale>
              <uri>model://pal_sea_arm_description/meshes/arm_tiago_pro/arm_4_link_collision.stl</uri>
            </mesh>
          </geometry>
          <surface>
            <contact>
              <ode/>
            </contact>
            <friction>
              <ode>
                <mu>0.9</mu>
                <mu2>0.9</mu2>
              </ode>
              <torsional>
                <ode/>
              </torsional>
            </friction>
            <bounce/>
          </surface>
          <max_contacts>10</max_contacts>
        </collision>
        <visual name='arm_left_4_link_visual'>
          <pose>0 0 0 0 -0 0</pose>
          <geometry>
            <mesh>
              <scale>1 1 1</scale>
              <uri>model://pal_sea_arm_description/meshes/arm_tiago_pro/arm_4_link.stl</uri>
            </mesh>
          </geometry>
          <material>
            <script>
              <name>Gazebo/DarkGrey</name>
              <uri>file://media/materials/scripts/gazebo.material</uri>
            </script>
          </material>
        </visual>
        <self_collide>0</self_collide>
        <enable_wind>0</enable_wind>
        <kinematic>0</kinematic>
      </link>
      <joint name='arm_left_5_joint' type='revolute'>
        <pose relative_to='arm_left_4_link'>-0.15 -0.02 0 3.14159 -1.57079 3.14159</pose>
        <parent>arm_left_4_link</parent>
        <child>arm_left_5_link</child>
        <axis>
          <xyz>0 0 1</xyz>
          <limit>
            <lower>-2.60002</lower>
            <upper>2.60002</upper>
            <effort>26</effort>
            <velocity>2.35</velocity>
          </limit>
          <dynamics>
            <damping>1</damping>
            <friction>1</friction>
            <spring_reference>0</spring_reference>
            <spring_stiffness>0</spring_stiffness>
          </dynamics>
        </axis>
        <physics>
          <ode>
            <implicit_spring_damper>1</implicit_spring_damper>
            <cfm_damping>1</cfm_damping>
            <limit>
              <cfm>0</cfm>
              <erp>0.2</erp>
            </limit>
          </ode>
        </physics>
      </joint>
      <link name='arm_left_5_link'>
        <pose relative_to='arm_left_5_joint'>0 0 0 0 -0 0</pose>
        <inertial>
          <pose>0.000486 0.000143 0.129 0 -0 0</pose>
          <mass>0.52538</mass>
          <inertia>
            <ixx>0.0019111</ixx>
            <ixy>-1.4245e-08</ixy>
            <ixz>3.8663e-05</ixz>
            <iyy>0.0018565</iyy>
            <iyz>1.1356e-06</iyz>
            <izz>0.00046496</izz>
          </inertia>
        </inertial>
        <collision name='arm_left_5_link_collision'>
          <pose>0 0 0 0 -0 0</pose>
          <geometry>
            <mesh>
              <scale>1 1 1</scale>
              <uri>model://pal_sea_arm_description/meshes/arm_tiago_pro/arm_5_link_collision.stl</uri>
            </mesh>
          </geometry>
          <surface>
            <contact>
              <ode/>
            </contact>
            <friction>
              <ode>
                <mu>0.9</mu>
                <mu2>0.9</mu2>
              </ode>
              <torsional>
                <ode/>
              </torsional>
            </friction>
            <bounce/>
          </surface>
          <max_contacts>10</max_contacts>
        </collision>
        <visual name='arm_left_5_link_visual'>
          <pose>0 0 0 0 -0 0</pose>
          <geometry>
            <mesh>
              <scale>1 1 1</scale>
              <uri>model://pal_sea_arm_description/meshes/arm_tiago_pro/arm_5_link.stl</uri>
            </mesh>
          </geometry>
          <material>
            <script>
              <name>Gazebo/DarkGrey</name>
              <uri>file://media/materials/scripts/gazebo.material</uri>
            </script>
          </material>
        </visual>
        <self_collide>0</self_collide>
        <enable_wind>0</enable_wind>
        <kinematic>0</kinematic>
      </link>
      <joint name='arm_left_6_joint' type='revolute'>
        <pose relative_to='arm_left_5_link'>0 0 0.185 3.14159 1.57079 3.14159</pose>
        <parent>arm_left_5_link</parent>
        <child>arm_left_6_link</child>
        <axis>
          <xyz>0 0 1</xyz>
          <limit>
            <lower>-1.99997</lower>
            <upper>1.99997</upper>
            <effort>26</effort>
            <velocity>2.35</velocity>
          </limit>
          <dynamics>
            <damping>1</damping>
            <friction>1</friction>
            <spring_reference>0</spring_reference>
            <spring_stiffness>0</spring_stiffness>
          </dynamics>
        </axis>
        <physics>
          <ode>
            <implicit_spring_damper>1</implicit_spring_damper>
            <cfm_damping>1</cfm_damping>
            <limit>
              <cfm>0</cfm>
              <erp>0.2</erp>
            </limit>
          </ode>
        </physics>
      </joint>
      <link name='arm_left_6_link'>
        <pose relative_to='arm_left_6_joint'>0 0 0 0 -0 0</pose>
        <inertial>
          <pose>-0.086822 -8e-06 0.004526 0 -0 0</pose>
          <mass>0.66725</mass>
          <inertia>
            <ixx>0.00035696</ixx>
            <ixy>1.6019e-07</ixy>
            <ixz>-9.5191e-05</ixz>
            <iyy>0.00073846</iyy>
            <iyz>2.118e-08</iyz>
            <izz>0.00075321</izz>
          </inertia>
        </inertial>
        <collision name='arm_left_6_link_collision'>
          <pose>0 0 0 0 -0 0</pose>
          <geometry>
            <mesh>
              <scale>1 1 1</scale>
              <uri>model://pal_sea_arm_description/meshes/arm_tiago_pro/arm_6_link_collision.stl</uri>
            </mesh>
          </geometry>
          <surface>
            <contact>
              <ode/>
            </contact>
            <friction>
              <ode>
                <mu>0.9</mu>
                <mu2>0.9</mu2>
              </ode>
              <torsional>
                <ode/>
              </torsional>
            </friction>
            <bounce/>
          </surface>
          <max_contacts>10</max_contacts>
        </collision>
        <visual name='arm_left_6_link_visual'>
          <pose>0 0 0 0 -0 0</pose>
          <geometry>
            <mesh>
              <scale>1 1 1</scale>
              <uri>model://pal_sea_arm_description/meshes/arm_tiago_pro/arm_6_link.stl</uri>
            </mesh>
          </geometry>
          <material>
            <script>
              <name>Gazebo/DarkGrey</name>
              <uri>file://media/materials/scripts/gazebo.material</uri>
            </script>
          </material>
        </visual>
        <self_collide>0</self_collide>
        <enable_wind>0</enable_wind>
        <kinematic>0</kinematic>
      </link>
      <joint name='arm_left_7_joint' type='revolute'>
        <pose relative_to='arm_left_6_link'>-0.1166 0 0 3.14159 -1.57079 3.14159</pose>
        <parent>arm_left_6_link</parent>
        <child>arm_left_7_link</child>
        <axis>
          <xyz>0 0 1</xyz>
          <limit>
            <lower>-2.60002</lower>
            <upper>2.60002</upper>
            <effort>26</effort>
            <velocity>2.35</velocity>
          </limit>
          <dynamics>
            <damping>1</damping>
            <friction>1</friction>
            <spring_reference>0</spring_reference>
            <spring_stiffness>0</spring_stiffness>
          </dynamics>
        </axis>
        <physics>
          <provide_feedback>1</provide_feedback>
          <ode>
            <implicit_spring_damper>1</implicit_spring_damper>
            <cfm_damping>1</cfm_damping>
            <limit>
              <cfm>0</cfm>
              <erp>0.2</erp>
            </limit>
            <provide_feedback>1</provide_feedback>
          </ode>
        </physics>
      </joint>
      <link name='arm_left_7_link'>
        <pose relative_to='arm_left_7_joint'>0 0 0 0 -0 0</pose>
        <inertial>
          <pose>7.2e-05 0.000608 0.08376 0 -0 0</pose>
          <mass>1.21226</mass>
          <inertia>
            <ixx>0.00249211</ixx>
            <ixy>-5.0396e-06</ixy>
            <ixz>2.53757e-06</ixz>
            <iyy>0.00246185</iyy>
            <iyz>5.27397e-05</iyz>
            <izz>0.000820829</izz>
          </inertia>
        </inertial>
        <collision name='arm_left_7_link_collision'>
          <pose>0 0 0 0 -0 0</pose>
          <geometry>
            <mesh>
              <scale>1 1 1</scale>
              <uri>model://pal_sea_arm_description/meshes/arm_tiago_pro/arm_7_link_collision.stl</uri>
            </mesh>
          </geometry>
          <surface>
            <contact>
              <ode/>
            </contact>
            <friction>
              <ode>
                <mu>0.9</mu>
                <mu2>0.9</mu2>
              </ode>
              <torsional>
                <ode/>
              </torsional>
            </friction>
            <bounce/>
          </surface>
          <max_contacts>10</max_contacts>
        </collision>
        <collision name='arm_left_7_link_fixed_joint_lump__arm_left_tool_link_collision_1'>
          <pose>0 0 0.0194 0 -0 1.5708</pose>
          <geometry>
            <cylinder>
              <length>0.01</length>
              <radius>0.032</radius>
            </cylinder>
          </geometry>
          <max_contacts>10</max_contacts>
          <surface>
            <contact>
              <ode/>
            </contact>
            <bounce/>
            <friction>
              <torsional>
                <ode/>
              </torsional>
              <ode/>
            </friction>
          </surface>
        </collision>
        <collision name='arm_left_7_link_fixed_joint_lump__wrist_left_ft_link_collision_2'>
          <pose>0 0 0.0334 0 -0 0.785398</pose>
          <geometry>
            <cylinder>
              <length>0.05</length>
              <radius>0.035</radius>
            </cylinder>
          </geometry>
          <surface>
            <contact>
              <ode/>
            </contact>
            <friction>
              <ode>
                <mu>0.9</mu>
                <mu2>0.9</mu2>
              </ode>
              <torsional>
                <ode/>
              </torsional>
            </friction>
            <bounce/>
          </surface>
          <max_contacts>10</max_contacts>
        </collision>
        <collision name='arm_left_7_link_fixed_joint_lump__wrist_left_ft_link_collision_3'>
          <pose>0.016971 0.032527 0.0284 0 -0 1.22173</pose>
          <geometry>
            <box>
              <size>0.0395 0.0496 0.053</size>
            </box>
          </geometry>
          <surface>
            <contact>
              <ode/>
            </contact>
            <friction>
              <ode>
                <mu>0.9</mu>
                <mu2>0.9</mu2>
              </ode>
              <torsional>
                <ode/>
              </torsional>
            </friction>
            <bounce/>
          </surface>
          <max_contacts>10</max_contacts>
        </collision>
        <collision name='arm_left_7_link_fixed_joint_lump__wrist_left_ft_tool_link_collision_4'>
          <pose>0 0 0.0694 0 -0 1.5708</pose>
          <geometry>
            <cylinder>
              <length>0.01</length>
              <radius>0.032</radius>
            </cylinder>
          </geometry>
          <max_contacts>10</max_contacts>
          <surface>
            <contact>
              <ode/>
            </contact>
            <bounce/>
            <friction>
              <torsional>
                <ode/>
              </torsional>
              <ode/>
            </friction>
          </surface>
        </collision>
        <collision name='arm_left_7_link_fixed_joint_lump__gripper_left_base_link_collision_5'>
          <pose>0 0 0.1204 0 -0 1.5708</pose>
          <geometry>
            <mesh>
              <scale>1 1 1</scale>
              <uri>model://pal_pro_gripper_description/meshes/base_link.stl</uri>
            </mesh>
          </geometry>
          <surface>
            <contact>
              <ode/>
            </contact>
            <friction>
              <ode>
                <mu>0.9</mu>
                <mu2>0.9</mu2>
              </ode>
              <torsional>
                <ode/>
              </torsional>
            </friction>
            <bounce/>
          </surface>
          <max_contacts>10</max_contacts>
        </collision>
        <visual name='arm_left_7_link_visual'>
          <pose>0 0 0 0 -0 0</pose>
          <geometry>
            <mesh>
              <scale>1 1 1</scale>
              <uri>model://pal_sea_arm_description/meshes/arm_tiago_pro/arm_7_link.stl</uri>
            </mesh>
          </geometry>
          <material>
            <script>
              <name>Gazebo/DarkGrey</name>
              <uri>file://media/materials/scripts/gazebo.material</uri>
            </script>
          </material>
        </visual>
        <visual name='arm_left_7_link_fixed_joint_lump__arm_left_tool_link_visual_1'>
          <pose>0 0 0.0194 0 -0 1.5708</pose>
          <geometry>
            <cylinder>
              <length>0.01</length>
              <radius>0.032</radius>
            </cylinder>
          </geometry>
        </visual>
        <visual name='arm_left_7_link_fixed_joint_lump__wrist_left_ft_link_visual_2'>
          <pose>0 0 0.0634 0 -0 0.785398</pose>
          <geometry>
            <mesh>
              <scale>1 1 1</scale>
              <uri>model://pal_sea_arm_description/meshes/sensors/rokubi_ft_sensor.STL</uri>
            </mesh>
          </geometry>
          <material>
            <script>
              <name>Gazebo/DarkGrey</name>
              <uri>file://media/materials/scripts/gazebo.material</uri>
            </script>
          </material>
        </visual>
        <visual name='arm_left_7_link_fixed_joint_lump__wrist_left_ft_tool_link_visual_3'>
          <pose>0 0 0.0694 0 -0 1.5708</pose>
          <geometry>
            <cylinder>
              <length>0.01</length>
              <radius>0.032</radius>
            </cylinder>
          </geometry>
        </visual>
        <visual name='arm_left_7_link_fixed_joint_lump__gripper_left_base_link_visual_4'>
          <pose>0 0 0.1204 0 -0 1.5708</pose>
          <geometry>
            <mesh>
              <scale>1 1 1</scale>
              <uri>model://pal_pro_gripper_description/meshes/base_link.stl</uri>
            </mesh>
          </geometry>
          <material>
            <script>
              <name>Gazebo/DarkGrey</name>
              <uri>file://media/materials/scripts/gazebo.material</uri>
            </script>
          </material>
        </visual>
        <self_collide>0</self_collide>
        <enable_wind>0</enable_wind>
        <kinematic>0</kinematic>
      </link>
      <joint name='gripper_left_finger_joint' type='revolute'>
        <pose relative_to='arm_left_7_link'>0 -0.0288 0.1489 1.5708 0.837758 -1.5708</pose>
        <parent>arm_left_7_link</parent>
        <child>gripper_left_outer_finger_left_link</child>
        <axis>
          <xyz>0 0 1</xyz>
          <limit>
            <lower>0</lower>
            <upper>0.925025</upper>
            <effort>0.1</effort>
            <velocity>2</velocity>
          </limit>
          <dynamics>
            <damping>0.03</damping>
            <friction>0</friction>
            <spring_reference>0</spring_reference>
            <spring_stiffness>0</spring_stiffness>
          </dynamics>
        </axis>
        <physics>
          <provide_feedback>1</provide_feedback>
          <ode>
            <implicit_spring_damper>1</implicit_spring_damper>
            <cfm_damping>1</cfm_damping>
            <limit>
              <cfm>0</cfm>
              <erp>0.2</erp>
            </limit>
            <provide_feedback>1</provide_feedback>
          </ode>
        </physics>
      </joint>
      <link name='gripper_left_outer_finger_left_link'>
        <pose relative_to='gripper_left_finger_joint'>0 0 0 0 -0 0</pose>
        <inertial>
          <pose>-0.001283 0.014397 0 0 -0 0</pose>
          <mass>0.015989</mass>
          <inertia>
            <ixx>5.9879e-06</ixx>
            <ixy>-5.2173e-07</ixy>
            <ixz>5.9144e-23</ixz>
            <iyy>4.8725e-07</iyy>
            <iyz>7.3911e-23</iyz>
            <izz>6.1497e-06</izz>
          </inertia>
        </inertial>
        <collision name='gripper_left_outer_finger_left_link_collision'>
          <pose>0 0 0 0 -0 0</pose>
          <geometry>
            <mesh>
              <scale>1 1 1</scale>
              <uri>model://pal_pro_gripper_description/meshes/outer_finger.stl</uri>
            </mesh>
          </geometry>
          <surface>
            <contact>
              <ode/>
            </contact>
            <friction>
              <ode>
                <mu>0.9</mu>
                <mu2>0.9</mu2>
              </ode>
              <torsional>
                <ode/>
              </torsional>
            </friction>
            <bounce/>
          </surface>
          <max_contacts>10</max_contacts>
        </collision>
        <visual name='gripper_left_outer_finger_left_link_visual'>
          <pose>0 0 0 0 -0 0</pose>
          <geometry>
            <mesh>
              <scale>1 1 1</scale>
              <uri>model://pal_pro_gripper_description/meshes/outer_finger.stl</uri>
            </mesh>
          </geometry>
          <material>
            <script>
              <name>Gazebo/White</name>
              <uri>file://media/materials/scripts/gazebo.material</uri>
            </script>
          </material>
        </visual>
        <self_collide>0</self_collide>
        <enable_wind>0</enable_wind>
        <kinematic>0</kinematic>
      </link>
      <joint name='gripper_left_inner_finger_left_joint' type='revolute'>
        <pose relative_to='arm_left_7_link'>0 -0.013977 0.153432 1.5708 0.837758 -1.5708</pose>
        <parent>arm_left_7_link</parent>
        <child>gripper_left_inner_finger_left_link</child>
        <axis>
          <xyz>0 0 1</xyz>
          <limit>
            <lower>0</lower>
            <upper>0.925025</upper>
            <effort>0.1</effort>
            <velocity>2</velocity>
          </limit>
          <dynamics>
            <spring_reference>0</spring_reference>
            <spring_stiffness>0</spring_stiffness>
          </dynamics>
        </axis>
      </joint>
      <link name='gripper_left_inner_finger_left_link'>
        <pose relative_to='gripper_left_inner_finger_left_joint'>0 0 0 0 -0 0</pose>
        <inertial>
          <pose>-0 0.024759 0 0 -0 0</pose>
          <mass>0.018619</mass>
          <inertia>
            <ixx>4.8806e-06</ixx>
            <ixy>-7.6762e-22</ixy>
            <ixz>1.0244e-22</ixz>
            <iyy>2.5471e-07</iyy>
            <iyz>-1.1841e-21</iyz>
            <izz>4.9573e-06</izz>
          </inertia>
        </inertial>
        <collision name='gripper_left_inner_finger_left_link_collision'>
          <pose>0 0 0 0 -0 0</pose>
          <geometry>
            <mesh>
              <scale>1 1 1</scale>
              <uri>model://pal_pro_gripper_description/meshes/inner_finger.stl</uri>
            </mesh>
          </geometry>
          <surface>
            <contact>
              <ode/>
            </contact>
            <friction>
              <ode>
                <mu>0.9</mu>
                <mu2>0.9</mu2>
              </ode>
              <torsional>
                <ode/>
              </torsional>
            </friction>
            <bounce/>
          </surface>
          <max_contacts>10</max_contacts>
        </collision>
        <visual name='gripper_left_inner_finger_left_link_visual'>
          <pose>0 0 0 0 -0 0</pose>
          <geometry>
            <mesh>
              <scale>1 1 1</scale>
              <uri>model://pal_pro_gripper_description/meshes/inner_finger.stl</uri>
            </mesh>
          </geometry>
          <material>
            <script>
              <name>Gazebo/White</name>
              <uri>file://media/materials/scripts/gazebo.material</uri>
            </script>
          </material>
        </visual>
        <self_collide>0</self_collide>
        <enable_wind>0</enable_wind>
        <kinematic>0</kinematic>
      </link>
      <joint name='gripper_left_fingertip_left_joint' type='revolute'>
        <pose relative_to='gripper_left_inner_finger_left_link'>0 0.05 0 0 -0 0.837758</pose>
        <parent>gripper_left_inner_finger_left_link</parent>
        <child>gripper_left_fingertip_left_link</child>
        <axis>
          <xyz>0 0 1</xyz>
          <limit>
            <lower>-0.925025</lower>
            <upper>0</upper>
            <effort>0.1</effort>
            <velocity>2</velocity>
          </limit>
          <dynamics>
            <spring_reference>0</spring_reference>
            <spring_stiffness>0</spring_stiffness>
          </dynamics>
        </axis>
      </joint>
      <link name='gripper_left_fingertip_left_link'>
        <pose relative_to='gripper_left_fingertip_left_joint'>0 0 0 0 -0 0</pose>
        <inertial>
          <pose>-0.0007 0.01167 0 0 -0 0</pose>
          <mass>0.03266</mass>
          <inertia>
            <ixx>3.6361e-06</ixx>
            <ixy>3.4071e-07</ixy>
            <ixz>-1.4191e-14</ixz>
            <iyy>1.707e-06</iyy>
            <iyz>-3.3433e-14</iyz>
            <izz>2.8395e-06</izz>
          </inertia>
        </inertial>
        <collision name='gripper_left_fingertip_left_link_collision'>
          <pose>0 0 0 0 -0 0</pose>
          <geometry>
            <mesh>
              <scale>1 1 1</scale>
              <uri>model://pal_pro_gripper_description/meshes/fingertip.stl</uri>
            </mesh>
          </geometry>
          <surface>
            <contact>
              <ode/>
            </contact>
            <friction>
              <ode>
                <mu>0.9</mu>
                <mu2>0.9</mu2>
              </ode>
              <torsional>
                <ode/>
              </torsional>
            </friction>
            <bounce/>
          </surface>
          <max_contacts>10</max_contacts>
        </collision>
        <visual name='gripper_left_fingertip_left_link_visual'>
          <pose>0 0 0 0 -0 0</pose>
          <geometry>
            <mesh>
              <scale>1 1 1</scale>
              <uri>model://pal_pro_gripper_description/meshes/fingertip.stl</uri>
            </mesh>
          </geometry>
          <material>
            <script>
              <name>Gazebo/White</name>
              <uri>file://media/materials/scripts/gazebo.material</uri>
            </script>
          </material>
        </visual>
        <self_collide>0</self_collide>
        <enable_wind>0</enable_wind>
        <kinematic>0</kinematic>
      </link>
      <joint name='gripper_left_inner_finger_right_joint' type='revolute'>
        <pose relative_to='arm_left_7_link'>0 0.013977 0.153432 1.5708 0.837758 1.5708</pose>
        <parent>arm_left_7_link</parent>
        <child>gripper_left_inner_finger_right_link</child>
        <axis>
          <xyz>0 0 1</xyz>
          <limit>
            <lower>0</lower>
            <upper>0.925025</upper>
            <effort>0.1</effort>
            <velocity>2</velocity>
          </limit>
          <dynamics>
            <spring_reference>0</spring_reference>
            <spring_stiffness>0</spring_stiffness>
          </dynamics>
        </axis>
      </joint>
      <link name='gripper_left_inner_finger_right_link'>
        <pose relative_to='gripper_left_inner_finger_right_joint'>0 0 0 0 -0 0</pose>
        <inertial>
          <pose>-0 0.024759 0 0 -0 0</pose>
          <mass>0.018619</mass>
          <inertia>
            <ixx>4.8806e-06</ixx>
            <ixy>-7.6762e-22</ixy>
            <ixz>1.0244e-22</ixz>
            <iyy>2.5471e-07</iyy>
            <iyz>-1.1841e-21</iyz>
            <izz>4.9573e-06</izz>
          </inertia>
        </inertial>
        <collision name='gripper_left_inner_finger_right_link_collision'>
          <pose>0 0 0 0 -0 0</pose>
          <geometry>
            <mesh>
              <scale>1 1 1</scale>
              <uri>model://pal_pro_gripper_description/meshes/inner_finger.stl</uri>
            </mesh>
          </geometry>
          <surface>
            <contact>
              <ode/>
            </contact>
            <friction>
              <ode>
                <mu>0.9</mu>
                <mu2>0.9</mu2>
              </ode>
              <torsional>
                <ode/>
              </torsional>
            </friction>
            <bounce/>
          </surface>
          <max_contacts>10</max_contacts>
        </collision>
        <visual name='gripper_left_inner_finger_right_link_visual'>
          <pose>0 0 0 0 -0 0</pose>
          <geometry>
            <mesh>
              <scale>1 1 1</scale>
              <uri>model://pal_pro_gripper_description/meshes/inner_finger.stl</uri>
            </mesh>
          </geometry>
          <material>
            <script>
              <name>Gazebo/White</name>
              <uri>file://media/materials/scripts/gazebo.material</uri>
            </script>
          </material>
        </visual>
        <self_collide>0</self_collide>
        <enable_wind>0</enable_wind>
        <kinematic>0</kinematic>
      </link>
      <joint name='gripper_left_fingertip_right_joint' type='revolute'>
        <pose relative_to='gripper_left_inner_finger_right_link'>0 0.05 0 0 -0 0.837758</pose>
        <parent>gripper_left_inner_finger_right_link</parent>
        <child>gripper_left_fingertip_right_link</child>
        <axis>
          <xyz>0 0 1</xyz>
          <limit>
            <lower>-0.925025</lower>
            <upper>0</upper>
            <effort>0.1</effort>
            <velocity>2</velocity>
          </limit>
          <dynamics>
            <spring_reference>0</spring_reference>
            <spring_stiffness>0</spring_stiffness>
          </dynamics>
        </axis>
      </joint>
      <link name='gripper_left_fingertip_right_link'>
        <pose relative_to='gripper_left_fingertip_right_joint'>0 0 0 0 -0 0</pose>
        <inertial>
          <pose>-0.0007 0.01167 0 0 -0 0</pose>
          <mass>0.03266</mass>
          <inertia>
            <ixx>3.6361e-06</ixx>
            <ixy>3.4071e-07</ixy>
            <ixz>-1.4191e-14</ixz>
            <iyy>1.707e-06</iyy>
            <iyz>-3.3433e-14</iyz>
            <izz>2.8395e-06</izz>
          </inertia>
        </inertial>
        <collision name='gripper_left_fingertip_right_link_collision'>
          <pose>0 0 0 0 -0 0</pose>
          <geometry>
            <mesh>
              <scale>1 1 1</scale>
              <uri>model://pal_pro_gripper_description/meshes/fingertip.stl</uri>
            </mesh>
          </geometry>
          <surface>
            <contact>
              <ode/>
            </contact>
            <friction>
              <ode>
                <mu>0.9</mu>
                <mu2>0.9</mu2>
              </ode>
              <torsional>
                <ode/>
              </torsional>
            </friction>
            <bounce/>
          </surface>
          <max_contacts>10</max_contacts>
        </collision>
        <visual name='gripper_left_fingertip_right_link_visual'>
          <pose>0 0 0 0 -0 0</pose>
          <geometry>
            <mesh>
              <scale>1 1 1</scale>
              <uri>model://pal_pro_gripper_description/meshes/fingertip.stl</uri>
            </mesh>
          </geometry>
          <material>
            <script>
              <name>Gazebo/White</name>
              <uri>file://media/materials/scripts/gazebo.material</uri>
            </script>
          </material>
        </visual>
        <self_collide>0</self_collide>
        <enable_wind>0</enable_wind>
        <kinematic>0</kinematic>
      </link>
      <joint name='gripper_left_outer_finger_right_joint' type='revolute'>
        <pose relative_to='arm_left_7_link'>0 0.0288 0.1489 1.5708 0.837758 1.5708</pose>
        <parent>arm_left_7_link</parent>
        <child>gripper_left_outer_finger_right_link</child>
        <axis>
          <xyz>0 0 1</xyz>
          <limit>
            <lower>0</lower>
            <upper>0.925025</upper>
            <effort>0.1</effort>
            <velocity>2</velocity>
          </limit>
          <dynamics>
            <spring_reference>0</spring_reference>
            <spring_stiffness>0</spring_stiffness>
          </dynamics>
        </axis>
      </joint>
      <link name='gripper_left_outer_finger_right_link'>
        <pose relative_to='gripper_left_outer_finger_right_joint'>0 0 0 0 -0 0</pose>
        <inertial>
          <pose>-0.001283 0.014397 0 0 -0 0</pose>
          <mass>0.015989</mass>
          <inertia>
            <ixx>5.9879e-06</ixx>
            <ixy>-5.2173e-07</ixy>
            <ixz>5.9144e-23</ixz>
            <iyy>4.8725e-07</iyy>
            <iyz>7.3911e-23</iyz>
            <izz>6.1497e-06</izz>
          </inertia>
        </inertial>
        <collision name='gripper_left_outer_finger_right_link_collision'>
          <pose>0 0 0 0 -0 0</pose>
          <geometry>
            <mesh>
              <scale>1 1 1</scale>
              <uri>model://pal_pro_gripper_description/meshes/outer_finger.stl</uri>
            </mesh>
          </geometry>
          <surface>
            <contact>
              <ode/>
            </contact>
            <friction>
              <ode>
                <mu>0.9</mu>
                <mu2>0.9</mu2>
              </ode>
              <torsional>
                <ode/>
              </torsional>
            </friction>
            <bounce/>
          </surface>
          <max_contacts>10</max_contacts>
        </collision>
        <visual name='gripper_left_outer_finger_right_link_visual'>
          <pose>0 0 0 0 -0 0</pose>
          <geometry>
            <mesh>
              <scale>1 1 1</scale>
              <uri>model://pal_pro_gripper_description/meshes/outer_finger.stl</uri>
            </mesh>
          </geometry>
          <material>
            <script>
              <name>Gazebo/White</name>
              <uri>file://media/materials/scripts/gazebo.material</uri>
            </script>
          </material>
        </visual>
        <self_collide>0</self_collide>
        <enable_wind>0</enable_wind>
        <kinematic>0</kinematic>
      </link>
      <joint name='arm_right_1_joint' type='revolute'>
        <pose relative_to='torso_lift_link'>0.08976 -0.15918 -0.092008 -2.0679 0 -1.91989</pose>
        <parent>torso_lift_link</parent>
        <child>arm_right_1_link</child>
        <axis>
          <xyz>0 0 1</xyz>
          <limit>
            <lower>-2.60002</lower>
            <upper>2.60002</upper>
            <effort>43</effort>
            <velocity>1.95</velocity>
          </limit>
          <dynamics>
            <damping>1</damping>
            <friction>1</friction>
            <spring_reference>0</spring_reference>
            <spring_stiffness>0</spring_stiffness>
          </dynamics>
        </axis>
        <physics>
          <ode>
            <implicit_spring_damper>1</implicit_spring_damper>
            <cfm_damping>1</cfm_damping>
            <limit>
              <cfm>0</cfm>
              <erp>0.2</erp>
            </limit>
          </ode>
        </physics>
      </joint>
      <link name='arm_right_1_link'>
        <pose relative_to='arm_right_1_joint'>0 0 0 0 -0 0</pose>
        <inertial>
          <pose>0.002391 0.015901 0.1545 0 -0 0</pose>
          <mass>1.0816</mass>
          <inertia>
            <ixx>0.0024426</ixx>
            <ixy>2.3307e-05</ixy>
            <ixz>5.9333e-05</ixz>
            <iyy>0.0023089</iyy>
            <iyz>-0.00020369</iyz>
            <izz>0.00092843</izz>
          </inertia>
        </inertial>
        <collision name='arm_right_1_link_collision'>
          <pose>0 0 0 0 -0 0</pose>
          <geometry>
            <mesh>
              <scale>1 1 1</scale>
              <uri>model://pal_sea_arm_description/meshes/arm_tiago_pro/arm_1_link_collision.stl</uri>
            </mesh>
          </geometry>
          <surface>
            <contact>
              <ode/>
            </contact>
            <friction>
              <ode>
                <mu>0.9</mu>
                <mu2>0.9</mu2>
              </ode>
              <torsional>
                <ode/>
              </torsional>
            </friction>
            <bounce/>
          </surface>
          <max_contacts>10</max_contacts>
        </collision>
        <visual name='arm_right_1_link_visual'>
          <pose>0 0 0 0 -0 0</pose>
          <geometry>
            <mesh>
              <scale>1 1 1</scale>
              <uri>model://pal_sea_arm_description/meshes/arm_tiago_pro/arm_1_link.stl</uri>
            </mesh>
          </geometry>
          <material>
            <script>
              <name>Gazebo/DarkGrey</name>
              <uri>file://media/materials/scripts/gazebo.material</uri>
            </script>
          </material>
        </visual>
        <self_collide>0</self_collide>
        <enable_wind>0</enable_wind>
        <kinematic>0</kinematic>
      </link>
      <joint name='arm_right_2_joint' type='revolute'>
        <pose relative_to='arm_right_1_link'>0 0.02 0.18 3.14159 1.57079 3.14159</pose>
        <parent>arm_right_1_link</parent>
        <child>arm_right_2_link</child>
        <axis>
          <xyz>0 0 1</xyz>
          <limit>
            <lower>-2.43997</lower>
            <upper>1.10008</upper>
            <effort>43</effort>
            <velocity>1.95</velocity>
          </limit>
          <dynamics>
            <damping>1</damping>
            <friction>1</friction>
            <spring_reference>0</spring_reference>
            <spring_stiffness>0</spring_stiffness>
          </dynamics>
        </axis>
        <physics>
          <ode>
            <implicit_spring_damper>1</implicit_spring_damper>
            <cfm_damping>1</cfm_damping>
            <limit>
              <cfm>0</cfm>
              <erp>0.2</erp>
            </limit>
          </ode>
        </physics>
      </joint>
      <link name='arm_right_2_link'>
        <pose relative_to='arm_right_2_joint'>0 0 0 0 -0 0</pose>
        <inertial>
          <pose>-0.11649 -0.017864 0.005377 0 -0 0</pose>
          <mass>0.99204</mass>
          <inertia>
            <ixx>0.00077294</ixx>
            <ixy>-0.00011001</ixy>
            <ixz>-0.00016136</ixz>
            <iyy>0.0014605</iyy>
            <iyz>-1.3224e-05</iyz>
            <izz>0.0015605</izz>
          </inertia>
        </inertial>
        <collision name='arm_right_2_link_collision'>
          <pose>0 0 0 0 -0 0</pose>
          <geometry>
            <mesh>
              <scale>1 1 1</scale>
              <uri>model://pal_sea_arm_description/meshes/arm_tiago_pro/arm_2_link_collision.stl</uri>
            </mesh>
          </geometry>
          <surface>
            <contact>
              <ode/>
            </contact>
            <friction>
              <ode>
                <mu>0.9</mu>
                <mu2>0.9</mu2>
              </ode>
              <torsional>
                <ode/>
              </torsional>
            </friction>
            <bounce/>
          </surface>
          <max_contacts>10</max_contacts>
        </collision>
        <visual name='arm_right_2_link_visual'>
          <pose>0 0 0 0 -0 0</pose>
          <geometry>
            <mesh>
              <scale>1 1 1</scale>
              <uri>model://pal_sea_arm_description/meshes/arm_tiago_pro/arm_2_link.stl</uri>
            </mesh>
          </geometry>
          <material>
            <script>
              <name>Gazebo/DarkGrey</name>
              <uri>file://media/materials/scripts/gazebo.material</uri>
            </script>
          </material>
        </visual>
        <self_collide>0</self_collide>
        <enable_wind>0</enable_wind>
        <kinematic>0</kinematic>
      </link>
      <joint name='arm_right_3_joint' type='revolute'>
        <pose relative_to='arm_right_2_link'>-0.15 -0.02 0 3.1415 1.5707 0</pose>
        <parent>arm_right_2_link</parent>
        <child>arm_right_3_link</child>
        <axis>
          <xyz>0 0 1</xyz>
          <limit>
            <lower>-2.60002</lower>
            <upper>2.60002</upper>
            <effort>26</effort>
            <velocity>2.35</velocity>
          </limit>
          <dynamics>
            <damping>1</damping>
            <friction>1</friction>
            <spring_reference>0</spring_reference>
            <spring_stiffness>0</spring_stiffness>
          </dynamics>
        </axis>
        <physics>
          <ode>
            <implicit_spring_damper>1</implicit_spring_damper>
            <cfm_damping>1</cfm_damping>
            <limit>
              <cfm>0</cfm>
              <erp>0.2</erp>
            </limit>
          </ode>
        </physics>
      </joint>
      <link name='arm_right_3_link'>
        <pose relative_to='arm_right_3_joint'>0 0 0 0 -0 0</pose>
        <inertial>
          <pose>0.002391 0.015901 0.1545 0 -0 0</pose>
          <mass>1.0816</mass>
          <inertia>
            <ixx>0.0024426</ixx>
            <ixy>2.3307e-05</ixy>
            <ixz>5.9333e-05</ixz>
            <iyy>0.0023089</iyy>
            <iyz>-0.00020369</iyz>
            <izz>0.00092843</izz>
          </inertia>
        </inertial>
        <collision name='arm_right_3_link_collision'>
          <pose>0 0 0 0 -0 0</pose>
          <geometry>
            <mesh>
              <scale>1 1 1</scale>
              <uri>model://pal_sea_arm_description/meshes/arm_tiago_pro/arm_3_link_collision.stl</uri>
            </mesh>
          </geometry>
          <surface>
            <contact>
              <ode/>
            </contact>
            <friction>
              <ode>
                <mu>0.9</mu>
                <mu2>0.9</mu2>
              </ode>
              <torsional>
                <ode/>
              </torsional>
            </friction>
            <bounce/>
          </surface>
          <max_contacts>10</max_contacts>
        </collision>
        <visual name='arm_right_3_link_visual'>
          <pose>0 0 0 0 -0 0</pose>
          <geometry>
            <mesh>
              <scale>1 1 1</scale>
              <uri>model://pal_sea_arm_description/meshes/arm_tiago_pro/arm_3_link.stl</uri>
            </mesh>
          </geometry>
          <material>
            <script>
              <name>Gazebo/DarkGrey</name>
              <uri>file://media/materials/scripts/gazebo.material</uri>
            </script>
          </material>
        </visual>
        <self_collide>0</self_collide>
        <enable_wind>0</enable_wind>
        <kinematic>0</kinematic>
      </link>
      <joint name='arm_right_4_joint' type='revolute'>
        <pose relative_to='arm_right_3_link'>0 0.02 0.18 3.14159 1.57079 3.14159</pose>
        <parent>arm_right_3_link</parent>
        <child>arm_right_4_link</child>
        <axis>
          <xyz>0 0 1</xyz>
          <limit>
            <lower>-2.43997</lower>
            <upper>1.10008</upper>
            <effort>26</effort>
            <velocity>2.35</velocity>
          </limit>
          <dynamics>
            <damping>1</damping>
            <friction>1</friction>
            <spring_reference>0</spring_reference>
            <spring_stiffness>0</spring_stiffness>
          </dynamics>
        </axis>
        <physics>
          <ode>
            <implicit_spring_damper>1</implicit_spring_damper>
            <cfm_damping>1</cfm_damping>
            <limit>
              <cfm>0</cfm>
              <erp>0.2</erp>
            </limit>
          </ode>
        </physics>
      </joint>
      <link name='arm_right_4_link'>
        <pose relative_to='arm_right_4_joint'>0 0 0 0 -0 0</pose>
        <inertial>
          <pose>-0.11649 -0.017864 0.005377 0 -0 0</pose>
          <mass>0.99204</mass>
          <inertia>
            <ixx>0.00077294</ixx>
            <ixy>-0.00011001</ixy>
            <ixz>-0.00016136</ixz>
            <iyy>0.0014605</iyy>
            <iyz>-1.3224e-05</iyz>
            <izz>0.0015605</izz>
          </inertia>
        </inertial>
        <collision name='arm_right_4_link_collision'>
          <pose>0 0 0 0 -0 0</pose>
          <geometry>
            <mesh>
              <scale>1 1 1</scale>
              <uri>model://pal_sea_arm_description/meshes/arm_tiago_pro/arm_4_link_collision.stl</uri>
            </mesh>
          </geometry>
          <surface>
            <contact>
              <ode/>
            </contact>
            <friction>
              <ode>
                <mu>0.9</mu>
                <mu2>0.9</mu2>
              </ode>
              <torsional>
                <ode/>
              </torsional>
            </friction>
            <bounce/>
          </surface>
          <max_contacts>10</max_contacts>
        </collision>
        <visual name='arm_right_4_link_visual'>
          <pose>0 0 0 0 -0 0</pose>
          <geometry>
            <mesh>
              <scale>1 1 1</scale>
              <uri>model://pal_sea_arm_description/meshes/arm_tiago_pro/arm_4_link.stl</uri>
            </mesh>
          </geometry>
          <material>
            <script>
              <name>Gazebo/DarkGrey</name>
              <uri>file://media/materials/scripts/gazebo.material</uri>
            </script>
          </material>
        </visual>
        <self_collide>0</self_collide>
        <enable_wind>0</enable_wind>
        <kinematic>0</kinematic>
      </link>
      <joint name='arm_right_5_joint' type='revolute'>
        <pose relative_to='arm_right_4_link'>-0.15 -0.02 0 3.14159 -1.57079 3.14159</pose>
        <parent>arm_right_4_link</parent>
        <child>arm_right_5_link</child>
        <axis>
          <xyz>0 0 1</xyz>
          <limit>
            <lower>-2.60002</lower>
            <upper>2.60002</upper>
            <effort>26</effort>
            <velocity>2.35</velocity>
          </limit>
          <dynamics>
            <damping>1</damping>
            <friction>1</friction>
            <spring_reference>0</spring_reference>
            <spring_stiffness>0</spring_stiffness>
          </dynamics>
        </axis>
        <physics>
          <ode>
            <implicit_spring_damper>1</implicit_spring_damper>
            <cfm_damping>1</cfm_damping>
            <limit>
              <cfm>0</cfm>
              <erp>0.2</erp>
            </limit>
          </ode>
        </physics>
      </joint>
      <link name='arm_right_5_link'>
        <pose relative_to='arm_right_5_joint'>0 0 0 0 -0 0</pose>
        <inertial>
          <pose>0.000486 0.000143 0.129 0 -0 0</pose>
          <mass>0.52538</mass>
          <inertia>
            <ixx>0.0019111</ixx>
            <ixy>-1.4245e-08</ixy>
            <ixz>3.8663e-05</ixz>
            <iyy>0.0018565</iyy>
            <iyz>1.1356e-06</iyz>
            <izz>0.00046496</izz>
          </inertia>
        </inertial>
        <collision name='arm_right_5_link_collision'>
          <pose>0 0 0 0 -0 0</pose>
          <geometry>
            <mesh>
              <scale>1 1 1</scale>
              <uri>model://pal_sea_arm_description/meshes/arm_tiago_pro/arm_5_link_collision.stl</uri>
            </mesh>
          </geometry>
          <surface>
            <contact>
              <ode/>
            </contact>
            <friction>
              <ode>
                <mu>0.9</mu>
                <mu2>0.9</mu2>
              </ode>
              <torsional>
                <ode/>
              </torsional>
            </friction>
            <bounce/>
          </surface>
          <max_contacts>10</max_contacts>
        </collision>
        <visual name='arm_right_5_link_visual'>
          <pose>0 0 0 0 -0 0</pose>
          <geometry>
            <mesh>
              <scale>1 1 1</scale>
              <uri>model://pal_sea_arm_description/meshes/arm_tiago_pro/arm_5_link.stl</uri>
            </mesh>
          </geometry>
          <material>
            <script>
              <name>Gazebo/DarkGrey</name>
              <uri>file://media/materials/scripts/gazebo.material</uri>
            </script>
          </material>
        </visual>
        <self_collide>0</self_collide>
        <enable_wind>0</enable_wind>
        <kinematic>0</kinematic>
      </link>
      <joint name='arm_right_6_joint' type='revolute'>
        <pose relative_to='arm_right_5_link'>0 0 0.185 3.14159 1.57079 3.14159</pose>
        <parent>arm_right_5_link</parent>
        <child>arm_right_6_link</child>
        <axis>
          <xyz>0 0 1</xyz>
          <limit>
            <lower>-1.99997</lower>
            <upper>1.99997</upper>
            <effort>26</effort>
            <velocity>2.35</velocity>
          </limit>
          <dynamics>
            <damping>1</damping>
            <friction>1</friction>
            <spring_reference>0</spring_reference>
            <spring_stiffness>0</spring_stiffness>
          </dynamics>
        </axis>
        <physics>
          <ode>
            <implicit_spring_damper>1</implicit_spring_damper>
            <cfm_damping>1</cfm_damping>
            <limit>
              <cfm>0</cfm>
              <erp>0.2</erp>
            </limit>
          </ode>
        </physics>
      </joint>
      <link name='arm_right_6_link'>
        <pose relative_to='arm_right_6_joint'>0 0 0 0 -0 0</pose>
        <inertial>
          <pose>-0.086822 -8e-06 0.004526 0 -0 0</pose>
          <mass>0.66725</mass>
          <inertia>
            <ixx>0.00035696</ixx>
            <ixy>1.6019e-07</ixy>
            <ixz>-9.5191e-05</ixz>
            <iyy>0.00073846</iyy>
            <iyz>2.118e-08</iyz>
            <izz>0.00075321</izz>
          </inertia>
        </inertial>
        <collision name='arm_right_6_link_collision'>
          <pose>0 0 0 0 -0 0</pose>
          <geometry>
            <mesh>
              <scale>1 1 1</scale>
              <uri>model://pal_sea_arm_description/meshes/arm_tiago_pro/arm_6_link_collision.stl</uri>
            </mesh>
          </geometry>
          <surface>
            <contact>
              <ode/>
            </contact>
            <friction>
              <ode>
                <mu>0.9</mu>
                <mu2>0.9</mu2>
              </ode>
              <torsional>
                <ode/>
              </torsional>
            </friction>
            <bounce/>
          </surface>
          <max_contacts>10</max_contacts>
        </collision>
        <visual name='arm_right_6_link_visual'>
          <pose>0 0 0 0 -0 0</pose>
          <geometry>
            <mesh>
              <scale>1 1 1</scale>
              <uri>model://pal_sea_arm_description/meshes/arm_tiago_pro/arm_6_link.stl</uri>
            </mesh>
          </geometry>
          <material>
            <script>
              <name>Gazebo/DarkGrey</name>
              <uri>file://media/materials/scripts/gazebo.material</uri>
            </script>
          </material>
        </visual>
        <self_collide>0</self_collide>
        <enable_wind>0</enable_wind>
        <kinematic>0</kinematic>
      </link>
      <joint name='arm_right_7_joint' type='revolute'>
        <pose relative_to='arm_right_6_link'>-0.1166 0 0 3.14159 -1.57079 3.14159</pose>
        <parent>arm_right_6_link</parent>
        <child>arm_right_7_link</child>
        <axis>
          <xyz>0 0 1</xyz>
          <limit>
            <lower>-2.60002</lower>
            <upper>2.60002</upper>
            <effort>26</effort>
            <velocity>2.35</velocity>
          </limit>
          <dynamics>
            <damping>1</damping>
            <friction>1</friction>
            <spring_reference>0</spring_reference>
            <spring_stiffness>0</spring_stiffness>
          </dynamics>
        </axis>
        <physics>
          <provide_feedback>1</provide_feedback>
          <ode>
            <implicit_spring_damper>1</implicit_spring_damper>
            <cfm_damping>1</cfm_damping>
            <limit>
              <cfm>0</cfm>
              <erp>0.2</erp>
            </limit>
            <provide_feedback>1</provide_feedback>
          </ode>
        </physics>
      </joint>
      <link name='arm_right_7_link'>
        <pose relative_to='arm_right_7_joint'>0 0 0 0 -0 0</pose>
        <inertial>
          <pose>7.2e-05 0.000608 0.08376 0 -0 0</pose>
          <mass>1.21226</mass>
          <inertia>
            <ixx>0.00249211</ixx>
            <ixy>-5.0396e-06</ixy>
            <ixz>2.53757e-06</ixz>
            <iyy>0.00246185</iyy>
            <iyz>5.27397e-05</iyz>
            <izz>0.000820829</izz>
          </inertia>
        </inertial>
        <collision name='arm_right_7_link_collision'>
          <pose>0 0 0 0 -0 0</pose>
          <geometry>
            <mesh>
              <scale>1 1 1</scale>
              <uri>model://pal_sea_arm_description/meshes/arm_tiago_pro/arm_7_link_collision.stl</uri>
            </mesh>
          </geometry>
          <surface>
            <contact>
              <ode/>
            </contact>
            <friction>
              <ode>
                <mu>0.9</mu>
                <mu2>0.9</mu2>
              </ode>
              <torsional>
                <ode/>
              </torsional>
            </friction>
            <bounce/>
          </surface>
          <max_contacts>10</max_contacts>
        </collision>
        <collision name='arm_right_7_link_fixed_joint_lump__arm_right_tool_link_collision_1'>
          <pose>0 0 0.0194 0 -0 1.5708</pose>
          <geometry>
            <cylinder>
              <length>0.01</length>
              <radius>0.032</radius>
            </cylinder>
          </geometry>
          <max_contacts>10</max_contacts>
          <surface>
            <contact>
              <ode/>
            </contact>
            <bounce/>
            <friction>
              <torsional>
                <ode/>
              </torsional>
              <ode/>
            </friction>
          </surface>
        </collision>
        <collision name='arm_right_7_link_fixed_joint_lump__wrist_right_ft_link_collision_2'>
          <pose>0 0 0.0334 0 -0 0.785398</pose>
          <geometry>
            <cylinder>
              <length>0.05</length>
              <radius>0.035</radius>
            </cylinder>
          </geometry>
          <surface>
            <contact>
              <ode/>
            </contact>
            <friction>
              <ode>
                <mu>0.9</mu>
                <mu2>0.9</mu2>
              </ode>
              <torsional>
                <ode/>
              </torsional>
            </friction>
            <bounce/>
          </surface>
          <max_contacts>10</max_contacts>
        </collision>
        <collision name='arm_right_7_link_fixed_joint_lump__wrist_right_ft_link_collision_3'>
          <pose>0.016971 0.032527 0.0284 0 -0 1.22173</pose>
          <geometry>
            <box>
              <size>0.0395 0.0496 0.053</size>
            </box>
          </geometry>
          <surface>
            <contact>
              <ode/>
            </contact>
            <friction>
              <ode>
                <mu>0.9</mu>
                <mu2>0.9</mu2>
              </ode>
              <torsional>
                <ode/>
              </torsional>
            </friction>
            <bounce/>
          </surface>
          <max_contacts>10</max_contacts>
        </collision>
        <collision name='arm_right_7_link_fixed_joint_lump__wrist_right_ft_tool_link_collision_4'>
          <pose>0 0 0.0694 0 -0 1.5708</pose>
          <geometry>
            <cylinder>
              <length>0.01</length>
              <radius>0.032</radius>
            </cylinder>
          </geometry>
          <max_contacts>10</max_contacts>
          <surface>
            <contact>
              <ode/>
            </contact>
            <bounce/>
            <friction>
              <torsional>
                <ode/>
              </torsional>
              <ode/>
            </friction>
          </surface>
        </collision>
        <collision name='arm_right_7_link_fixed_joint_lump__gripper_right_base_link_collision_5'>
          <pose>0 0 0.1204 0 -0 1.5708</pose>
          <geometry>
            <mesh>
              <scale>1 1 1</scale>
              <uri>model://pal_pro_gripper_description/meshes/base_link.stl</uri>
            </mesh>
          </geometry>
          <surface>
            <contact>
              <ode/>
            </contact>
            <friction>
              <ode>
                <mu>0.9</mu>
                <mu2>0.9</mu2>
              </ode>
              <torsional>
                <ode/>
              </torsional>
            </friction>
            <bounce/>
          </surface>
          <max_contacts>10</max_contacts>
        </collision>
        <visual name='arm_right_7_link_visual'>
          <pose>0 0 0 0 -0 0</pose>
          <geometry>
            <mesh>
              <scale>1 1 1</scale>
              <uri>model://pal_sea_arm_description/meshes/arm_tiago_pro/arm_7_link.stl</uri>
            </mesh>
          </geometry>
          <material>
            <script>
              <name>Gazebo/DarkGrey</name>
              <uri>file://media/materials/scripts/gazebo.material</uri>
            </script>
          </material>
        </visual>
        <visual name='arm_right_7_link_fixed_joint_lump__arm_right_tool_link_visual_1'>
          <pose>0 0 0.0194 0 -0 1.5708</pose>
          <geometry>
            <cylinder>
              <length>0.01</length>
              <radius>0.032</radius>
            </cylinder>
          </geometry>
        </visual>
        <visual name='arm_right_7_link_fixed_joint_lump__wrist_right_ft_link_visual_2'>
          <pose>0 0 0.0634 0 -0 0.785398</pose>
          <geometry>
            <mesh>
              <scale>1 1 1</scale>
              <uri>model://pal_sea_arm_description/meshes/sensors/rokubi_ft_sensor.STL</uri>
            </mesh>
          </geometry>
          <material>
            <script>
              <name>Gazebo/DarkGrey</name>
              <uri>file://media/materials/scripts/gazebo.material</uri>
            </script>
          </material>
        </visual>
        <visual name='arm_right_7_link_fixed_joint_lump__wrist_right_ft_tool_link_visual_3'>
          <pose>0 0 0.0694 0 -0 1.5708</pose>
          <geometry>
            <cylinder>
              <length>0.01</length>
              <radius>0.032</radius>
            </cylinder>
          </geometry>
        </visual>
        <visual name='arm_right_7_link_fixed_joint_lump__gripper_right_base_link_visual_4'>
          <pose>0 0 0.1204 0 -0 1.5708</pose>
          <geometry>
            <mesh>
              <scale>1 1 1</scale>
              <uri>model://pal_pro_gripper_description/meshes/base_link.stl</uri>
            </mesh>
          </geometry>
          <material>
            <script>
              <name>Gazebo/DarkGrey</name>
              <uri>file://media/materials/scripts/gazebo.material</uri>
            </script>
          </material>
        </visual>
        <self_collide>0</self_collide>
        <enable_wind>0</enable_wind>
        <kinematic>0</kinematic>
      </link>
      <joint name='gripper_right_finger_joint' type='revolute'>
        <pose relative_to='arm_right_7_link'>0 -0.0288 0.1489 1.5708 0.837758 -1.5708</pose>
        <parent>arm_right_7_link</parent>
        <child>gripper_right_outer_finger_left_link</child>
        <axis>
          <xyz>0 0 1</xyz>
          <limit>
            <lower>0</lower>
            <upper>0.925025</upper>
            <effort>0.1</effort>
            <velocity>2</velocity>
          </limit>
          <dynamics>
            <damping>0.03</damping>
            <friction>0</friction>
            <spring_reference>0</spring_reference>
            <spring_stiffness>0</spring_stiffness>
          </dynamics>
        </axis>
        <physics>
          <provide_feedback>1</provide_feedback>
          <ode>
            <implicit_spring_damper>1</implicit_spring_damper>
            <cfm_damping>1</cfm_damping>
            <limit>
              <cfm>0</cfm>
              <erp>0.2</erp>
            </limit>
            <provide_feedback>1</provide_feedback>
          </ode>
        </physics>
      </joint>
      <link name='gripper_right_outer_finger_left_link'>
        <pose relative_to='gripper_right_finger_joint'>0 0 0 0 -0 0</pose>
        <inertial>
          <pose>-0.001283 0.014397 0 0 -0 0</pose>
          <mass>0.015989</mass>
          <inertia>
            <ixx>5.9879e-06</ixx>
            <ixy>-5.2173e-07</ixy>
            <ixz>5.9144e-23</ixz>
            <iyy>4.8725e-07</iyy>
            <iyz>7.3911e-23</iyz>
            <izz>6.1497e-06</izz>
          </inertia>
        </inertial>
        <collision name='gripper_right_outer_finger_left_link_collision'>
          <pose>0 0 0 0 -0 0</pose>
          <geometry>
            <mesh>
              <scale>1 1 1</scale>
              <uri>model://pal_pro_gripper_description/meshes/outer_finger.stl</uri>
            </mesh>
          </geometry>
          <surface>
            <contact>
              <ode/>
            </contact>
            <friction>
              <ode>
                <mu>0.9</mu>
                <mu2>0.9</mu2>
              </ode>
              <torsional>
                <ode/>
              </torsional>
            </friction>
            <bounce/>
          </surface>
          <max_contacts>10</max_contacts>
        </collision>
        <visual name='gripper_right_outer_finger_left_link_visual'>
          <pose>0 0 0 0 -0 0</pose>
          <geometry>
            <mesh>
              <scale>1 1 1</scale>
              <uri>model://pal_pro_gripper_description/meshes/outer_finger.stl</uri>
            </mesh>
          </geometry>
          <material>
            <script>
              <name>Gazebo/White</name>
              <uri>file://media/materials/scripts/gazebo.material</uri>
            </script>
          </material>
        </visual>
        <self_collide>0</self_collide>
        <enable_wind>0</enable_wind>
        <kinematic>0</kinematic>
      </link>
      <joint name='gripper_right_inner_finger_left_joint' type='revolute'>
        <pose relative_to='arm_right_7_link'>0 -0.013977 0.153432 1.5708 0.837758 -1.5708</pose>
        <parent>arm_right_7_link</parent>
        <child>gripper_right_inner_finger_left_link</child>
        <axis>
          <xyz>0 0 1</xyz>
          <limit>
            <lower>0</lower>
            <upper>0.925025</upper>
            <effort>0.1</effort>
            <velocity>2</velocity>
          </limit>
          <dynamics>
            <spring_reference>0</spring_reference>
            <spring_stiffness>0</spring_stiffness>
          </dynamics>
        </axis>
      </joint>
      <link name='gripper_right_inner_finger_left_link'>
        <pose relative_to='gripper_right_inner_finger_left_joint'>0 0 0 0 -0 0</pose>
        <inertial>
          <pose>-0 0.024759 0 0 -0 0</pose>
          <mass>0.018619</mass>
          <inertia>
            <ixx>4.8806e-06</ixx>
            <ixy>-7.6762e-22</ixy>
            <ixz>1.0244e-22</ixz>
            <iyy>2.5471e-07</iyy>
            <iyz>-1.1841e-21</iyz>
            <izz>4.9573e-06</izz>
          </inertia>
        </inertial>
        <collision name='gripper_right_inner_finger_left_link_collision'>
          <pose>0 0 0 0 -0 0</pose>
          <geometry>
            <mesh>
              <scale>1 1 1</scale>
              <uri>model://pal_pro_gripper_description/meshes/inner_finger.stl</uri>
            </mesh>
          </geometry>
          <surface>
            <contact>
              <ode/>
            </contact>
            <friction>
              <ode>
                <mu>0.9</mu>
                <mu2>0.9</mu2>
              </ode>
              <torsional>
                <ode/>
              </torsional>
            </friction>
            <bounce/>
          </surface>
          <max_contacts>10</max_contacts>
        </collision>
        <visual name='gripper_right_inner_finger_left_link_visual'>
          <pose>0 0 0 0 -0 0</pose>
          <geometry>
            <mesh>
              <scale>1 1 1</scale>
              <uri>model://pal_pro_gripper_description/meshes/inner_finger.stl</uri>
            </mesh>
          </geometry>
          <material>
            <script>
              <name>Gazebo/White</name>
              <uri>file://media/materials/scripts/gazebo.material</uri>
            </script>
          </material>
        </visual>
        <self_collide>0</self_collide>
        <enable_wind>0</enable_wind>
        <kinematic>0</kinematic>
      </link>
      <joint name='gripper_right_fingertip_left_joint' type='revolute'>
        <pose relative_to='gripper_right_inner_finger_left_link'>0 0.05 0 0 -0 0.837758</pose>
        <parent>gripper_right_inner_finger_left_link</parent>
        <child>gripper_right_fingertip_left_link</child>
        <axis>
          <xyz>0 0 1</xyz>
          <limit>
            <lower>-0.925025</lower>
            <upper>0</upper>
            <effort>0.1</effort>
            <velocity>2</velocity>
          </limit>
          <dynamics>
            <spring_reference>0</spring_reference>
            <spring_stiffness>0</spring_stiffness>
          </dynamics>
        </axis>
      </joint>
      <link name='gripper_right_fingertip_left_link'>
        <pose relative_to='gripper_right_fingertip_left_joint'>0 0 0 0 -0 0</pose>
        <inertial>
          <pose>-0.0007 0.01167 0 0 -0 0</pose>
          <mass>0.03266</mass>
          <inertia>
            <ixx>3.6361e-06</ixx>
            <ixy>3.4071e-07</ixy>
            <ixz>-1.4191e-14</ixz>
            <iyy>1.707e-06</iyy>
            <iyz>-3.3433e-14</iyz>
            <izz>2.8395e-06</izz>
          </inertia>
        </inertial>
        <collision name='gripper_right_fingertip_left_link_collision'>
          <pose>0 0 0 0 -0 0</pose>
          <geometry>
            <mesh>
              <scale>1 1 1</scale>
              <uri>model://pal_pro_gripper_description/meshes/fingertip.stl</uri>
            </mesh>
          </geometry>
          <surface>
            <contact>
              <ode/>
            </contact>
            <friction>
              <ode>
                <mu>0.9</mu>
                <mu2>0.9</mu2>
              </ode>
              <torsional>
                <ode/>
              </torsional>
            </friction>
            <bounce/>
          </surface>
          <max_contacts>10</max_contacts>
        </collision>
        <visual name='gripper_right_fingertip_left_link_visual'>
          <pose>0 0 0 0 -0 0</pose>
          <geometry>
            <mesh>
              <scale>1 1 1</scale>
              <uri>model://pal_pro_gripper_description/meshes/fingertip.stl</uri>
            </mesh>
          </geometry>
          <material>
            <script>
              <name>Gazebo/White</name>
              <uri>file://media/materials/scripts/gazebo.material</uri>
            </script>
          </material>
        </visual>
        <self_collide>0</self_collide>
        <enable_wind>0</enable_wind>
        <kinematic>0</kinematic>
      </link>
      <joint name='gripper_right_inner_finger_right_joint' type='revolute'>
        <pose relative_to='arm_right_7_link'>0 0.013977 0.153432 1.5708 0.837758 1.5708</pose>
        <parent>arm_right_7_link</parent>
        <child>gripper_right_inner_finger_right_link</child>
        <axis>
          <xyz>0 0 1</xyz>
          <limit>
            <lower>0</lower>
            <upper>0.925025</upper>
            <effort>0.1</effort>
            <velocity>2</velocity>
          </limit>
          <dynamics>
            <spring_reference>0</spring_reference>
            <spring_stiffness>0</spring_stiffness>
          </dynamics>
        </axis>
      </joint>
      <link name='gripper_right_inner_finger_right_link'>
        <pose relative_to='gripper_right_inner_finger_right_joint'>0 0 0 0 -0 0</pose>
        <inertial>
          <pose>-0 0.024759 0 0 -0 0</pose>
          <mass>0.018619</mass>
          <inertia>
            <ixx>4.8806e-06</ixx>
            <ixy>-7.6762e-22</ixy>
            <ixz>1.0244e-22</ixz>
            <iyy>2.5471e-07</iyy>
            <iyz>-1.1841e-21</iyz>
            <izz>4.9573e-06</izz>
          </inertia>
        </inertial>
        <collision name='gripper_right_inner_finger_right_link_collision'>
          <pose>0 0 0 0 -0 0</pose>
          <geometry>
            <mesh>
              <scale>1 1 1</scale>
              <uri>model://pal_pro_gripper_description/meshes/inner_finger.stl</uri>
            </mesh>
          </geometry>
          <surface>
            <contact>
              <ode/>
            </contact>
            <friction>
              <ode>
                <mu>0.9</mu>
                <mu2>0.9</mu2>
              </ode>
              <torsional>
                <ode/>
              </torsional>
            </friction>
            <bounce/>
          </surface>
          <max_contacts>10</max_contacts>
        </collision>
        <visual name='gripper_right_inner_finger_right_link_visual'>
          <pose>0 0 0 0 -0 0</pose>
          <geometry>
            <mesh>
              <scale>1 1 1</scale>
              <uri>model://pal_pro_gripper_description/meshes/inner_finger.stl</uri>
            </mesh>
          </geometry>
          <material>
            <script>
              <name>Gazebo/White</name>
              <uri>file://media/materials/scripts/gazebo.material</uri>
            </script>
          </material>
        </visual>
        <self_collide>0</self_collide>
        <enable_wind>0</enable_wind>
        <kinematic>0</kinematic>
      </link>
      <joint name='gripper_right_fingertip_right_joint' type='revolute'>
        <pose relative_to='gripper_right_inner_finger_right_link'>0 0.05 0 0 -0 0.837758</pose>
        <parent>gripper_right_inner_finger_right_link</parent>
        <child>gripper_right_fingertip_right_link</child>
        <axis>
          <xyz>0 0 1</xyz>
          <limit>
            <lower>-0.925025</lower>
            <upper>0</upper>
            <effort>0.1</effort>
            <velocity>2</velocity>
          </limit>
          <dynamics>
            <spring_reference>0</spring_reference>
            <spring_stiffness>0</spring_stiffness>
          </dynamics>
        </axis>
      </joint>
      <link name='gripper_right_fingertip_right_link'>
        <pose relative_to='gripper_right_fingertip_right_joint'>0 0 0 0 -0 0</pose>
        <inertial>
          <pose>-0.0007 0.01167 0 0 -0 0</pose>
          <mass>0.03266</mass>
          <inertia>
            <ixx>3.6361e-06</ixx>
            <ixy>3.4071e-07</ixy>
            <ixz>-1.4191e-14</ixz>
            <iyy>1.707e-06</iyy>
            <iyz>-3.3433e-14</iyz>
            <izz>2.8395e-06</izz>
          </inertia>
        </inertial>
        <collision name='gripper_right_fingertip_right_link_collision'>
          <pose>0 0 0 0 -0 0</pose>
          <geometry>
            <mesh>
              <scale>1 1 1</scale>
              <uri>model://pal_pro_gripper_description/meshes/fingertip.stl</uri>
            </mesh>
          </geometry>
          <surface>
            <contact>
              <ode/>
            </contact>
            <friction>
              <ode>
                <mu>0.9</mu>
                <mu2>0.9</mu2>
              </ode>
              <torsional>
                <ode/>
              </torsional>
            </friction>
            <bounce/>
          </surface>
          <max_contacts>10</max_contacts>
        </collision>
        <visual name='gripper_right_fingertip_right_link_visual'>
          <pose>0 0 0 0 -0 0</pose>
          <geometry>
            <mesh>
              <scale>1 1 1</scale>
              <uri>model://pal_pro_gripper_description/meshes/fingertip.stl</uri>
            </mesh>
          </geometry>
          <material>
            <script>
              <name>Gazebo/White</name>
              <uri>file://media/materials/scripts/gazebo.material</uri>
            </script>
          </material>
        </visual>
        <self_collide>0</self_collide>
        <enable_wind>0</enable_wind>
        <kinematic>0</kinematic>
      </link>
      <joint name='gripper_right_outer_finger_right_joint' type='revolute'>
        <pose relative_to='arm_right_7_link'>0 0.0288 0.1489 1.5708 0.837758 1.5708</pose>
        <parent>arm_right_7_link</parent>
        <child>gripper_right_outer_finger_right_link</child>
        <axis>
          <xyz>0 0 1</xyz>
          <limit>
            <lower>0</lower>
            <upper>0.925025</upper>
            <effort>0.1</effort>
            <velocity>2</velocity>
          </limit>
          <dynamics>
            <spring_reference>0</spring_reference>
            <spring_stiffness>0</spring_stiffness>
          </dynamics>
        </axis>
      </joint>
      <link name='gripper_right_outer_finger_right_link'>
        <pose relative_to='gripper_right_outer_finger_right_joint'>0 0 0 0 -0 0</pose>
        <inertial>
          <pose>-0.001283 0.014397 0 0 -0 0</pose>
          <mass>0.015989</mass>
          <inertia>
            <ixx>5.9879e-06</ixx>
            <ixy>-5.2173e-07</ixy>
            <ixz>5.9144e-23</ixz>
            <iyy>4.8725e-07</iyy>
            <iyz>7.3911e-23</iyz>
            <izz>6.1497e-06</izz>
          </inertia>
        </inertial>
        <collision name='gripper_right_outer_finger_right_link_collision'>
          <pose>0 0 0 0 -0 0</pose>
          <geometry>
            <mesh>
              <scale>1 1 1</scale>
              <uri>model://pal_pro_gripper_description/meshes/outer_finger.stl</uri>
            </mesh>
          </geometry>
          <surface>
            <contact>
              <ode/>
            </contact>
            <friction>
              <ode>
                <mu>0.9</mu>
                <mu2>0.9</mu2>
              </ode>
              <torsional>
                <ode/>
              </torsional>
            </friction>
            <bounce/>
          </surface>
          <max_contacts>10</max_contacts>
        </collision>
        <visual name='gripper_right_outer_finger_right_link_visual'>
          <pose>0 0 0 0 -0 0</pose>
          <geometry>
            <mesh>
              <scale>1 1 1</scale>
              <uri>model://pal_pro_gripper_description/meshes/outer_finger.stl</uri>
            </mesh>
          </geometry>
          <material>
            <script>
              <name>Gazebo/White</name>
              <uri>file://media/materials/scripts/gazebo.material</uri>
            </script>
          </material>
        </visual>
        <self_collide>0</self_collide>
        <enable_wind>0</enable_wind>
        <kinematic>0</kinematic>
      </link>
      <joint name='head_1_joint' type='revolute'>
        <pose relative_to='torso_lift_link'>0 0 0.04 0 -0 0</pose>
        <parent>torso_lift_link</parent>
        <child>head_1_link</child>
        <axis>
          <xyz>0 0 1</xyz>
          <limit>
            <lower>-0.959931</lower>
            <upper>0.959931</upper>
            <effort>5.197</effort>
            <velocity>3</velocity>
          </limit>
          <dynamics>
            <damping>0.5</damping>
            <friction>1</friction>
            <spring_reference>0</spring_reference>
            <spring_stiffness>0</spring_stiffness>
          </dynamics>
        </axis>
        <physics>
          <ode>
            <implicit_spring_damper>1</implicit_spring_damper>
            <cfm_damping>1</cfm_damping>
            <limit>
              <cfm>0</cfm>
              <erp>0.2</erp>
            </limit>
          </ode>
        </physics>
      </joint>
      <link name='head_1_link'>
        <pose relative_to='head_1_joint'>0 0 0 0 -0 0</pose>
        <inertial>
          <pose>0.013723 0.001529 0.091095 0 -0 0</pose>
          <mass>0.50253</mass>
          <inertia>
            <ixx>0.00073252</ixx>
            <ixy>-1.0801e-06</ixy>
            <ixz>-6.3715e-05</ixz>
            <iyy>0.0005861</iyy>
            <iyz>4.157e-10</iyz>
            <izz>0.00060232</izz>
          </inertia>
        </inertial>
        <collision name='head_1_link_collision'>
          <pose>0 0 0 0 -0 0</pose>
          <geometry>
            <mesh>
              <scale>1 1 1</scale>
              <uri>model://tiago_pro_description/meshes/head/head_1_link_collision.stl</uri>
            </mesh>
          </geometry>
          <surface>
            <contact>
              <ode/>
            </contact>
            <friction>
              <ode>
                <mu>0.9</mu>
                <mu2>0.9</mu2>
              </ode>
              <torsional>
                <ode/>
              </torsional>
            </friction>
            <bounce/>
          </surface>
          <max_contacts>10</max_contacts>
        </collision>
        <visual name='head_1_link_visual'>
          <pose>0 0 0 0 -0 0</pose>
          <geometry>
            <mesh>
              <scale>1 1 1</scale>
              <uri>model://tiago_pro_description/meshes/head/head_1_link.stl</uri>
            </mesh>
          </geometry>
          <material>
            <script>
              <name>Gazebo/DarkGrey</name>
              <uri>file://media/materials/scripts/gazebo.material</uri>
            </script>
          </material>
        </visual>
        <self_collide>0</self_collide>
        <enable_wind>0</enable_wind>
        <kinematic>0</kinematic>
      </link>
      <joint name='head_2_joint' type='revolute'>
        <pose relative_to='head_1_link'>0.04597 0 0.10075 1.5708 -0 0</pose>
        <parent>head_1_link</parent>
        <child>head_2_link</child>
        <axis>
          <xyz>0 0 1</xyz>
          <limit>
            <lower>-0.349066</lower>
            <upper>0.959931</upper>
            <effort>2.77</effort>
            <velocity>3</velocity>
          </limit>
          <dynamics>
            <damping>0.5</damping>
            <friction>1</friction>
            <spring_reference>0</spring_reference>
            <spring_stiffness>0</spring_stiffness>
          </dynamics>
        </axis>
        <physics>
          <ode>
            <implicit_spring_damper>1</implicit_spring_damper>
            <cfm_damping>1</cfm_damping>
            <limit>
              <cfm>0</cfm>
              <erp>0.2</erp>
            </limit>
          </ode>
        </physics>
      </joint>
      <link name='head_2_link'>
        <pose relative_to='head_2_joint'>0 0 0 0 -0 0</pose>
        <inertial>
          <pose>0.00519 0.117283 -0.000783 0 -0 0</pose>
          <mass>1.2813</mass>
          <inertia>
            <ixx>0.0104115</ixx>
            <ixy>0.000378721</ixy>
            <ixz>4.70847e-05</ixz>
            <iyy>0.00864113</iyy>
            <iyz>6.41262e-05</iyz>
            <izz>0.00398239</izz>
          </inertia>
        </inertial>
        <collision name='head_2_link_collision'>
          <pose>0 0 0 0 -0 0</pose>
          <geometry>
            <mesh>
              <scale>1 1 1</scale>
              <uri>model://tiago_pro_description/meshes/head/head_2_link_collision.stl</uri>
            </mesh>
          </geometry>
          <surface>
            <contact>
              <ode/>
            </contact>
            <friction>
              <ode>
                <mu>0.9</mu>
                <mu2>0.9</mu2>
              </ode>
              <torsional>
                <ode/>
              </torsional>
            </friction>
            <bounce/>
          </surface>
          <max_contacts>10</max_contacts>
        </collision>
        <collision name='head_2_link_fixed_joint_lump__head_front_camera_link_collision_1'>
          <pose>0.04875 0.16 0 -1.5708 0 0</pose>
          <geometry>
            <box>
              <size>0.02505 0.09 0.025</size>
            </box>
          </geometry>
          <surface>
            <contact>
              <ode>
                <kp>1e+13</kp>
                <kd>1</kd>
              </ode>
            </contact>
            <friction>
              <ode>
                <mu2>1</mu2>
                <fdir1>0 0 0</fdir1>
              </ode>
              <torsional>
                <ode/>
              </torsional>
            </friction>
            <bounce/>
          </surface>
          <max_contacts>10</max_contacts>
        </collision>
        <visual name='head_2_link_visual'>
          <pose>0 0 0 0 -0 0</pose>
          <geometry>
            <mesh>
              <scale>1 1 1</scale>
              <uri>model://tiago_pro_description/meshes/head/head_2_link.stl</uri>
            </mesh>
          </geometry>
          <material>
            <script>
              <name>Gazebo/White</name>
              <uri>file://media/materials/scripts/gazebo.material</uri>
            </script>
          </material>
        </visual>
        <visual name='head_2_link_fixed_joint_lump__head_front_camera_link_visual_1'>
          <pose>0.05305 0.16 0 3.14159 1.57079 3.14159</pose>
          <geometry>
            <mesh>
              <scale>1 1 1</scale>
              <uri>file:///opt/pal/alum/share/realsense2_description/meshes/d435.dae</uri>
            </mesh>
          </geometry>
        </visual>
        <self_collide>0</self_collide>
        <enable_wind>0</enable_wind>
        <kinematic>0</kinematic>
        <gravity>1</gravity>
        <sensor name='head_front_cameracolor' type='camera'>
          <camera name='head_front_camera'>
            <horizontal_fov>1.21126</horizontal_fov>
            <image>
              <width>640</width>
              <height>480</height>
              <format>RGB_INT8</format>
            </image>
            <clip>
              <near>0.1</near>
              <far>100</far>
            </clip>
            <noise>
              <type>gaussian</type>
              <mean>0</mean>
              <stddev>0.007</stddev>
            </noise>
          </camera>
          <always_on>1</always_on>
          <update_rate>30</update_rate>
          <visualize>1</visualize>
          <pose>0.04875 0.16 -0.0175 -1.5708 0 0</pose>
        </sensor>
        <sensor name='head_front_cameraired1' type='camera'>
          <camera name='head_front_camera'>
            <horizontal_fov>1.48702</horizontal_fov>
            <image>
              <width>1280</width>
              <height>720</height>
              <format>L_INT8</format>
            </image>
            <clip>
              <near>0.1</near>
              <far>100</far>
            </clip>
            <noise>
              <type>gaussian</type>
              <mean>0</mean>
              <stddev>0.05</stddev>
            </noise>
          </camera>
          <always_on>1</always_on>
          <update_rate>90</update_rate>
          <visualize>0</visualize>
          <pose>0.04875 0.16 -0.0175 -1.5708 0 0</pose>
        </sensor>
        <sensor name='head_front_cameraired2' type='camera'>
          <camera name='head_front_camera'>
            <horizontal_fov>1.48702</horizontal_fov>
            <image>
              <width>1280</width>
              <height>720</height>
              <format>L_INT8</format>
            </image>
            <clip>
              <near>0.1</near>
              <far>100</far>
            </clip>
            <noise>
              <type>gaussian</type>
              <mean>0</mean>
              <stddev>0.05</stddev>
            </noise>
          </camera>
          <always_on>1</always_on>
          <update_rate>90</update_rate>
          <visualize>0</visualize>
          <pose>0.04875 0.16 -0.0175 -1.5708 0 0</pose>
        </sensor>
        <sensor name='head_front_cameradepth' type='depth'>
          <camera name='head_front_camera'>
            <horizontal_fov>1.48702</horizontal_fov>
            <image>
              <width>1280</width>
              <height>720</height>
            </image>
            <clip>
              <near>0.1</near>
              <far>100</far>
            </clip>
            <noise>
              <type>gaussian</type>
              <mean>0</mean>
              <stddev>0.1</stddev>
            </noise>
          </camera>
          <always_on>1</always_on>
          <update_rate>90</update_rate>
          <visualize>0</visualize>
          <pose>0.04875 0.16 -0.0175 -1.5708 0 0</pose>
        </sensor>
      </link>
      <plugin name='gazebo_ros2_control' filename='libgazebo_ros2_control.so'>
        <parameters>/opt/pal/alum/share/tiago_pro_controller_configuration/config/gazebo_controller_manager_cfg.yaml</parameters>
      </plugin>
      <plugin name='gazebo_ros_planar_move' filename='libgazebo_ros_planar_move.so'>
        <ros>
          <remapping>cmd_vel:=mobile_base_controller/cmd_vel_unstamped</remapping>
          <remapping>odom:=mobile_base_controller/odom</remapping>
        </ros>
        <update_rate>50</update_rate>
        <publish_rate>50</publish_rate>
        <publish_odom>1</publish_odom>
        <publish_odom_tf>0</publish_odom_tf>
        <odometry_frame>odom</odometry_frame>
        <robot_base_frame>base_footprint</robot_base_frame>
        <covariance_x>0.0001</covariance_x>
        <covariance_y>0.0001</covariance_y>
        <covariance_yaw>0.01</covariance_yaw>
      </plugin>
      <static>0</static>
      <plugin name='head_front_camera' filename='librealsense_gazebo_plugin.so'>
        <prefix>head_front_camera</prefix>
        <depthUpdateRate>30.0</depthUpdateRate>
        <colorUpdateRate>30.0</colorUpdateRate>
        <infraredUpdateRate>30.0</infraredUpdateRate>
        <depthTopicName>depth/image_raw</depthTopicName>
        <colorTopicName>color/image_raw</colorTopicName>
        <infrared1TopicName>infra1/image_raw</infrared1TopicName>
        <infrared2TopicName>infra2/image_raw</infrared2TopicName>
        <colorOpticalframeName>head_front_camera_color_optical_frame</colorOpticalframeName>
        <depthOpticalframeName>head_front_camera_depth_optical_frame</depthOpticalframeName>
        <infrared1OpticalframeName>head_front_camera_infra1_ir_optical_frame</infrared1OpticalframeName>
        <infrared2OpticalframeName>head_front_camera_infra2_ir_optical_frame</infrared2OpticalframeName>
        <rangeMinDepth>0.2</rangeMinDepth>
        <rangeMaxDepth>10.0</rangeMaxDepth>
        <pointCloud>1</pointCloud>
        <pointCloudTopicName>depth/color/points</pointCloudTopicName>
        <pointCloudCutoff>0.25</pointCloudCutoff>
        <pointCloudCutoffMax>9.0</pointCloudCutoffMax>
      </plugin>
      <pose>0 0 0 0 -0 0</pose>
    </model>
    <model name='MaleVisitorSit'>
      <static>1</static>
      <link name='body'>
        <pose>0 0 0 0 -0 0</pose>
        <visual name='visual'>
          <geometry>
            <mesh>
              <uri>model://MaleVisitorSit/meshes/MaleVisitorSit.obj</uri>
            </mesh>
          </geometry>
        </visual>
        <collision name='collision'>
          <geometry>
            <mesh>
              <uri>model://MaleVisitorSit/meshes/MaleVisitorSit_Col.obj</uri>
            </mesh>
          </geometry>
          <max_contacts>10</max_contacts>
          <surface>
            <contact>
              <ode/>
            </contact>
            <bounce/>
            <friction>
              <torsional>
                <ode/>
              </torsional>
              <ode/>
            </friction>
          </surface>
        </collision>
        <self_collide>0</self_collide>
        <enable_wind>0</enable_wind>
        <kinematic>0</kinematic>
      </link>
      <pose>3.08988 -0.03417 0 0 -0 0</pose>
    </model>
    <model name='ikea_folke_chair'>
      <link name='link'>
        <inertial>
          <mass>10</mass>
          <inertia>
            <ixx>0</ixx>
            <ixy>0</ixy>
            <ixz>0</ixz>
            <iyy>0</iyy>
            <iyz>0</iyz>
            <izz>0.1</izz>
          </inertia>
          <pose>0 0 0 0 -0 0</pose>
        </inertial>
        <collision name='collision'>
          <pose>0 0 0 0 -0 1.6</pose>
          <geometry>
            <mesh>
              <uri>model://ikea_folke_chair/meshes/mesh.dae</uri>
            </mesh>
          </geometry>
          <max_contacts>10</max_contacts>
          <surface>
            <contact>
              <ode/>
            </contact>
            <bounce/>
            <friction>
              <torsional>
                <ode/>
              </torsional>
              <ode/>
            </friction>
          </surface>
        </collision>
        <visual name='visual'>
          <pose>0 0 0 0 -0 1.6</pose>
          <geometry>
            <mesh>
              <uri>model://ikea_folke_chair/meshes/mesh.dae</uri>
            </mesh>
          </geometry>
        </visual>
        <self_collide>0</self_collide>
        <enable_wind>0</enable_wind>
        <kinematic>0</kinematic>
      </link>
      <pose>1.70465 -0.344615 0 0 -0 0</pose>
    </model>
    <model name='aws_robomaker_hospital_curtain_half_open_01'>
      <link name='link'>
        <visual name='visual'>
          <geometry>
            <mesh>
              <uri>model://aws_robomaker_hospital_curtain_half_open_01/meshes/aws_robomaker_hospital_curtain_half_open_01_visual.dae</uri>
            </mesh>
          </geometry>
        </visual>
        <collision name='collision'>
          <geometry>
            <mesh>
              <uri>model://aws_robomaker_hospital_curtain_half_open_01/meshes/aws_robomaker_hospital_curtain_half_open_01_collision.dae</uri>
            </mesh>
          </geometry>
          <max_contacts>10</max_contacts>
          <surface>
            <contact>
              <ode/>
            </contact>
            <bounce/>
            <friction>
              <torsional>
                <ode/>
              </torsional>
              <ode/>
            </friction>
          </surface>
        </collision>
        <self_collide>0</self_collide>
        <enable_wind>0</enable_wind>
        <kinematic>0</kinematic>
      </link>
      <static>1</static>
      <pose>0.010711 -0.259997 0 0 -0 0</pose>
    </model>
    <model name='aws_robomaker_hospital_curtain_half_open_01_0'>
      <link name='link'>
        <visual name='visual'>
          <geometry>
            <mesh>
              <uri>model://aws_robomaker_hospital_curtain_half_open_01/meshes/aws_robomaker_hospital_curtain_half_open_01_visual.dae</uri>
            </mesh>
          </geometry>
        </visual>
        <collision name='collision'>
          <geometry>
            <mesh>
              <uri>model://aws_robomaker_hospital_curtain_half_open_01/meshes/aws_robomaker_hospital_curtain_half_open_01_collision.dae</uri>
            </mesh>
          </geometry>
          <max_contacts>10</max_contacts>
          <surface>
            <contact>
              <ode/>
            </contact>
            <bounce/>
            <friction>
              <torsional>
                <ode/>
              </torsional>
              <ode/>
            </friction>
          </surface>
        </collision>
        <self_collide>0</self_collide>
        <enable_wind>0</enable_wind>
        <kinematic>0</kinematic>
      </link>
      <static>1</static>
      <pose>2.33827 -0.32409 0 0 -0 0</pose>
    </model>
    <state world_name='default'>
      <sim_time>1546 452000000</sim_time>
      <real_time>2759 202869489</real_time>
      <wall_time>1734372483 433327215</wall_time>
      <iterations>1546452</iterations>
      <model name='MaleVisitorSit'>
        <pose>2.90879 -0.301217 0.081455 0 -0 1.54405</pose>
        <scale>1 1 1</scale>
        <link name='body'>
          <pose>2.90879 -0.301217 0.081455 0 -0 1.54405</pose>
          <velocity>0 0 0 0 -0 0</velocity>
          <acceleration>0 0 0 0 -0 0</acceleration>
          <wrench>0 0 0 0 -0 0</wrench>
        </link>
      </model>
      <model name='aws_robomaker_hospital_curtain_half_open_01'>
        <pose>0.01642 0.457761 0 0 0 -1.57875</pose>
        <scale>1 1 1</scale>
        <link name='link'>
          <pose>0.01642 0.457761 0 0 0 -1.57875</pose>
          <velocity>0 0 0 0 -0 0</velocity>
          <acceleration>0 0 0 0 -0 0</acceleration>
          <wrench>0 0 0 0 -0 0</wrench>
        </link>
      </model>
      <model name='aws_robomaker_hospital_curtain_half_open_01_0'>
        <pose>2.66653 0.448761 -0.017834 0 0 -1.56823</pose>
        <scale>1 1 1</scale>
        <link name='link'>
          <pose>2.66653 0.448761 -0.017834 0 0 -1.56823</pose>
          <velocity>0 0 0 0 -0 0</velocity>
          <acceleration>0 0 0 0 -0 0</acceleration>
          <wrench>0 0 0 0 -0 0</wrench>
        </link>
      </model>
      <model name='ground_plane'>
        <pose>0 0 0 0 -0 0</pose>
        <scale>1 1 1</scale>
        <link name='link'>
          <pose>0 0 0 0 -0 0</pose>
          <velocity>0 0 0 0 -0 0</velocity>
          <acceleration>0 0 0 0 -0 0</acceleration>
          <wrench>0 0 0 0 -0 0</wrench>
        </link>
      </model>
      <model name='ikea_folke_chair'>
        <pose>2.933 -0.397572 0.001165 0.000129 -0.00376 1.51378</pose>
        <scale>1 1 1</scale>
        <link name='link'>
          <pose>2.933 -0.397572 0.001165 0.000129 -0.00376 1.51378</pose>
          <velocity>0 0 0 0 -0 0</velocity>
          <acceleration>0.002081 0.029118 0.57024 1.07461 0.007631 6.9e-05</acceleration>
          <wrench>0.020811 0.291175 5.7024 0 -0 0</wrench>
        </link>
      </model>
      <model name='tiago-pro'>
        <pose>-4.11362 -1.6732 -6.8e-05 3e-06 0 2.46003</pose>
        <scale>1 1 1</scale>
        <link name='arm_left_1_link'>
          <pose>-4.26458 -1.7557 0.753616 -2.0679 4e-06 1.23833</pose>
          <velocity>-0.000581 0.000597 -0.007697 -0.000204 0.00039 -0.000704</velocity>
          <acceleration>0.098113 -0.080046 -9.28417 -1.00108 0.319885 -0.568634</acceleration>
          <wrench>0.106119 -0.086578 -10.0418 0 -0 0</wrench>
        </link>
        <link name='arm_left_2_link'>
          <pose>-4.40512 -1.70718 0.650198 -1.5708 -0.497104 -0.332465</pose>
          <velocity>-0.000577 0.000681 -0.007655 -0.000725 -0.001356 -0.000686</velocity>
          <acceleration>0.182307 -0.085784 -9.48995 -0.50362 -1.38723 -0.240501</acceleration>
          <wrench>0.180856 -0.085102 -9.41441 0 -0 0</wrench>
        </link>
        <link name='arm_left_3_link'>
          <pose>-4.53876 -1.66104 0.596245 2.06781 -4.9e-05 -1.90318</pose>
          <velocity>-0.000463 0.000735 -0.007873 -0.000715 -0.001356 -0.00067</velocity>
          <acceleration>0.322079 -0.111255 -9.80732 -1.402 -1.32618 -0.16551</acceleration>
          <wrench>0.348361 -0.120334 -10.6076 0 -0 0</wrench>
        </link>
        <link name='arm_left_4_link'>
          <pose>-4.69733 -1.6063 0.528001 1.57074 -0.497008 -0.332348</pose>
          <velocity>-0.000323 0.000791 -0.008133 0.000213 0.001355 -0.000678</velocity>
          <acceleration>0.276796 -0.092407 -9.75846 -0.563066 1.34273 -0.695893</acceleration>
          <wrench>0.274592 -0.091671 -9.68078 0 -0 0</wrench>
        </link>
        <link name='arm_left_5_link'>
          <pose>-4.81296 -1.56639 0.438901 2.0678 -4.9e-05 -1.90318</pose>
          <velocity>-0.000409 0.000887 -0.007968 0.000503 0.001245 -0.000507</velocity>
          <acceleration>0.2108 -0.060305 -9.61311 0.113508 1.03196 -0.115645</acceleration>
          <wrench>0.11075 -0.031683 -5.05054 0 -0 0</wrench>
        </link>
        <link name='arm_left_6_link'>
          <pose>-4.96668 -1.51334 0.350695 1.57074 -0.497004 -0.332347</pose>
          <velocity>-0.000485 0.001008 -0.007751 -1.8e-05 -0.000259 -0.000512</velocity>
          <acceleration>0.21456 -0.05301 -9.60618 0.044071 -0.57765 0.026422</acceleration>
          <wrench>0.143165 -0.035371 -6.40972 0 -0 0</wrench>
        </link>
        <link name='arm_left_7_link'>
          <pose>-5.06356 -1.4799 0.295101 2.06779 -4.9e-05 -1.90318</pose>
          <velocity>-0.000453 0.001057 -0.007778 3.2e-05 -0.000274 -0.000486</velocity>
          <acceleration>0.245725 -0.056843 -9.66287 -0.20215 -0.511428 -0.045041</acceleration>
          <wrench>0.297882 -0.068908 -11.7139 0 -0 0</wrench>
        </link>
        <link name='arm_right_1_link'>
          <pose>-4.06401 -1.50847 0.753615 -2.0679 3e-06 0.540144</pose>
          <velocity>-0.000479 0.000497 -0.007699 -0.000148 0.000827 -0.000762</velocity>
          <acceleration>0.081143 -0.10225 -9.28919 -0.86485 1.32369 -0.846083</acceleration>
          <wrench>0.087765 -0.110593 -10.0472 0 -0 0</wrench>
        </link>
        <link name='arm_right_2_link'>
          <pose>-4.14047 -1.38096 0.650197 -1.57079 -0.497106 -1.03066</pose>
          <velocity>-0.000452 0.000537 -0.007658 -0.001728 -2.5e-05 -0.00072</velocity>
          <acceleration>0.133657 -0.167901 -9.49546 -1.28733 0.312978 -0.299197</acceleration>
          <wrench>0.132593 -0.166565 -9.41987 0 -0 0</wrench>
        </link>
        <link name='arm_right_3_link'>
          <pose>-4.21318 -1.2597 0.596244 2.06781 -4.5e-05 -2.60137</pose>
          <velocity>-0.000347 0.000494 -0.007872 -0.001529 -0.000352 -0.000508</velocity>
          <acceleration>0.206925 -0.289601 -9.80697 -1.98621 -0.135244 -0.215671</acceleration>
          <wrench>0.22381 -0.313232 -10.6072 0 -0 0</wrench>
        </link>
        <link name='arm_right_4_link'>
          <pose>-4.29946 -1.11583 0.528 1.57074 -0.497011 -1.03054</pose>
          <velocity>-0.000239 0.000425 -0.008128 0.000928 0.001158 -0.000513</velocity>
          <acceleration>0.166725 -0.256136 -9.75361 0.109089 1.37184 -0.597845</acceleration>
          <wrench>0.165398 -0.254097 -9.67597 0 -0 0</wrench>
        </link>
        <link name='arm_right_5_link'>
          <pose>-4.36238 -1.01094 0.438899 2.0678 -4.4e-05 -2.60137</pose>
          <velocity>-0.000279 0.000535 -0.007958 0.001071 0.000902 -0.000353</velocity>
          <acceleration>0.115011 -0.199301 -9.60321 0.727541 0.870353 -0.110125</acceleration>
          <wrench>0.060425 -0.104709 -5.04533 0 -0 0</wrench>
        </link>
        <link name='arm_right_6_link'>
          <pose>-4.44602 -0.871481 0.350692 1.57074 -0.497007 -1.03054</pose>
          <velocity>-0.000301 0.000655 -0.007735 -0.000352 6.2e-05 -0.00036</velocity>
          <acceleration>0.106198 -0.208249 -9.59592 -0.220226 -0.342787 0.227385</acceleration>
          <wrench>0.070861 -0.138954 -6.40288 0 -0 0</wrench>
        </link>
        <link name='arm_right_7_link'>
          <pose>-4.49874 -0.783585 0.295098 2.0678 -4.3e-05 -2.60137</pose>
          <velocity>-0.000272 0.000654 -0.007763 -0.000333 3.5e-05 -0.000346</velocity>
          <acceleration>0.112184 -0.241399 -9.65531 -0.611631 -0.098591 -0.053253</acceleration>
          <wrench>0.135996 -0.292638 -11.7047 0 -0 0</wrench>
        </link>
        <link name='base_footprint'>
          <pose>-4.11362 -1.6732 -6.8e-05 3e-06 0 2.46003</pose>
          <velocity>-0.00073 0.000671 0.000919 0.000186 0.000215 -0.000414</velocity>
          <acceleration>-0.05423 0.047022 -0.63802 -0.010669 -0.020298 0.012946</acceleration>
          <wrench>-3.00449 2.60515 -35.348 0 -0 0</wrench>
        </link>
        <link name='gripper_left_fingertip_left_link'>
          <pose>-5.20255 -1.43193 0.16334 -1.57089 1.07379 -0.332461</pose>
          <velocity>-0.000689 0.001225 -0.007688 -0.003445 -0.009852 -0.000501</velocity>
          <acceleration>0.051056 0.009139 -9.69066 -1.66468 0.479683 -1.06611</acceleration>
          <wrench>0.001667 0.000298 -0.316497 0 -0 0</wrench>
        </link>
        <link name='gripper_left_fingertip_right_link'>
          <pose>-5.24376 -1.4177 0.243712 -1.57069 -1.07381 2.80912</pose>
          <velocity>-0.000447 0.001159 -0.008039 0.004263 0.011827 -0.000476</velocity>
          <acceleration>0.144441 -0.013948 -9.81959 1.55237 0.727419 1.69832</acceleration>
          <wrench>0.004717 -0.000456 -0.320708 0 -0 0</wrench>
        </link>
        <link name='gripper_left_inner_finger_left_link'>
          <pose>-5.18475 -1.43807 0.20966 -1.57084 0.386046 -0.332398</pose>
          <velocity>-0.000409 0.001118 -0.007809 0.002126 0.006124 -0.000465</velocity>
          <acceleration>0.137174 -0.018672 -9.63503 -0.45547 -1.0589 -2.40903</acceleration>
          <wrench>0.002554 -0.000348 -0.179395 0 -0 0</wrench>
        </link>
        <link name='gripper_left_inner_finger_right_link'>
          <pose>-5.19735 -1.43372 0.234232 1.57053 -1.38004 -0.332118</pose>
          <velocity>-0.000413 0.001124 -0.007813 -0.001361 -0.004398 -0.000472</velocity>
          <acceleration>0.237781 -0.048545 -9.81984 0.427766 1.47165 -1.60413</acceleration>
          <wrench>0.004427 -0.000904 -0.182836 0 -0 0</wrench>
        </link>
        <link name='gripper_left_outer_finger_left_link'>
          <pose>-5.1743 -1.44167 0.198791 -1.57084 0.386041 -0.332398</pose>
          <velocity>-0.000408 0.001114 -0.007807 0.000452 0.00095 -0.000488</velocity>
          <acceleration>0.267715 -0.061098 -9.68229 0.121866 0.053352 -0.261416</acceleration>
          <wrench>0.00428 -0.000977 -0.15481 0 -0 0</wrench>
        </link>
        <link name='gripper_left_outer_finger_right_link'>
          <pose>-5.20026 -1.43271 0.249422 1.57053 -1.38004 -0.332115</pose>
          <velocity>-0.000418 0.001125 -0.007814 -0.000757 -0.002587 -0.000487</velocity>
          <acceleration>0.246304 -0.05149 -9.74531 1.91752 0.935234 -1.10292</acceleration>
          <wrench>0.003938 -0.000823 -0.155818 0 -0 0</wrench>
        </link>
        <link name='gripper_right_fingertip_left_link'>
          <pose>-4.57436 -0.657495 0.163336 -1.57087 1.07378 -1.03063</pose>
          <velocity>-0.000399 0.000917 -0.007669 -0.00954 -0.005547 -0.000338</velocity>
          <acceleration>-0.011115 -0.062462 -9.68452 1.64429 0.044161 2.40839</acceleration>
          <wrench>-0.000363 -0.00204 -0.316297 0 -0 0</wrench>
        </link>
        <link name='gripper_right_fingertip_right_link'>
          <pose>-4.59678 -0.620106 0.243709 -1.5707 -1.07381 2.11094</pose>
          <velocity>-0.000237 0.000709 -0.00804 0.011229 0.007042 -0.000349</velocity>
          <acceleration>0.04476 -0.146707 -9.82069 -0.207494 -1.29933 -1.64512</acceleration>
          <wrench>0.001462 -0.004791 -0.320744 0 -0 0</wrench>
        </link>
        <link name='gripper_right_inner_finger_left_link'>
          <pose>-4.56468 -0.673639 0.209657 -1.57083 0.386044 -1.03059</pose>
          <velocity>-0.000236 0.000648 -0.007797 0.005761 0.003649 -0.000351</velocity>
          <acceleration>0.040687 -0.142499 -9.62567 3.02918 0.042097 -0.469327</acceleration>
          <wrench>0.000758 -0.002653 -0.17922 0 -0 0</wrench>
        </link>
        <link name='gripper_right_inner_finger_right_link'>
          <pose>-4.57153 -0.662209 0.234229 1.57056 -1.38004 -1.03034</pose>
          <velocity>-0.00023 0.000659 -0.007801 -0.004314 -0.00229 -0.000351</velocity>
          <acceleration>0.10065 -0.235608 -9.8207 -2.55034 1.19609 -1.81418</acceleration>
          <wrench>0.001874 -0.004387 -0.182852 0 -0 0</wrench>
        </link>
        <link name='gripper_right_outer_finger_left_link'>
          <pose>-4.559 -0.683117 0.198788 -1.57083 0.386038 -1.03059</pose>
          <velocity>-0.00024 0.000643 -0.007795 0.000832 0.000738 -0.00035</velocity>
          <acceleration>0.114992 -0.266508 -9.67547 0.871521 -0.529191 2.05411</acceleration>
          <wrench>0.001839 -0.004261 -0.154701 0 -0 0</wrench>
        </link>
        <link name='gripper_right_outer_finger_right_link'>
          <pose>-4.57312 -0.659564 0.249419 1.57056 -1.38004 -1.03034</pose>
          <velocity>-0.00023 0.000665 -0.007802 -0.002554 -0.001312 -0.000347</velocity>
          <acceleration>0.105496 -0.243927 -9.74198 -1.99745 0.820599 1.96886</acceleration>
          <wrench>0.001687 -0.0039 -0.155765 0 -0 0</wrench>
        </link>
        <link name='head_1_link'>
          <pose>-4.09459 -1.68863 0.885623 2e-06 -0 2.46003</pose>
          <velocity>-0.000556 0.000509 -0.007715 0.000213 0.000269 -0.000485</velocity>
          <acceleration>0.063077 -0.064643 -9.27165 0.01266 0.013816 -0.059814</acceleration>
          <wrench>0.031698 -0.032485 -4.65928 0 -0 0</wrench>
        </link>
        <link name='head_2_link'>
          <pose>-4.13029 -1.65967 0.986373 1.5708 1e-06 2.46003</pose>
          <velocity>-0.000517 0.000506 -0.0077 -0.00027 -0.000329 -0.000483</velocity>
          <acceleration>-0.004962 -0.005319 -9.27603 -1.22758 -1.37831 -0.023511</acceleration>
          <wrench>-0.006358 -0.006815 -11.8854 0 -0 0</wrench>
        </link>
        <link name='torso_lift_link'>
          <pose>-4.09459 -1.68863 0.845623 3e-06 0 2.46003</pose>
          <velocity>-0.000552 0.000506 -0.007712 0.000194 0.00023 -0.00041</velocity>
          <acceleration>0.07928 -0.080261 -9.26901 -0.022153 -0.022268 0.014943</acceleration>
          <wrench>0.75689 -0.766254 -88.4912 0 -0 0</wrench>
        </link>
        <link name='wheel_front_left_link'>
          <pose>-4.44371 -1.69279 0.076133 1.5708 -0.011171 -0.681558</pose>
          <velocity>-0.000722 0.000794 0.000985 0.000216 0.000191 -0.000414</velocity>
          <acceleration>-0.05111 0.039713 -0.645002 0.015975 -0.041583 0.017158</acceleration>
          <wrench>-0.036169 0.028104 -0.456448 0 -0 0</wrench>
        </link>
        <link name='wheel_front_right_link'>
          <pose>-4.1625 -1.34616 0.076131 1.5708 0.035452 -0.681558</pose>
          <velocity>-0.000578 0.000677 0.000989 0.000162 0.000234 -0.000414</velocity>
          <acceleration>-0.056005 0.043716 -0.644845 -0.037988 0.00195 0.016787</acceleration>
          <wrench>-0.039633 0.030936 -0.456337 0 -0 0</wrench>
        </link>
        <link name='wheel_rear_left_link'>
          <pose>-4.06473 -2.00024 0.076132 1.5708 0.015164 -0.681558</pose>
          <velocity>-0.000849 0.000637 0.000848 0.000178 0.000221 -0.000414</velocity>
          <acceleration>-0.046547 0.045385 -0.631677 -0.022081 -0.011154 0.017081</acceleration>
          <wrench>-0.03294 0.032117 -0.447019 0 -0 0</wrench>
        </link>
        <link name='wheel_rear_right_link'>
          <pose>-3.78353 -1.6536 0.076131 1.5708 0.229711 -0.681558</pose>
          <velocity>-0.000705 0.00052 0.000852 0.000199 0.000203 -0.000414</velocity>
          <acceleration>-0.051456 0.049344 -0.631572 -0.000589 -0.028724 0.016734</acceleration>
          <wrench>-0.036414 0.034919 -0.446944 0 -0 0</wrench>
        </link>
      </model>
      <light name='sun'>
        <pose>0 0 10 0 -0 0</pose>
      </light>
    </state>
    <gui fullscreen='0'>
      <camera name='user_camera'>
        <pose>6.30337 -9.69229 4.15402 0 0.251643 2.11782</pose>
        <view_controller>orbit</view_controller>
        <projection_type>perspective</projection_type>
      </camera>
    </gui>
  </world>
</sdf>
