<sdf version='1.7'>
  <world name='default'>
    <light name='sun' type='directional'>
      <cast_shadows>1</cast_shadows>
      <pose>0 0 10 0 -0 0</pose>
      <diffuse>0.8 0.8 0.8 1</diffuse>
      <specular>0.2 0.2 0.2 1</specular>
      <attenuation>
        <range>1000</range>
        <constant>0.9</constant>
        <linear>0.01</linear>
        <quadratic>0.001</quadratic>
      </attenuation>
      <direction>-0.5 0.1 -0.9</direction>
      <spot>
        <inner_angle>0</inner_angle>
        <outer_angle>0</outer_angle>
        <falloff>0</falloff>
      </spot>
    </light>
    <model name='ground_plane'>
      <static>1</static>
      <link name='link'>
        <collision name='collision'>
          <geometry>
            <plane>
              <normal>0 0 1</normal>
              <size>100 100</size>
            </plane>
          </geometry>
          <surface>
            <friction>
              <ode>
                <mu>100</mu>
                <mu2>50</mu2>
              </ode>
              <torsional>
                <ode/>
              </torsional>
            </friction>
            <contact>
              <ode/>
            </contact>
            <bounce/>
          </surface>
          <max_contacts>10</max_contacts>
        </collision>
        <visual name='visual'>
          <cast_shadows>0</cast_shadows>
          <geometry>
            <plane>
              <normal>0 0 1</normal>
              <size>100 100</size>
            </plane>
          </geometry>
          <material>
            <script>
              <uri>file://media/materials/scripts/gazebo.material</uri>
              <name>Gazebo/Grey</name>
            </script>
          </material>
        </visual>
        <self_collide>0</self_collide>
        <enable_wind>0</enable_wind>
        <kinematic>0</kinematic>
      </link>
    </model>
    <gravity>0 0 -9.8</gravity>
    <magnetic_field>6e-06 2.3e-05 -4.2e-05</magnetic_field>
    <atmosphere type='adiabatic'/>
    <physics type='ode'>
      <max_step_size>0.001</max_step_size>
      <real_time_factor>1</real_time_factor>
      <real_time_update_rate>1000</real_time_update_rate>
    </physics>
    <scene>
      <ambient>0.4 0.4 0.4 1</ambient>
      <background>0.7 0.7 0.7 1</background>
      <shadows>1</shadows>
    </scene>
    <audio>
      <device>default</device>
    </audio>
    <wind/>
    <spherical_coordinates>
      <surface_model>EARTH_WGS84</surface_model>
      <latitude_deg>0</latitude_deg>
      <longitude_deg>0</longitude_deg>
      <elevation>0</elevation>
      <heading_deg>0</heading_deg>
    </spherical_coordinates>
    <model name='tiago-pro'>
      <link name='base_footprint'>
        <inertial>
          <pose>-0.004805 -0.001991 0.232434 0 -0 0</pose>
          <mass>55.4026</mass>
          <inertia>
            <ixx>1.45363</ixx>
            <ixy>0.0228042</ixy>
            <ixz>0.0765957</ixz>
            <iyy>1.81443</iyy>
            <iyz>0.0254408</iyz>
            <izz>0.983133</izz>
          </inertia>
        </inertial>
        <collision name='base_footprint_fixed_joint_lump__base_link_collision'>
          <pose>0 0 0.26545 0 -0 0</pose>
          <geometry>
            <box>
              <size>0.717 0.497 0.0845</size>
            </box>
          </geometry>
          <max_contacts>10</max_contacts>
          <surface>
            <contact>
              <ode/>
            </contact>
            <bounce/>
            <friction>
              <torsional>
                <ode/>
              </torsional>
              <ode/>
            </friction>
          </surface>
        </collision>
        <collision name='base_footprint_fixed_joint_lump__base_link_collision_1'>
          <pose>0 0 0.2082 0 -0 0</pose>
          <geometry>
            <box>
              <size>0.58 0.39 0.03</size>
            </box>
          </geometry>
          <max_contacts>10</max_contacts>
          <surface>
            <contact>
              <ode/>
            </contact>
            <bounce/>
            <friction>
              <torsional>
                <ode/>
              </torsional>
              <ode/>
            </friction>
          </surface>
        </collision>
        <collision name='base_footprint_fixed_joint_lump__base_link_collision_2'>
          <pose>0 0 0.1097 0 -0 0</pose>
          <geometry>
            <box>
              <size>0.705 0.48 0.167</size>
            </box>
          </geometry>
          <max_contacts>10</max_contacts>
          <surface>
            <contact>
              <ode/>
            </contact>
            <bounce/>
            <friction>
              <torsional>
                <ode/>
              </torsional>
              <ode/>
            </friction>
          </surface>
        </collision>
        <collision name='base_footprint_fixed_joint_lump__base_antenna_left_link_collision_3'>
          <pose>-0.2015 0.13 0.2927 0 -0 0</pose>
          <geometry>
            <mesh>
              <scale>1 -1 1</scale>
              <uri>model://omni_base_description/meshes/base/base_antena_link.stl</uri>
            </mesh>
          </geometry>
          <surface>
            <contact>
              <ode/>
            </contact>
            <friction>
              <ode/>
              <torsional>
                <ode/>
              </torsional>
            </friction>
            <bounce/>
          </surface>
          <max_contacts>10</max_contacts>
        </collision>
        <collision name='base_footprint_fixed_joint_lump__base_antenna_right_link_collision_4'>
          <pose>-0.2015 -0.13 0.2927 0 -0 0</pose>
          <geometry>
            <mesh>
              <scale>1 1 1</scale>
              <uri>model://omni_base_description/meshes/base/base_antena_link.stl</uri>
            </mesh>
          </geometry>
          <surface>
            <contact>
              <ode/>
            </contact>
            <friction>
              <ode/>
              <torsional>
                <ode/>
              </torsional>
            </friction>
            <bounce/>
          </surface>
          <max_contacts>10</max_contacts>
        </collision>
        <collision name='base_footprint_fixed_joint_lump__base_dock_link_collision_5'>
          <pose>0.3535 0 0.1358 0 -0 0</pose>
          <geometry>
            <mesh>
              <scale>1 1 1</scale>
              <uri>model://omni_base_description/meshes/base/base_dock_link.stl</uri>
            </mesh>
          </geometry>
          <max_contacts>10</max_contacts>
          <surface>
            <contact>
              <ode/>
            </contact>
            <bounce/>
            <friction>
              <torsional>
                <ode/>
              </torsional>
              <ode/>
            </friction>
          </surface>
        </collision>
        <collision name='base_footprint_fixed_joint_lump__base_front_laser_link_collision_6'>
          <pose>0.27512 -0.18297 0.20864 -3.14159 -0 -0.785398</pose>
          <geometry>
            <cylinder>
              <length>0.01</length>
              <radius>0.01</radius>
            </cylinder>
          </geometry>
          <surface>
            <contact>
              <ode/>
            </contact>
            <friction>
              <ode/>
              <torsional>
                <ode/>
              </torsional>
            </friction>
            <bounce/>
          </surface>
          <max_contacts>10</max_contacts>
        </collision>
        <collision name='base_footprint_fixed_joint_lump__base_rear_laser_link_collision_7'>
          <pose>-0.27512 0.18297 0.20864 -3.14159 -0 2.35619</pose>
          <geometry>
            <cylinder>
              <length>0.01</length>
              <radius>0.01</radius>
            </cylinder>
          </geometry>
          <surface>
            <contact>
              <ode/>
            </contact>
            <friction>
              <ode/>
              <torsional>
                <ode/>
              </torsional>
            </friction>
            <bounce/>
          </surface>
          <max_contacts>10</max_contacts>
        </collision>
        <collision name='base_footprint_fixed_joint_lump__suspension_front_left_link_collision_8'>
          <pose>0.244 0.1725 0.0762 0 -0 1.5708</pose>
          <geometry>
            <mesh>
              <scale>1 -1 1</scale>
              <uri>model://omni_base_description/meshes/wheels/suspension_front_link.stl</uri>
            </mesh>
          </geometry>
          <max_contacts>10</max_contacts>
          <surface>
            <contact>
              <ode/>
            </contact>
            <bounce/>
            <friction>
              <torsional>
                <ode/>
              </torsional>
              <ode/>
            </friction>
          </surface>
        </collision>
        <collision name='base_footprint_fixed_joint_lump__suspension_front_right_link_collision_9'>
          <pose>0.244 -0.1725 0.0762 0 0 -1.5708</pose>
          <geometry>
            <mesh>
              <scale>1 1 1</scale>
              <uri>model://omni_base_description/meshes/wheels/suspension_front_link.stl</uri>
            </mesh>
          </geometry>
          <max_contacts>10</max_contacts>
          <surface>
            <contact>
              <ode/>
            </contact>
            <bounce/>
            <friction>
              <torsional>
                <ode/>
              </torsional>
              <ode/>
            </friction>
          </surface>
        </collision>
        <collision name='base_footprint_fixed_joint_lump__suspension_rear_left_link_collision_10'>
          <pose>-0.244 0.1725 0.0762 0 -0 1.5708</pose>
          <geometry>
            <mesh>
              <scale>1 -1 1</scale>
              <uri>model://omni_base_description/meshes/wheels/suspension_rear_link.stl</uri>
            </mesh>
          </geometry>
          <max_contacts>10</max_contacts>
          <surface>
            <contact>
              <ode/>
            </contact>
            <bounce/>
            <friction>
              <torsional>
                <ode/>
              </torsional>
              <ode/>
            </friction>
          </surface>
        </collision>
        <collision name='base_footprint_fixed_joint_lump__suspension_rear_right_link_collision_11'>
          <pose>-0.244 -0.1725 0.0762 0 0 -1.5708</pose>
          <geometry>
            <mesh>
              <scale>1 1 1</scale>
              <uri>model://omni_base_description/meshes/wheels/suspension_rear_link.stl</uri>
            </mesh>
          </geometry>
          <max_contacts>10</max_contacts>
          <surface>
            <contact>
              <ode/>
            </contact>
            <bounce/>
            <friction>
              <torsional>
                <ode/>
              </torsional>
              <ode/>
            </friction>
          </surface>
        </collision>
        <collision name='base_footprint_fixed_joint_lump__torso_fixed_column_link_collision_12'>
          <pose>-0.028 0 0.5562 0 -0 0</pose>
          <geometry>
            <box>
              <size>0.23 0.253 0.45</size>
            </box>
          </geometry>
          <surface>
            <contact>
              <ode/>
            </contact>
            <friction>
              <ode/>
              <torsional>
                <ode/>
              </torsional>
            </friction>
            <bounce/>
          </surface>
          <max_contacts>10</max_contacts>
        </collision>
        <collision name='base_footprint_fixed_joint_lump__torso_fixed_link_collision_13'>
          <pose>-0.0245 0 0.3912 0 -0 0</pose>
          <geometry>
            <box>
              <size>0.23 0.253 0.2</size>
            </box>
          </geometry>
          <surface>
            <contact>
              <ode/>
            </contact>
            <friction>
              <ode/>
              <torsional>
                <ode/>
              </torsional>
            </friction>
            <bounce/>
          </surface>
          <max_contacts>10</max_contacts>
        </collision>
        <collision name='base_footprint_fixed_joint_lump__torso_fixed_link_collision_14'>
          <pose>0.1555 0 0.3212 0 -0 0</pose>
          <geometry>
            <box>
              <size>0.15 0.253 0.06</size>
            </box>
          </geometry>
          <surface>
            <contact>
              <ode/>
            </contact>
            <friction>
              <ode/>
              <torsional>
                <ode/>
              </torsional>
            </friction>
            <bounce/>
          </surface>
          <max_contacts>10</max_contacts>
        </collision>
        <collision name='base_footprint_fixed_joint_lump__torso_fixed_link_collision_15'>
          <pose>-0.1145 0 0.2912 0 -0 0</pose>
          <geometry>
            <box>
              <size>0.47 0.5 0.02</size>
            </box>
          </geometry>
          <surface>
            <contact>
              <ode/>
            </contact>
            <friction>
              <ode/>
              <torsional>
                <ode/>
              </torsional>
            </friction>
            <bounce/>
          </surface>
          <max_contacts>10</max_contacts>
        </collision>
        <visual name='base_footprint_fixed_joint_lump__base_link_visual'>
          <pose>0 0 0.0762 0 -0 0</pose>
          <geometry>
            <mesh>
              <scale>1 1 1</scale>
              <uri>model://omni_base_description/meshes/base/base_link.stl</uri>
            </mesh>
          </geometry>
        </visual>
        <visual name='base_footprint_fixed_joint_lump__base_antenna_left_link_visual_1'>
          <pose>-0.2015 0.13 0.2927 0 -0 0</pose>
          <geometry>
            <mesh>
              <scale>1 -1 1</scale>
              <uri>model://omni_base_description/meshes/base/base_antena_link.stl</uri>
            </mesh>
          </geometry>
          <material>
            <script>
              <name>Gazebo/Black</name>
              <uri>file://media/materials/scripts/gazebo.material</uri>
            </script>
          </material>
        </visual>
        <visual name='base_footprint_fixed_joint_lump__base_antenna_right_link_visual_2'>
          <pose>-0.2015 -0.13 0.2927 0 -0 0</pose>
          <geometry>
            <mesh>
              <scale>1 1 1</scale>
              <uri>model://omni_base_description/meshes/base/base_antena_link.stl</uri>
            </mesh>
          </geometry>
          <material>
            <script>
              <name>Gazebo/Black</name>
              <uri>file://media/materials/scripts/gazebo.material</uri>
            </script>
          </material>
        </visual>
        <visual name='base_footprint_fixed_joint_lump__base_dock_link_visual_3'>
          <pose>0.3535 0 0.1358 0 -0 0</pose>
          <geometry>
            <mesh>
              <scale>1 1 1</scale>
              <uri>model://omni_base_description/meshes/base/base_dock_link.stl</uri>
            </mesh>
          </geometry>
        </visual>
        <visual name='base_footprint_fixed_joint_lump__base_front_laser_link_visual_4'>
          <pose>0.27512 -0.18297 0.20864 -3.14159 -0 -0.785398</pose>
          <geometry>
            <mesh>
              <scale>1 1 1</scale>
              <uri>model://omni_base_description/meshes/sensors/sick_tim551.stl</uri>
            </mesh>
          </geometry>
          <material>
            <script>
              <name>Gazebo/DarkGrey</name>
              <uri>file://media/materials/scripts/gazebo.material</uri>
            </script>
          </material>
        </visual>
        <visual name='base_footprint_fixed_joint_lump__base_rear_laser_link_visual_5'>
          <pose>-0.27512 0.18297 0.20864 -3.14159 -0 2.35619</pose>
          <geometry>
            <mesh>
              <scale>1 1 1</scale>
              <uri>model://omni_base_description/meshes/sensors/sick_tim551.stl</uri>
            </mesh>
          </geometry>
          <material>
            <script>
              <name>Gazebo/DarkGrey</name>
              <uri>file://media/materials/scripts/gazebo.material</uri>
            </script>
          </material>
        </visual>
        <visual name='base_footprint_fixed_joint_lump__suspension_front_left_link_visual_6'>
          <pose>0.244 0.1725 0.0762 0 -0 1.5708</pose>
          <geometry>
            <mesh>
              <scale>1 -1 1</scale>
              <uri>model://omni_base_description/meshes/wheels/suspension_front_link.stl</uri>
            </mesh>
          </geometry>
        </visual>
        <visual name='base_footprint_fixed_joint_lump__suspension_front_right_link_visual_7'>
          <pose>0.244 -0.1725 0.0762 0 0 -1.5708</pose>
          <geometry>
            <mesh>
              <scale>1 1 1</scale>
              <uri>model://omni_base_description/meshes/wheels/suspension_front_link.stl</uri>
            </mesh>
          </geometry>
        </visual>
        <visual name='base_footprint_fixed_joint_lump__suspension_rear_left_link_visual_8'>
          <pose>-0.244 0.1725 0.0762 0 -0 1.5708</pose>
          <geometry>
            <mesh>
              <scale>1 -1 1</scale>
              <uri>model://omni_base_description/meshes/wheels/suspension_rear_link.stl</uri>
            </mesh>
          </geometry>
        </visual>
        <visual name='base_footprint_fixed_joint_lump__suspension_rear_right_link_visual_9'>
          <pose>-0.244 -0.1725 0.0762 0 0 -1.5708</pose>
          <geometry>
            <mesh>
              <scale>1 1 1</scale>
              <uri>model://omni_base_description/meshes/wheels/suspension_rear_link.stl</uri>
            </mesh>
          </geometry>
        </visual>
        <visual name='base_footprint_fixed_joint_lump__torso_fixed_column_link_visual_10'>
          <pose>-0.028 0 0.5562 0 -0 0</pose>
          <geometry>
            <box>
              <size>0.18 0.2 0.55</size>
            </box>
          </geometry>
          <material>
            <script>
              <name>Gazebo/DarkGrey</name>
              <uri>file://media/materials/scripts/gazebo.material</uri>
            </script>
          </material>
        </visual>
        <visual name='base_footprint_fixed_joint_lump__torso_fixed_link_visual_11'>
          <pose>-0.0245 0 0.2912 0 -0 0</pose>
          <geometry>
            <mesh>
              <scale>1 1 1</scale>
              <uri>model://tiago_pro_description/meshes/torso/torso_fixed_link.stl</uri>
            </mesh>
          </geometry>
          <material>
            <script>
              <name>Gazebo/DarkGrey</name>
              <uri>file://media/materials/scripts/gazebo.material</uri>
            </script>
          </material>
        </visual>
        <sensor name='base_front_laser' type='gpu_ray'>
          <update_rate>10</update_rate>
          <visualize>1</visualize>
          <ray>
            <scan>
              <horizontal>
                <samples>818</samples>
                <resolution>1</resolution>
                <min_angle>-2.35619</min_angle>
                <max_angle>2.35619</max_angle>
              </horizontal>
              <vertical>
                <samples>1</samples>
                <min_angle>0</min_angle>
                <max_angle>0</max_angle>
              </vertical>
            </scan>
            <range>
              <min>0.05</min>
              <max>25</max>
              <resolution>0.001</resolution>
            </range>
            <noise>
              <type>gaussian</type>
              <mean>0</mean>
              <stddev>0.01</stddev>
            </noise>
          </ray>
          <plugin name='base_front_laser' filename='libgazebo_ros_ray_sensor.so'>
            <ros>
              <remapping>~/out:=scan_front_raw</remapping>
            </ros>
            <output_type>sensor_msgs/LaserScan</output_type>
            <frame_name>base_front_laser_link</frame_name>
          </plugin>
          <pose>0.27512 -0.18297 0.20864 -3.14159 -0 -0.785398</pose>
        </sensor>
        <sensor name='imu_sensor' type='imu'>
          <always_on>1</always_on>
          <update_rate>10</update_rate>
          <imu>
            <noise>
              <type>gaussian</type>
              <rate>
                <mean>0.0</mean>
                <stddev>2e-4</stddev>
                <bias_mean>0.0000075</bias_mean>
                <bias_stddev>0.0000008</bias_stddev>
              </rate>
              <accel>
                <mean>0.0</mean>
                <stddev>1.7e-2</stddev>
                <bias_mean>0.1</bias_mean>
                <bias_stddev>0.001</bias_stddev>
              </accel>
            </noise>
          </imu>
          <plugin name='base_imu' filename='libgazebo_ros_imu_sensor.so'>
            <ros>
              <remapping>~/out:=base_imu</remapping>
            </ros>
          </plugin>
          <pose>-0.287 0 0.168363 0 -0 1.5708</pose>
        </sensor>
        <sensor name='base_imu_sensor' type='imu'>
          <always_on>1</always_on>
          <update_rate>100</update_rate>
          <imu>
            <noise>
              <type>gaussian</type>
              <rate>
                <mean>0.0</mean>
                <stddev>2e-4</stddev>
                <bias_mean>0.0000075</bias_mean>
                <bias_stddev>0.0000008</bias_stddev>
              </rate>
              <accel>
                <mean>0.0</mean>
                <stddev>1.7e-2</stddev>
                <bias_mean>0.1</bias_mean>
                <bias_stddev>0.001</bias_stddev>
              </accel>
            </noise>
          </imu>
          <pose>-0.287 0 0.168363 0 -0 1.5708</pose>
        </sensor>
        <sensor name='base_rear_laser' type='gpu_ray'>
          <update_rate>10</update_rate>
          <visualize>1</visualize>
          <ray>
            <scan>
              <horizontal>
                <samples>818</samples>
                <resolution>1</resolution>
                <min_angle>-2.35619</min_angle>
                <max_angle>2.35619</max_angle>
              </horizontal>
              <vertical>
                <samples>1</samples>
                <min_angle>0</min_angle>
                <max_angle>0</max_angle>
              </vertical>
            </scan>
            <range>
              <min>0.05</min>
              <max>25</max>
              <resolution>0.001</resolution>
            </range>
            <noise>
              <type>gaussian</type>
              <mean>0</mean>
              <stddev>0.01</stddev>
            </noise>
          </ray>
          <plugin name='base_rear_laser' filename='libgazebo_ros_ray_sensor.so'>
            <ros>
              <remapping>~/out:=scan_rear_raw</remapping>
            </ros>
            <output_type>sensor_msgs/LaserScan</output_type>
            <frame_name>base_rear_laser_link</frame_name>
          </plugin>
          <pose>-0.27512 0.18297 0.20864 -3.14159 -0 2.35619</pose>
        </sensor>
        <self_collide>0</self_collide>
        <enable_wind>0</enable_wind>
        <kinematic>0</kinematic>
      </link>
      <joint name='wheel_front_left_joint' type='revolute'>
        <pose relative_to='base_footprint'>0.244 0.223175 0.0762 -1.5708 0 0</pose>
        <parent>base_footprint</parent>
        <child>wheel_front_left_link</child>
        <axis>
          <xyz>0 0 1</xyz>
          <limit>
            <effort>6</effort>
            <velocity>13.1234</velocity>
            <lower>-1e+16</lower>
            <upper>1e+16</upper>
          </limit>
          <dynamics>
            <damping>1</damping>
            <friction>2</friction>
            <spring_reference>0</spring_reference>
            <spring_stiffness>0</spring_stiffness>
          </dynamics>
        </axis>
      </joint>
      <link name='wheel_front_left_link'>
        <pose relative_to='wheel_front_left_joint'>0 0 0 0 -0 0</pose>
        <inertial>
          <pose>0 -7e-05 -0.011144 0 -0 0</pose>
          <mass>0.70767</mass>
          <inertia>
            <ixx>0.00035492</ixx>
            <ixy>7.5685e-13</ixy>
            <ixz>3.8795e-11</ixz>
            <iyy>0.00035529</iyy>
            <iyz>-2.0284e-07</iyz>
            <izz>0.00040131</izz>
          </inertia>
        </inertial>
        <collision name='wheel_front_left_link_collision'>
          <pose>0 0 0 0 -0 0</pose>
          <geometry>
            <cylinder>
              <length>0.05</length>
              <radius>0.0762</radius>
            </cylinder>
          </geometry>
          <surface>
            <contact>
              <ode>
                <kp>1e+06</kp>
                <kd>1000</kd>
                <max_vel>1</max_vel>
                <min_depth>0</min_depth>
              </ode>
            </contact>
            <friction>
              <ode>
                <mu>0</mu>
                <mu2>0</mu2>
                <fdir1>1 0 0</fdir1>
              </ode>
              <torsional>
                <ode/>
              </torsional>
            </friction>
            <bounce/>
          </surface>
          <max_contacts>10</max_contacts>
        </collision>
        <visual name='wheel_front_left_link_visual'>
          <pose>0 0 0 0 -0 0</pose>
          <geometry>
            <mesh>
              <scale>1 1 -1</scale>
              <uri>model://omni_base_description/meshes/wheels/wheel_link.stl</uri>
            </mesh>
          </geometry>
          <material>
            <script>
              <name>Gazebo/Grey</name>
              <uri>file://media/materials/scripts/gazebo.material</uri>
            </script>
          </material>
        </visual>
        <self_collide>0</self_collide>
        <enable_wind>0</enable_wind>
        <kinematic>0</kinematic>
      </link>
      <joint name='wheel_front_right_joint' type='revolute'>
        <pose relative_to='base_footprint'>0.244 -0.223175 0.0762 -1.5708 0 0</pose>
        <parent>base_footprint</parent>
        <child>wheel_front_right_link</child>
        <axis>
          <xyz>0 0 1</xyz>
          <limit>
            <effort>6</effort>
            <velocity>13.1234</velocity>
            <lower>-1e+16</lower>
            <upper>1e+16</upper>
          </limit>
          <dynamics>
            <damping>1</damping>
            <friction>2</friction>
            <spring_reference>0</spring_reference>
            <spring_stiffness>0</spring_stiffness>
          </dynamics>
        </axis>
      </joint>
      <link name='wheel_front_right_link'>
        <pose relative_to='wheel_front_right_joint'>0 0 0 0 -0 0</pose>
        <inertial>
          <pose>0 7e-05 0.011144 0 -0 0</pose>
          <mass>0.70767</mass>
          <inertia>
            <ixx>0.00035492</ixx>
            <ixy>7.5685e-13</ixy>
            <ixz>3.8795e-11</ixz>
            <iyy>0.00035529</iyy>
            <iyz>-2.0284e-07</iyz>
            <izz>0.00040131</izz>
          </inertia>
        </inertial>
        <collision name='wheel_front_right_link_collision'>
          <pose>0 0 0 0 -0 0</pose>
          <geometry>
            <cylinder>
              <length>0.05</length>
              <radius>0.0762</radius>
            </cylinder>
          </geometry>
          <surface>
            <contact>
              <ode>
                <kp>1e+06</kp>
                <kd>1000</kd>
                <max_vel>1</max_vel>
                <min_depth>0</min_depth>
              </ode>
            </contact>
            <friction>
              <ode>
                <mu>0</mu>
                <mu2>0</mu2>
                <fdir1>1 0 0</fdir1>
              </ode>
              <torsional>
                <ode/>
              </torsional>
            </friction>
            <bounce/>
          </surface>
          <max_contacts>10</max_contacts>
        </collision>
        <visual name='wheel_front_right_link_visual'>
          <pose>0 0 0 0 -0 0</pose>
          <geometry>
            <mesh>
              <scale>1 1 1</scale>
              <uri>model://omni_base_description/meshes/wheels/wheel_link.stl</uri>
            </mesh>
          </geometry>
          <material>
            <script>
              <name>Gazebo/Grey</name>
              <uri>file://media/materials/scripts/gazebo.material</uri>
            </script>
          </material>
        </visual>
        <self_collide>0</self_collide>
        <enable_wind>0</enable_wind>
        <kinematic>0</kinematic>
      </link>
      <joint name='wheel_rear_left_joint' type='revolute'>
        <pose relative_to='base_footprint'>-0.244 0.223175 0.0762 -1.5708 0 0</pose>
        <parent>base_footprint</parent>
        <child>wheel_rear_left_link</child>
        <axis>
          <xyz>0 0 1</xyz>
          <limit>
            <effort>6</effort>
            <velocity>13.1234</velocity>
            <lower>-1e+16</lower>
            <upper>1e+16</upper>
          </limit>
          <dynamics>
            <damping>1</damping>
            <friction>2</friction>
            <spring_reference>0</spring_reference>
            <spring_stiffness>0</spring_stiffness>
          </dynamics>
        </axis>
      </joint>
      <link name='wheel_rear_left_link'>
        <pose relative_to='wheel_rear_left_joint'>0 0 0 0 -0 0</pose>
        <inertial>
          <pose>-0 7e-05 -0.011144 0 -0 0</pose>
          <mass>0.70767</mass>
          <inertia>
            <ixx>0.00035492</ixx>
            <ixy>-7.5685e-13</ixy>
            <ixz>3.8795e-11</ixz>
            <iyy>0.00035529</iyy>
            <iyz>2.0284e-07</iyz>
            <izz>0.00040131</izz>
          </inertia>
        </inertial>
        <collision name='wheel_rear_left_link_collision'>
          <pose>0 0 0 0 -0 0</pose>
          <geometry>
            <cylinder>
              <length>0.05</length>
              <radius>0.0762</radius>
            </cylinder>
          </geometry>
          <surface>
            <contact>
              <ode>
                <kp>1e+06</kp>
                <kd>1000</kd>
                <max_vel>1</max_vel>
                <min_depth>0</min_depth>
              </ode>
            </contact>
            <friction>
              <ode>
                <mu>0</mu>
                <mu2>0</mu2>
                <fdir1>1 0 0</fdir1>
              </ode>
              <torsional>
                <ode/>
              </torsional>
            </friction>
            <bounce/>
          </surface>
          <max_contacts>10</max_contacts>
        </collision>
        <visual name='wheel_rear_left_link_visual'>
          <pose>0 0 0 0 -0 0</pose>
          <geometry>
            <mesh>
              <scale>1 1 -1</scale>
              <uri>model://omni_base_description/meshes/wheels/wheel_link.stl</uri>
            </mesh>
          </geometry>
          <material>
            <script>
              <name>Gazebo/Grey</name>
              <uri>file://media/materials/scripts/gazebo.material</uri>
            </script>
          </material>
        </visual>
        <self_collide>0</self_collide>
        <enable_wind>0</enable_wind>
        <kinematic>0</kinematic>
      </link>
      <joint name='wheel_rear_right_joint' type='revolute'>
        <pose relative_to='base_footprint'>-0.244 -0.223175 0.0762 -1.5708 0 0</pose>
        <parent>base_footprint</parent>
        <child>wheel_rear_right_link</child>
        <axis>
          <xyz>0 0 1</xyz>
          <limit>
            <effort>6</effort>
            <velocity>13.1234</velocity>
            <lower>-1e+16</lower>
            <upper>1e+16</upper>
          </limit>
          <dynamics>
            <damping>1</damping>
            <friction>2</friction>
            <spring_reference>0</spring_reference>
            <spring_stiffness>0</spring_stiffness>
          </dynamics>
        </axis>
      </joint>
      <link name='wheel_rear_right_link'>
        <pose relative_to='wheel_rear_right_joint'>0 0 0 0 -0 0</pose>
        <inertial>
          <pose>-0 -7e-05 0.011144 0 -0 0</pose>
          <mass>0.70767</mass>
          <inertia>
            <ixx>0.00035492</ixx>
            <ixy>-7.5685e-13</ixy>
            <ixz>3.8795e-11</ixz>
            <iyy>0.00035529</iyy>
            <iyz>2.0284e-07</iyz>
            <izz>0.00040131</izz>
          </inertia>
        </inertial>
        <collision name='wheel_rear_right_link_collision'>
          <pose>0 0 0 0 -0 0</pose>
          <geometry>
            <cylinder>
              <length>0.05</length>
              <radius>0.0762</radius>
            </cylinder>
          </geometry>
          <surface>
            <contact>
              <ode>
                <kp>1e+06</kp>
                <kd>1000</kd>
                <max_vel>1</max_vel>
                <min_depth>0</min_depth>
              </ode>
            </contact>
            <friction>
              <ode>
                <mu>0</mu>
                <mu2>0</mu2>
                <fdir1>1 0 0</fdir1>
              </ode>
              <torsional>
                <ode/>
              </torsional>
            </friction>
            <bounce/>
          </surface>
          <max_contacts>10</max_contacts>
        </collision>
        <visual name='wheel_rear_right_link_visual'>
          <pose>0 0 0 0 -0 0</pose>
          <geometry>
            <mesh>
              <scale>1 1 1</scale>
              <uri>model://omni_base_description/meshes/wheels/wheel_link.stl</uri>
            </mesh>
          </geometry>
          <material>
            <script>
              <name>Gazebo/Grey</name>
              <uri>file://media/materials/scripts/gazebo.material</uri>
            </script>
          </material>
        </visual>
        <self_collide>0</self_collide>
        <enable_wind>0</enable_wind>
        <kinematic>0</kinematic>
      </link>
      <joint name='torso_lift_joint' type='prismatic'>
        <pose relative_to='base_footprint'>-0.0245 0 0.8457 0 -0 0</pose>
        <parent>base_footprint</parent>
        <child>torso_lift_link</child>
        <axis>
          <xyz>0 0 1</xyz>
          <limit>
            <lower>0</lower>
            <upper>0.35</upper>
            <effort>2000</effort>
            <velocity>0.07</velocity>
          </limit>
          <dynamics>
            <damping>1000</damping>
            <friction>0</friction>
            <spring_reference>0</spring_reference>
            <spring_stiffness>0</spring_stiffness>
          </dynamics>
        </axis>
        <physics>
          <ode>
            <implicit_spring_damper>1</implicit_spring_damper>
            <cfm_damping>1</cfm_damping>
            <limit>
              <cfm>0</cfm>
              <erp>0.2</erp>
            </limit>
          </ode>
        </physics>
      </joint>
      <link name='torso_lift_link'>
        <pose relative_to='torso_lift_joint'>0 0 0 0 -0 0</pose>
        <inertial>
          <pose>0.001474 0.006528 -0.20301 0 -0 0</pose>
          <mass>9.547</mass>
          <inertia>
            <ixx>0.042078</ixx>
            <ixy>5.6766e-05</ixy>
            <ixz>0.00014731</ixz>
            <iyy>0.031115</iyy>
            <iyz>-5.0165e-05</iyz>
            <izz>0.018659</izz>
          </inertia>
        </inertial>
        <collision name='torso_lift_link_collision'>
          <pose>0 0 0 0 -0 0</pose>
          <geometry>
            <mesh>
              <scale>1 1 1</scale>
              <uri>model://tiago_pro_description/meshes/torso/torso_lift_link_collision.stl</uri>
            </mesh>
          </geometry>
          <max_contacts>10</max_contacts>
          <surface>
            <contact>
              <ode/>
            </contact>
            <bounce/>
            <friction>
              <torsional>
                <ode/>
              </torsional>
              <ode/>
            </friction>
          </surface>
        </collision>
        <visual name='torso_lift_link_visual'>
          <pose>0 0 0 0 -0 0</pose>
          <geometry>
            <mesh>
              <scale>1 1 1</scale>
              <uri>model://tiago_pro_description/meshes/torso/torso_lift_link.stl</uri>
            </mesh>
          </geometry>
        </visual>
        <self_collide>0</self_collide>
        <enable_wind>0</enable_wind>
        <kinematic>0</kinematic>
      </link>
      <joint name='arm_left_1_joint' type='revolute'>
        <pose relative_to='torso_lift_link'>0.08976 0.15918 -0.092008 -2.0679 0 -1.2217</pose>
        <parent>torso_lift_link</parent>
        <child>arm_left_1_link</child>
        <axis>
          <xyz>0 0 1</xyz>
          <limit>
            <lower>-2.60002</lower>
            <upper>2.60002</upper>
            <effort>43</effort>
            <velocity>1.95</velocity>
          </limit>
          <dynamics>
            <damping>1</damping>
            <friction>1</friction>
            <spring_reference>0</spring_reference>
            <spring_stiffness>0</spring_stiffness>
          </dynamics>
        </axis>
        <physics>
          <ode>
            <implicit_spring_damper>1</implicit_spring_damper>
            <cfm_damping>1</cfm_damping>
            <limit>
              <cfm>0</cfm>
              <erp>0.2</erp>
            </limit>
          </ode>
        </physics>
      </joint>
      <link name='arm_left_1_link'>
        <pose relative_to='arm_left_1_joint'>0 0 0 0 -0 0</pose>
        <inertial>
          <pose>0.002391 0.015901 0.1545 0 -0 0</pose>
          <mass>1.0816</mass>
          <inertia>
            <ixx>0.0024426</ixx>
            <ixy>2.3307e-05</ixy>
            <ixz>5.9333e-05</ixz>
            <iyy>0.0023089</iyy>
            <iyz>-0.00020369</iyz>
            <izz>0.00092843</izz>
          </inertia>
        </inertial>
        <collision name='arm_left_1_link_collision'>
          <pose>0 0 0 0 -0 0</pose>
          <geometry>
            <mesh>
              <scale>1 1 1</scale>
              <uri>model://pal_sea_arm_description/meshes/arm_tiago_pro/arm_1_link_collision.stl</uri>
            </mesh>
          </geometry>
          <surface>
            <contact>
              <ode/>
            </contact>
            <friction>
              <ode>
                <mu>0.9</mu>
                <mu2>0.9</mu2>
              </ode>
              <torsional>
                <ode/>
              </torsional>
            </friction>
            <bounce/>
          </surface>
          <max_contacts>10</max_contacts>
        </collision>
        <visual name='arm_left_1_link_visual'>
          <pose>0 0 0 0 -0 0</pose>
          <geometry>
            <mesh>
              <scale>1 1 1</scale>
              <uri>model://pal_sea_arm_description/meshes/arm_tiago_pro/arm_1_link.stl</uri>
            </mesh>
          </geometry>
          <material>
            <script>
              <name>Gazebo/DarkGrey</name>
              <uri>file://media/materials/scripts/gazebo.material</uri>
            </script>
          </material>
        </visual>
        <self_collide>0</self_collide>
        <enable_wind>0</enable_wind>
        <kinematic>0</kinematic>
      </link>
      <joint name='arm_left_2_joint' type='revolute'>
        <pose relative_to='arm_left_1_link'>0 0.02 0.18 3.14159 1.57079 3.14159</pose>
        <parent>arm_left_1_link</parent>
        <child>arm_left_2_link</child>
        <axis>
          <xyz>0 0 1</xyz>
          <limit>
            <lower>-2.43997</lower>
            <upper>1.10008</upper>
            <effort>43</effort>
            <velocity>1.95</velocity>
          </limit>
          <dynamics>
            <damping>1</damping>
            <friction>1</friction>
            <spring_reference>0</spring_reference>
            <spring_stiffness>0</spring_stiffness>
          </dynamics>
        </axis>
        <physics>
          <ode>
            <implicit_spring_damper>1</implicit_spring_damper>
            <cfm_damping>1</cfm_damping>
            <limit>
              <cfm>0</cfm>
              <erp>0.2</erp>
            </limit>
          </ode>
        </physics>
      </joint>
      <link name='arm_left_2_link'>
        <pose relative_to='arm_left_2_joint'>0 0 0 0 -0 0</pose>
        <inertial>
          <pose>-0.11649 -0.017864 0.005377 0 -0 0</pose>
          <mass>0.99204</mass>
          <inertia>
            <ixx>0.00077294</ixx>
            <ixy>-0.00011001</ixy>
            <ixz>-0.00016136</ixz>
            <iyy>0.0014605</iyy>
            <iyz>-1.3224e-05</iyz>
            <izz>0.0015605</izz>
          </inertia>
        </inertial>
        <collision name='arm_left_2_link_collision'>
          <pose>0 0 0 0 -0 0</pose>
          <geometry>
            <mesh>
              <scale>1 1 1</scale>
              <uri>model://pal_sea_arm_description/meshes/arm_tiago_pro/arm_2_link_collision.stl</uri>
            </mesh>
          </geometry>
          <surface>
            <contact>
              <ode/>
            </contact>
            <friction>
              <ode>
                <mu>0.9</mu>
                <mu2>0.9</mu2>
              </ode>
              <torsional>
                <ode/>
              </torsional>
            </friction>
            <bounce/>
          </surface>
          <max_contacts>10</max_contacts>
        </collision>
        <visual name='arm_left_2_link_visual'>
          <pose>0 0 0 0 -0 0</pose>
          <geometry>
            <mesh>
              <scale>1 1 1</scale>
              <uri>model://pal_sea_arm_description/meshes/arm_tiago_pro/arm_2_link.stl</uri>
            </mesh>
          </geometry>
          <material>
            <script>
              <name>Gazebo/DarkGrey</name>
              <uri>file://media/materials/scripts/gazebo.material</uri>
            </script>
          </material>
        </visual>
        <self_collide>0</self_collide>
        <enable_wind>0</enable_wind>
        <kinematic>0</kinematic>
      </link>
      <joint name='arm_left_3_joint' type='revolute'>
        <pose relative_to='arm_left_2_link'>-0.15 -0.02 0 3.1415 1.5707 0</pose>
        <parent>arm_left_2_link</parent>
        <child>arm_left_3_link</child>
        <axis>
          <xyz>0 0 1</xyz>
          <limit>
            <lower>-2.60002</lower>
            <upper>2.60002</upper>
            <effort>26</effort>
            <velocity>2.35</velocity>
          </limit>
          <dynamics>
            <damping>1</damping>
            <friction>1</friction>
            <spring_reference>0</spring_reference>
            <spring_stiffness>0</spring_stiffness>
          </dynamics>
        </axis>
        <physics>
          <ode>
            <implicit_spring_damper>1</implicit_spring_damper>
            <cfm_damping>1</cfm_damping>
            <limit>
              <cfm>0</cfm>
              <erp>0.2</erp>
            </limit>
          </ode>
        </physics>
      </joint>
      <link name='arm_left_3_link'>
        <pose relative_to='arm_left_3_joint'>0 0 0 0 -0 0</pose>
        <inertial>
          <pose>0.002391 0.015901 0.1545 0 -0 0</pose>
          <mass>1.0816</mass>
          <inertia>
            <ixx>0.0024426</ixx>
            <ixy>2.3307e-05</ixy>
            <ixz>5.9333e-05</ixz>
            <iyy>0.0023089</iyy>
            <iyz>-0.00020369</iyz>
            <izz>0.00092843</izz>
          </inertia>
        </inertial>
        <collision name='arm_left_3_link_collision'>
          <pose>0 0 0 0 -0 0</pose>
          <geometry>
            <mesh>
              <scale>1 1 1</scale>
              <uri>model://pal_sea_arm_description/meshes/arm_tiago_pro/arm_3_link_collision.stl</uri>
            </mesh>
          </geometry>
          <surface>
            <contact>
              <ode/>
            </contact>
            <friction>
              <ode>
                <mu>0.9</mu>
                <mu2>0.9</mu2>
              </ode>
              <torsional>
                <ode/>
              </torsional>
            </friction>
            <bounce/>
          </surface>
          <max_contacts>10</max_contacts>
        </collision>
        <visual name='arm_left_3_link_visual'>
          <pose>0 0 0 0 -0 0</pose>
          <geometry>
            <mesh>
              <scale>1 1 1</scale>
              <uri>model://pal_sea_arm_description/meshes/arm_tiago_pro/arm_3_link.stl</uri>
            </mesh>
          </geometry>
          <material>
            <script>
              <name>Gazebo/DarkGrey</name>
              <uri>file://media/materials/scripts/gazebo.material</uri>
            </script>
          </material>
        </visual>
        <self_collide>0</self_collide>
        <enable_wind>0</enable_wind>
        <kinematic>0</kinematic>
      </link>
      <joint name='arm_left_4_joint' type='revolute'>
        <pose relative_to='arm_left_3_link'>0 0.02 0.18 3.14159 1.57079 3.14159</pose>
        <parent>arm_left_3_link</parent>
        <child>arm_left_4_link</child>
        <axis>
          <xyz>0 0 1</xyz>
          <limit>
            <lower>-2.43997</lower>
            <upper>1.10008</upper>
            <effort>26</effort>
            <velocity>2.35</velocity>
          </limit>
          <dynamics>
            <damping>1</damping>
            <friction>1</friction>
            <spring_reference>0</spring_reference>
            <spring_stiffness>0</spring_stiffness>
          </dynamics>
        </axis>
        <physics>
          <ode>
            <implicit_spring_damper>1</implicit_spring_damper>
            <cfm_damping>1</cfm_damping>
            <limit>
              <cfm>0</cfm>
              <erp>0.2</erp>
            </limit>
          </ode>
        </physics>
      </joint>
      <link name='arm_left_4_link'>
        <pose relative_to='arm_left_4_joint'>0 0 0 0 -0 0</pose>
        <inertial>
          <pose>-0.11649 -0.017864 0.005377 0 -0 0</pose>
          <mass>0.99204</mass>
          <inertia>
            <ixx>0.00077294</ixx>
            <ixy>-0.00011001</ixy>
            <ixz>-0.00016136</ixz>
            <iyy>0.0014605</iyy>
            <iyz>-1.3224e-05</iyz>
            <izz>0.0015605</izz>
          </inertia>
        </inertial>
        <collision name='arm_left_4_link_collision'>
          <pose>0 0 0 0 -0 0</pose>
          <geometry>
            <mesh>
              <scale>1 1 1</scale>
              <uri>model://pal_sea_arm_description/meshes/arm_tiago_pro/arm_4_link_collision.stl</uri>
            </mesh>
          </geometry>
          <surface>
            <contact>
              <ode/>
            </contact>
            <friction>
              <ode>
                <mu>0.9</mu>
                <mu2>0.9</mu2>
              </ode>
              <torsional>
                <ode/>
              </torsional>
            </friction>
            <bounce/>
          </surface>
          <max_contacts>10</max_contacts>
        </collision>
        <visual name='arm_left_4_link_visual'>
          <pose>0 0 0 0 -0 0</pose>
          <geometry>
            <mesh>
              <scale>1 1 1</scale>
              <uri>model://pal_sea_arm_description/meshes/arm_tiago_pro/arm_4_link.stl</uri>
            </mesh>
          </geometry>
          <material>
            <script>
              <name>Gazebo/DarkGrey</name>
              <uri>file://media/materials/scripts/gazebo.material</uri>
            </script>
          </material>
        </visual>
        <self_collide>0</self_collide>
        <enable_wind>0</enable_wind>
        <kinematic>0</kinematic>
      </link>
      <joint name='arm_left_5_joint' type='revolute'>
        <pose relative_to='arm_left_4_link'>-0.15 -0.02 0 3.14159 -1.57079 3.14159</pose>
        <parent>arm_left_4_link</parent>
        <child>arm_left_5_link</child>
        <axis>
          <xyz>0 0 1</xyz>
          <limit>
            <lower>-2.60002</lower>
            <upper>2.60002</upper>
            <effort>26</effort>
            <velocity>2.35</velocity>
          </limit>
          <dynamics>
            <damping>1</damping>
            <friction>1</friction>
            <spring_reference>0</spring_reference>
            <spring_stiffness>0</spring_stiffness>
          </dynamics>
        </axis>
        <physics>
          <ode>
            <implicit_spring_damper>1</implicit_spring_damper>
            <cfm_damping>1</cfm_damping>
            <limit>
              <cfm>0</cfm>
              <erp>0.2</erp>
            </limit>
          </ode>
        </physics>
      </joint>
      <link name='arm_left_5_link'>
        <pose relative_to='arm_left_5_joint'>0 0 0 0 -0 0</pose>
        <inertial>
          <pose>0.000486 0.000143 0.129 0 -0 0</pose>
          <mass>0.52538</mass>
          <inertia>
            <ixx>0.0019111</ixx>
            <ixy>-1.4245e-08</ixy>
            <ixz>3.8663e-05</ixz>
            <iyy>0.0018565</iyy>
            <iyz>1.1356e-06</iyz>
            <izz>0.00046496</izz>
          </inertia>
        </inertial>
        <collision name='arm_left_5_link_collision'>
          <pose>0 0 0 0 -0 0</pose>
          <geometry>
            <mesh>
              <scale>1 1 1</scale>
              <uri>model://pal_sea_arm_description/meshes/arm_tiago_pro/arm_5_link_collision.stl</uri>
            </mesh>
          </geometry>
          <surface>
            <contact>
              <ode/>
            </contact>
            <friction>
              <ode>
                <mu>0.9</mu>
                <mu2>0.9</mu2>
              </ode>
              <torsional>
                <ode/>
              </torsional>
            </friction>
            <bounce/>
          </surface>
          <max_contacts>10</max_contacts>
        </collision>
        <visual name='arm_left_5_link_visual'>
          <pose>0 0 0 0 -0 0</pose>
          <geometry>
            <mesh>
              <scale>1 1 1</scale>
              <uri>model://pal_sea_arm_description/meshes/arm_tiago_pro/arm_5_link.stl</uri>
            </mesh>
          </geometry>
          <material>
            <script>
              <name>Gazebo/DarkGrey</name>
              <uri>file://media/materials/scripts/gazebo.material</uri>
            </script>
          </material>
        </visual>
        <self_collide>0</self_collide>
        <enable_wind>0</enable_wind>
        <kinematic>0</kinematic>
      </link>
      <joint name='arm_left_6_joint' type='revolute'>
        <pose relative_to='arm_left_5_link'>0 0 0.185 3.14159 1.57079 3.14159</pose>
        <parent>arm_left_5_link</parent>
        <child>arm_left_6_link</child>
        <axis>
          <xyz>0 0 1</xyz>
          <limit>
            <lower>-1.99997</lower>
            <upper>1.99997</upper>
            <effort>26</effort>
            <velocity>2.35</velocity>
          </limit>
          <dynamics>
            <damping>1</damping>
            <friction>1</friction>
            <spring_reference>0</spring_reference>
            <spring_stiffness>0</spring_stiffness>
          </dynamics>
        </axis>
        <physics>
          <ode>
            <implicit_spring_damper>1</implicit_spring_damper>
            <cfm_damping>1</cfm_damping>
            <limit>
              <cfm>0</cfm>
              <erp>0.2</erp>
            </limit>
          </ode>
        </physics>
      </joint>
      <link name='arm_left_6_link'>
        <pose relative_to='arm_left_6_joint'>0 0 0 0 -0 0</pose>
        <inertial>
          <pose>-0.086822 -8e-06 0.004526 0 -0 0</pose>
          <mass>0.66725</mass>
          <inertia>
            <ixx>0.00035696</ixx>
            <ixy>1.6019e-07</ixy>
            <ixz>-9.5191e-05</ixz>
            <iyy>0.00073846</iyy>
            <iyz>2.118e-08</iyz>
            <izz>0.00075321</izz>
          </inertia>
        </inertial>
        <collision name='arm_left_6_link_collision'>
          <pose>0 0 0 0 -0 0</pose>
          <geometry>
            <mesh>
              <scale>1 1 1</scale>
              <uri>model://pal_sea_arm_description/meshes/arm_tiago_pro/arm_6_link_collision.stl</uri>
            </mesh>
          </geometry>
          <surface>
            <contact>
              <ode/>
            </contact>
            <friction>
              <ode>
                <mu>0.9</mu>
                <mu2>0.9</mu2>
              </ode>
              <torsional>
                <ode/>
              </torsional>
            </friction>
            <bounce/>
          </surface>
          <max_contacts>10</max_contacts>
        </collision>
        <visual name='arm_left_6_link_visual'>
          <pose>0 0 0 0 -0 0</pose>
          <geometry>
            <mesh>
              <scale>1 1 1</scale>
              <uri>model://pal_sea_arm_description/meshes/arm_tiago_pro/arm_6_link.stl</uri>
            </mesh>
          </geometry>
          <material>
            <script>
              <name>Gazebo/DarkGrey</name>
              <uri>file://media/materials/scripts/gazebo.material</uri>
            </script>
          </material>
        </visual>
        <self_collide>0</self_collide>
        <enable_wind>0</enable_wind>
        <kinematic>0</kinematic>
      </link>
      <joint name='arm_left_7_joint' type='revolute'>
        <pose relative_to='arm_left_6_link'>-0.1166 0 0 3.14159 -1.57079 3.14159</pose>
        <parent>arm_left_6_link</parent>
        <child>arm_left_7_link</child>
        <axis>
          <xyz>0 0 1</xyz>
          <limit>
            <lower>-2.60002</lower>
            <upper>2.60002</upper>
            <effort>26</effort>
            <velocity>2.35</velocity>
          </limit>
          <dynamics>
            <damping>1</damping>
            <friction>1</friction>
            <spring_reference>0</spring_reference>
            <spring_stiffness>0</spring_stiffness>
          </dynamics>
        </axis>
        <physics>
          <provide_feedback>1</provide_feedback>
          <ode>
            <implicit_spring_damper>1</implicit_spring_damper>
            <cfm_damping>1</cfm_damping>
            <limit>
              <cfm>0</cfm>
              <erp>0.2</erp>
            </limit>
            <provide_feedback>1</provide_feedback>
          </ode>
        </physics>
      </joint>
      <link name='arm_left_7_link'>
        <pose relative_to='arm_left_7_joint'>0 0 0 0 -0 0</pose>
        <inertial>
          <pose>7.2e-05 0.000608 0.08376 0 -0 0</pose>
          <mass>1.21226</mass>
          <inertia>
            <ixx>0.00249211</ixx>
            <ixy>-5.0396e-06</ixy>
            <ixz>2.53757e-06</ixz>
            <iyy>0.00246185</iyy>
            <iyz>5.27397e-05</iyz>
            <izz>0.000820829</izz>
          </inertia>
        </inertial>
        <collision name='arm_left_7_link_collision'>
          <pose>0 0 0 0 -0 0</pose>
          <geometry>
            <mesh>
              <scale>1 1 1</scale>
              <uri>model://pal_sea_arm_description/meshes/arm_tiago_pro/arm_7_link_collision.stl</uri>
            </mesh>
          </geometry>
          <surface>
            <contact>
              <ode/>
            </contact>
            <friction>
              <ode>
                <mu>0.9</mu>
                <mu2>0.9</mu2>
              </ode>
              <torsional>
                <ode/>
              </torsional>
            </friction>
            <bounce/>
          </surface>
          <max_contacts>10</max_contacts>
        </collision>
        <collision name='arm_left_7_link_fixed_joint_lump__arm_left_tool_link_collision_1'>
          <pose>0 0 0.0194 0 -0 1.5708</pose>
          <geometry>
            <cylinder>
              <length>0.01</length>
              <radius>0.032</radius>
            </cylinder>
          </geometry>
          <max_contacts>10</max_contacts>
          <surface>
            <contact>
              <ode/>
            </contact>
            <bounce/>
            <friction>
              <torsional>
                <ode/>
              </torsional>
              <ode/>
            </friction>
          </surface>
        </collision>
        <collision name='arm_left_7_link_fixed_joint_lump__wrist_left_ft_link_collision_2'>
          <pose>0 0 0.0334 0 -0 0.785398</pose>
          <geometry>
            <cylinder>
              <length>0.05</length>
              <radius>0.035</radius>
            </cylinder>
          </geometry>
          <surface>
            <contact>
              <ode/>
            </contact>
            <friction>
              <ode>
                <mu>0.9</mu>
                <mu2>0.9</mu2>
              </ode>
              <torsional>
                <ode/>
              </torsional>
            </friction>
            <bounce/>
          </surface>
          <max_contacts>10</max_contacts>
        </collision>
        <collision name='arm_left_7_link_fixed_joint_lump__wrist_left_ft_link_collision_3'>
          <pose>0.016971 0.032527 0.0284 0 -0 1.22173</pose>
          <geometry>
            <box>
              <size>0.0395 0.0496 0.053</size>
            </box>
          </geometry>
          <surface>
            <contact>
              <ode/>
            </contact>
            <friction>
              <ode>
                <mu>0.9</mu>
                <mu2>0.9</mu2>
              </ode>
              <torsional>
                <ode/>
              </torsional>
            </friction>
            <bounce/>
          </surface>
          <max_contacts>10</max_contacts>
        </collision>
        <collision name='arm_left_7_link_fixed_joint_lump__wrist_left_ft_tool_link_collision_4'>
          <pose>0 0 0.0694 0 -0 1.5708</pose>
          <geometry>
            <cylinder>
              <length>0.01</length>
              <radius>0.032</radius>
            </cylinder>
          </geometry>
          <max_contacts>10</max_contacts>
          <surface>
            <contact>
              <ode/>
            </contact>
            <bounce/>
            <friction>
              <torsional>
                <ode/>
              </torsional>
              <ode/>
            </friction>
          </surface>
        </collision>
        <collision name='arm_left_7_link_fixed_joint_lump__gripper_left_base_link_collision_5'>
          <pose>0 0 0.1204 0 -0 1.5708</pose>
          <geometry>
            <mesh>
              <scale>1 1 1</scale>
              <uri>model://pal_pro_gripper_description/meshes/base_link.stl</uri>
            </mesh>
          </geometry>
          <surface>
            <contact>
              <ode/>
            </contact>
            <friction>
              <ode>
                <mu>0.9</mu>
                <mu2>0.9</mu2>
              </ode>
              <torsional>
                <ode/>
              </torsional>
            </friction>
            <bounce/>
          </surface>
          <max_contacts>10</max_contacts>
        </collision>
        <visual name='arm_left_7_link_visual'>
          <pose>0 0 0 0 -0 0</pose>
          <geometry>
            <mesh>
              <scale>1 1 1</scale>
              <uri>model://pal_sea_arm_description/meshes/arm_tiago_pro/arm_7_link.stl</uri>
            </mesh>
          </geometry>
          <material>
            <script>
              <name>Gazebo/DarkGrey</name>
              <uri>file://media/materials/scripts/gazebo.material</uri>
            </script>
          </material>
        </visual>
        <visual name='arm_left_7_link_fixed_joint_lump__arm_left_tool_link_visual_1'>
          <pose>0 0 0.0194 0 -0 1.5708</pose>
          <geometry>
            <cylinder>
              <length>0.01</length>
              <radius>0.032</radius>
            </cylinder>
          </geometry>
        </visual>
        <visual name='arm_left_7_link_fixed_joint_lump__wrist_left_ft_link_visual_2'>
          <pose>0 0 0.0634 0 -0 0.785398</pose>
          <geometry>
            <mesh>
              <scale>1 1 1</scale>
              <uri>model://pal_sea_arm_description/meshes/sensors/rokubi_ft_sensor.STL</uri>
            </mesh>
          </geometry>
          <material>
            <script>
              <name>Gazebo/DarkGrey</name>
              <uri>file://media/materials/scripts/gazebo.material</uri>
            </script>
          </material>
        </visual>
        <visual name='arm_left_7_link_fixed_joint_lump__wrist_left_ft_tool_link_visual_3'>
          <pose>0 0 0.0694 0 -0 1.5708</pose>
          <geometry>
            <cylinder>
              <length>0.01</length>
              <radius>0.032</radius>
            </cylinder>
          </geometry>
        </visual>
        <visual name='arm_left_7_link_fixed_joint_lump__gripper_left_base_link_visual_4'>
          <pose>0 0 0.1204 0 -0 1.5708</pose>
          <geometry>
            <mesh>
              <scale>1 1 1</scale>
              <uri>model://pal_pro_gripper_description/meshes/base_link.stl</uri>
            </mesh>
          </geometry>
          <material>
            <script>
              <name>Gazebo/DarkGrey</name>
              <uri>file://media/materials/scripts/gazebo.material</uri>
            </script>
          </material>
        </visual>
        <self_collide>0</self_collide>
        <enable_wind>0</enable_wind>
        <kinematic>0</kinematic>
      </link>
      <joint name='gripper_left_finger_joint' type='revolute'>
        <pose relative_to='arm_left_7_link'>0 -0.0288 0.1489 1.5708 0.837758 -1.5708</pose>
        <parent>arm_left_7_link</parent>
        <child>gripper_left_outer_finger_left_link</child>
        <axis>
          <xyz>0 0 1</xyz>
          <limit>
            <lower>0</lower>
            <upper>0.925025</upper>
            <effort>0.1</effort>
            <velocity>2</velocity>
          </limit>
          <dynamics>
            <damping>0.03</damping>
            <friction>0</friction>
            <spring_reference>0</spring_reference>
            <spring_stiffness>0</spring_stiffness>
          </dynamics>
        </axis>
        <physics>
          <provide_feedback>1</provide_feedback>
          <ode>
            <implicit_spring_damper>1</implicit_spring_damper>
            <cfm_damping>1</cfm_damping>
            <limit>
              <cfm>0</cfm>
              <erp>0.2</erp>
            </limit>
            <provide_feedback>1</provide_feedback>
          </ode>
        </physics>
      </joint>
      <link name='gripper_left_outer_finger_left_link'>
        <pose relative_to='gripper_left_finger_joint'>0 0 0 0 -0 0</pose>
        <inertial>
          <pose>-0.001283 0.014397 0 0 -0 0</pose>
          <mass>0.015989</mass>
          <inertia>
            <ixx>5.9879e-06</ixx>
            <ixy>-5.2173e-07</ixy>
            <ixz>5.9144e-23</ixz>
            <iyy>4.8725e-07</iyy>
            <iyz>7.3911e-23</iyz>
            <izz>6.1497e-06</izz>
          </inertia>
        </inertial>
        <collision name='gripper_left_outer_finger_left_link_collision'>
          <pose>0 0 0 0 -0 0</pose>
          <geometry>
            <mesh>
              <scale>1 1 1</scale>
              <uri>model://pal_pro_gripper_description/meshes/outer_finger.stl</uri>
            </mesh>
          </geometry>
          <surface>
            <contact>
              <ode/>
            </contact>
            <friction>
              <ode>
                <mu>0.9</mu>
                <mu2>0.9</mu2>
              </ode>
              <torsional>
                <ode/>
              </torsional>
            </friction>
            <bounce/>
          </surface>
          <max_contacts>10</max_contacts>
        </collision>
        <visual name='gripper_left_outer_finger_left_link_visual'>
          <pose>0 0 0 0 -0 0</pose>
          <geometry>
            <mesh>
              <scale>1 1 1</scale>
              <uri>model://pal_pro_gripper_description/meshes/outer_finger.stl</uri>
            </mesh>
          </geometry>
          <material>
            <script>
              <name>Gazebo/White</name>
              <uri>file://media/materials/scripts/gazebo.material</uri>
            </script>
          </material>
        </visual>
        <self_collide>0</self_collide>
        <enable_wind>0</enable_wind>
        <kinematic>0</kinematic>
      </link>
      <joint name='gripper_left_inner_finger_left_joint' type='revolute'>
        <pose relative_to='arm_left_7_link'>0 -0.013977 0.153432 1.5708 0.837758 -1.5708</pose>
        <parent>arm_left_7_link</parent>
        <child>gripper_left_inner_finger_left_link</child>
        <axis>
          <xyz>0 0 1</xyz>
          <limit>
            <lower>0</lower>
            <upper>0.925025</upper>
            <effort>0.1</effort>
            <velocity>2</velocity>
          </limit>
          <dynamics>
            <spring_reference>0</spring_reference>
            <spring_stiffness>0</spring_stiffness>
          </dynamics>
        </axis>
      </joint>
      <link name='gripper_left_inner_finger_left_link'>
        <pose relative_to='gripper_left_inner_finger_left_joint'>0 0 0 0 -0 0</pose>
        <inertial>
          <pose>-0 0.024759 0 0 -0 0</pose>
          <mass>0.018619</mass>
          <inertia>
            <ixx>4.8806e-06</ixx>
            <ixy>-7.6762e-22</ixy>
            <ixz>1.0244e-22</ixz>
            <iyy>2.5471e-07</iyy>
            <iyz>-1.1841e-21</iyz>
            <izz>4.9573e-06</izz>
          </inertia>
        </inertial>
        <collision name='gripper_left_inner_finger_left_link_collision'>
          <pose>0 0 0 0 -0 0</pose>
          <geometry>
            <mesh>
              <scale>1 1 1</scale>
              <uri>model://pal_pro_gripper_description/meshes/inner_finger.stl</uri>
            </mesh>
          </geometry>
          <surface>
            <contact>
              <ode/>
            </contact>
            <friction>
              <ode>
                <mu>0.9</mu>
                <mu2>0.9</mu2>
              </ode>
              <torsional>
                <ode/>
              </torsional>
            </friction>
            <bounce/>
          </surface>
          <max_contacts>10</max_contacts>
        </collision>
        <visual name='gripper_left_inner_finger_left_link_visual'>
          <pose>0 0 0 0 -0 0</pose>
          <geometry>
            <mesh>
              <scale>1 1 1</scale>
              <uri>model://pal_pro_gripper_description/meshes/inner_finger.stl</uri>
            </mesh>
          </geometry>
          <material>
            <script>
              <name>Gazebo/White</name>
              <uri>file://media/materials/scripts/gazebo.material</uri>
            </script>
          </material>
        </visual>
        <self_collide>0</self_collide>
        <enable_wind>0</enable_wind>
        <kinematic>0</kinematic>
      </link>
      <joint name='gripper_left_fingertip_left_joint' type='revolute'>
        <pose relative_to='gripper_left_inner_finger_left_link'>0 0.05 0 0 -0 0.837758</pose>
        <parent>gripper_left_inner_finger_left_link</parent>
        <child>gripper_left_fingertip_left_link</child>
        <axis>
          <xyz>0 0 1</xyz>
          <limit>
            <lower>-0.925025</lower>
            <upper>0</upper>
            <effort>0.1</effort>
            <velocity>2</velocity>
          </limit>
          <dynamics>
            <spring_reference>0</spring_reference>
            <spring_stiffness>0</spring_stiffness>
          </dynamics>
        </axis>
      </joint>
      <link name='gripper_left_fingertip_left_link'>
        <pose relative_to='gripper_left_fingertip_left_joint'>0 0 0 0 -0 0</pose>
        <inertial>
          <pose>-0.0007 0.01167 0 0 -0 0</pose>
          <mass>0.03266</mass>
          <inertia>
            <ixx>3.6361e-06</ixx>
            <ixy>3.4071e-07</ixy>
            <ixz>-1.4191e-14</ixz>
            <iyy>1.707e-06</iyy>
            <iyz>-3.3433e-14</iyz>
            <izz>2.8395e-06</izz>
          </inertia>
        </inertial>
        <collision name='gripper_left_fingertip_left_link_collision'>
          <pose>0 0 0 0 -0 0</pose>
          <geometry>
            <mesh>
              <scale>1 1 1</scale>
              <uri>model://pal_pro_gripper_description/meshes/fingertip.stl</uri>
            </mesh>
          </geometry>
          <surface>
            <contact>
              <ode/>
            </contact>
            <friction>
              <ode>
                <mu>0.9</mu>
                <mu2>0.9</mu2>
              </ode>
              <torsional>
                <ode/>
              </torsional>
            </friction>
            <bounce/>
          </surface>
          <max_contacts>10</max_contacts>
        </collision>
        <visual name='gripper_left_fingertip_left_link_visual'>
          <pose>0 0 0 0 -0 0</pose>
          <geometry>
            <mesh>
              <scale>1 1 1</scale>
              <uri>model://pal_pro_gripper_description/meshes/fingertip.stl</uri>
            </mesh>
          </geometry>
          <material>
            <script>
              <name>Gazebo/White</name>
              <uri>file://media/materials/scripts/gazebo.material</uri>
            </script>
          </material>
        </visual>
        <self_collide>0</self_collide>
        <enable_wind>0</enable_wind>
        <kinematic>0</kinematic>
      </link>
      <joint name='gripper_left_inner_finger_right_joint' type='revolute'>
        <pose relative_to='arm_left_7_link'>0 0.013977 0.153432 1.5708 0.837758 1.5708</pose>
        <parent>arm_left_7_link</parent>
        <child>gripper_left_inner_finger_right_link</child>
        <axis>
          <xyz>0 0 1</xyz>
          <limit>
            <lower>0</lower>
            <upper>0.925025</upper>
            <effort>0.1</effort>
            <velocity>2</velocity>
          </limit>
          <dynamics>
            <spring_reference>0</spring_reference>
            <spring_stiffness>0</spring_stiffness>
          </dynamics>
        </axis>
      </joint>
      <link name='gripper_left_inner_finger_right_link'>
        <pose relative_to='gripper_left_inner_finger_right_joint'>0 0 0 0 -0 0</pose>
        <inertial>
          <pose>-0 0.024759 0 0 -0 0</pose>
          <mass>0.018619</mass>
          <inertia>
            <ixx>4.8806e-06</ixx>
            <ixy>-7.6762e-22</ixy>
            <ixz>1.0244e-22</ixz>
            <iyy>2.5471e-07</iyy>
            <iyz>-1.1841e-21</iyz>
            <izz>4.9573e-06</izz>
          </inertia>
        </inertial>
        <collision name='gripper_left_inner_finger_right_link_collision'>
          <pose>0 0 0 0 -0 0</pose>
          <geometry>
            <mesh>
              <scale>1 1 1</scale>
              <uri>model://pal_pro_gripper_description/meshes/inner_finger.stl</uri>
            </mesh>
          </geometry>
          <surface>
            <contact>
              <ode/>
            </contact>
            <friction>
              <ode>
                <mu>0.9</mu>
                <mu2>0.9</mu2>
              </ode>
              <torsional>
                <ode/>
              </torsional>
            </friction>
            <bounce/>
          </surface>
          <max_contacts>10</max_contacts>
        </collision>
        <visual name='gripper_left_inner_finger_right_link_visual'>
          <pose>0 0 0 0 -0 0</pose>
          <geometry>
            <mesh>
              <scale>1 1 1</scale>
              <uri>model://pal_pro_gripper_description/meshes/inner_finger.stl</uri>
            </mesh>
          </geometry>
          <material>
            <script>
              <name>Gazebo/White</name>
              <uri>file://media/materials/scripts/gazebo.material</uri>
            </script>
          </material>
        </visual>
        <self_collide>0</self_collide>
        <enable_wind>0</enable_wind>
        <kinematic>0</kinematic>
      </link>
      <joint name='gripper_left_fingertip_right_joint' type='revolute'>
        <pose relative_to='gripper_left_inner_finger_right_link'>0 0.05 0 0 -0 0.837758</pose>
        <parent>gripper_left_inner_finger_right_link</parent>
        <child>gripper_left_fingertip_right_link</child>
        <axis>
          <xyz>0 0 1</xyz>
          <limit>
            <lower>-0.925025</lower>
            <upper>0</upper>
            <effort>0.1</effort>
            <velocity>2</velocity>
          </limit>
          <dynamics>
            <spring_reference>0</spring_reference>
            <spring_stiffness>0</spring_stiffness>
          </dynamics>
        </axis>
      </joint>
      <link name='gripper_left_fingertip_right_link'>
        <pose relative_to='gripper_left_fingertip_right_joint'>0 0 0 0 -0 0</pose>
        <inertial>
          <pose>-0.0007 0.01167 0 0 -0 0</pose>
          <mass>0.03266</mass>
          <inertia>
            <ixx>3.6361e-06</ixx>
            <ixy>3.4071e-07</ixy>
            <ixz>-1.4191e-14</ixz>
            <iyy>1.707e-06</iyy>
            <iyz>-3.3433e-14</iyz>
            <izz>2.8395e-06</izz>
          </inertia>
        </inertial>
        <collision name='gripper_left_fingertip_right_link_collision'>
          <pose>0 0 0 0 -0 0</pose>
          <geometry>
            <mesh>
              <scale>1 1 1</scale>
              <uri>model://pal_pro_gripper_description/meshes/fingertip.stl</uri>
            </mesh>
          </geometry>
          <surface>
            <contact>
              <ode/>
            </contact>
            <friction>
              <ode>
                <mu>0.9</mu>
                <mu2>0.9</mu2>
              </ode>
              <torsional>
                <ode/>
              </torsional>
            </friction>
            <bounce/>
          </surface>
          <max_contacts>10</max_contacts>
        </collision>
        <visual name='gripper_left_fingertip_right_link_visual'>
          <pose>0 0 0 0 -0 0</pose>
          <geometry>
            <mesh>
              <scale>1 1 1</scale>
              <uri>model://pal_pro_gripper_description/meshes/fingertip.stl</uri>
            </mesh>
          </geometry>
          <material>
            <script>
              <name>Gazebo/White</name>
              <uri>file://media/materials/scripts/gazebo.material</uri>
            </script>
          </material>
        </visual>
        <self_collide>0</self_collide>
        <enable_wind>0</enable_wind>
        <kinematic>0</kinematic>
      </link>
      <joint name='gripper_left_outer_finger_right_joint' type='revolute'>
        <pose relative_to='arm_left_7_link'>0 0.0288 0.1489 1.5708 0.837758 1.5708</pose>
        <parent>arm_left_7_link</parent>
        <child>gripper_left_outer_finger_right_link</child>
        <axis>
          <xyz>0 0 1</xyz>
          <limit>
            <lower>0</lower>
            <upper>0.925025</upper>
            <effort>0.1</effort>
            <velocity>2</velocity>
          </limit>
          <dynamics>
            <spring_reference>0</spring_reference>
            <spring_stiffness>0</spring_stiffness>
          </dynamics>
        </axis>
      </joint>
      <link name='gripper_left_outer_finger_right_link'>
        <pose relative_to='gripper_left_outer_finger_right_joint'>0 0 0 0 -0 0</pose>
        <inertial>
          <pose>-0.001283 0.014397 0 0 -0 0</pose>
          <mass>0.015989</mass>
          <inertia>
            <ixx>5.9879e-06</ixx>
            <ixy>-5.2173e-07</ixy>
            <ixz>5.9144e-23</ixz>
            <iyy>4.8725e-07</iyy>
            <iyz>7.3911e-23</iyz>
            <izz>6.1497e-06</izz>
          </inertia>
        </inertial>
        <collision name='gripper_left_outer_finger_right_link_collision'>
          <pose>0 0 0 0 -0 0</pose>
          <geometry>
            <mesh>
              <scale>1 1 1</scale>
              <uri>model://pal_pro_gripper_description/meshes/outer_finger.stl</uri>
            </mesh>
          </geometry>
          <surface>
            <contact>
              <ode/>
            </contact>
            <friction>
              <ode>
                <mu>0.9</mu>
                <mu2>0.9</mu2>
              </ode>
              <torsional>
                <ode/>
              </torsional>
            </friction>
            <bounce/>
          </surface>
          <max_contacts>10</max_contacts>
        </collision>
        <visual name='gripper_left_outer_finger_right_link_visual'>
          <pose>0 0 0 0 -0 0</pose>
          <geometry>
            <mesh>
              <scale>1 1 1</scale>
              <uri>model://pal_pro_gripper_description/meshes/outer_finger.stl</uri>
            </mesh>
          </geometry>
          <material>
            <script>
              <name>Gazebo/White</name>
              <uri>file://media/materials/scripts/gazebo.material</uri>
            </script>
          </material>
        </visual>
        <self_collide>0</self_collide>
        <enable_wind>0</enable_wind>
        <kinematic>0</kinematic>
      </link>
      <joint name='arm_right_1_joint' type='revolute'>
        <pose relative_to='torso_lift_link'>0.08976 -0.15918 -0.092008 -2.0679 0 -1.91989</pose>
        <parent>torso_lift_link</parent>
        <child>arm_right_1_link</child>
        <axis>
          <xyz>0 0 1</xyz>
          <limit>
            <lower>-2.60002</lower>
            <upper>2.60002</upper>
            <effort>43</effort>
            <velocity>1.95</velocity>
          </limit>
          <dynamics>
            <damping>1</damping>
            <friction>1</friction>
            <spring_reference>0</spring_reference>
            <spring_stiffness>0</spring_stiffness>
          </dynamics>
        </axis>
        <physics>
          <ode>
            <implicit_spring_damper>1</implicit_spring_damper>
            <cfm_damping>1</cfm_damping>
            <limit>
              <cfm>0</cfm>
              <erp>0.2</erp>
            </limit>
          </ode>
        </physics>
      </joint>
      <link name='arm_right_1_link'>
        <pose relative_to='arm_right_1_joint'>0 0 0 0 -0 0</pose>
        <inertial>
          <pose>0.002391 0.015901 0.1545 0 -0 0</pose>
          <mass>1.0816</mass>
          <inertia>
            <ixx>0.0024426</ixx>
            <ixy>2.3307e-05</ixy>
            <ixz>5.9333e-05</ixz>
            <iyy>0.0023089</iyy>
            <iyz>-0.00020369</iyz>
            <izz>0.00092843</izz>
          </inertia>
        </inertial>
        <collision name='arm_right_1_link_collision'>
          <pose>0 0 0 0 -0 0</pose>
          <geometry>
            <mesh>
              <scale>1 1 1</scale>
              <uri>model://pal_sea_arm_description/meshes/arm_tiago_pro/arm_1_link_collision.stl</uri>
            </mesh>
          </geometry>
          <surface>
            <contact>
              <ode/>
            </contact>
            <friction>
              <ode>
                <mu>0.9</mu>
                <mu2>0.9</mu2>
              </ode>
              <torsional>
                <ode/>
              </torsional>
            </friction>
            <bounce/>
          </surface>
          <max_contacts>10</max_contacts>
        </collision>
        <visual name='arm_right_1_link_visual'>
          <pose>0 0 0 0 -0 0</pose>
          <geometry>
            <mesh>
              <scale>1 1 1</scale>
              <uri>model://pal_sea_arm_description/meshes/arm_tiago_pro/arm_1_link.stl</uri>
            </mesh>
          </geometry>
          <material>
            <script>
              <name>Gazebo/DarkGrey</name>
              <uri>file://media/materials/scripts/gazebo.material</uri>
            </script>
          </material>
        </visual>
        <self_collide>0</self_collide>
        <enable_wind>0</enable_wind>
        <kinematic>0</kinematic>
      </link>
      <joint name='arm_right_2_joint' type='revolute'>
        <pose relative_to='arm_right_1_link'>0 0.02 0.18 3.14159 1.57079 3.14159</pose>
        <parent>arm_right_1_link</parent>
        <child>arm_right_2_link</child>
        <axis>
          <xyz>0 0 1</xyz>
          <limit>
            <lower>-2.43997</lower>
            <upper>1.10008</upper>
            <effort>43</effort>
            <velocity>1.95</velocity>
          </limit>
          <dynamics>
            <damping>1</damping>
            <friction>1</friction>
            <spring_reference>0</spring_reference>
            <spring_stiffness>0</spring_stiffness>
          </dynamics>
        </axis>
        <physics>
          <ode>
            <implicit_spring_damper>1</implicit_spring_damper>
            <cfm_damping>1</cfm_damping>
            <limit>
              <cfm>0</cfm>
              <erp>0.2</erp>
            </limit>
          </ode>
        </physics>
      </joint>
      <link name='arm_right_2_link'>
        <pose relative_to='arm_right_2_joint'>0 0 0 0 -0 0</pose>
        <inertial>
          <pose>-0.11649 -0.017864 0.005377 0 -0 0</pose>
          <mass>0.99204</mass>
          <inertia>
            <ixx>0.00077294</ixx>
            <ixy>-0.00011001</ixy>
            <ixz>-0.00016136</ixz>
            <iyy>0.0014605</iyy>
            <iyz>-1.3224e-05</iyz>
            <izz>0.0015605</izz>
          </inertia>
        </inertial>
        <collision name='arm_right_2_link_collision'>
          <pose>0 0 0 0 -0 0</pose>
          <geometry>
            <mesh>
              <scale>1 1 1</scale>
              <uri>model://pal_sea_arm_description/meshes/arm_tiago_pro/arm_2_link_collision.stl</uri>
            </mesh>
          </geometry>
          <surface>
            <contact>
              <ode/>
            </contact>
            <friction>
              <ode>
                <mu>0.9</mu>
                <mu2>0.9</mu2>
              </ode>
              <torsional>
                <ode/>
              </torsional>
            </friction>
            <bounce/>
          </surface>
          <max_contacts>10</max_contacts>
        </collision>
        <visual name='arm_right_2_link_visual'>
          <pose>0 0 0 0 -0 0</pose>
          <geometry>
            <mesh>
              <scale>1 1 1</scale>
              <uri>model://pal_sea_arm_description/meshes/arm_tiago_pro/arm_2_link.stl</uri>
            </mesh>
          </geometry>
          <material>
            <script>
              <name>Gazebo/DarkGrey</name>
              <uri>file://media/materials/scripts/gazebo.material</uri>
            </script>
          </material>
        </visual>
        <self_collide>0</self_collide>
        <enable_wind>0</enable_wind>
        <kinematic>0</kinematic>
      </link>
      <joint name='arm_right_3_joint' type='revolute'>
        <pose relative_to='arm_right_2_link'>-0.15 -0.02 0 3.1415 1.5707 0</pose>
        <parent>arm_right_2_link</parent>
        <child>arm_right_3_link</child>
        <axis>
          <xyz>0 0 1</xyz>
          <limit>
            <lower>-2.60002</lower>
            <upper>2.60002</upper>
            <effort>26</effort>
            <velocity>2.35</velocity>
          </limit>
          <dynamics>
            <damping>1</damping>
            <friction>1</friction>
            <spring_reference>0</spring_reference>
            <spring_stiffness>0</spring_stiffness>
          </dynamics>
        </axis>
        <physics>
          <ode>
            <implicit_spring_damper>1</implicit_spring_damper>
            <cfm_damping>1</cfm_damping>
            <limit>
              <cfm>0</cfm>
              <erp>0.2</erp>
            </limit>
          </ode>
        </physics>
      </joint>
      <link name='arm_right_3_link'>
        <pose relative_to='arm_right_3_joint'>0 0 0 0 -0 0</pose>
        <inertial>
          <pose>0.002391 0.015901 0.1545 0 -0 0</pose>
          <mass>1.0816</mass>
          <inertia>
            <ixx>0.0024426</ixx>
            <ixy>2.3307e-05</ixy>
            <ixz>5.9333e-05</ixz>
            <iyy>0.0023089</iyy>
            <iyz>-0.00020369</iyz>
            <izz>0.00092843</izz>
          </inertia>
        </inertial>
        <collision name='arm_right_3_link_collision'>
          <pose>0 0 0 0 -0 0</pose>
          <geometry>
            <mesh>
              <scale>1 1 1</scale>
              <uri>model://pal_sea_arm_description/meshes/arm_tiago_pro/arm_3_link_collision.stl</uri>
            </mesh>
          </geometry>
          <surface>
            <contact>
              <ode/>
            </contact>
            <friction>
              <ode>
                <mu>0.9</mu>
                <mu2>0.9</mu2>
              </ode>
              <torsional>
                <ode/>
              </torsional>
            </friction>
            <bounce/>
          </surface>
          <max_contacts>10</max_contacts>
        </collision>
        <visual name='arm_right_3_link_visual'>
          <pose>0 0 0 0 -0 0</pose>
          <geometry>
            <mesh>
              <scale>1 1 1</scale>
              <uri>model://pal_sea_arm_description/meshes/arm_tiago_pro/arm_3_link.stl</uri>
            </mesh>
          </geometry>
          <material>
            <script>
              <name>Gazebo/DarkGrey</name>
              <uri>file://media/materials/scripts/gazebo.material</uri>
            </script>
          </material>
        </visual>
        <self_collide>0</self_collide>
        <enable_wind>0</enable_wind>
        <kinematic>0</kinematic>
      </link>
      <joint name='arm_right_4_joint' type='revolute'>
        <pose relative_to='arm_right_3_link'>0 0.02 0.18 3.14159 1.57079 3.14159</pose>
        <parent>arm_right_3_link</parent>
        <child>arm_right_4_link</child>
        <axis>
          <xyz>0 0 1</xyz>
          <limit>
            <lower>-2.43997</lower>
            <upper>1.10008</upper>
            <effort>26</effort>
            <velocity>2.35</velocity>
          </limit>
          <dynamics>
            <damping>1</damping>
            <friction>1</friction>
            <spring_reference>0</spring_reference>
            <spring_stiffness>0</spring_stiffness>
          </dynamics>
        </axis>
        <physics>
          <ode>
            <implicit_spring_damper>1</implicit_spring_damper>
            <cfm_damping>1</cfm_damping>
            <limit>
              <cfm>0</cfm>
              <erp>0.2</erp>
            </limit>
          </ode>
        </physics>
      </joint>
      <link name='arm_right_4_link'>
        <pose relative_to='arm_right_4_joint'>0 0 0 0 -0 0</pose>
        <inertial>
          <pose>-0.11649 -0.017864 0.005377 0 -0 0</pose>
          <mass>0.99204</mass>
          <inertia>
            <ixx>0.00077294</ixx>
            <ixy>-0.00011001</ixy>
            <ixz>-0.00016136</ixz>
            <iyy>0.0014605</iyy>
            <iyz>-1.3224e-05</iyz>
            <izz>0.0015605</izz>
          </inertia>
        </inertial>
        <collision name='arm_right_4_link_collision'>
          <pose>0 0 0 0 -0 0</pose>
          <geometry>
            <mesh>
              <scale>1 1 1</scale>
              <uri>model://pal_sea_arm_description/meshes/arm_tiago_pro/arm_4_link_collision.stl</uri>
            </mesh>
          </geometry>
          <surface>
            <contact>
              <ode/>
            </contact>
            <friction>
              <ode>
                <mu>0.9</mu>
                <mu2>0.9</mu2>
              </ode>
              <torsional>
                <ode/>
              </torsional>
            </friction>
            <bounce/>
          </surface>
          <max_contacts>10</max_contacts>
        </collision>
        <visual name='arm_right_4_link_visual'>
          <pose>0 0 0 0 -0 0</pose>
          <geometry>
            <mesh>
              <scale>1 1 1</scale>
              <uri>model://pal_sea_arm_description/meshes/arm_tiago_pro/arm_4_link.stl</uri>
            </mesh>
          </geometry>
          <material>
            <script>
              <name>Gazebo/DarkGrey</name>
              <uri>file://media/materials/scripts/gazebo.material</uri>
            </script>
          </material>
        </visual>
        <self_collide>0</self_collide>
        <enable_wind>0</enable_wind>
        <kinematic>0</kinematic>
      </link>
      <joint name='arm_right_5_joint' type='revolute'>
        <pose relative_to='arm_right_4_link'>-0.15 -0.02 0 3.14159 -1.57079 3.14159</pose>
        <parent>arm_right_4_link</parent>
        <child>arm_right_5_link</child>
        <axis>
          <xyz>0 0 1</xyz>
          <limit>
            <lower>-2.60002</lower>
            <upper>2.60002</upper>
            <effort>26</effort>
            <velocity>2.35</velocity>
          </limit>
          <dynamics>
            <damping>1</damping>
            <friction>1</friction>
            <spring_reference>0</spring_reference>
            <spring_stiffness>0</spring_stiffness>
          </dynamics>
        </axis>
        <physics>
          <ode>
            <implicit_spring_damper>1</implicit_spring_damper>
            <cfm_damping>1</cfm_damping>
            <limit>
              <cfm>0</cfm>
              <erp>0.2</erp>
            </limit>
          </ode>
        </physics>
      </joint>
      <link name='arm_right_5_link'>
        <pose relative_to='arm_right_5_joint'>0 0 0 0 -0 0</pose>
        <inertial>
          <pose>0.000486 0.000143 0.129 0 -0 0</pose>
          <mass>0.52538</mass>
          <inertia>
            <ixx>0.0019111</ixx>
            <ixy>-1.4245e-08</ixy>
            <ixz>3.8663e-05</ixz>
            <iyy>0.0018565</iyy>
            <iyz>1.1356e-06</iyz>
            <izz>0.00046496</izz>
          </inertia>
        </inertial>
        <collision name='arm_right_5_link_collision'>
          <pose>0 0 0 0 -0 0</pose>
          <geometry>
            <mesh>
              <scale>1 1 1</scale>
              <uri>model://pal_sea_arm_description/meshes/arm_tiago_pro/arm_5_link_collision.stl</uri>
            </mesh>
          </geometry>
          <surface>
            <contact>
              <ode/>
            </contact>
            <friction>
              <ode>
                <mu>0.9</mu>
                <mu2>0.9</mu2>
              </ode>
              <torsional>
                <ode/>
              </torsional>
            </friction>
            <bounce/>
          </surface>
          <max_contacts>10</max_contacts>
        </collision>
        <visual name='arm_right_5_link_visual'>
          <pose>0 0 0 0 -0 0</pose>
          <geometry>
            <mesh>
              <scale>1 1 1</scale>
              <uri>model://pal_sea_arm_description/meshes/arm_tiago_pro/arm_5_link.stl</uri>
            </mesh>
          </geometry>
          <material>
            <script>
              <name>Gazebo/DarkGrey</name>
              <uri>file://media/materials/scripts/gazebo.material</uri>
            </script>
          </material>
        </visual>
        <self_collide>0</self_collide>
        <enable_wind>0</enable_wind>
        <kinematic>0</kinematic>
      </link>
      <joint name='arm_right_6_joint' type='revolute'>
        <pose relative_to='arm_right_5_link'>0 0 0.185 3.14159 1.57079 3.14159</pose>
        <parent>arm_right_5_link</parent>
        <child>arm_right_6_link</child>
        <axis>
          <xyz>0 0 1</xyz>
          <limit>
            <lower>-1.99997</lower>
            <upper>1.99997</upper>
            <effort>26</effort>
            <velocity>2.35</velocity>
          </limit>
          <dynamics>
            <damping>1</damping>
            <friction>1</friction>
            <spring_reference>0</spring_reference>
            <spring_stiffness>0</spring_stiffness>
          </dynamics>
        </axis>
        <physics>
          <ode>
            <implicit_spring_damper>1</implicit_spring_damper>
            <cfm_damping>1</cfm_damping>
            <limit>
              <cfm>0</cfm>
              <erp>0.2</erp>
            </limit>
          </ode>
        </physics>
      </joint>
      <link name='arm_right_6_link'>
        <pose relative_to='arm_right_6_joint'>0 0 0 0 -0 0</pose>
        <inertial>
          <pose>-0.086822 -8e-06 0.004526 0 -0 0</pose>
          <mass>0.66725</mass>
          <inertia>
            <ixx>0.00035696</ixx>
            <ixy>1.6019e-07</ixy>
            <ixz>-9.5191e-05</ixz>
            <iyy>0.00073846</iyy>
            <iyz>2.118e-08</iyz>
            <izz>0.00075321</izz>
          </inertia>
        </inertial>
        <collision name='arm_right_6_link_collision'>
          <pose>0 0 0 0 -0 0</pose>
          <geometry>
            <mesh>
              <scale>1 1 1</scale>
              <uri>model://pal_sea_arm_description/meshes/arm_tiago_pro/arm_6_link_collision.stl</uri>
            </mesh>
          </geometry>
          <surface>
            <contact>
              <ode/>
            </contact>
            <friction>
              <ode>
                <mu>0.9</mu>
                <mu2>0.9</mu2>
              </ode>
              <torsional>
                <ode/>
              </torsional>
            </friction>
            <bounce/>
          </surface>
          <max_contacts>10</max_contacts>
        </collision>
        <visual name='arm_right_6_link_visual'>
          <pose>0 0 0 0 -0 0</pose>
          <geometry>
            <mesh>
              <scale>1 1 1</scale>
              <uri>model://pal_sea_arm_description/meshes/arm_tiago_pro/arm_6_link.stl</uri>
            </mesh>
          </geometry>
          <material>
            <script>
              <name>Gazebo/DarkGrey</name>
              <uri>file://media/materials/scripts/gazebo.material</uri>
            </script>
          </material>
        </visual>
        <self_collide>0</self_collide>
        <enable_wind>0</enable_wind>
        <kinematic>0</kinematic>
      </link>
      <joint name='arm_right_7_joint' type='revolute'>
        <pose relative_to='arm_right_6_link'>-0.1166 0 0 3.14159 -1.57079 3.14159</pose>
        <parent>arm_right_6_link</parent>
        <child>arm_right_7_link</child>
        <axis>
          <xyz>0 0 1</xyz>
          <limit>
            <lower>-2.60002</lower>
            <upper>2.60002</upper>
            <effort>26</effort>
            <velocity>2.35</velocity>
          </limit>
          <dynamics>
            <damping>1</damping>
            <friction>1</friction>
            <spring_reference>0</spring_reference>
            <spring_stiffness>0</spring_stiffness>
          </dynamics>
        </axis>
        <physics>
          <provide_feedback>1</provide_feedback>
          <ode>
            <implicit_spring_damper>1</implicit_spring_damper>
            <cfm_damping>1</cfm_damping>
            <limit>
              <cfm>0</cfm>
              <erp>0.2</erp>
            </limit>
            <provide_feedback>1</provide_feedback>
          </ode>
        </physics>
      </joint>
      <link name='arm_right_7_link'>
        <pose relative_to='arm_right_7_joint'>0 0 0 0 -0 0</pose>
        <inertial>
          <pose>7.2e-05 0.000608 0.08376 0 -0 0</pose>
          <mass>1.21226</mass>
          <inertia>
            <ixx>0.00249211</ixx>
            <ixy>-5.0396e-06</ixy>
            <ixz>2.53757e-06</ixz>
            <iyy>0.00246185</iyy>
            <iyz>5.27397e-05</iyz>
            <izz>0.000820829</izz>
          </inertia>
        </inertial>
        <collision name='arm_right_7_link_collision'>
          <pose>0 0 0 0 -0 0</pose>
          <geometry>
            <mesh>
              <scale>1 1 1</scale>
              <uri>model://pal_sea_arm_description/meshes/arm_tiago_pro/arm_7_link_collision.stl</uri>
            </mesh>
          </geometry>
          <surface>
            <contact>
              <ode/>
            </contact>
            <friction>
              <ode>
                <mu>0.9</mu>
                <mu2>0.9</mu2>
              </ode>
              <torsional>
                <ode/>
              </torsional>
            </friction>
            <bounce/>
          </surface>
          <max_contacts>10</max_contacts>
        </collision>
        <collision name='arm_right_7_link_fixed_joint_lump__arm_right_tool_link_collision_1'>
          <pose>0 0 0.0194 0 -0 1.5708</pose>
          <geometry>
            <cylinder>
              <length>0.01</length>
              <radius>0.032</radius>
            </cylinder>
          </geometry>
          <max_contacts>10</max_contacts>
          <surface>
            <contact>
              <ode/>
            </contact>
            <bounce/>
            <friction>
              <torsional>
                <ode/>
              </torsional>
              <ode/>
            </friction>
          </surface>
        </collision>
        <collision name='arm_right_7_link_fixed_joint_lump__wrist_right_ft_link_collision_2'>
          <pose>0 0 0.0334 0 -0 0.785398</pose>
          <geometry>
            <cylinder>
              <length>0.05</length>
              <radius>0.035</radius>
            </cylinder>
          </geometry>
          <surface>
            <contact>
              <ode/>
            </contact>
            <friction>
              <ode>
                <mu>0.9</mu>
                <mu2>0.9</mu2>
              </ode>
              <torsional>
                <ode/>
              </torsional>
            </friction>
            <bounce/>
          </surface>
          <max_contacts>10</max_contacts>
        </collision>
        <collision name='arm_right_7_link_fixed_joint_lump__wrist_right_ft_link_collision_3'>
          <pose>0.016971 0.032527 0.0284 0 -0 1.22173</pose>
          <geometry>
            <box>
              <size>0.0395 0.0496 0.053</size>
            </box>
          </geometry>
          <surface>
            <contact>
              <ode/>
            </contact>
            <friction>
              <ode>
                <mu>0.9</mu>
                <mu2>0.9</mu2>
              </ode>
              <torsional>
                <ode/>
              </torsional>
            </friction>
            <bounce/>
          </surface>
          <max_contacts>10</max_contacts>
        </collision>
        <collision name='arm_right_7_link_fixed_joint_lump__wrist_right_ft_tool_link_collision_4'>
          <pose>0 0 0.0694 0 -0 1.5708</pose>
          <geometry>
            <cylinder>
              <length>0.01</length>
              <radius>0.032</radius>
            </cylinder>
          </geometry>
          <max_contacts>10</max_contacts>
          <surface>
            <contact>
              <ode/>
            </contact>
            <bounce/>
            <friction>
              <torsional>
                <ode/>
              </torsional>
              <ode/>
            </friction>
          </surface>
        </collision>
        <collision name='arm_right_7_link_fixed_joint_lump__gripper_right_base_link_collision_5'>
          <pose>0 0 0.1204 0 -0 1.5708</pose>
          <geometry>
            <mesh>
              <scale>1 1 1</scale>
              <uri>model://pal_pro_gripper_description/meshes/base_link.stl</uri>
            </mesh>
          </geometry>
          <surface>
            <contact>
              <ode/>
            </contact>
            <friction>
              <ode>
                <mu>0.9</mu>
                <mu2>0.9</mu2>
              </ode>
              <torsional>
                <ode/>
              </torsional>
            </friction>
            <bounce/>
          </surface>
          <max_contacts>10</max_contacts>
        </collision>
        <visual name='arm_right_7_link_visual'>
          <pose>0 0 0 0 -0 0</pose>
          <geometry>
            <mesh>
              <scale>1 1 1</scale>
              <uri>model://pal_sea_arm_description/meshes/arm_tiago_pro/arm_7_link.stl</uri>
            </mesh>
          </geometry>
          <material>
            <script>
              <name>Gazebo/DarkGrey</name>
              <uri>file://media/materials/scripts/gazebo.material</uri>
            </script>
          </material>
        </visual>
        <visual name='arm_right_7_link_fixed_joint_lump__arm_right_tool_link_visual_1'>
          <pose>0 0 0.0194 0 -0 1.5708</pose>
          <geometry>
            <cylinder>
              <length>0.01</length>
              <radius>0.032</radius>
            </cylinder>
          </geometry>
        </visual>
        <visual name='arm_right_7_link_fixed_joint_lump__wrist_right_ft_link_visual_2'>
          <pose>0 0 0.0634 0 -0 0.785398</pose>
          <geometry>
            <mesh>
              <scale>1 1 1</scale>
              <uri>model://pal_sea_arm_description/meshes/sensors/rokubi_ft_sensor.STL</uri>
            </mesh>
          </geometry>
          <material>
            <script>
              <name>Gazebo/DarkGrey</name>
              <uri>file://media/materials/scripts/gazebo.material</uri>
            </script>
          </material>
        </visual>
        <visual name='arm_right_7_link_fixed_joint_lump__wrist_right_ft_tool_link_visual_3'>
          <pose>0 0 0.0694 0 -0 1.5708</pose>
          <geometry>
            <cylinder>
              <length>0.01</length>
              <radius>0.032</radius>
            </cylinder>
          </geometry>
        </visual>
        <visual name='arm_right_7_link_fixed_joint_lump__gripper_right_base_link_visual_4'>
          <pose>0 0 0.1204 0 -0 1.5708</pose>
          <geometry>
            <mesh>
              <scale>1 1 1</scale>
              <uri>model://pal_pro_gripper_description/meshes/base_link.stl</uri>
            </mesh>
          </geometry>
          <material>
            <script>
              <name>Gazebo/DarkGrey</name>
              <uri>file://media/materials/scripts/gazebo.material</uri>
            </script>
          </material>
        </visual>
        <self_collide>0</self_collide>
        <enable_wind>0</enable_wind>
        <kinematic>0</kinematic>
      </link>
      <joint name='gripper_right_finger_joint' type='revolute'>
        <pose relative_to='arm_right_7_link'>0 -0.0288 0.1489 1.5708 0.837758 -1.5708</pose>
        <parent>arm_right_7_link</parent>
        <child>gripper_right_outer_finger_left_link</child>
        <axis>
          <xyz>0 0 1</xyz>
          <limit>
            <lower>0</lower>
            <upper>0.925025</upper>
            <effort>0.1</effort>
            <velocity>2</velocity>
          </limit>
          <dynamics>
            <damping>0.03</damping>
            <friction>0</friction>
            <spring_reference>0</spring_reference>
            <spring_stiffness>0</spring_stiffness>
          </dynamics>
        </axis>
        <physics>
          <provide_feedback>1</provide_feedback>
          <ode>
            <implicit_spring_damper>1</implicit_spring_damper>
            <cfm_damping>1</cfm_damping>
            <limit>
              <cfm>0</cfm>
              <erp>0.2</erp>
            </limit>
            <provide_feedback>1</provide_feedback>
          </ode>
        </physics>
      </joint>
      <link name='gripper_right_outer_finger_left_link'>
        <pose relative_to='gripper_right_finger_joint'>0 0 0 0 -0 0</pose>
        <inertial>
          <pose>-0.001283 0.014397 0 0 -0 0</pose>
          <mass>0.015989</mass>
          <inertia>
            <ixx>5.9879e-06</ixx>
            <ixy>-5.2173e-07</ixy>
            <ixz>5.9144e-23</ixz>
            <iyy>4.8725e-07</iyy>
            <iyz>7.3911e-23</iyz>
            <izz>6.1497e-06</izz>
          </inertia>
        </inertial>
        <collision name='gripper_right_outer_finger_left_link_collision'>
          <pose>0 0 0 0 -0 0</pose>
          <geometry>
            <mesh>
              <scale>1 1 1</scale>
              <uri>model://pal_pro_gripper_description/meshes/outer_finger.stl</uri>
            </mesh>
          </geometry>
          <surface>
            <contact>
              <ode/>
            </contact>
            <friction>
              <ode>
                <mu>0.9</mu>
                <mu2>0.9</mu2>
              </ode>
              <torsional>
                <ode/>
              </torsional>
            </friction>
            <bounce/>
          </surface>
          <max_contacts>10</max_contacts>
        </collision>
        <visual name='gripper_right_outer_finger_left_link_visual'>
          <pose>0 0 0 0 -0 0</pose>
          <geometry>
            <mesh>
              <scale>1 1 1</scale>
              <uri>model://pal_pro_gripper_description/meshes/outer_finger.stl</uri>
            </mesh>
          </geometry>
          <material>
            <script>
              <name>Gazebo/White</name>
              <uri>file://media/materials/scripts/gazebo.material</uri>
            </script>
          </material>
        </visual>
        <self_collide>0</self_collide>
        <enable_wind>0</enable_wind>
        <kinematic>0</kinematic>
      </link>
      <joint name='gripper_right_inner_finger_left_joint' type='revolute'>
        <pose relative_to='arm_right_7_link'>0 -0.013977 0.153432 1.5708 0.837758 -1.5708</pose>
        <parent>arm_right_7_link</parent>
        <child>gripper_right_inner_finger_left_link</child>
        <axis>
          <xyz>0 0 1</xyz>
          <limit>
            <lower>0</lower>
            <upper>0.925025</upper>
            <effort>0.1</effort>
            <velocity>2</velocity>
          </limit>
          <dynamics>
            <spring_reference>0</spring_reference>
            <spring_stiffness>0</spring_stiffness>
          </dynamics>
        </axis>
      </joint>
      <link name='gripper_right_inner_finger_left_link'>
        <pose relative_to='gripper_right_inner_finger_left_joint'>0 0 0 0 -0 0</pose>
        <inertial>
          <pose>-0 0.024759 0 0 -0 0</pose>
          <mass>0.018619</mass>
          <inertia>
            <ixx>4.8806e-06</ixx>
            <ixy>-7.6762e-22</ixy>
            <ixz>1.0244e-22</ixz>
            <iyy>2.5471e-07</iyy>
            <iyz>-1.1841e-21</iyz>
            <izz>4.9573e-06</izz>
          </inertia>
        </inertial>
        <collision name='gripper_right_inner_finger_left_link_collision'>
          <pose>0 0 0 0 -0 0</pose>
          <geometry>
            <mesh>
              <scale>1 1 1</scale>
              <uri>model://pal_pro_gripper_description/meshes/inner_finger.stl</uri>
            </mesh>
          </geometry>
          <surface>
            <contact>
              <ode/>
            </contact>
            <friction>
              <ode>
                <mu>0.9</mu>
                <mu2>0.9</mu2>
              </ode>
              <torsional>
                <ode/>
              </torsional>
            </friction>
            <bounce/>
          </surface>
          <max_contacts>10</max_contacts>
        </collision>
        <visual name='gripper_right_inner_finger_left_link_visual'>
          <pose>0 0 0 0 -0 0</pose>
          <geometry>
            <mesh>
              <scale>1 1 1</scale>
              <uri>model://pal_pro_gripper_description/meshes/inner_finger.stl</uri>
            </mesh>
          </geometry>
          <material>
            <script>
              <name>Gazebo/White</name>
              <uri>file://media/materials/scripts/gazebo.material</uri>
            </script>
          </material>
        </visual>
        <self_collide>0</self_collide>
        <enable_wind>0</enable_wind>
        <kinematic>0</kinematic>
      </link>
      <joint name='gripper_right_fingertip_left_joint' type='revolute'>
        <pose relative_to='gripper_right_inner_finger_left_link'>0 0.05 0 0 -0 0.837758</pose>
        <parent>gripper_right_inner_finger_left_link</parent>
        <child>gripper_right_fingertip_left_link</child>
        <axis>
          <xyz>0 0 1</xyz>
          <limit>
            <lower>-0.925025</lower>
            <upper>0</upper>
            <effort>0.1</effort>
            <velocity>2</velocity>
          </limit>
          <dynamics>
            <spring_reference>0</spring_reference>
            <spring_stiffness>0</spring_stiffness>
          </dynamics>
        </axis>
      </joint>
      <link name='gripper_right_fingertip_left_link'>
        <pose relative_to='gripper_right_fingertip_left_joint'>0 0 0 0 -0 0</pose>
        <inertial>
          <pose>-0.0007 0.01167 0 0 -0 0</pose>
          <mass>0.03266</mass>
          <inertia>
            <ixx>3.6361e-06</ixx>
            <ixy>3.4071e-07</ixy>
            <ixz>-1.4191e-14</ixz>
            <iyy>1.707e-06</iyy>
            <iyz>-3.3433e-14</iyz>
            <izz>2.8395e-06</izz>
          </inertia>
        </inertial>
        <collision name='gripper_right_fingertip_left_link_collision'>
          <pose>0 0 0 0 -0 0</pose>
          <geometry>
            <mesh>
              <scale>1 1 1</scale>
              <uri>model://pal_pro_gripper_description/meshes/fingertip.stl</uri>
            </mesh>
          </geometry>
          <surface>
            <contact>
              <ode/>
            </contact>
            <friction>
              <ode>
                <mu>0.9</mu>
                <mu2>0.9</mu2>
              </ode>
              <torsional>
                <ode/>
              </torsional>
            </friction>
            <bounce/>
          </surface>
          <max_contacts>10</max_contacts>
        </collision>
        <visual name='gripper_right_fingertip_left_link_visual'>
          <pose>0 0 0 0 -0 0</pose>
          <geometry>
            <mesh>
              <scale>1 1 1</scale>
              <uri>model://pal_pro_gripper_description/meshes/fingertip.stl</uri>
            </mesh>
          </geometry>
          <material>
            <script>
              <name>Gazebo/White</name>
              <uri>file://media/materials/scripts/gazebo.material</uri>
            </script>
          </material>
        </visual>
        <self_collide>0</self_collide>
        <enable_wind>0</enable_wind>
        <kinematic>0</kinematic>
      </link>
      <joint name='gripper_right_inner_finger_right_joint' type='revolute'>
        <pose relative_to='arm_right_7_link'>0 0.013977 0.153432 1.5708 0.837758 1.5708</pose>
        <parent>arm_right_7_link</parent>
        <child>gripper_right_inner_finger_right_link</child>
        <axis>
          <xyz>0 0 1</xyz>
          <limit>
            <lower>0</lower>
            <upper>0.925025</upper>
            <effort>0.1</effort>
            <velocity>2</velocity>
          </limit>
          <dynamics>
            <spring_reference>0</spring_reference>
            <spring_stiffness>0</spring_stiffness>
          </dynamics>
        </axis>
      </joint>
      <link name='gripper_right_inner_finger_right_link'>
        <pose relative_to='gripper_right_inner_finger_right_joint'>0 0 0 0 -0 0</pose>
        <inertial>
          <pose>-0 0.024759 0 0 -0 0</pose>
          <mass>0.018619</mass>
          <inertia>
            <ixx>4.8806e-06</ixx>
            <ixy>-7.6762e-22</ixy>
            <ixz>1.0244e-22</ixz>
            <iyy>2.5471e-07</iyy>
            <iyz>-1.1841e-21</iyz>
            <izz>4.9573e-06</izz>
          </inertia>
        </inertial>
        <collision name='gripper_right_inner_finger_right_link_collision'>
          <pose>0 0 0 0 -0 0</pose>
          <geometry>
            <mesh>
              <scale>1 1 1</scale>
              <uri>model://pal_pro_gripper_description/meshes/inner_finger.stl</uri>
            </mesh>
          </geometry>
          <surface>
            <contact>
              <ode/>
            </contact>
            <friction>
              <ode>
                <mu>0.9</mu>
                <mu2>0.9</mu2>
              </ode>
              <torsional>
                <ode/>
              </torsional>
            </friction>
            <bounce/>
          </surface>
          <max_contacts>10</max_contacts>
        </collision>
        <visual name='gripper_right_inner_finger_right_link_visual'>
          <pose>0 0 0 0 -0 0</pose>
          <geometry>
            <mesh>
              <scale>1 1 1</scale>
              <uri>model://pal_pro_gripper_description/meshes/inner_finger.stl</uri>
            </mesh>
          </geometry>
          <material>
            <script>
              <name>Gazebo/White</name>
              <uri>file://media/materials/scripts/gazebo.material</uri>
            </script>
          </material>
        </visual>
        <self_collide>0</self_collide>
        <enable_wind>0</enable_wind>
        <kinematic>0</kinematic>
      </link>
      <joint name='gripper_right_fingertip_right_joint' type='revolute'>
        <pose relative_to='gripper_right_inner_finger_right_link'>0 0.05 0 0 -0 0.837758</pose>
        <parent>gripper_right_inner_finger_right_link</parent>
        <child>gripper_right_fingertip_right_link</child>
        <axis>
          <xyz>0 0 1</xyz>
          <limit>
            <lower>-0.925025</lower>
            <upper>0</upper>
            <effort>0.1</effort>
            <velocity>2</velocity>
          </limit>
          <dynamics>
            <spring_reference>0</spring_reference>
            <spring_stiffness>0</spring_stiffness>
          </dynamics>
        </axis>
      </joint>
      <link name='gripper_right_fingertip_right_link'>
        <pose relative_to='gripper_right_fingertip_right_joint'>0 0 0 0 -0 0</pose>
        <inertial>
          <pose>-0.0007 0.01167 0 0 -0 0</pose>
          <mass>0.03266</mass>
          <inertia>
            <ixx>3.6361e-06</ixx>
            <ixy>3.4071e-07</ixy>
            <ixz>-1.4191e-14</ixz>
            <iyy>1.707e-06</iyy>
            <iyz>-3.3433e-14</iyz>
            <izz>2.8395e-06</izz>
          </inertia>
        </inertial>
        <collision name='gripper_right_fingertip_right_link_collision'>
          <pose>0 0 0 0 -0 0</pose>
          <geometry>
            <mesh>
              <scale>1 1 1</scale>
              <uri>model://pal_pro_gripper_description/meshes/fingertip.stl</uri>
            </mesh>
          </geometry>
          <surface>
            <contact>
              <ode/>
            </contact>
            <friction>
              <ode>
                <mu>0.9</mu>
                <mu2>0.9</mu2>
              </ode>
              <torsional>
                <ode/>
              </torsional>
            </friction>
            <bounce/>
          </surface>
          <max_contacts>10</max_contacts>
        </collision>
        <visual name='gripper_right_fingertip_right_link_visual'>
          <pose>0 0 0 0 -0 0</pose>
          <geometry>
            <mesh>
              <scale>1 1 1</scale>
              <uri>model://pal_pro_gripper_description/meshes/fingertip.stl</uri>
            </mesh>
          </geometry>
          <material>
            <script>
              <name>Gazebo/White</name>
              <uri>file://media/materials/scripts/gazebo.material</uri>
            </script>
          </material>
        </visual>
        <self_collide>0</self_collide>
        <enable_wind>0</enable_wind>
        <kinematic>0</kinematic>
      </link>
      <joint name='gripper_right_outer_finger_right_joint' type='revolute'>
        <pose relative_to='arm_right_7_link'>0 0.0288 0.1489 1.5708 0.837758 1.5708</pose>
        <parent>arm_right_7_link</parent>
        <child>gripper_right_outer_finger_right_link</child>
        <axis>
          <xyz>0 0 1</xyz>
          <limit>
            <lower>0</lower>
            <upper>0.925025</upper>
            <effort>0.1</effort>
            <velocity>2</velocity>
          </limit>
          <dynamics>
            <spring_reference>0</spring_reference>
            <spring_stiffness>0</spring_stiffness>
          </dynamics>
        </axis>
      </joint>
      <link name='gripper_right_outer_finger_right_link'>
        <pose relative_to='gripper_right_outer_finger_right_joint'>0 0 0 0 -0 0</pose>
        <inertial>
          <pose>-0.001283 0.014397 0 0 -0 0</pose>
          <mass>0.015989</mass>
          <inertia>
            <ixx>5.9879e-06</ixx>
            <ixy>-5.2173e-07</ixy>
            <ixz>5.9144e-23</ixz>
            <iyy>4.8725e-07</iyy>
            <iyz>7.3911e-23</iyz>
            <izz>6.1497e-06</izz>
          </inertia>
        </inertial>
        <collision name='gripper_right_outer_finger_right_link_collision'>
          <pose>0 0 0 0 -0 0</pose>
          <geometry>
            <mesh>
              <scale>1 1 1</scale>
              <uri>model://pal_pro_gripper_description/meshes/outer_finger.stl</uri>
            </mesh>
          </geometry>
          <surface>
            <contact>
              <ode/>
            </contact>
            <friction>
              <ode>
                <mu>0.9</mu>
                <mu2>0.9</mu2>
              </ode>
              <torsional>
                <ode/>
              </torsional>
            </friction>
            <bounce/>
          </surface>
          <max_contacts>10</max_contacts>
        </collision>
        <visual name='gripper_right_outer_finger_right_link_visual'>
          <pose>0 0 0 0 -0 0</pose>
          <geometry>
            <mesh>
              <scale>1 1 1</scale>
              <uri>model://pal_pro_gripper_description/meshes/outer_finger.stl</uri>
            </mesh>
          </geometry>
          <material>
            <script>
              <name>Gazebo/White</name>
              <uri>file://media/materials/scripts/gazebo.material</uri>
            </script>
          </material>
        </visual>
        <self_collide>0</self_collide>
        <enable_wind>0</enable_wind>
        <kinematic>0</kinematic>
      </link>
      <joint name='head_1_joint' type='revolute'>
        <pose relative_to='torso_lift_link'>0 0 0.04 0 -0 0</pose>
        <parent>torso_lift_link</parent>
        <child>head_1_link</child>
        <axis>
          <xyz>0 0 1</xyz>
          <limit>
            <lower>-0.959931</lower>
            <upper>0.959931</upper>
            <effort>5.197</effort>
            <velocity>3</velocity>
          </limit>
          <dynamics>
            <damping>0.5</damping>
            <friction>1</friction>
            <spring_reference>0</spring_reference>
            <spring_stiffness>0</spring_stiffness>
          </dynamics>
        </axis>
        <physics>
          <ode>
            <implicit_spring_damper>1</implicit_spring_damper>
            <cfm_damping>1</cfm_damping>
            <limit>
              <cfm>0</cfm>
              <erp>0.2</erp>
            </limit>
          </ode>
        </physics>
      </joint>
      <link name='head_1_link'>
        <pose relative_to='head_1_joint'>0 0 0 0 -0 0</pose>
        <inertial>
          <pose>0.013723 0.001529 0.091095 0 -0 0</pose>
          <mass>0.50253</mass>
          <inertia>
            <ixx>0.00073252</ixx>
            <ixy>-1.0801e-06</ixy>
            <ixz>-6.3715e-05</ixz>
            <iyy>0.0005861</iyy>
            <iyz>4.157e-10</iyz>
            <izz>0.00060232</izz>
          </inertia>
        </inertial>
        <collision name='head_1_link_collision'>
          <pose>0 0 0 0 -0 0</pose>
          <geometry>
            <mesh>
              <scale>1 1 1</scale>
              <uri>model://tiago_pro_description/meshes/head/head_1_link_collision.stl</uri>
            </mesh>
          </geometry>
          <surface>
            <contact>
              <ode/>
            </contact>
            <friction>
              <ode>
                <mu>0.9</mu>
                <mu2>0.9</mu2>
              </ode>
              <torsional>
                <ode/>
              </torsional>
            </friction>
            <bounce/>
          </surface>
          <max_contacts>10</max_contacts>
        </collision>
        <visual name='head_1_link_visual'>
          <pose>0 0 0 0 -0 0</pose>
          <geometry>
            <mesh>
              <scale>1 1 1</scale>
              <uri>model://tiago_pro_description/meshes/head/head_1_link.stl</uri>
            </mesh>
          </geometry>
          <material>
            <script>
              <name>Gazebo/DarkGrey</name>
              <uri>file://media/materials/scripts/gazebo.material</uri>
            </script>
          </material>
        </visual>
        <self_collide>0</self_collide>
        <enable_wind>0</enable_wind>
        <kinematic>0</kinematic>
      </link>
      <joint name='head_2_joint' type='revolute'>
        <pose relative_to='head_1_link'>0.04597 0 0.10075 1.5708 -0 0</pose>
        <parent>head_1_link</parent>
        <child>head_2_link</child>
        <axis>
          <xyz>0 0 1</xyz>
          <limit>
            <lower>-0.349066</lower>
            <upper>0.959931</upper>
            <effort>2.77</effort>
            <velocity>3</velocity>
          </limit>
          <dynamics>
            <damping>0.5</damping>
            <friction>1</friction>
            <spring_reference>0</spring_reference>
            <spring_stiffness>0</spring_stiffness>
          </dynamics>
        </axis>
        <physics>
          <ode>
            <implicit_spring_damper>1</implicit_spring_damper>
            <cfm_damping>1</cfm_damping>
            <limit>
              <cfm>0</cfm>
              <erp>0.2</erp>
            </limit>
          </ode>
        </physics>
      </joint>
      <link name='head_2_link'>
        <pose relative_to='head_2_joint'>0 0 0 0 -0 0</pose>
        <inertial>
          <pose>0.00519 0.117283 -0.000783 0 -0 0</pose>
          <mass>1.2813</mass>
          <inertia>
            <ixx>0.0104115</ixx>
            <ixy>0.000378721</ixy>
            <ixz>4.70847e-05</ixz>
            <iyy>0.00864113</iyy>
            <iyz>6.41262e-05</iyz>
            <izz>0.00398239</izz>
          </inertia>
        </inertial>
        <collision name='head_2_link_collision'>
          <pose>0 0 0 0 -0 0</pose>
          <geometry>
            <mesh>
              <scale>1 1 1</scale>
              <uri>model://tiago_pro_description/meshes/head/head_2_link_collision.stl</uri>
            </mesh>
          </geometry>
          <surface>
            <contact>
              <ode/>
            </contact>
            <friction>
              <ode>
                <mu>0.9</mu>
                <mu2>0.9</mu2>
              </ode>
              <torsional>
                <ode/>
              </torsional>
            </friction>
            <bounce/>
          </surface>
          <max_contacts>10</max_contacts>
        </collision>
        <collision name='head_2_link_fixed_joint_lump__head_front_camera_link_collision_1'>
          <pose>0.04875 0.16 0 -1.5708 0 0</pose>
          <geometry>
            <box>
              <size>0.02505 0.09 0.025</size>
            </box>
          </geometry>
          <surface>
            <contact>
              <ode>
                <kp>1e+13</kp>
                <kd>1</kd>
              </ode>
            </contact>
            <friction>
              <ode>
                <mu2>1</mu2>
                <fdir1>0 0 0</fdir1>
              </ode>
              <torsional>
                <ode/>
              </torsional>
            </friction>
            <bounce/>
          </surface>
          <max_contacts>10</max_contacts>
        </collision>
        <visual name='head_2_link_visual'>
          <pose>0 0 0 0 -0 0</pose>
          <geometry>
            <mesh>
              <scale>1 1 1</scale>
              <uri>model://tiago_pro_description/meshes/head/head_2_link.stl</uri>
            </mesh>
          </geometry>
          <material>
            <script>
              <name>Gazebo/White</name>
              <uri>file://media/materials/scripts/gazebo.material</uri>
            </script>
          </material>
        </visual>
        <visual name='head_2_link_fixed_joint_lump__head_front_camera_link_visual_1'>
          <pose>0.05305 0.16 0 3.14159 1.57079 3.14159</pose>
          <geometry>
            <mesh>
              <scale>1 1 1</scale>
              <uri>file:///opt/pal/alum/share/realsense2_description/meshes/d435.dae</uri>
            </mesh>
          </geometry>
        </visual>
        <self_collide>0</self_collide>
        <enable_wind>0</enable_wind>
        <kinematic>0</kinematic>
        <gravity>1</gravity>
        <sensor name='head_front_cameracolor' type='camera'>
          <camera name='head_front_camera'>
            <horizontal_fov>1.21126</horizontal_fov>
            <image>
              <width>640</width>
              <height>480</height>
              <format>RGB_INT8</format>
            </image>
            <clip>
              <near>0.1</near>
              <far>100</far>
            </clip>
            <noise>
              <type>gaussian</type>
              <mean>0</mean>
              <stddev>0.007</stddev>
            </noise>
          </camera>
          <always_on>1</always_on>
          <update_rate>30</update_rate>
          <visualize>1</visualize>
          <pose>0.04875 0.16 -0.0175 -1.5708 0 0</pose>
        </sensor>
        <sensor name='head_front_cameraired1' type='camera'>
          <camera name='head_front_camera'>
            <horizontal_fov>1.48702</horizontal_fov>
            <image>
              <width>1280</width>
              <height>720</height>
              <format>L_INT8</format>
            </image>
            <clip>
              <near>0.1</near>
              <far>100</far>
            </clip>
            <noise>
              <type>gaussian</type>
              <mean>0</mean>
              <stddev>0.05</stddev>
            </noise>
          </camera>
          <always_on>1</always_on>
          <update_rate>90</update_rate>
          <visualize>0</visualize>
          <pose>0.04875 0.16 -0.0175 -1.5708 0 0</pose>
        </sensor>
        <sensor name='head_front_cameraired2' type='camera'>
          <camera name='head_front_camera'>
            <horizontal_fov>1.48702</horizontal_fov>
            <image>
              <width>1280</width>
              <height>720</height>
              <format>L_INT8</format>
            </image>
            <clip>
              <near>0.1</near>
              <far>100</far>
            </clip>
            <noise>
              <type>gaussian</type>
              <mean>0</mean>
              <stddev>0.05</stddev>
            </noise>
          </camera>
          <always_on>1</always_on>
          <update_rate>90</update_rate>
          <visualize>0</visualize>
          <pose>0.04875 0.16 -0.0175 -1.5708 0 0</pose>
        </sensor>
        <sensor name='head_front_cameradepth' type='depth'>
          <camera name='head_front_camera'>
            <horizontal_fov>1.48702</horizontal_fov>
            <image>
              <width>1280</width>
              <height>720</height>
            </image>
            <clip>
              <near>0.1</near>
              <far>100</far>
            </clip>
            <noise>
              <type>gaussian</type>
              <mean>0</mean>
              <stddev>0.1</stddev>
            </noise>
          </camera>
          <always_on>1</always_on>
          <update_rate>90</update_rate>
          <visualize>0</visualize>
          <pose>0.04875 0.16 -0.0175 -1.5708 0 0</pose>
        </sensor>
      </link>
      <plugin name='gazebo_ros2_control' filename='libgazebo_ros2_control.so'>
        <parameters>/opt/pal/alum/share/tiago_pro_controller_configuration/config/gazebo_controller_manager_cfg.yaml</parameters>
      </plugin>
      <plugin name='gazebo_ros_planar_move' filename='libgazebo_ros_planar_move.so'>
        <ros>
          <remapping>cmd_vel:=mobile_base_controller/cmd_vel_unstamped</remapping>
          <remapping>odom:=mobile_base_controller/odom</remapping>
        </ros>
        <update_rate>50</update_rate>
        <publish_rate>50</publish_rate>
        <publish_odom>1</publish_odom>
        <publish_odom_tf>0</publish_odom_tf>
        <odometry_frame>odom</odometry_frame>
        <robot_base_frame>base_footprint</robot_base_frame>
        <covariance_x>0.0001</covariance_x>
        <covariance_y>0.0001</covariance_y>
        <covariance_yaw>0.01</covariance_yaw>
      </plugin>
      <static>0</static>
      <plugin name='head_front_camera' filename='librealsense_gazebo_plugin.so'>
        <prefix>head_front_camera</prefix>
        <depthUpdateRate>30.0</depthUpdateRate>
        <colorUpdateRate>30.0</colorUpdateRate>
        <infraredUpdateRate>30.0</infraredUpdateRate>
        <depthTopicName>depth/image_raw</depthTopicName>
        <colorTopicName>color/image_raw</colorTopicName>
        <infrared1TopicName>infra1/image_raw</infrared1TopicName>
        <infrared2TopicName>infra2/image_raw</infrared2TopicName>
        <colorOpticalframeName>head_front_camera_color_optical_frame</colorOpticalframeName>
        <depthOpticalframeName>head_front_camera_depth_optical_frame</depthOpticalframeName>
        <infrared1OpticalframeName>head_front_camera_infra1_ir_optical_frame</infrared1OpticalframeName>
        <infrared2OpticalframeName>head_front_camera_infra2_ir_optical_frame</infrared2OpticalframeName>
        <rangeMinDepth>0.2</rangeMinDepth>
        <rangeMaxDepth>10.0</rangeMaxDepth>
        <pointCloud>1</pointCloud>
        <pointCloudTopicName>depth/color/points</pointCloudTopicName>
        <pointCloudCutoff>0.25</pointCloudCutoff>
        <pointCloudCutoffMax>9.0</pointCloudCutoffMax>
      </plugin>
      <pose>0 0 0 0 -0 0</pose>
    </model>
    <model name='unit_box'>
      <pose>2.5935 -0.005003 0.5 0 -0 0</pose>
      <link name='link'>
        <inertial>
          <mass>1</mass>
          <inertia>
            <ixx>0.166667</ixx>
            <ixy>0</ixy>
            <ixz>0</ixz>
            <iyy>0.166667</iyy>
            <iyz>0</iyz>
            <izz>0.166667</izz>
          </inertia>
          <pose>0 0 0 0 -0 0</pose>
        </inertial>
        <collision name='collision'>
          <geometry>
            <box>
              <size>1 1 1</size>
            </box>
          </geometry>
          <max_contacts>10</max_contacts>
          <surface>
            <contact>
              <ode/>
            </contact>
            <bounce/>
            <friction>
              <torsional>
                <ode/>
              </torsional>
              <ode/>
            </friction>
          </surface>
        </collision>
        <visual name='visual'>
          <geometry>
            <box>
              <size>1 1 1</size>
            </box>
          </geometry>
          <material>
            <script>
              <name>Gazebo/Grey</name>
              <uri>file://media/materials/scripts/gazebo.material</uri>
            </script>
          </material>
        </visual>
        <self_collide>0</self_collide>
        <enable_wind>0</enable_wind>
        <kinematic>0</kinematic>
      </link>
    </model>
    <state world_name='default'>
      <sim_time>205 461000000</sim_time>
      <real_time>69 951309455</real_time>
      <wall_time>1734438616 360197018</wall_time>
      <iterations>49723</iterations>
      <model name='ground_plane'>
        <pose>0 0 0 0 -0 0</pose>
        <scale>1 1 1</scale>
        <link name='link'>
          <pose>0 0 0 0 -0 0</pose>
          <velocity>0 0 0 0 -0 0</velocity>
          <acceleration>0 0 0 0 -0 0</acceleration>
          <wrench>0 0 0 0 -0 0</wrench>
        </link>
      </model>
      <model name='tiago-pro'>
        <pose>0.089756 -0.002746 -7.2e-05 3e-06 -3e-06 -0.004823</pose>
        <scale>1 1 1</scale>
        <link name='arm_left_1_link'>
          <pose>0.15578 0.156116 0.753611 -2.0679 2e-06 -1.22652</pose>
          <velocity>9.4e-05 1e-06 -0.008972 0.000711 0.000186 -0.000403</velocity>
          <acceleration>-0.015858 0.011184 -9.21089 1.61087 0.66089 -0.876408</acceleration>
          <wrench>-0.017152 0.012096 -9.9625 0 -0 0</wrench>
        </link>
        <link name='arm_left_2_link'>
          <pose>0.295733 0.206296 0.650194 -1.5708 -0.497102 -2.79732</pose>
          <velocity>9.4e-05 1.8e-05 -0.008962 -1.5e-05 0.002181 -0.000407</velocity>
          <acceleration>-0.093298 -0.030161 -9.44924 -2.25084 0.44927 2.26473</acceleration>
          <wrench>-0.092556 -0.029921 -9.37402 0 -0 0</wrench>
        </link>
        <link name='arm_left_3_link'>
          <pose>0.42882 0.254014 0.596241 2.06781 -4.6e-05 1.91515</pose>
          <velocity>-5e-06 -3.6e-05 -0.009254 -0.000345 0.002063 -0.000221</velocity>
          <acceleration>-0.235462 -0.093011 -9.81426 -2.91475 0.935436 2.63204</acceleration>
          <wrench>-0.254676 -0.1006 -10.6151 0 -0 0</wrench>
        </link>
        <link name='arm_left_4_link'>
          <pose>0.586729 0.31065 0.527997 1.57074 -0.497007 -2.79721</pose>
          <velocity>-0.000135 -9.5e-05 -0.0096 0.000644 -0.000716 -0.000228</velocity>
          <acceleration>-0.198821 -0.076532 -9.78825 0.784245 -0.590104 -0.601593</acceleration>
          <wrench>-0.197239 -0.075923 -9.71033 0 -0 0</wrench>
        </link>
        <link name='arm_left_5_link'>
          <pose>0.701862 0.351948 0.438898 2.0678 -4.6e-05 1.91515</pose>
          <velocity>-6.2e-05 -6.4e-05 -0.009491 0.000369 -0.000813 -7.2e-05</velocity>
          <acceleration>-0.138377 -0.058224 -9.67363 0.669658 -0.621179 -0.185563</acceleration>
          <wrench>-0.0727 -0.03059 -5.08233 0 -0 0</wrench>
        </link>
        <link name='arm_left_6_link'>
          <pose>0.854932 0.406849 0.350691 1.57074 -0.497002 -2.79721</pose>
          <velocity>1.2e-05 -4.2e-05 -0.009346 -5.9e-05 0.000352 -7.4e-05</velocity>
          <acceleration>-0.132923 -0.060722 -9.66507 0.04262 0.409361 -0.107082</acceleration>
          <wrench>-0.088693 -0.040517 -6.44902 0 -0 0</wrench>
        </link>
        <link name='arm_left_7_link'>
          <pose>0.951408 0.441453 0.295097 2.06779 -4.6e-05 1.91515</pose>
          <velocity>-5e-06 -5.3e-05 -0.009382 -0.000111 0.000333 -4.2e-05</velocity>
          <acceleration>-0.153267 -0.071827 -9.70753 -0.066372 0.416031 -0.037273</acceleration>
          <wrench>-0.1858 -0.087072 -11.768 0 -0 0</wrench>
        </link>
        <link name='arm_right_1_link'>
          <pose>0.154245 -0.162241 0.75361 -2.0679 4e-06 -1.92471</pose>
          <velocity>9.7e-05 0 -0.008972 0.000756 -0.000347 -0.000423</velocity>
          <acceleration>-0.006596 0.012756 -9.21102 1.66394 -0.508649 -0.825057</acceleration>
          <wrench>-0.007134 0.013796 -9.96265 0 -0 0</wrench>
        </link>
        <link name='arm_right_2_link'>
          <pose>0.293707 -0.213768 0.650193 -1.5708 -0.497104 2.78767</pose>
          <velocity>0.00011 1.8e-05 -0.008963 0.001501 0.001641 -0.000413</velocity>
          <acceleration>-0.092222 0.031489 -9.44973 1.29896 1.38085 -0.866538</acceleration>
          <wrench>-0.091488 0.031239 -9.3745 0 -0 0</wrench>
        </link>
        <link name='arm_right_3_link'>
          <pose>0.426327 -0.262768 0.59624 2.06781 -4.6e-05 1.21696</pose>
          <velocity>0 4.4e-05 -0.009255 0.001124 0.00178 -0.00019</velocity>
          <acceleration>-0.239852 0.078853 -9.81437 1.74052 1.52234 -0.461025</acceleration>
          <wrench>-0.259424 0.085287 -10.6152 0 -0 0</wrench>
        </link>
        <link name='arm_right_4_link'>
          <pose>0.583694 -0.320893 0.527996 1.57074 -0.497008 2.78779</pose>
          <velocity>-0.000133 9.1e-05 -0.009601 0.000113 -0.000989 -0.000186</velocity>
          <acceleration>-0.199084 0.074484 -9.78832 0.614991 -1.16705 -0.604749</acceleration>
          <wrench>-0.197499 0.073891 -9.71041 0 -0 0</wrench>
        </link>
        <link name='arm_right_5_link'>
          <pose>0.698434 -0.363271 0.438896 2.0678 -4.5e-05 1.21696</pose>
          <velocity>-5.4e-05 8e-05 -0.009492 -0.000166 -0.000885 -2.3e-05</velocity>
          <acceleration>-0.138043 0.057763 -9.67399 0.160173 -0.922263 -0.203052</acceleration>
          <wrench>-0.072525 0.030348 -5.08252 0 -0 0</wrench>
        </link>
        <link name='arm_right_6_link'>
          <pose>0.850979 -0.419615 0.350689 1.57074 -0.497004 2.78779</pose>
          <velocity>2.2e-05 6.2e-05 -0.009348 0.000272 0.000275 -2.3e-05</velocity>
          <acceleration>-0.132628 0.060631 -9.6652 0.086782 0.358944 -0.042562</acceleration>
          <wrench>-0.088496 0.040456 -6.44911 0 -0 0</wrench>
        </link>
        <link name='arm_right_7_link'>
          <pose>0.947124 -0.455126 0.295095 2.06779 -4.5e-05 1.21696</pose>
          <velocity>6e-06 7.5e-05 -0.009384 0.000217 0.000295 7e-06</velocity>
          <acceleration>-0.152683 0.071809 -9.70776 0.316878 0.323646 -0.055555</acceleration>
          <wrench>-0.185091 0.087052 -11.7683 0 -0 0</wrench>
        </link>
        <link name='base_footprint'>
          <pose>0.089756 -0.002746 -7.2e-05 3e-06 -3e-06 -0.004823</pose>
          <velocity>0.000145 1e-06 0.000253 1e-06 -6.3e-05 1.3e-05</velocity>
          <acceleration>0.03265 -7e-06 0.022923 -0.000907 0.007024 0.00236</acceleration>
          <wrench>1.80891 -0.000407 1.27002 0 -0 0</wrench>
        </link>
        <link name='gripper_left_fingertip_left_link'>
          <pose>1.08981 0.491095 0.163336 -1.57088 1.07379 -2.79731</pose>
          <velocity>0.000154 -3e-06 -0.009347 -0.002428 0.00666 -3.8e-05</velocity>
          <acceleration>-0.021519 -0.028047 -9.72737 0.323618 -0.428865 -2.92288</acceleration>
          <wrench>-0.000703 -0.000916 -0.317696 0 -0 0</wrench>
        </link>
        <link name='gripper_left_fingertip_right_link'>
          <pose>1.13084 0.505809 0.243709 -1.5707 -1.07381 0.344269</pose>
          <velocity>6e-06 -5.7e-05 -0.009588 0.002857 -0.007856 -4.9e-05</velocity>
          <acceleration>-0.082408 -0.053511 -9.81308 -0.023509 1.05302 2.56387</acceleration>
          <wrench>-0.002691 -0.001748 -0.320495 0 -0 0</wrench>
        </link>
        <link name='gripper_left_inner_finger_left_link'>
          <pose>1.07208 0.484738 0.209657 -1.57084 0.386046 -2.79725</pose>
          <velocity>-3.1e-05 -6.7e-05 -0.009427 0.001414 -0.004008 -4.8e-05</velocity>
          <acceleration>-0.080512 -0.04807 -9.69126 -1.46026 1.02913 -2.70124</acceleration>
          <wrench>-0.001499 -0.000895 -0.180442 0 -0 0</wrench>
        </link>
        <link name='gripper_left_inner_finger_right_link'>
          <pose>1.08463 0.489236 0.234229 1.57055 -1.38004 -2.79699</pose>
          <velocity>-2.3e-05 -6.5e-05 -0.009432 -0.001052 0.003001 -5.1e-05</velocity>
          <acceleration>-0.145892 -0.074285 -9.81487 2.14254 0.821446 3.00837</acceleration>
          <wrench>-0.002716 -0.001383 -0.182743 0 -0 0</wrench>
        </link>
        <link name='gripper_left_outer_finger_left_link'>
          <pose>1.06168 0.481007 0.198788 -1.57084 0.386042 -2.79725</pose>
          <velocity>-3.5e-05 -6.8e-05 -0.009423 0.00019 -0.000513 -4e-05</velocity>
          <acceleration>-0.169771 -0.078307 -9.72253 0.592772 0.082314 -1.35176</acceleration>
          <wrench>-0.002714 -0.001252 -0.155453 0 -0 0</wrench>
        </link>
        <link name='gripper_left_outer_finger_right_link'>
          <pose>1.08753 0.490276 0.249419 1.57054 -1.38004 -2.79699</pose>
          <velocity>-1.8e-05 -6.3e-05 -0.009433 -0.000622 0.001772 -4.1e-05</velocity>
          <acceleration>-0.151559 -0.075857 -9.76516 1.12678 -0.638348 0.751046</acceleration>
          <wrench>-0.002423 -0.001213 -0.156135 0 -0 0</wrench>
        </link>
        <link name='gripper_right_fingertip_left_link'>
          <pose>1.08505 -0.506067 0.163334 -1.57087 1.07379 2.78769</pose>
          <velocity>0.000167 3.2e-05 -0.009349 0.002591 0.006581 3e-06</velocity>
          <acceleration>-0.019698 0.032226 -9.72756 2.36037 -0.656075 2.44741</acceleration>
          <wrench>-0.000643 0.001053 -0.317702 0 -0 0</wrench>
        </link>
        <link name='gripper_right_fingertip_right_link'>
          <pose>1.12594 -0.521176 0.243706 -1.5707 -1.07381 -0.353924</pose>
          <velocity>1.6e-05 7.9e-05 -0.009589 -0.002825 -0.007845 1.4e-05</velocity>
          <acceleration>-0.084011 0.047925 -9.81305 -2.26118 1.55624 -1.9644</acceleration>
          <wrench>-0.002744 0.001565 -0.320494 0 -0 0</wrench>
        </link>
        <link name='gripper_right_inner_finger_left_link'>
          <pose>1.06739 -0.499545 0.209654 -1.57084 0.386044 2.78774</pose>
          <velocity>-1.9e-05 9.4e-05 -0.009429 -0.001343 -0.004023 1.3e-05</velocity>
          <acceleration>-0.079032 0.050946 -9.69155 2.05721 0.868934 1.28717</acceleration>
          <wrench>-0.001472 0.000949 -0.180447 0 -0 0</wrench>
        </link>
        <link name='gripper_right_inner_finger_right_link'>
          <pose>1.07989 -0.504165 0.234226 1.57055 -1.38004 2.788</pose>
          <velocity>-1.2e-05 8.9e-05 -0.009434 0.001177 0.002948 1.6e-05</velocity>
          <acceleration>-0.146498 0.070979 -9.81485 -0.439544 0.065489 -2.72946</acceleration>
          <wrench>-0.002728 0.001322 -0.182743 0 -0 0</wrench>
        </link>
        <link name='gripper_right_outer_finger_left_link'>
          <pose>1.05702 -0.495716 0.198785 -1.57084 0.38604 2.78774</pose>
          <velocity>-2.2e-05 9.6e-05 -0.009425 -9.2e-05 -0.000546 5e-06</velocity>
          <acceleration>-0.167522 0.082678 -9.72274 -0.070055 -0.022571 0.059717</acceleration>
          <wrench>-0.002679 0.001322 -0.155457 0 -0 0</wrench>
        </link>
        <link name='gripper_right_outer_finger_right_link'>
          <pose>1.08278 -0.505234 0.249417 1.57055 -1.38004 2.788</pose>
          <velocity>-7e-06 8.6e-05 -0.009435 0.00074 0.001724 7e-06</velocity>
          <acceleration>-0.152444 0.07174 -9.76526 3.08466 -1.13053 -1.38467</acceleration>
          <wrench>-0.002437 0.001147 -0.156137 0 -0 0</wrench>
        </link>
        <link name='head_1_link'>
          <pose>0.065253 -0.00263 0.885619 3e-06 -3e-06 -0.004823</pose>
          <velocity>9e-05 -0 -0.008977 0 -6.6e-05 1.7e-05</velocity>
          <acceleration>-0.006029 -0.00064 -9.20701 -0.001522 0.005395 0.006234</acceleration>
          <wrench>-0.00303 -0.000322 -4.6268 0 -0 0</wrench>
        </link>
        <link name='head_2_link'>
          <pose>0.111222 -0.002852 0.986369 1.5708 -2e-06 -0.004823</pose>
          <velocity>8.3e-05 0 -0.008974 2e-06 0.000146 1.8e-05</velocity>
          <acceleration>0.019619 -0.000543 -9.20842 0.012204 0.472947 0.00773</acceleration>
          <wrench>0.025138 -0.000695 -11.7987 0 -0 0</wrench>
        </link>
        <link name='torso_lift_link'>
          <pose>0.065253 -0.00263 0.845619 3e-06 -3e-06 -0.004823</pose>
          <velocity>9.2e-05 -0 -0.008977 1e-06 -6.5e-05 1.4e-05</velocity>
          <acceleration>-0.008842 -0.000805 -9.20684 -0.000876 0.006848 0.002397</acceleration>
          <wrench>-0.084418 -0.007685 -87.8977 0 -0 0</wrench>
        </link>
        <link name='wheel_front_left_link'>
          <pose>0.334829 0.21925 0.076129 -1.5708 1.4e-05 -0.004823</pose>
          <velocity>0.000137 4e-06 0.000269 -8e-06 -6.3e-05 1.3e-05</velocity>
          <acceleration>0.031057 0.000444 0.020921 -0.008974 0.006404 0.002702</acceleration>
          <wrench>0.021978 0.000314 0.014805 0 -0 0</wrench>
        </link>
        <link name='wheel_front_right_link'>
          <pose>0.332676 -0.227095 0.076128 -1.5708 3.1e-05 -0.004823</pose>
          <velocity>0.000143 4e-06 0.000268 8e-06 -6.3e-05 1.3e-05</velocity>
          <acceleration>0.032055 0.000436 0.021337 0.00645 0.006479 0.002647</acceleration>
          <wrench>0.022685 0.000308 0.0151 0 -0 0</wrench>
        </link>
        <link name='wheel_rear_left_link'>
          <pose>-0.153165 0.221603 0.076128 -1.5708 4.6e-05 -0.004823</pose>
          <velocity>0.000137 -3e-06 0.000238 1e-06 -6.2e-05 1.3e-05</velocity>
          <acceleration>0.031055 -0.000709 0.024506 -0.000902 0.006647 0.002714</acceleration>
          <wrench>0.021977 -0.000502 0.017342 0 -0 0</wrench>
        </link>
        <link name='wheel_rear_right_link'>
          <pose>-0.155318 -0.224742 0.076126 -1.5708 5.4e-05 -0.004823</pose>
          <velocity>0.000143 -3e-06 0.000238 -0 -6.2e-05 1.3e-05</velocity>
          <acceleration>0.032055 -0.00071 0.024913 -0.001571 0.00672 0.002662</acceleration>
          <wrench>0.022684 -0.000502 0.01763 0 -0 0</wrench>
        </link>
      </model>
      <model name='unit_box'>
        <pose>2.59351 -0.004999 0.702356 -2e-06 -0 -0.000211</pose>
        <scale>0.369786 0.610221 1.40471</scale>
        <link name='link'>
          <pose>2.59351 -0.004999 0.702356 -2e-06 -0 -0.000211</pose>
          <velocity>0 0 0 0 -0 0</velocity>
          <acceleration>0.291513 -4.11497 2.87804 -0.414839 0.326062 -0.253537</acceleration>
          <wrench>0.291513 -4.11497 2.87804 0 -0 0</wrench>
        </link>
      </model>
      <light name='sun'>
        <pose>0 0 10 0 -0 0</pose>
      </light>
    </state>
    <gui fullscreen='0'>
      <camera name='user_camera'>
        <pose>1.53919 -4.47942 1.51198 -0 0.227643 1.7562</pose>
        <view_controller>orbit</view_controller>
        <projection_type>perspective</projection_type>
      </camera>
    </gui>
  </world>
</sdf>
